Workbook

Sheet FORMULARIO 1
A1: MINISTERIO DE ECONOMIA Y FINANZAS
A2: FORMULARIO 1: "FUENTES DE FINANCIAMIENTO DEL PROYECTO DE CONTRATO COLECTIVO"
A3: DETALLE DE INGRESOS
A5: GOBIERNO AUTÓNOMO DESCENTRALIZADO: Provincial de Loja
A6: Nº PROYECTO CONTRATO COLECTIVO: Décimo Noveno
A8: FUENTES DE FINANCIAMIENTO | C8: FINANCIAMIENTO CONTRATO COLECTIVO VIGENTE 2014 | D8: FINANCIAMIENTO CONTRATO COLECTIVO PROPUESTO 2015 | E8: FINANCIAMIENTO CONTRATO COLECTIVO PROPUESTO 2016 | F8: FINANCIAMIENTO CONTRATO COLECTIVO PROPUESTO 2017 | G8: FINANCIAMIENTO CONTRATO COLECTIVO PROPUESTO 2018 | H8: FINANCIAMIENTO CONTRATO COLECTIVO PROPUESTO 2019 | I8: OBSERVACIONES
A9: INGRESOS DE INVERSION Y CAPITAL
A10: 28 | B10: TRANSFERENCIAS Y DONACIONES INVERSION
A11: 2806 | B11: Aportes y Participaciones de Capital e Inversión del Régimen Seccional Autónomo | C11: =+'FORMULARIO 2'!C28 -> 2650827.1 | D11: =+'FORMULARIO 2'!D28 -> 2742689 | E11: =+'FORMULARIO 2'!E28 -> 2740745.7 | F11: =+'FORMULARIO 2'!F28 -> 2930353.4 | G11: =+'FORMULARIO 2'!G28 -> 2895724.2 | H11: =+'FORMULARIO 2'!H28 -> 3086266
A12: TOTAL | C12: =+C11 -> 2650827.1 | D12: =+D11 -> 2742689 | E12: =+E11 -> 2740745.7 | F12: =+F11 -> 2930353.4 | G12: =+G11 -> 2895724.2 | H12: =+H11 -> 3086266
A13: INCREMENTO PORCENTUAL | D13: 0.0347 | E13: 0.0339 | F13: 0.1054 | G13: 0.0924 | H13: 0.1643
A18: ____________________________________________________
A19: DIRECTOR FINANCIERO GAD PROVINCIAL LOJA
A20: Ing. Eduardo Aguirre Valdiviezo
A22: Loja, 24 de junio de 2019

Sheet FORMULARIO 2
A1: MINISTERIO DE ECONOMIA Y FINANZAS
A2: FORMULARIO 2: "COSTOS DEL PROYECTO DE CONTRATO COLECTIVO"
A4: GOBIERNO AUTÓNOMO DESCENTRALIZADO: Provincial de Loja
A5: Nº PROYECTO CONTRATO COLECTIVO: Proyecto décimo noveno
A7: CLASIFICADOR PRESUPUESTARIO | B7: GASTO DEL PERSONAL | C7: COSTO CONTRATO COLECTIVO VIGENTE 2014 | D7: COSTO CONTRATO COLECTIVO PROPUESTO 2015 | E7: COSTO CONTRATO COLECTIVO PROPUESTO 2016 | F7: COSTO CONTRATO COLECTIVO PROPUESTO 2017 | G7: COSTO CONTRATO COLECTIVO PROPUESTO 2018 | H7: COSTO CONTRATO COLECTIVO PROPUESTO 2019 | I7: OBSERVACIONES
A8: GASTO PERSONAL
A9: 7101 | B9: REMUNERACIONES BASICAS
A10: 710106 | B10: SALARIOS UNIFICADOS | C10: 1580916.1 | D10: 1567033.3 | E10: 1673589.2 | F10: 1766386.4 | G10: 1752619.8 | H10: 1718996.9
A11: 7102 | B11: REMUNERACIONES COMPLEMENTARIAS
A12: 710203 | B12: DECIMOTERCER SUELDO | C12: =+(C10/C31)*12 -> 87828.673 | D12: =+(D10/D31)*12 -> 88283.567 | E12: =+(E10/E31)*12 -> 88083.644 | F12: =+(F10/F31)*12 -> 88319.322 | G12: =+(G10/G31)*12 -> 88367.385 | H12: =+(H10/H31)*12 -> 87778.564
A13: 710204 | B13: DECIMOCUARTO SUELDO | C13: =340*C31 -> 73440 | D13: =354*D31 -> 75402 | E13: =366*E31 -> 83448 | F13: =375*F31 -> 90000 | G13: =386*G31 -> 91868 | H13: =394*H31 -> 92590
A14: 7103 | B14: REMUNERACIONES COMPENSATORIAS
A15: 710304 | B15: COMPENSACION POR TRANSPORTE | C15: 24792 | D15: 24665 | E15: 25362.5 | F15: 26445.5 | G15: 26470.5 | H15: 30855
A16: 710307 | B16: ALIMENTACION | C16: 198336 | D16: 197320 | E16: 202900 | F16: 211564 | G16: 213924 | H16: 246840
A17: 7104 | B17: SUBSIDIOS
A18: 710401 | B18: POR CARGAS FAMILIARES | C18: 9274.75 | D18: 9258.49 | E18: 10811.64 | F18: 11186.43 | G18: 11282.78 | H18: 11173.84
A19: 710401 | B19: POR ANTIGÜEDAD | C19: 14670.37 | D19: 18348.32 | E19: 22366.63 | F19: 27864.59 | G19: 31746.47 | H19: 38498.22
A20: 7106 | B20: APORTES A LA SEGURIDAD SOCIAL
A21: 710601 | B21: APORTE PATRONAL | C21: =ROUND(C10*12.15%,2) -> 192081.31 | D21: =ROUND(D10*12.15%,2) -> 190394.55 | E21: =ROUND(E10*12.15%,2) -> 203341.09 | F21: =ROUND(F10*12.15%,2) -> 214615.95 | G21: =ROUND(G10*12.15%,2) -> 212943.31 | H21: =ROUND(H10*12.15%,2) -> 208858.12
A22: 710602 | B22: FONDO DE RESERVA | C22: =ROUND(C10*8.33%,2) -> 131690.31 | D22: =ROUND(D10*8.33%,2) -> 130533.88 | E22: =ROUND(E10*8.33%,2) -> 139409.98 | F22: =ROUND(F10*8.33%,2) -> 147139.99 | G22: =ROUND(G10*8.33%,2) -> 145993.23 | H22: =ROUND(H10*8.33%,2) -> 143192.44
A23: 710603 | B23: FONDO DE JUBILACION PATRONAL | C23: 247746.67 | D23: 283639.82 | E23: 281538.82 | F23: 271965.82 | G23: 265160.17 | H23: 254961.71
A24: 7307 | B24: IDEMNIZACIONES
A25: 710706 | B25: BENEFICIOS POR JUBILACION | G25: 55348.56 | H25: 162521.24
A26: 7308 | B26: BIENES DE USO Y CONSUMO DE INVERSION
A27: 730802 | B27: VESTUARIO, LENCERIA Y PRENDAS DE PROTECCION | C27: 90050.91 | D27: 157810.02 | E27: 9894.19 | F27: 74865.34 | G27: 0 | H27: 90000
A28: TOTAL | C28: =SUM(C10:C27) -> 2650827.1 | D28: =SUM(D10:D27) -> 2742689 | E28: =SUM(E10:E27) -> 2740745.7 | F28: =SUM(F10:F27) -> 2930353.4 | G28: =SUM(G10:G27) -> 2895724.2 | H28: =SUM(H10:H27) -> 3086266
A29: INCREMENTO PORCENTUAL | D29: 0.0347 | E29: 0.0339 | F29: 0.1054 | G29: 0.0924 | H29: 0.1643
C31: =248-32 -> 216 | D31: =248-35 -> 213 | E31: =248-20 -> 228 | F31: =248-8 -> 240 | G31: =248-10 -> 238 | H31: =248-13 -> 235
A35: ______________________________________________________
A36: DIRECTOR FINANCIERO GAD PROVINCIAL LOJA
A37: Ing. Eduardo Aguirre Valdiviezo
A39: Loja, 24 de junio de 2019

Sheet FORMULARIO 3 
A1: MINISTERIO DE ECONOMIA Y FINANZAS
A2: FORMULARIO 3: "COMPARATIVO ENTRE REMUNERACIÓN UNIFICADA Y PROPUESTA"
A3: DISTRIBUTIVO DE SALARIO UNIFICADO DESAGREGADO POR TRABAJADOR
A5: GOBIERNO AUTÓNOMO DESCENTRALIZADO DE LA PROVINCIA DE LOJA
A6: Nº PROYECTO CONTRATO COLECTIVO DÉCIMO NOVENO
A8: CEDULA | B8: APELLIDOS Y NOMBRES | C8: No. TRABAJ | D8: GRADO DEL CARGO O PUESTO | E8: DENOMINACIÓN DEL PUESTO O CARGO DE OCUPACIÓN | F8: REMUNERACION UNIFICADA CONTRATO COLECTIVO VIGENTE 2014 | G8: REMUNERACION UNIFICADA CONTRATO COLECTIVO VIGENTE 2015 | H8: REMUNERACION UNIFICADA CONTRATO COLECTIVO VIGENTE 2016 | I8: REMUNERACION UNIFICADA CONTRATO COLECTIVO VIGENTE 2017 | J8: REMUNERACION UNIFICADA CONTRATO COLECTIVO VIGENTE 2018 | K8: REMUNERACION UNIFICADA CONTRATO COLECTIVO PROPUESTO 2019 | L8: FECHA DE INGRESO | M8: PROYECTO DE INVERSION
A9: 1712052750 | B9: ABAD RAMIREZ FABRICIO MARCELO | C9: 1 | D9: 1 | E9: AUXILIAR DE SERVICIOS | F9: 565.22 | G9: 565.22 | H9: 565.22 | I9: 565.22 | J9: 565.22 | K9: 565.22 | L9: 40709 | M9: Atención Social Matilde Hidalgo
A10: 1103496830 | B10: AGUILAR ORDOÑEZ DARWIN JAVIER | C10: =C9+1 -> 2 | D10: 6 | E10: SUPERVISOR DE VIVEROS Y ÁREAS REFORESTADAS | F10: 822.37 | G10: 822.37 | H10: 822.37 | I10: 822.37 | J10: 822.37 | K10: 822.37 | L10: 36601 | M10: Obras de Administración Directa
A11: 1102409560 | B11: AGUINSACA LOARTE MIGUEL NUMAN | C11: =C10+1 -> 3 | D11: 1 | E11: AUXILIAR DE SERVICIOS | F11: 565.22 | G11: 565.22 | H11: 565.22 | I11: 565.22 | J11: 565.22 | K11: 565.22 | L11: 40544 | M11: Obras de Administración Directa
A12: 1102809330 | B12: ALULIMA BUELE JOSE RODRIGO | C12: =C11+1 -> 4 | D12: 2 | E12: ALBAÑIL | F12: 581.22 | G12: 581.22 | H12: 581.22 | I12: 581.22 | J12: 581.22 | K12: 581.22 | L12: 40544 | M12: Vialidad y Obras Civiles
A13: 1100414141 | B13: ALVARADO MEDINA EULOGIO AMADO | C13: =C12+1 -> 5 | D13: 2 | E13: ALBAÑIL | F13: 581.22 | G13: 581.22 | H13: 581.22 | I13: 581.22 | J13: 581.22 | K13: 581.22 | L13: 40544 | M13: Vialidad y Obras Civiles
A14: 1104542905 | B14: ALVEAR CALDERON CARLOS VINICIO | C14: =C13+1 -> 6 | D14: 1 | E14: AUXILIAR DE SERVICIOS | F14: 565.22 | G14: 565.22 | H14: 565.22 | I14: 565.22 | J14: 565.22 | K14: 565.22 | L14: 40544 | M14: Obras de Administración Directa
A15: 1102900600 | B15: ALVEAR OCHOA ANGEL PATRICIO | C15: =C14+1 -> 7 | D15: 1 | E15: AYUDANTE DE ALBAÑIL | F15: 565.22 | G15: 565.22 | H15: 565.22 | I15: 565.22 | J15: 565.22 | K15: 565.22 | L15: 40544 | M15: Obras de Administración Directa
A16: 1900350123 | B16: ALVERCA ABAD FRANCLIN ERNAN | C16: =C15+1 -> 8 | D16: 2 | E16: ALBAÑIL | F16: 581.22 | G16: 581.22 | H16: 581.22 | I16: 581.22 | J16: 581.22 | K16: 581.22 | L16: 40544 | M16: Vialidad y Obras Civiles
A17: 1102749536 | B17: AMBULUDI CALERO ROOSEVELTH GEOVANNY | C17: =C16+1 -> 9 | D17: 3 | E17: CHOFER DE VEHÍCULOS LIVIANOS | F17: 876 | G17: 876 | H17: 876 | I17: 876 | J17: 876 | K17: 876 | L17: 32807 | M17: Obras de Administración Directa
A18: 1103297279 | B18: AMBULUDI PUGLLA CARLOS AURELIO | C18: =C17+1 -> 10 | D18: 4 | E18: CHOFER DE VEHÍCULOS PESADOS | F18: 620.87 | G18: 620.87 | H18: 620.87 | I18: 620.87 | J18: 620.87 | K18: 620.87 | L18: 37347 | M18: Obras de Administración Directa
A19: 1103949044 | B19: ANDRADE CHALAN YURI DANIEL | C19: =C18+1 -> 11 | D19: 1 | E19: AYUDANTE DE CULTIVOS | F19: 615.22 | G19: 615.22 | H19: 615.22 | I19: 615.22 | J19: 615.22 | K19: 615.22 | L19: 40544 | M19: Riego y Gestión Ambiental
A20: 1103530927 | B20: AREVALO CARRILLO MANUEL DE JESUS | C20: =C19+1 -> 12 | D20: 1 | E20: AYUDANTE DE CARPINTERÍA | F20: 565.22 | G20: 565.22 | H20: 565.22 | I20: 565.22 | J20: 565.22 | K20: 565.22 | L20: 40544 | M20: Obras de Administración Directa
A21: 1102091509 | B21: AREVALO FRANCO CARLOS ANTONIO | C21: =C20+1 -> 13 | D21: 3 | E21: CONSERJE CON RESIDENCIA | H21: 612 | I21: 612 | J21: 612 | K21: 612 | L21: 36923 | M21: Obras de Administración Directa (CAMBIO DE REGIMEN LABORAL - RESOLUCION N° RP-RDE-22-2016)
A22: 1104148026 | B22: ARMIJOS AMBULUDI JOSE ANTONIO | C22: =C21+1 -> 14 | D22: 1 | E22: AUXILIAR DE SERVICIOS | F22: 565.22 | G22: 565.22 | H22: 565.22 | I22: 565.22 | J22: 565.22 | K22: 565.22 | L22: 40787 | M22: Obras de Administración Directa
A23: 0703002816 | B23: ARMIJOS CHAMORRO CECILIA ANGELICA | C23: =C22+1 -> 15 | D23: 1 | E23: CONSERJE | H23: 582 | I23: 582 | J23: 582 | K23: 582 | L23: 39814 | M23: Obras de Administración Directa (CAMBIO DE REGIMEN LABORAL - RESOLUCION N° RP-RDE-22-2016)
A24: 1102374806 | B24: ARMIJOS CORDOVA FRANCO VINICIO | C24: =C23+1 -> 16 | D24: 4 | E24: CHOFER DE VEHÍCULOS PESADOS | F24: 615.22 | G24: 615.22 | H24: 615.22 | I24: 615.22 | J24: 615.22 | K24: 615.22 | L24: 40544 | M24: Obras de Administración Directa
A25: 1103166524 | B25: ASTUDILLO ESPARZA LUISA ENRIQUETA | C25: =C24+1 -> 17 | D25: 1 | E25: CONSERJE EXTERNO | F25: 565.22 | G25: 565.22 | H25: 565.22 | I25: 565.22 | J25: 565.22 | K25: 565.22 | L25: 40544 | M25: Obras de Administración Directa
A26: 1102854229 | B26: ATARIHUANA NOLIVOS INRY HECTOR | C26: =C25+1 -> 18 | D26: 1 | E26: GUARDIÁN | F26: 565.22 | G26: 565.22 | H26: 565.22 | I26: 565.22 | J26: 565.22 | K26: 565.22 | L26: 40544 | M26: Vialidad y Obras Civiles
A27: 1103021562 | B27: AUQUILLA GALAN JUAN BOLIVAR | C27: =C26+1 -> 19 | D27: 3 | E27: CONSERJE CON RESIDENCIA | F27: 598.22 | G27: 598.22 | H27: 598.22 | I27: 598.22 | J27: 598.22 | K27: 598.22 | L27: 36342 | M27: Atención Social Matilde Hidalgo
A28: 1103386668 | B28: BANEGAS BANEGAS BRAULIO BENJAMIN | C28: =C27+1 -> 20 | D28: 3 | E28: CHOFER DE VEHÍCULOS LIVIANOS | I28: 598.22 | J28: 598.22 | K28: 598.22 | L28: 40544 | M28: Desarrollo Productivo (TRASPASO DESDE DEPROSUR EP EL 01 DE ENERO DE 2017)
A29: 1104670664 | B29: BARRIGAS JARAMILLO MARCO ANTONIO | C29: =C28+1 -> 21 | D29: 1 | E29: AYUDANTE DE CULTIVOS | F29: 615.22 | G29: 615.22 | H29: 615.22 | I29: 615.22 | J29: 615.22 | K29: 615.22 | L29: 40544 | M29: Riego y Gestión Ambiental
A30: 1303281222 | B30: BAZURTO CHAVEZ NARSISO RUBEN | C30: =C29+1 -> 22 | D30: 2 | E30: ALBAÑIL | F30: 581.22 | G30: 581.22 | H30: 581.22 | I30: 581.22 | J30: 581.22 | K30: 581.22 | L30: 40544 | M30: Vialidad y Obras Civiles
A31: 0703689463 | B31: BENAVIDES ROJAS LUCIO ARTEMIO | C31: =C30+1 -> 23 | D31: 2 | E31: ALBAÑIL | F31: 581.22 | G31: 581.22 | H31: 581.22 | I31: 581.22 | J31: 581.22 | K31: 581.22 | L31: 40544 | M31: Obras de Administración Directa
A32: 1101353900 | B32: BURI LOARTE VICTOR EMILIO | C32: =C31+1 -> 24 | D32: 2 | E32: ALBAÑIL | F32: 581.22 | G32: 581.22 | H32: 581.22 | I32: 581.22 | J32: 581.22 | K32: 581.22 | L32: 40544 | M32: Obras de Administración Directa
A33: 1103559520 | B33: BUSTOS SAMANIEGO ALEX ENRIQUE | C33: =C32+1 -> 25 | D33: 1 | E33: CONSERJE EXTERNO | F33: 565.22 | G33: 565.22 | H33: 565.22 | I33: 565.22 | J33: 565.22 | K33: 565.22 | L33: 40544 | M33: Obras de Administración Directa
A34: 1103702971 | B34: CABRERA CABRERA SANTOS BENJAMIN | C34: =C33+1 -> 26 | D34: 2 | E34: ALBAÑIL | F34: 581.22 | G34: 581.22 | H34: 581.22 | I34: 581.22 | J34: 581.22 | K34: 581.22 | L34: 40544 | M34: Vialidad y Obras Civiles
A35: 1103034201 | B35: CABRERA GRANDA CESAR HUMBERTO | C35: =C34+1 -> 27 | D35: 2 | E35: ALBAÑIL | I35: 581 | J35: 581 | K35: 581 | L35: 40909 | M35: Riego y Gestión Ambiental (TRASPASO DESDE RIDRENSUR EP EL 01 DE ENERO DE 2017)
A36: 1100646353 | B36: CABRERA PARDO ROBERT FRANCISCO | C36: =C35+1 -> 28 | D36: 1 | E36: AYUDANTE DE MECÁNICA DE EQUIPO Y/O MAQUINARIA | F36: 596.82 | G36: 596.82 | H36: 596.82 | I36: 596.82 | J36: 596.82 | K36: 596.82 | L36: 40909 | M36: Obras de Administración Directa
A37: 1104389372 | B37: CAJAMARCA AMBULUDI JAIME ANTONIO | C37: =C36+1 -> 29 | D37: 1 | E37: AYUDANTE DE CULTIVOS | F37: 565.22 | G37: 565.22 | H37: 565.22 | I37: 565.22 | J37: 565.22 | K37: 565.22 | L37: 40709 | M37: Riego y Gestión Ambiental
A38: 1103934640 | B38: CALLE CARRION RONNAL FRANCISCO | C38: =C37+1 -> 30 | D38: 1 | E38: GUARDIÁN | F38: 565.22 | G38: 565.22 | H38: 565.22 | I38: 565.22 | J38: 565.22 | K38: 565.22 | L38: 40544 | M38: Vialidad y Obras Civiles
A39: 1101408217 | B39: CALVAS JORGE ENRIQUE | C39: =C38+1 -> 31 | D39: 2 | E39: PINTOR | F39: 581.22 | G39: 581.22 | H39: 581.22 | I39: 581.22 | J39: 581.22 | K39: 581.22 | L39: 38322 | M39: Vialidad y Obras Civiles
A40: 1102772413 | B40: CAMACHO CASTILLO LILIANA ELIZABETH | C40: =C39+1 -> 32 | D40: 1 | E40: CONSERJE EXTERNO | F40: 565.22 | G40: 565.22 | H40: 565.22 | I40: 565.22 | J40: 565.22 | K40: 565.22 | L40: 40909 | M40: Obras de Administración Directa
A41: 1100794245 | B41: CAMBISACA BAILON LUIS AFRANIO | C41: =C40+1 -> 33 | D41: 1 | E41: GUARDIÁN | F41: 681.97 | G41: 681.97 | H41: 681.97 | I41: 681.97 | J41: 681.97 | L41: 37469 | M41: Vialidad y Obras Civiles - SE DESVINCULO EL 31 DE JULIO DE 2018
A42: 1104195811 | B42: CAMPOVERDE ANDRADE LEONCIO DAVID | C42: =C41+1 -> 34 | D42: 1 | E42: CONSERJE EXTERNO | F42: 565.22 | G42: 565.22 | H42: 565.22 | I42: 565.22 | J42: 565.22 | K42: 565.22 | L42: 40544 | M42: Obras de Administración Directa
...

Sheet FORMULARIO 4
A1: MINISTERIO DE ECONOMIA Y FINANZAS
A2: FORMULARIO 4
A3: FLUJO PRESUPUESTARIO DE INGRESOS Y GASTOS
A5: GOBIERNO AUTÓNOMO DESCENTRALIZADO: Provincial de Loja
A7: DETALLE DE GRUPOS Y SUBGRUPOS | C7: FLUJO HISTÓRICO | H7: FLUJO PROYECTADO | J7: OBSERVACIONES
A8: Grupo y Subgrupo | B8: Descripción | C8: 2014 | D8: 2015 | E8: 2016 | F8: 2017 | G8: 2018 | H8: 2019 | I8: 2020
A9: TOTAL INGRESOS CORRIENTES (1) | C9: =+C10+C15+C20+C23+C27+C30 -> 10536290 | D9: =+D10+D15+D20+D23+D27+D30 -> 8827658.7 | E9: =+E10+E15+E20+E23+E27+E30 -> 10185824 | F9: =+F10+F15+F20+F23+F27+F30 -> 8802351.1 | G9: =+G10+G15+G20+G23+G27+G30 -> 10057107 | H9: =+H10+H15+H20+H23+H27+H30 -> 11298696 | I9: =+I10+I15+I20+I23+I27+I30 -> 11298696
A10: 11 | B10: Impuestos | C10: =SUM(C11:C14) -> 15743.09 | D10: =SUM(D11:D14) -> 19479.48 | E10: =SUM(E11:E14) -> 17063.76 | F10: =SUM(F11:F14) -> 21342.2 | G10: =SUM(G11:G14) -> 27624.72 | H10: =SUM(H11:H14) -> 20865.41 | I10: =SUM(I11:I14) -> 20865.41
A11: 1101 | B11: Sobre la Renta, Utilidades y Ganancias de Capital | C11: 0 | D11: 0 | E11: 0 | F11: 0 | G11: 0 | H11: 0 | I11: 0
A12: 1102 | B12: Sobre la propiedad | C12: 15743.09 | D12: 19479.48 | E12: 17063.76 | F12: 21342.2 | G12: 27624.72 | H12: 20865.41 | I12: 20865.41
A13: 1103 | B13: Al consumo de Bienes y Servicios | C13: 0 | D13: 0 | E13: 0 | F13: 0 | G13: 0 | H13: 0 | I13: 0
A14: 1107 | B14: Impuestos Diversos | C14: 0 | D14: 0 | E14: 0 | F14: 0 | G14: 0 | H14: 0 | I14: 0
A15: 13 | B15: Tasas y contribuciones | C15: =SUM(C16:C19) -> 21915.88 | D15: =SUM(D16:D19) -> 34937.9 | E15: =SUM(E16:E19) -> 84158.7 | F15: =SUM(F16:F19) -> 56468 | G15: =SUM(G16:G19) -> 73442.99 | H15: =SUM(H16:H19) -> 40255.3 | I15: =SUM(I16:I19) -> 40255.3
A16: 1301 | B16: Tasas generales | C16: 21915.88 | D16: 34937.9 | E16: 84158.7 | F16: 56468 | G16: 73442.99 | H16: 40255.3 | I16: 40255.3
A17: 1302 | B17: Tasas portuarias y aeroportuarias | C17: 0 | D17: 0 | E17: 0 | F17: 0 | G17: 0 | H17: 0 | I17: 0
A18: 1303 | B18: Tasas diversas | C18: 0 | D18: 0 | E18: 0 | F18: 0 | G18: 0 | H18: 0 | I18: 0
A19: 1304 | B19: Contribuciones | C19: 0 | D19: 0 | E19: 0 | F19: 0 | G19: 0 | H19: 0 | I19: 0
A20: 14 | B20: Venta de Bienes y Servicios | C20: =SUM(C21:C22) -> 2352.82 | D20: =SUM(D21:D22) -> 0 | E20: =SUM(E21:E22) -> 166.21 | F20: =SUM(F21:F22) -> 58567.58 | G20: =SUM(G21:G22) -> 245707.01 | H20: =SUM(H21:H22) -> 82999.31 | I20: =SUM(I21:I22) -> 82999.31
A21: 1402 | B21: Venta de Productos y Materiales | C21: 2105.07 | D21: 0 | E21: 0 | F21: 58567.58 | G21: 21636.52 | H21: 75943.67 | I21: 75943.67
A22: 1403 | B22: Ventas no industriales | C22: 247.75 | D22: 0 | E22: 166.21 | F22: 0 | G22: 224070.49 | H22: 7055.64 | I22: 7055.64
A23: 17 | B23: Rentas de Invesiones y Multas | C23: =SUM(C24:C26) -> 1686.76 | D23: =SUM(D24:D26) -> 2434.12 | E23: =SUM(E24:E26) -> 1160 | F23: =SUM(F24:F26) -> 22279.4 | G23: =SUM(G24:G26) -> 1489.3 | H23: =SUM(H24:H26) -> 1160 | I23: =SUM(I24:I26) -> 1160
A24: 1701 | B24: Renta de inversiones | C24: 26.76 | D24: 0 | E24: 0 | F24: 0 | G24: 0 | H24: 0 | I24: 0
A25: 1702 | B25: Renta por arrendamiento de Bienes | C25: 1660 | D25: 1520 | E25: 1160 | F25: 1517.2 | G25: 1489.3 | H25: 1160 | I25: 1160
A26: 1704 | B26: Multas | C26: 0 | D26: 914.12 | E26: 0 | F26: 20762.2 | G26: 0 | H26: 0 | I26: 0
A27: 18 | B27: Transferencias y Donaciones Corrientes | C27: =SUM(C28:C29) -> 10430444 | D27: =SUM(D28:D29) -> 8668729.9 | E27: =SUM(E28:E29) -> 9939519.5 | F27: =SUM(F28:F29) -> 8546360.2 | G27: =SUM(G28:G29) -> 9424413.8 | H27: =SUM(H28:H29) -> 11054500 | I27: =SUM(I28:I29) -> 11054500
A28: 1801 | B28: Transferencias Corrientes del Sector Publico | C28: 9798828.3 | D28: 0 | E28: 0 | F28: 6417.01 | G28: 0 | H28: 0 | I28: 0
A29: 1806 | B29: Aportes y participaciones Corrientes del régimen Seccional Autónomo | C29: 631615.38 | D29: 8668729.9 | E29: 9939519.5 | F29: 8539943.2 | G29: 9424413.8 | H29: 11054500 | I29: 11054500
A30: 19 | B30: Otros ingresos | C30: =+C31 -> 64147.51 | D30: =+D31 -> 102077.27 | E30: =+E31 -> 143755.98 | F30: =+F31 -> 97333.7 | G30: =+G31 -> 284428.99 | H30: =+H31 -> 98915.94 | I30: =+I31 -> 98915.94
A31: 1904 | B31: Otros no Operacionales | C31: 64147.51 | D31: 102077.27 | E31: 143755.98 | F31: 97333.7 | G31: 284428.99 | H31: 98915.94 | I31: 98915.94
A32: TOTAL GASTOS CORRIENTES (2) | C32: =+C33+C42+C43+C44+C45+C46 -> 4995776.9 | D32: =+D33+D42+D43+D44+D45+D46 -> 6920481.2 | E32: =+E33+E42+E43+E44+E45+E46 -> 5982372.7 | F32: =+F33+F42+F43+F44+F45+F46 -> 6051206 | G32: =+G33+G42+G43+G44+G45+G46 -> 6077631.8 | H32: =+H33+H42+H43+H44+H45+H46 -> 7718671.6 | I32: =+I33+I42+I43+I44+I45+I46 -> 7718671.6
A33: 51 | B33: Gastos en personal | C33: =SUM(C34:C41) -> 3605533.1 | D33: =SUM(D34:D41) -> 3794540.7 | E33: =SUM(E34:E41) -> 3487547.7 | F33: =SUM(F34:F41) -> 3961263.7 | G33: =SUM(G34:G41) -> 3921804 | H33: =SUM(H34:H41) -> 4951922.9 | I33: =SUM(I34:I41) -> 4951922.9
A34: 5101 | B34: Remuneraciones Básicas | C34: 2566196.7 | D34: 2587001.4 | E34: 2482429.6 | F34: 2841525.2 | G34: 2841180.1 | H34: 3452914 | I34: 3452914
A35: 5102 | B35: Remuneraciones Complementarias | C35: =214892+55126.22 -> 270018.22 | D35: =243284.26+67979.31 -> 311263.57 | E35: =221107.63+59517.46 -> 280625.09 | F35: =251414.25+67256.05 -> 318670.3 | G35: =246733.57+70370.13 -> 317103.7 | H35: =297058.81+85357.98 -> 382416.79 | I35: =297058.81+85357.98 -> 382416.79
A36: 5103 | B36: Remuneraciones Compensatorias | C36: 0 | D36: 0 | E36: 0 | F36: 0 | G36: 0 | H36: 0 | I36: 0
A37: 5104 | B37: Subsidios | C37: 0 | D37: 0 | E37: 0 | F37: 0 | G37: 0 | H37: 0 | I37: 0
A38: 5105 | B38: Remuneraciones Temporales | C38: =18494.52+14013.33+23178.46 -> 55686.31 | D38: =9304.6+273298.55+13218.64+24894.97 -> 320716.76 | E38: =711.2+103320.03+9374.43+54401.99 -> 167807.65 | F38: =3783+129396.03+17207.53+18082.43 -> 168468.99 | G38: =4855.76+81033.87+9285.32+25078.16 -> 120253.11 | H38: =72708+19462.44+13464.31 -> 105634.75 | I38: =72708+19462.44+13464.31 -> 105634.75
A39: 5106 | B39: Aportes Patronales a la Seguridad Social | C39: =302946.02+188416.05 -> 491362.07 | D39: =338757.03+212509.09 -> 551266.12 | E39: =308759.89+209446.5 -> 518206.39 | F39: =350671.1+243235.28 -> 593906.38 | G39: =345013.83+238780.61 -> 583794.44 | H39: =415211.1+294787.35 -> 709998.45 | I39: =415211.1+294787.35 -> 709998.45
A40: 5107 | B40: Indemnizaciones | C40: =81292.3+140977.45 -> 222269.75 | D40: 24292.84 | E40: =27168.12+11310.78 -> 38478.9 | F40: =13275+13889.48+11528.35 -> 38692.83 | G40: =29352.5+16923.82+13196.33 -> 59472.65 | H40: =103245.08+34893.5+162820.33 -> 300958.91 | I40: =103245.08+34893.5+162820.33 -> 300958.91
A41: 5199 | B41: Asignaciones a distribuir | C41: 0 | D41: 0 | E41: 0 | F41: 0 | G41: 0 | H41: 0 | I41: 0
A42: 53 | B42: Bienes y servicios de consumo | C42: 0 | D42: 1017489.2 | E42: 808405.93 | F42: 681827.81 | G42: 790006.61 | H42: 874708.92 | I42: 874708.92
...
