Workbook
Name ACT_INS: #REF!
Name ACT_INS: #REF!
Name Amortización_de_la_deuda_pública: #REF!
Name Bienes_de_larga_duración_propiedades_planta_y_equipo: Tabla86[84]
Name Bienes_y_servicios_de_consumo: Tabla74[53]
Name Bienes_y_servicios_para_inversión: Tabla82[73]
Name Bienes_y_servicios_para_la_producción: #REF!
Name Coordinación_de_Inteligencia_de_Información_y_Estudios_del_Trabajo: Tabla13[Coordinación_de_Inteligencia_de_Información_y_Estudios_del_Trabajo]
Name Coordinación_General_Administrativa_Financiera: Tabla4[Coordinación_General_Administrativa_Financiera]
Name Coordinación_General_de_Planificación_y_Gestión_Estratégica: Tabla20[Coordinación_General_de_Planificación_y_Gestión_Estratégica]
Name Cuentas_pendientes_por_cobrar: #REF!
Name Despacho_Ministerial: Tabla14[Despacho_Ministerial]
Name Despacho_Ministerial.: Tabla21[Despacho_Ministerial.]
Name Despacho_Ministerial_MDT: Tabla21[Despacho_Ministerial.]
Name Direcciones_Regionales_de_Trabajo_y_Servicio_Público: Tabla22[Direcciones_Regionales_de_Trabajo_y_Servicio_Público]
Name Egresos_en_personal: Tabla72[51]
Name Egresos_en_personal_para_inversión: Tabla81[71]
Name Egresos_en_personal_para_la_producción: #REF!
Name Egresos_financieros: #REF!
Name FERIADOS_2022: #REF!
Name FERIADOS_2022: #REF!
Name Financiamiento_público: #REF!
Name Impuestos: #REF!
Name Inversiones_financieras: #REF!
Name jose_perez: #REF!
Name Obligaciones_por_Ventas_Anticipadas_de_Petróleo_Derivados_y_por_Convenios_con_Entidades_del_Sector_Público_No_Financiero: #REF!
Name Obras_públicas: #REF!
Name Otros_egresos_corrientes: Tabla76[57]
Name Otros_egresos_de_inversión: Tabla84[77]
Name Otros_egresos_de_producción: #REF!
Name Otros_ingresos: #REF!
Name Otros_pasivos: Tabla92[99]
Name PAP: #REF!
Name PAP: #REF!
Name Pasivo_circulante: #REF!
Name Prestaciones_de_la_seguridad_social: #REF!
Name PRG_PRY: #REF!
Name PRG_PRY: #REF!
Name Recuperación_de_inversiones_y_de_recursos_públicos: #REF!
Name Rentas_de_inversiones_y_multas: #REF!
Name Saldos_disponibles: #REF!
Name Seguridad_social: #REF!
Name Subsecretaría_de_Calidad_en_el_Servicio_Público: Tabla9[Subsecretaría_de_Calidad_en_el_Servicio_Público]
Name Subsecretaría_de_Cualificaciones_Profesionales: Tabla15[Subsecretaría_de_Cualificaciones_Profesionales]
Name Subsecretaría_de_Empleo_y_Salarios: Tabla6[Subsecretaría_de_Empleo_y_Salarios]
Name Subsecretaría_de_Evaluación_y_Control_del_Servicio_Público: Tabla10[Subsecretaría_de_Evaluación_y_Control_del_Servicio_Público]
Name Subsecretaría_de_Fortalecimiento_del_Servicio_Público: Tabla11[Subsecretaría_de_Fortalecimiento_del_Servicio_Público]
Name Subsecretaría_de_Meritocracia_y_Desarrollo_del_Talento_Humano: Tabla12[Subsecretaría_de_Meritocracia_y_Desarrollo_del_Talento_Humano]
Name Subsecretaría_de_Políticas_y_Normas: Tabla16[Subsecretaría_de_Políticas_y_Normas]
Name Subsecretaría_de_Trabajo: Tabla7[Subsecretaría_de_Trabajo]
Name Subsecretaría_Interinstitucional_de_Servicio_Público_Trabajo_y_Empleo: Tabla17[Subsecretaría_Interinstitucional_de_Servicio_Público_Trabajo_y_Empleo]
Name Tasas_y_contribuciones: #REF!
Name Transferencias_o_donaciones_corrientes: #REF!
Name Transferencias_o_donaciones_de_capital: #REF!
Name Transferencias_o_donaciones_de_capital_e_inversión: #REF!
Name Transferencias_o_donaciones_para_inversion: Tabla85[78]
Name UNIDAD: Tabla1[UNIDADES_N2]
Name Venta_de_activos_no_financieros: #REF!
Name Ventas_anticipadas_de_petróleo_derivados_y_por_convenios_con_entidades_del_sector_público_no_financiero: #REF!
Name Ventas_de_bienes_y_servicios_de_entidades_e_ingresos_operativos_de_empresas_públicas: #REF!

Sheet PAP 2023
B1: MINISTERIO DEL TRABAJO PAP Inicial 2023
AC3: TOTALES | AD3: =SUBTOTAL(9,AD8:AD5551) -> 46253 | AE3: =SUBTOTAL(9,AE8:AE5551) -> 0 | AF3: =SUBTOTAL(9,AF8:AF5551) -> 0 | AG3: =SUBTOTAL(9,AG8:AG5551) -> 46253 | AH3: =SUBTOTAL(9,AH8:AH5551) -> 2300 | AI3: =SUBTOTAL(9,AI8:AI5551) -> 2300 | AJ3: =SUBTOTAL(9,AJ8:AJ5551) -> 2300 | AK3: =SUBTOTAL(9,AK8:AK5551) -> 2300 | ... AT3: =SUBTOTAL(9,AT8:AT5551) -> 27600
B6: ESTRUCTURA ORGANICA | E6: DESCRIPCIONES DE LA ACTIVIDAD | I6: VINCULACIÓN A LA PLANIFICACIÓN | L6: VINCULACIÓN CLASIFICACIÓN Y PLANIFICACIÓN DEL PRESUPUESTO
A7: Línea PAP | B7: UNIDAD ADMINISTRATIVA N2 (VICEMINISTERIO / DESPACHO) | C7: UNIDAD ADMINISTRATIVA N3 (SUBSECRETARÍA / COORDINACIÓN) | D7: UNIDAD ADMINISTRATIVA N4 (DIRECCIÓN TÉCNICA) | E7: COMPONENTE DEL PROYECTO | F7: DESCRIPCIÓN DE LA ACTIVIDAD | G7: METAS | H7: INDICADORES | I7: OBJETIVO NACIONAL DE DESARROLLO - O.N.D. | J7: OBJETIVO ESTRATÉGICO INSTITUCIONAL - O.E.I. | K7: OBJETIVO ESPECÍFICO | L7: IDENTIDAD OPERATIVA DESCONCENTRADA(EOD) | M7: GEOGRÁFICO | N7: PROGRAMA INSTITUCIONAL | O7: PROYECTO | P7: ACTIVIDAD INSTITUCIONAL | Q7: NUEVO-ARRASTRE | R7: PLURIANUAL | S7: CÓDIGO UNICO DE PROYECTO(CUP) | T7: POLÍTICA AMBIENTAL | U7: POLÍTICA DE IGUALDAD | V7: FUENTE | W7: COD. ORG. | X7: COD. CORRE. | Y7: NATURALEZA DEL GASTO | Z7: GRUPO GASTO | AA7: DESCRIPCIÓN GRUPO DE GASTO | AB7: ITEM | AC7: DESCRIPCIÓN ITEM | AD7: TOTAL PAP 2023 | AE7: MODIFICACIONES PAP (+) | AF7: MODIFICACIONES PAP (-) | AG7: CODIFICADO | AH7: ENERO | AI7: FEBRERO | AJ7: MARZO | AK7: ABRIL | AL7: MAYO | AM7: JUNIO | AN7: JULIO | AO7: AGOSTO | AP7: SEPTIEMBRE | AQ7: OCTUBRE | AR7: NOVIEMBRE | AS7: DICIEMBRE | AT7: TOTAL PROFORMA 2023 | AU7: CUADRE PROFORMA 2023 | AV7: OBSERVACIONES | AW7: RESPONSABLE DE ANÁLISIS
A8: 1 | B8: Despacho_Ministerial | C8: Coordinación_General_de_Planificación_y_Gestión_Estratégica | D8: Dirección_de_Servicios,_Procesos_y_Cambio_y_Cultura | E8: =IF(D8="Programa_de_Reforma_Institucional_de_la_Gestion_Publica","Fortalecimiento del marco Institucional para la Reforma",IF(D8="Programa_de_Capacitacion_en_Gestion_del_Talento_Humano","Implimentar un Programa de Capacitación en Gestión del Talento Humano", "N/A")) -> N/A | I8: Fortalecer las capacidades del Estado con énfasis en la administración de justicia y eficiencia en los procesos de regulación y control, con independencia y autonomía. | J8: Fortalecer las capacidades institucionales | K8: Incrementar la excelencia y calidad de los servicios públicos en la gestión de las Entidades del Estado. | L8: 4-Dirección_Regional_de_Trabajo_y_Servicio_Público_de_Cuenca | M8: =IF(L8="2-Dirección_Regional_de_Trabajo_y_Servicio_Público_de_Guayaquil","901",IF(L8="3-Dirección_Regional_de_Trabajo_y_Servicio_Público_de_Ambato","1801",IF(L8="4-Dirección_Regional_de_Trabajo_y_Servicio_Público_de_Cuenca","101",IF(L8="10-Dirección_Regional_de_Trabajo_y_Servicio_Público_de_Ibarra","1001",IF(L8="11-Dirección_Regional_de_Trabajo_y_Servicio_Público_de_Loja","1101",IF(L8="13-Dirección_Regional_de_Trabajo_y_Servicio_Público_de_Portoviejo","1301","1701")))))) -> 101 | N8: 001-Administracion central | O8: 000-Sin proyecto | P8: 001-Fortalecimiento institucional | Q8: Nuevo | R8: SI | S8: N/A | T8: N/A | U8: N/A | V8: 202 | W8: 0 | X8: 0 | Y8: =IF(V8=1,"Recursos fiscales",IF(V8=2,"Recursos fiscales generados por las instituciones",IF(V8=202,"Préstamos externos"))) -> Préstamos externos | Z8: 71 | AA8: =VLOOKUP($Z8,'clacificaror presupuestario'!$K$2:$L$11,2,FALSE) -> Egresos_en_personal_para_inversión | AB8: 570102 | AC8: =VLOOKUP($AB8,'clacificaror presupuestario'!$A$2:$C$506,3,FALSE) -> Tasas Generales, Impuestos, Contribuciones, Permisos, Licencias y Patentes. | AD8: 2000 | AG8: =+AD8+AE8-AF8 -> 2000 | AH8: 100 | AI8: 100 | AJ8: 100 | AK8: 100 | AL8: 100 | AM8: 100 | AN8: 100 | AO8: 100 | AP8: 100 | AQ8: 100 | AR8: 100 | AS8: 100 | AT8: =SUM(AH8:AS8) -> 1200 | AU8: =+AD8-AT8 -> 800 | AV8: =IF(B8<>"",IF(B8="","Escoger UNIDAD ADMINISTRATIVA N2 (VICEMINISTERIO / DESPACHO);",)&" "&(IF(C8="","Escoger UNIDAD ADMINISTRATIVA N3 (SUBSECRETARÍA / COORDINACIÓN);",)&" "&(IF(D8="","Escoger UNIDAD ADMINISTRATIVA N4 (DIRECCIÓN TÉCNICA);",)&" "&(IF(F8="","Colocar DESCRIPCIÓN DE LA ACTIVIDAD;",)&" "&(IF(G8="","Colocar METAS;",)&" "&(IF(H8="","Colocar INDICADORES;",)&" "&(IF(I8="","Escoger OBJETIVO NACIONAL DE DESARROLLO - O.N.D.;",)&" "&(IF(J8="","Escoger OBJETIVO ESTRATÉGICO INSTITUCIONAL - O.E.I.;",)&" "&(IF(K8="","Escoger OBJETIVO ESPECÍFICO;",)&" "&(IF(L8="","Escoger IDENTIDAD OPERATIVA DESCONCENTRADA(EOD);",)&" "&(IF(N8="","Escoger PROGRAMA INSTITUCIONAL;",)&" "&(IF(O8="","Escoger PROYECTO;",)&" "&(IF(P8="","Escoger ACTIVIDAD INSTITUCIONAL;",)&" "&(IF(Q8="","Escoger NUEVO-ARRASTRE;",)&" "&(IF(S8="","Escoger CÓDIGO UNICO DE PROYECTO(CUP);",)&" "&(IF(V8="","Escoger FUENTE;",)&" "&(IF(W8=""," Escoger COD. ORG.;",)&" "&(IF(X8="","Escoger COD. CORRE.;",)&" "&(IF(Z8="","Escoger GRUPO GASTO;",)&" "&(IF(AB8="","Escoger ITEM;",)&" "&(IF(AD8="","Colocar TOTAL PROFORMA 2023;",)))))))))))))))))))))," ") -> Colocar DESCRIPCIÓN DE LA ACTIVIDAD; Colocar METAS; Colocar INDICADORES;
B9: Despacho_Ministerial | C9: Coordinación_General_de_Planificación_y_Gestión_Estratégica | D9: Dirección_de_Servicios,_Procesos_y_Cambio_y_Cultura | E9: =IF(D9="Programa_de_Reforma_Institucional_de_la_Gestion_Publica","Fortalecimiento del marco Institucional para la Reforma",IF(D9="Programa_de_Capacitacion_en_Gestion_del_Talento_Humano","Implimentar un Programa de Capacitación en Gestión del Talento Humano", "N/A")) -> N/A | I9: Fortalecer las capacidades del Estado con énfasis en la administración de justicia y eficiencia en los procesos de regulación y control, con independencia y autonomía. | J9: Fortalecer las capacidades institucionales | K9: Incrementar la excelencia y calidad de los servicios públicos en la gestión de las Entidades del Estado. | L9: 4-Dirección_Regional_de_Trabajo_y_Servicio_Público_de_Cuenca | M9: =IF(L9="2-Dirección_Regional_de_Trabajo_y_Servicio_Público_de_Guayaquil","901",IF(L9="3-Dirección_Regional_de_Trabajo_y_Servicio_Público_de_Ambato","1801",IF(L9="4-Dirección_Regional_de_Trabajo_y_Servicio_Público_de_Cuenca","101",IF(L9="10-Dirección_Regional_de_Trabajo_y_Servicio_Público_de_Ibarra","1001",IF(L9="11-Dirección_Regional_de_Trabajo_y_Servicio_Público_de_Loja","1101",IF(L9="13-Dirección_Regional_de_Trabajo_y_Servicio_Público_de_Portoviejo","1301","1701")))))) -> 101 | N9: 001-Administracion central | O9: 000-Sin proyecto | P9: 001-Fortalecimiento institucional | Q9: Nuevo | R9: SI | S9: N/A | T9: N/A | U9: N/A | V9: 202 | W9: 0 | X9: 0 | Y9: =IF(V9=1,"Recursos fiscales",IF(V9=2,"Recursos fiscales generados por las instituciones",IF(V9=202,"Préstamos externos"))) -> Préstamos externos | Z9: 71 | AA9: =VLOOKUP($Z9,'clacificaror presupuestario'!$K$2:$L$11,2,FALSE) -> Egresos_en_personal_para_inversión | AB9: 710203 | AC9: =VLOOKUP($AB9,'clacificaror presupuestario'!$A$2:$C$506,3,FALSE) -> Decimo Tercer Sueldo | AD9: 2001 | AG9: =+AD9+AE9-AF9 -> 2001 | AH9: 100 | AI9: 100 | AJ9: 100 | AK9: 100 | AL9: 100 | AM9: 100 | AN9: 100 | AO9: 100 | AP9: 100 | AQ9: 100 | AR9: 100 | AS9: 100 | AT9: =SUM(AH9:AS9) -> 1200 | AU9: =+AD9-AT9 -> 801 | AV9: =IF(B9<>"",IF(B9="","Escoger UNIDAD ADMINISTRATIVA N2 (VICEMINISTERIO / DESPACHO);",)&" "&(IF(C9="","Escoger UNIDAD ADMINISTRATIVA N3 (SUBSECRETARÍA / COORDINACIÓN);",)&" "&(IF(D9="","Escoger UNIDAD ADMINISTRATIVA N4 (DIRECCIÓN TÉCNICA);",)&" "&(IF(F9="","Colocar DESCRIPCIÓN DE LA ACTIVIDAD;",)&" "&(IF(G9="","Colocar METAS;",)&" "&(IF(H9="","Colocar INDICADORES;",)&" "&(IF(I9="","Escoger OBJETIVO NACIONAL DE DESARROLLO - O.N.D.;",)&" "&(IF(J9="","Escoger OBJETIVO ESTRATÉGICO INSTITUCIONAL - O.E.I.;",)&" "&(IF(K9="","Escoger OBJETIVO ESPECÍFICO;",)&" "&(IF(L9="","Escoger IDENTIDAD OPERATIVA DESCONCENTRADA(EOD);",)&" "&(IF(N9="","Escoger PROGRAMA INSTITUCIONAL;",)&" "&(IF(O9="","Escoger PROYECTO;",)&" "&(IF(P9="","Escoger ACTIVIDAD INSTITUCIONAL;",)&" "&(IF(Q9="","Escoger NUEVO-ARRASTRE;",)&" "&(IF(S9="","Escoger CÓDIGO UNICO DE PROYECTO(CUP);",)&" "&(IF(V9="","Escoger FUENTE;",)&" "&(IF(W9=""," Escoger COD. ORG.;",)&" "&(IF(X9="","Escoger COD. CORRE.;",)&" "&(IF(Z9="","Escoger GRUPO GASTO;",)&" "&(IF(AB9="","Escoger ITEM;",)&" "&(IF(AD9="","Colocar TOTAL PROFORMA 2023;",)))))))))))))))))))))," ") -> Colocar DESCRIPCIÓN DE LA ACTIVIDAD; Colocar METAS; Colocar INDICADORES;
B10: Despacho_Ministerial | C10: Coordinación_General_de_Planificación_y_Gestión_Estratégica | D10: Dirección_de_Servicios,_Procesos_y_Cambio_y_Cultura | E10: =IF(D10="Programa_de_Reforma_Institucional_de_la_Gestion_Publica","Fortalecimiento del marco Institucional para la Reforma",IF(D10="Programa_de_Capacitacion_en_Gestion_del_Talento_Humano","Implimentar un Programa de Capacitación en Gestión del Talento Humano", "N/A")) -> N/A | I10: Fortalecer las capacidades del Estado con énfasis en la administración de justicia y eficiencia en los procesos de regulación y control, con independencia y autonomía. | J10: Fortalecer las capacidades institucionales | K10: Incrementar la excelencia y calidad de los servicios públicos en la gestión de las Entidades del Estado. | L10: 4-Dirección_Regional_de_Trabajo_y_Servicio_Público_de_Cuenca | M10: =IF(L10="2-Dirección_Regional_de_Trabajo_y_Servicio_Público_de_Guayaquil","901",IF(L10="3-Dirección_Regional_de_Trabajo_y_Servicio_Público_de_Ambato","1801",IF(L10="4-Dirección_Regional_de_Trabajo_y_Servicio_Público_de_Cuenca","101",IF(L10="10-Dirección_Regional_de_Trabajo_y_Servicio_Público_de_Ibarra","1001",IF(L10="11-Dirección_Regional_de_Trabajo_y_Servicio_Público_de_Loja","1101",IF(L10="13-Dirección_Regional_de_Trabajo_y_Servicio_Público_de_Portoviejo","1301","1701")))))) -> 101 | N10: 001-Administracion central | O10: 000-Sin proyecto | P10: 001-Fortalecimiento institucional | Q10: Nuevo | R10: SI | S10: N/A | T10: N/A | U10: N/A | V10: 202 | W10: 0 | X10: 0 | Y10: =IF(V10=1,"Recursos fiscales",IF(V10=2,"Recursos fiscales generados por las instituciones",IF(V10=202,"Préstamos externos"))) -> Préstamos externos | Z10: 99 | AA10: =VLOOKUP($Z10,'clacificaror presupuestario'!$K$2:$L$11,2,FALSE) -> Otros_pasivos | AB10: 570102 | AC10: =VLOOKUP($AB10,'clacificaror presupuestario'!$A$2:$C$506,3,FALSE) -> Tasas Generales, Impuestos, Contribuciones, Permisos, Licencias y Patentes. | AD10: 2002 | AG10: =+AD10+AE10-AF10 -> 2002 | AH10: 100 | AI10: 100 | AJ10: 100 | AK10: 100 | AL10: 100 | AM10: 100 | AN10: 100 | AO10: 100 | AP10: 100 | AQ10: 100 | AR10: 100 | AS10: 100 | AT10: =SUM(AH10:AS10) -> 1200 | AU10: =+AD10-AT10 -> 802 | AV10: =IF(B10<>"",IF(B10="","Escoger UNIDAD ADMINISTRATIVA N2 (VICEMINISTERIO / DESPACHO);",)&" "&(IF(C10="","Escoger UNIDAD ADMINISTRATIVA N3 (SUBSECRETARÍA / COORDINACIÓN);",)&" "&(IF(D10="","Escoger UNIDAD ADMINISTRATIVA N4 (DIRECCIÓN TÉCNICA);",)&" "&(IF(F10="","Colocar DESCRIPCIÓN DE LA ACTIVIDAD;",)&" "&(IF(G10="","Colocar METAS;",)&" "&(IF(H10="","Colocar INDICADORES;",)&" "&(IF(I10="","Escoger OBJETIVO NACIONAL DE DESARROLLO - O.N.D.;",)&" "&(IF(J10="","Escoger OBJETIVO ESTRATÉGICO INSTITUCIONAL - O.E.I.;",)&" "&(IF(K10="","Escoger OBJETIVO ESPECÍFICO;",)&" "&(IF(L10="","Escoger IDENTIDAD OPERATIVA DESCONCENTRADA(EOD);",)&" "&(IF(N10="","Escoger PROGRAMA INSTITUCIONAL;",)&" "&(IF(O10="","Escoger PROYECTO;",)&" "&(IF(P10="","Escoger ACTIVIDAD INSTITUCIONAL;",)&" "&(IF(Q10="","Escoger NUEVO-ARRASTRE;",)&" "&(IF(S10="","Escoger CÓDIGO UNICO DE PROYECTO(CUP);",)&" "&(IF(V10="","Escoger FUENTE;",)&" "&(IF(W10=""," Escoger COD. ORG.;",)&" "&(IF(X10="","Escoger COD. CORRE.;",)&" "&(IF(Z10="","Escoger GRUPO GASTO;",)&" "&(IF(AB10="","Escoger ITEM;",)&" "&(IF(AD10="","Colocar TOTAL PROFORMA 2023;",)))))))))))))))))))))," ") -> Colocar DESCRIPCIÓN DE LA ACTIVIDAD; Colocar METAS; Colocar INDICADORES;
B11: Despacho_Ministerial | C11: Coordinación_General_de_Planificación_y_Gestión_Estratégica | D11: Dirección_de_Servicios,_Procesos_y_Cambio_y_Cultura | E11: =IF(D11="Programa_de_Reforma_Institucional_de_la_Gestion_Publica","Fortalecimiento del marco Institucional para la Reforma",IF(D11="Programa_de_Capacitacion_en_Gestion_del_Talento_Humano","Implimentar un Programa de Capacitación en Gestión del Talento Humano", "N/A")) -> N/A | I11: Fortalecer las capacidades del Estado con énfasis en la administración de justicia y eficiencia en los procesos de regulación y control, con independencia y autonomía. | J11: Fortalecer las capacidades institucionales | K11: Incrementar la excelencia y calidad de los servicios públicos en la gestión de las Entidades del Estado. | L11: 4-Dirección_Regional_de_Trabajo_y_Servicio_Público_de_Cuenca | M11: =IF(L11="2-Dirección_Regional_de_Trabajo_y_Servicio_Público_de_Guayaquil","901",IF(L11="3-Dirección_Regional_de_Trabajo_y_Servicio_Público_de_Ambato","1801",IF(L11="4-Dirección_Regional_de_Trabajo_y_Servicio_Público_de_Cuenca","101",IF(L11="10-Dirección_Regional_de_Trabajo_y_Servicio_Público_de_Ibarra","1001",IF(L11="11-Dirección_Regional_de_Trabajo_y_Servicio_Público_de_Loja","1101",IF(L11="13-Dirección_Regional_de_Trabajo_y_Servicio_Público_de_Portoviejo","1301","1701")))))) -> 101 | N11: 001-Administracion central | O11: 000-Sin proyecto | P11: 001-Fortalecimiento institucional | Q11: Nuevo | R11: SI | S11: N/A | T11: N/A | U11: N/A | V11: 202 | W11: 0 | X11: 0 | Y11: =IF(V11=1,"Recursos fiscales",IF(V11=2,"Recursos fiscales generados por las instituciones",IF(V11=202,"Préstamos externos"))) -> Préstamos externos | Z11: 99 | AA11: =VLOOKUP($Z11,'clacificaror presupuestario'!$K$2:$L$11,2,FALSE) -> Otros_pasivos | AB11: 570102 | AC11: =VLOOKUP($AB11,'clacificaror presupuestario'!$A$2:$C$506,3,FALSE) -> Tasas Generales, Impuestos, Contribuciones, Permisos, Licencias y Patentes. | AD11: 2003 | AG11: =+AD11+AE11-AF11 -> 2003 | AH11: 100 | AI11: 100 | AJ11: 100 | AK11: 100 | AL11: 100 | AM11: 100 | AN11: 100 | AO11: 100 | AP11: 100 | AQ11: 100 | AR11: 100 | AS11: 100 | AT11: =SUM(AH11:AS11) -> 1200 | AU11: =+AD11-AT11 -> 803 | AV11: =IF(B11<>"",IF(B11="","Escoger UNIDAD ADMINISTRATIVA N2 (VICEMINISTERIO / DESPACHO);",)&" "&(IF(C11="","Escoger UNIDAD ADMINISTRATIVA N3 (SUBSECRETARÍA / COORDINACIÓN);",)&" "&(IF(D11="","Escoger UNIDAD ADMINISTRATIVA N4 (DIRECCIÓN TÉCNICA);",)&" "&(IF(F11="","Colocar DESCRIPCIÓN DE LA ACTIVIDAD;",)&" "&(IF(G11="","Colocar METAS;",)&" "&(IF(H11="","Colocar INDICADORES;",)&" "&(IF(I11="","Escoger OBJETIVO NACIONAL DE DESARROLLO - O.N.D.;",)&" "&(IF(J11="","Escoger OBJETIVO ESTRATÉGICO INSTITUCIONAL - O.E.I.;",)&" "&(IF(K11="","Escoger OBJETIVO ESPECÍFICO;",)&" "&(IF(L11="","Escoger IDENTIDAD OPERATIVA DESCONCENTRADA(EOD);",)&" "&(IF(N11="","Escoger PROGRAMA INSTITUCIONAL;",)&" "&(IF(O11="","Escoger PROYECTO;",)&" "&(IF(P11="","Escoger ACTIVIDAD INSTITUCIONAL;",)&" "&(IF(Q11="","Escoger NUEVO-ARRASTRE;",)&" "&(IF(S11="","Escoger CÓDIGO UNICO DE PROYECTO(CUP);",)&" "&(IF(V11="","Escoger FUENTE;",)&" "&(IF(W11=""," Escoger COD. ORG.;",)&" "&(IF(X11="","Escoger COD. CORRE.;",)&" "&(IF(Z11="","Escoger GRUPO GASTO;",)&" "&(IF(AB11="","Escoger ITEM;",)&" "&(IF(AD11="","Colocar TOTAL PROFORMA 2023;",)))))))))))))))))))))," ") -> Colocar DESCRIPCIÓN DE LA ACTIVIDAD; Colocar METAS; Colocar INDICADORES;
B12: Despacho_Ministerial | C12: Coordinación_General_de_Planificación_y_Gestión_Estratégica | D12: Dirección_de_Servicios,_Procesos_y_Cambio_y_Cultura | E12: =IF(D12="Programa_de_Reforma_Institucional_de_la_Gestion_Publica","Fortalecimiento del marco Institucional para la Reforma",IF(D12="Programa_de_Capacitacion_en_Gestion_del_Talento_Humano","Implimentar un Programa de Capacitación en Gestión del Talento Humano", "N/A")) -> N/A | I12: Fortalecer las capacidades del Estado con énfasis en la administración de justicia y eficiencia en los procesos de regulación y control, con independencia y autonomía. | J12: Fortalecer las capacidades institucionales | K12: Incrementar la excelencia y calidad de los servicios públicos en la gestión de las Entidades del Estado. | L12: 4-Dirección_Regional_de_Trabajo_y_Servicio_Público_de_Cuenca | M12: =IF(L12="2-Dirección_Regional_de_Trabajo_y_Servicio_Público_de_Guayaquil","901",IF(L12="3-Dirección_Regional_de_Trabajo_y_Servicio_Público_de_Ambato","1801",IF(L12="4-Dirección_Regional_de_Trabajo_y_Servicio_Público_de_Cuenca","101",IF(L12="10-Dirección_Regional_de_Trabajo_y_Servicio_Público_de_Ibarra","1001",IF(L12="11-Dirección_Regional_de_Trabajo_y_Servicio_Público_de_Loja","1101",IF(L12="13-Dirección_Regional_de_Trabajo_y_Servicio_Público_de_Portoviejo","1301","1701")))))) -> 101 | N12: 001-Administracion central | O12: 000-Sin proyecto | P12: 001-Fortalecimiento institucional | Q12: Nuevo | R12: SI | S12: N/A | T12: N/A | U12: N/A | V12: 202 | W12: 0 | X12: 0 | Y12: =IF(V12=1,"Recursos fiscales",IF(V12=2,"Recursos fiscales generados por las instituciones",IF(V12=202,"Préstamos externos"))) -> Préstamos externos | Z12: 99 | AA12: =VLOOKUP($Z12,'clacificaror presupuestario'!$K$2:$L$11,2,FALSE) -> Otros_pasivos | AB12: 570102 | AC12: =VLOOKUP($AB12,'clacificaror presupuestario'!$A$2:$C$506,3,FALSE) -> Tasas Generales, Impuestos, Contribuciones, Permisos, Licencias y Patentes. | AD12: 2004 | AG12: =+AD12+AE12-AF12 -> 2004 | AH12: 100 | AI12: 100 | AJ12: 100 | AK12: 100 | AL12: 100 | AM12: 100 | AN12: 100 | AO12: 100 | AP12: 100 | AQ12: 100 | AR12: 100 | AS12: 100 | AT12: =SUM(AH12:AS12) -> 1200 | AU12: =+AD12-AT12 -> 804 | AV12: =IF(B12<>"",IF(B12="","Escoger UNIDAD ADMINISTRATIVA N2 (VICEMINISTERIO / DESPACHO);",)&" "&(IF(C12="","Escoger UNIDAD ADMINISTRATIVA N3 (SUBSECRETARÍA / COORDINACIÓN);",)&" "&(IF(D12="","Escoger UNIDAD ADMINISTRATIVA N4 (DIRECCIÓN TÉCNICA);",)&" "&(IF(F12="","Colocar DESCRIPCIÓN DE LA ACTIVIDAD;",)&" "&(IF(G12="","Colocar METAS;",)&" "&(IF(H12="","Colocar INDICADORES;",)&" "&(IF(I12="","Escoger OBJETIVO NACIONAL DE DESARROLLO - O.N.D.;",)&" "&(IF(J12="","Escoger OBJETIVO ESTRATÉGICO INSTITUCIONAL - O.E.I.;",)&" "&(IF(K12="","Escoger OBJETIVO ESPECÍFICO;",)&" "&(IF(L12="","Escoger IDENTIDAD OPERATIVA DESCONCENTRADA(EOD);",)&" "&(IF(N12="","Escoger PROGRAMA INSTITUCIONAL;",)&" "&(IF(O12="","Escoger PROYECTO;",)&" "&(IF(P12="","Escoger ACTIVIDAD INSTITUCIONAL;",)&" "&(IF(Q12="","Escoger NUEVO-ARRASTRE;",)&" "&(IF(S12="","Escoger CÓDIGO UNICO DE PROYECTO(CUP);",)&" "&(IF(V12="","Escoger FUENTE;",)&" "&(IF(W12=""," Escoger COD. ORG.;",)&" "&(IF(X12="","Escoger COD. CORRE.;",)&" "&(IF(Z12="","Escoger GRUPO GASTO;",)&" "&(IF(AB12="","Escoger ITEM;",)&" "&(IF(AD12="","Colocar TOTAL PROFORMA 2023;",)))))))))))))))))))))," ") -> Colocar DESCRIPCIÓN DE LA ACTIVIDAD; Colocar METAS; Colocar INDICADORES;
B13: Despacho_Ministerial | C13: Coordinación_General_de_Planificación_y_Gestión_Estratégica | D13: Dirección_de_Servicios,_Procesos_y_Cambio_y_Cultura | E13: =IF(D13="Programa_de_Reforma_Institucional_de_la_Gestion_Publica","Fortalecimiento del marco Institucional para la Reforma",IF(D13="Programa_de_Capacitacion_en_Gestion_del_Talento_Humano","Implimentar un Programa de Capacitación en Gestión del Talento Humano", "N/A")) -> N/A | I13: Fortalecer las capacidades del Estado con énfasis en la administración de justicia y eficiencia en los procesos de regulación y control, con independencia y autonomía. | J13: Fortalecer las capacidades institucionales | K13: Incrementar la excelencia y calidad de los servicios públicos en la gestión de las Entidades del Estado. | L13: 4-Dirección_Regional_de_Trabajo_y_Servicio_Público_de_Cuenca | M13: =IF(L13="2-Dirección_Regional_de_Trabajo_y_Servicio_Público_de_Guayaquil","901",IF(L13="3-Dirección_Regional_de_Trabajo_y_Servicio_Público_de_Ambato","1801",IF(L13="4-Dirección_Regional_de_Trabajo_y_Servicio_Público_de_Cuenca","101",IF(L13="10-Dirección_Regional_de_Trabajo_y_Servicio_Público_de_Ibarra","1001",IF(L13="11-Dirección_Regional_de_Trabajo_y_Servicio_Público_de_Loja","1101",IF(L13="13-Dirección_Regional_de_Trabajo_y_Servicio_Público_de_Portoviejo","1301","1701")))))) -> 101 | N13: 001-Administracion central | O13: 000-Sin proyecto | P13: 001-Fortalecimiento institucional | Q13: Nuevo | R13: SI | S13: N/A | T13: N/A | U13: N/A | V13: 202 | W13: 0 | X13: 0 | Y13: =IF(V13=1,"Recursos fiscales",IF(V13=2,"Recursos fiscales generados por las instituciones",IF(V13=202,"Préstamos externos"))) -> Préstamos externos | Z13: 99 | AA13: =VLOOKUP($Z13,'clacificaror presupuestario'!$K$2:$L$11,2,FALSE) -> Otros_pasivos | AB13: 570102 | AC13: =VLOOKUP($AB13,'clacificaror presupuestario'!$A$2:$C$506,3,FALSE) -> Tasas Generales, Impuestos, Contribuciones, Permisos, Licencias y Patentes. | AD13: 2005 | AG13: =+AD13+AE13-AF13 -> 2005 | AH13: 100 | AI13: 100 | AJ13: 100 | AK13: 100 | AL13: 100 | AM13: 100 | AN13: 100 | AO13: 100 | AP13: 100 | AQ13: 100 | AR13: 100 | AS13: 100 | AT13: =SUM(AH13:AS13) -> 1200 | AU13: =+AD13-AT13 -> 805 | AV13: =IF(B13<>"",IF(B13="","Escoger UNIDAD ADMINISTRATIVA N2 (VICEMINISTERIO / DESPACHO);",)&" "&(IF(C13="","Escoger UNIDAD ADMINISTRATIVA N3 (SUBSECRETARÍA / COORDINACIÓN);",)&" "&(IF(D13="","Escoger UNIDAD ADMINISTRATIVA N4 (DIRECCIÓN TÉCNICA);",)&" "&(IF(F13="","Colocar DESCRIPCIÓN DE LA ACTIVIDAD;",)&" "&(IF(G13="","Colocar METAS;",)&" "&(IF(H13="","Colocar INDICADORES;",)&" "&(IF(I13="","Escoger OBJETIVO NACIONAL DE DESARROLLO - O.N.D.;",)&" "&(IF(J13="","Escoger OBJETIVO ESTRATÉGICO INSTITUCIONAL - O.E.I.;",)&" "&(IF(K13="","Escoger OBJETIVO ESPECÍFICO;",)&" "&(IF(L13="","Escoger IDENTIDAD OPERATIVA DESCONCENTRADA(EOD);",)&" "&(IF(N13="","Escoger PROGRAMA INSTITUCIONAL;",)&" "&(IF(O13="","Escoger PROYECTO;",)&" "&(IF(P13="","Escoger ACTIVIDAD INSTITUCIONAL;",)&" "&(IF(Q13="","Escoger NUEVO-ARRASTRE;",)&" "&(IF(S13="","Escoger CÓDIGO UNICO DE PROYECTO(CUP);",)&" "&(IF(V13="","Escoger FUENTE;",)&" "&(IF(W13=""," Escoger COD. ORG.;",)&" "&(IF(X13="","Escoger COD. CORRE.;",)&" "&(IF(Z13="","Escoger GRUPO GASTO;",)&" "&(IF(AB13="","Escoger ITEM;",)&" "&(IF(AD13="","Colocar TOTAL PROFORMA 2023;",)))))))))))))))))))))," ") -> Colocar DESCRIPCIÓN DE LA ACTIVIDAD; Colocar METAS; Colocar INDICADORES;
B14: Despacho_Ministerial | C14: Coordinación_General_de_Planificación_y_Gestión_Estratégica | D14: Dirección_de_Servicios,_Procesos_y_Cambio_y_Cultura | E14: =IF(D14="Programa_de_Reforma_Institucional_de_la_Gestion_Publica","Fortalecimiento del marco Institucional para la Reforma",IF(D14="Programa_de_Capacitacion_en_Gestion_del_Talento_Humano","Implimentar un Programa de Capacitación en Gestión del Talento Humano", "N/A")) -> N/A | I14: Fortalecer las capacidades del Estado con énfasis en la administración de justicia y eficiencia en los procesos de regulación y control, con independencia y autonomía. | J14: Fortalecer las capacidades institucionales | K14: Incrementar la excelencia y calidad de los servicios públicos en la gestión de las Entidades del Estado. | L14: 4-Dirección_Regional_de_Trabajo_y_Servicio_Público_de_Cuenca | M14: =IF(L14="2-Dirección_Regional_de_Trabajo_y_Servicio_Público_de_Guayaquil","901",IF(L14="3-Dirección_Regional_de_Trabajo_y_Servicio_Público_de_Ambato","1801",IF(L14="4-Dirección_Regional_de_Trabajo_y_Servicio_Público_de_Cuenca","101",IF(L14="10-Dirección_Regional_de_Trabajo_y_Servicio_Público_de_Ibarra","1001",IF(L14="11-Dirección_Regional_de_Trabajo_y_Servicio_Público_de_Loja","1101",IF(L14="13-Dirección_Regional_de_Trabajo_y_Servicio_Público_de_Portoviejo","1301","1701")))))) -> 101 | N14: 001-Administracion central | O14: 000-Sin proyecto | P14: 001-Fortalecimiento institucional | Q14: Nuevo | R14: SI | S14: N/A | T14: N/A | U14: N/A | V14: 202 | W14: 0 | X14: 0 | Y14: =IF(V14=1,"Recursos fiscales",IF(V14=2,"Recursos fiscales generados por las instituciones",IF(V14=202,"Préstamos externos"))) -> Préstamos externos | Z14: 99 | AA14: =VLOOKUP($Z14,'clacificaror presupuestario'!$K$2:$L$11,2,FALSE) -> Otros_pasivos | AB14: 570102 | AC14: =VLOOKUP($AB14,'clacificaror presupuestario'!$A$2:$C$506,3,FALSE) -> Tasas Generales, Impuestos, Contribuciones, Permisos, Licencias y Patentes. | AD14: 2006 | AG14: =+AD14+AE14-AF14 -> 2006 | AH14: 100 | AI14: 100 | AJ14: 100 | AK14: 100 | AL14: 100 | AM14: 100 | AN14: 100 | AO14: 100 | AP14: 100 | AQ14: 100 | AR14: 100 | AS14: 100 | AT14: =SUM(AH14:AS14) -> 1200 | AU14: =+AD14-AT14 -> 806 | AV14: =IF(B14<>"",IF(B14="","Escoger UNIDAD ADMINISTRATIVA N2 (VICEMINISTERIO / DESPACHO);",)&" "&(IF(C14="","Escoger UNIDAD ADMINISTRATIVA N3 (SUBSECRETARÍA / COORDINACIÓN);",)&" "&(IF(D14="","Escoger UNIDAD ADMINISTRATIVA N4 (DIRECCIÓN TÉCNICA);",)&" "&(IF(F14="","Colocar DESCRIPCIÓN DE LA ACTIVIDAD;",)&" "&(IF(G14="","Colocar METAS;",)&" "&(IF(H14="","Colocar INDICADORES;",)&" "&(IF(I14="","Escoger OBJETIVO NACIONAL DE DESARROLLO - O.N.D.;",)&" "&(IF(J14="","Escoger OBJETIVO ESTRATÉGICO INSTITUCIONAL - O.E.I.;",)&" "&(IF(K14="","Escoger OBJETIVO ESPECÍFICO;",)&" "&(IF(L14="","Escoger IDENTIDAD OPERATIVA DESCONCENTRADA(EOD);",)&" "&(IF(N14="","Escoger PROGRAMA INSTITUCIONAL;",)&" "&(IF(O14="","Escoger PROYECTO;",)&" "&(IF(P14="","Escoger ACTIVIDAD INSTITUCIONAL;",)&" "&(IF(Q14="","Escoger NUEVO-ARRASTRE;",)&" "&(IF(S14="","Escoger CÓDIGO UNICO DE PROYECTO(CUP);",)&" "&(IF(V14="","Escoger FUENTE;",)&" "&(IF(W14=""," Escoger COD. ORG.;",)&" "&(IF(X14="","Escoger COD. CORRE.;",)&" "&(IF(Z14="","Escoger GRUPO GASTO;",)&" "&(IF(AB14="","Escoger ITEM;",)&" "&(IF(AD14="","Colocar TOTAL PROFORMA 2023;",)))))))))))))))))))))," ") -> Colocar DESCRIPCIÓN DE LA ACTIVIDAD; Colocar METAS; Colocar INDICADORES;
B15: Despacho_Ministerial | C15: Coordinación_General_de_Planificación_y_Gestión_Estratégica | D15: Dirección_de_Servicios,_Procesos_y_Cambio_y_Cultura | E15: =IF(D15="Programa_de_Reforma_Institucional_de_la_Gestion_Publica","Fortalecimiento del marco Institucional para la Reforma",IF(D15="Programa_de_Capacitacion_en_Gestion_del_Talento_Humano","Implimentar un Programa de Capacitación en Gestión del Talento Humano", "N/A")) -> N/A | I15: Fortalecer las capacidades del Estado con énfasis en la administración de justicia y eficiencia en los procesos de regulación y control, con independencia y autonomía. | J15: Fortalecer las capacidades institucionales | K15: Incrementar la excelencia y calidad de los servicios públicos en la gestión de las Entidades del Estado. | L15: 4-Dirección_Regional_de_Trabajo_y_Servicio_Público_de_Cuenca | M15: =IF(L15="2-Dirección_Regional_de_Trabajo_y_Servicio_Público_de_Guayaquil","901",IF(L15="3-Dirección_Regional_de_Trabajo_y_Servicio_Público_de_Ambato","1801",IF(L15="4-Dirección_Regional_de_Trabajo_y_Servicio_Público_de_Cuenca","101",IF(L15="10-Dirección_Regional_de_Trabajo_y_Servicio_Público_de_Ibarra","1001",IF(L15="11-Dirección_Regional_de_Trabajo_y_Servicio_Público_de_Loja","1101",IF(L15="13-Dirección_Regional_de_Trabajo_y_Servicio_Público_de_Portoviejo","1301","1701")))))) -> 101 | N15: 001-Administracion central | O15: 000-Sin proyecto | P15: 001-Fortalecimiento institucional | Q15: Nuevo | R15: SI | S15: N/A | T15: N/A | U15: N/A | V15: 202 | W15: 0 | X15: 0 | Y15: =IF(V15=1,"Recursos fiscales",IF(V15=2,"Recursos fiscales generados por las instituciones",IF(V15=202,"Préstamos externos"))) -> Préstamos externos | Z15: 99 | AA15: =VLOOKUP($Z15,'clacificaror presupuestario'!$K$2:$L$11,2,FALSE) -> Otros_pasivos | AB15: 570102 | AC15: =VLOOKUP($AB15,'clacificaror presupuestario'!$A$2:$C$506,3,FALSE) -> Tasas Generales, Impuestos, Contribuciones, Permisos, Licencias y Patentes. | AD15: 2007 | AG15: =+AD15+AE15-AF15 -> 2007 | AH15: 100 | AI15: 100 | AJ15: 100 | AK15: 100 | AL15: 100 | AM15: 100 | AN15: 100 | AO15: 100 | AP15: 100 | AQ15: 100 | AR15: 100 | AS15: 100 | AT15: =SUM(AH15:AS15) -> 1200 | AU15: =+AD15-AT15 -> 807 | AV15: =IF(B15<>"",IF(B15="","Escoger UNIDAD ADMINISTRATIVA N2 (VICEMINISTERIO / DESPACHO);",)&" "&(IF(C15="","Escoger UNIDAD ADMINISTRATIVA N3 (SUBSECRETARÍA / COORDINACIÓN);",)&" "&(IF(D15="","Escoger UNIDAD ADMINISTRATIVA N4 (DIRECCIÓN TÉCNICA);",)&" "&(IF(F15="","Colocar DESCRIPCIÓN DE LA ACTIVIDAD;",)&" "&(IF(G15="","Colocar METAS;",)&" "&(IF(H15="","Colocar INDICADORES;",)&" "&(IF(I15="","Escoger OBJETIVO NACIONAL DE DESARROLLO - O.N.D.;",)&" "&(IF(J15="","Escoger OBJETIVO ESTRATÉGICO INSTITUCIONAL - O.E.I.;",)&" "&(IF(K15="","Escoger OBJETIVO ESPECÍFICO;",)&" "&(IF(L15="","Escoger IDENTIDAD OPERATIVA DESCONCENTRADA(EOD);",)&" "&(IF(N15="","Escoger PROGRAMA INSTITUCIONAL;",)&" "&(IF(O15="","Escoger PROYECTO;",)&" "&(IF(P15="","Escoger ACTIVIDAD INSTITUCIONAL;",)&" "&(IF(Q15="","Escoger NUEVO-ARRASTRE;",)&" "&(IF(S15="","Escoger CÓDIGO UNICO DE PROYECTO(CUP);",)&" "&(IF(V15="","Escoger FUENTE;",)&" "&(IF(W15=""," Escoger COD. ORG.;",)&" "&(IF(X15="","Escoger COD. CORRE.;",)&" "&(IF(Z15="","Escoger GRUPO GASTO;",)&" "&(IF(AB15="","Escoger ITEM;",)&" "&(IF(AD15="","Colocar TOTAL PROFORMA 2023;",)))))))))))))))))))))," ") -> Colocar DESCRIPCIÓN DE LA ACTIVIDAD; Colocar METAS; Colocar INDICADORES;
B16: Despacho_Ministerial | C16: Coordinación_General_de_Planificación_y_Gestión_Estratégica | D16: Dirección_de_Servicios,_Procesos_y_Cambio_y_Cultura | E16: =IF(D16="Programa_de_Reforma_Institucional_de_la_Gestion_Publica","Fortalecimiento del marco Institucional para la Reforma",IF(D16="Programa_de_Capacitacion_en_Gestion_del_Talento_Humano","Implimentar un Programa de Capacitación en Gestión del Talento Humano", "N/A")) -> N/A | I16: Fortalecer las capacidades del Estado con énfasis en la administración de justicia y eficiencia en los procesos de regulación y control, con independencia y autonomía. | J16: Fortalecer las capacidades institucionales | K16: Incrementar la excelencia y calidad de los servicios públicos en la gestión de las Entidades del Estado. | L16: 4-Dirección_Regional_de_Trabajo_y_Servicio_Público_de_Cuenca | M16: =IF(L16="2-Dirección_Regional_de_Trabajo_y_Servicio_Público_de_Guayaquil","901",IF(L16="3-Dirección_Regional_de_Trabajo_y_Servicio_Público_de_Ambato","1801",IF(L16="4-Dirección_Regional_de_Trabajo_y_Servicio_Público_de_Cuenca","101",IF(L16="10-Dirección_Regional_de_Trabajo_y_Servicio_Público_de_Ibarra","1001",IF(L16="11-Dirección_Regional_de_Trabajo_y_Servicio_Público_de_Loja","1101",IF(L16="13-Dirección_Regional_de_Trabajo_y_Servicio_Público_de_Portoviejo","1301","1701")))))) -> 101 | N16: 001-Administracion central | O16: 000-Sin proyecto | P16: 001-Fortalecimiento institucional | Q16: Nuevo | R16: SI | S16: N/A | T16: N/A | U16: N/A | V16: 202 | W16: 0 | X16: 0 | Y16: =IF(V16=1,"Recursos fiscales",IF(V16=2,"Recursos fiscales generados por las instituciones",IF(V16=202,"Préstamos externos"))) -> Préstamos externos | Z16: 71 | AA16: =VLOOKUP($Z16,'clacificaror presupuestario'!$K$2:$L$11,2,FALSE) -> Egresos_en_personal_para_inversión | AB16: 570102 | AC16: =VLOOKUP($AB16,'clacificaror presupuestario'!$A$2:$C$506,3,FALSE) -> Tasas Generales, Impuestos, Contribuciones, Permisos, Licencias y Patentes. | AD16: 2008 | AG16: =+AD16+AE16-AF16 -> 2008 | AH16: 100 | AI16: 100 | AJ16: 100 | AK16: 100 | AL16: 100 | AM16: 100 | AN16: 100 | AO16: 100 | AP16: 100 | AQ16: 100 | AR16: 100 | AS16: 100 | AT16: =SUM(AH16:AS16) -> 1200 | AU16: =+AD16-AT16 -> 808 | AV16: =IF(B16<>"",IF(B16="","Escoger UNIDAD ADMINISTRATIVA N2 (VICEMINISTERIO / DESPACHO);",)&" "&(IF(C16="","Escoger UNIDAD ADMINISTRATIVA N3 (SUBSECRETARÍA / COORDINACIÓN);",)&" "&(IF(D16="","Escoger UNIDAD ADMINISTRATIVA N4 (DIRECCIÓN TÉCNICA);",)&" "&(IF(F16="","Colocar DESCRIPCIÓN DE LA ACTIVIDAD;",)&" "&(IF(G16="","Colocar METAS;",)&" "&(IF(H16="","Colocar INDICADORES;",)&" "&(IF(I16="","Escoger OBJETIVO NACIONAL DE DESARROLLO - O.N.D.;",)&" "&(IF(J16="","Escoger OBJETIVO ESTRATÉGICO INSTITUCIONAL - O.E.I.;",)&" "&(IF(K16="","Escoger OBJETIVO ESPECÍFICO;",)&" "&(IF(L16="","Escoger IDENTIDAD OPERATIVA DESCONCENTRADA(EOD);",)&" "&(IF(N16="","Escoger PROGRAMA INSTITUCIONAL;",)&" "&(IF(O16="","Escoger PROYECTO;",)&" "&(IF(P16="","Escoger ACTIVIDAD INSTITUCIONAL;",)&" "&(IF(Q16="","Escoger NUEVO-ARRASTRE;",)&" "&(IF(S16="","Escoger CÓDIGO UNICO DE PROYECTO(CUP);",)&" "&(IF(V16="","Escoger FUENTE;",)&" "&(IF(W16=""," Escoger COD. ORG.;",)&" "&(IF(X16="","Escoger COD. CORRE.;",)&" "&(IF(Z16="","Escoger GRUPO GASTO;",)&" "&(IF(AB16="","Escoger ITEM;",)&" "&(IF(AD16="","Colocar TOTAL PROFORMA 2023;",)))))))))))))))))))))," ") -> Colocar DESCRIPCIÓN DE LA ACTIVIDAD; Colocar METAS; Colocar INDICADORES;
B17: Despacho_Ministerial | C17: Coordinación_General_de_Planificación_y_Gestión_Estratégica | D17: Dirección_de_Servicios,_Procesos_y_Cambio_y_Cultura | E17: =IF(D17="Programa_de_Reforma_Institucional_de_la_Gestion_Publica","Fortalecimiento del marco Institucional para la Reforma",IF(D17="Programa_de_Capacitacion_en_Gestion_del_Talento_Humano","Implimentar un Programa de Capacitación en Gestión del Talento Humano", "N/A")) -> N/A | I17: Fortalecer las capacidades del Estado con énfasis en la administración de justicia y eficiencia en los procesos de regulación y control, con independencia y autonomía. | J17: Fortalecer las capacidades institucionales | K17: Incrementar la excelencia y calidad de los servicios públicos en la gestión de las Entidades del Estado. | L17: 4-Dirección_Regional_de_Trabajo_y_Servicio_Público_de_Cuenca | M17: =IF(L17="2-Dirección_Regional_de_Trabajo_y_Servicio_Público_de_Guayaquil","901",IF(L17="3-Dirección_Regional_de_Trabajo_y_Servicio_Público_de_Ambato","1801",IF(L17="4-Dirección_Regional_de_Trabajo_y_Servicio_Público_de_Cuenca","101",IF(L17="10-Dirección_Regional_de_Trabajo_y_Servicio_Público_de_Ibarra","1001",IF(L17="11-Dirección_Regional_de_Trabajo_y_Servicio_Público_de_Loja","1101",IF(L17="13-Dirección_Regional_de_Trabajo_y_Servicio_Público_de_Portoviejo","1301","1701")))))) -> 101 | N17: 001-Administracion central | O17: 000-Sin proyecto | P17: 001-Fortalecimiento institucional | Q17: Nuevo | R17: SI | S17: N/A | T17: N/A | U17: N/A | V17: 202 | W17: 0 | X17: 0 | Y17: =IF(V17=1,"Recursos fiscales",IF(V17=2,"Recursos fiscales generados por las instituciones",IF(V17=202,"Préstamos externos"))) -> Préstamos externos | Z17: 99 | AA17: =VLOOKUP($Z17,'clacificaror presupuestario'!$K$2:$L$11,2,FALSE) -> Otros_pasivos | AB17: 570102 | AC17: =VLOOKUP($AB17,'clacificaror presupuestario'!$A$2:$C$506,3,FALSE) -> Tasas Generales, Impuestos, Contribuciones, Permisos, Licencias y Patentes. | AD17: 2009 | AG17: =+AD17+AE17-AF17 -> 2009 | AH17: 100 | AI17: 100 | AJ17: 100 | AK17: 100 | AL17: 100 | AM17: 100 | AN17: 100 | AO17: 100 | AP17: 100 | AQ17: 100 | AR17: 100 | AS17: 100 | AT17: =SUM(AH17:AS17) -> 1200 | AU17: =+AD17-AT17 -> 809 | AV17: =IF(B17<>"",IF(B17="","Escoger UNIDAD ADMINISTRATIVA N2 (VICEMINISTERIO / DESPACHO);",)&" "&(IF(C17="","Escoger UNIDAD ADMINISTRATIVA N3 (SUBSECRETARÍA / COORDINACIÓN);",)&" "&(IF(D17="","Escoger UNIDAD ADMINISTRATIVA N4 (DIRECCIÓN TÉCNICA);",)&" "&(IF(F17="","Colocar DESCRIPCIÓN DE LA ACTIVIDAD;",)&" "&(IF(G17="","Colocar METAS;",)&" "&(IF(H17="","Colocar INDICADORES;",)&" "&(IF(I17="","Escoger OBJETIVO NACIONAL DE DESARROLLO - O.N.D.;",)&" "&(IF(J17="","Escoger OBJETIVO ESTRATÉGICO INSTITUCIONAL - O.E.I.;",)&" "&(IF(K17="","Escoger OBJETIVO ESPECÍFICO;",)&" "&(IF(L17="","Escoger IDENTIDAD OPERATIVA DESCONCENTRADA(EOD);",)&" "&(IF(N17="","Escoger PROGRAMA INSTITUCIONAL;",)&" "&(IF(O17="","Escoger PROYECTO;",)&" "&(IF(P17="","Escoger ACTIVIDAD INSTITUCIONAL;",)&" "&(IF(Q17="","Escoger NUEVO-ARRASTRE;",)&" "&(IF(S17="","Escoger CÓDIGO UNICO DE PROYECTO(CUP);",)&" "&(IF(V17="","Escoger FUENTE;",)&" "&(IF(W17=""," Escoger COD. ORG.;",)&" "&(IF(X17="","Escoger COD. CORRE.;",)&" "&(IF(Z17="","Escoger GRUPO GASTO;",)&" "&(IF(AB17="","Escoger ITEM;",)&" "&(IF(AD17="","Colocar TOTAL PROFORMA 2023;",)))))))))))))))))))))," ") -> Colocar DESCRIPCIÓN DE LA ACTIVIDAD; Colocar METAS; Colocar INDICADORES;
B18: Despacho_Ministerial | C18: Coordinación_General_de_Planificación_y_Gestión_Estratégica | D18: Dirección_de_Servicios,_Procesos_y_Cambio_y_Cultura | E18: =IF(D18="Programa_de_Reforma_Institucional_de_la_Gestion_Publica","Fortalecimiento del marco Institucional para la Reforma",IF(D18="Programa_de_Capacitacion_en_Gestion_del_Talento_Humano","Implimentar un Programa de Capacitación en Gestión del Talento Humano", "N/A")) -> N/A | I18: Fortalecer las capacidades del Estado con énfasis en la administración de justicia y eficiencia en los procesos de regulación y control, con independencia y autonomía. | J18: Fortalecer las capacidades institucionales | K18: Incrementar la excelencia y calidad de los servicios públicos en la gestión de las Entidades del Estado. | L18: 4-Dirección_Regional_de_Trabajo_y_Servicio_Público_de_Cuenca | M18: =IF(L18="2-Dirección_Regional_de_Trabajo_y_Servicio_Público_de_Guayaquil","901",IF(L18="3-Dirección_Regional_de_Trabajo_y_Servicio_Público_de_Ambato","1801",IF(L18="4-Dirección_Regional_de_Trabajo_y_Servicio_Público_de_Cuenca","101",IF(L18="10-Dirección_Regional_de_Trabajo_y_Servicio_Público_de_Ibarra","1001",IF(L18="11-Dirección_Regional_de_Trabajo_y_Servicio_Público_de_Loja","1101",IF(L18="13-Dirección_Regional_de_Trabajo_y_Servicio_Público_de_Portoviejo","1301","1701")))))) -> 101 | N18: 001-Administracion central | O18: 000-Sin proyecto | P18: 001-Fortalecimiento institucional | Q18: Nuevo | R18: SI | S18: N/A | T18: N/A | U18: N/A | V18: 202 | W18: 0 | X18: 0 | Y18: =IF(V18=1,"Recursos fiscales",IF(V18=2,"Recursos fiscales generados por las instituciones",IF(V18=202,"Préstamos externos"))) -> Préstamos externos | Z18: 99 | AA18: =VLOOKUP($Z18,'clacificaror presupuestario'!$K$2:$L$11,2,FALSE) -> Otros_pasivos | AB18: 570102 | AC18: =VLOOKUP($AB18,'clacificaror presupuestario'!$A$2:$C$506,3,FALSE) -> Tasas Generales, Impuestos, Contribuciones, Permisos, Licencias y Patentes. | AD18: 2010 | AG18: =+AD18+AE18-AF18 -> 2010 | AH18: 100 | AI18: 100 | AJ18: 100 | AK18: 100 | AL18: 100 | AM18: 100 | AN18: 100 | AO18: 100 | AP18: 100 | AQ18: 100 | AR18: 100 | AS18: 100 | AT18: =SUM(AH18:AS18) -> 1200 | AU18: =+AD18-AT18 -> 810 | AV18: =IF(B18<>"",IF(B18="","Escoger UNIDAD ADMINISTRATIVA N2 (VICEMINISTERIO / DESPACHO);",)&" "&(IF(C18="","Escoger UNIDAD ADMINISTRATIVA N3 (SUBSECRETARÍA / COORDINACIÓN);",)&" "&(IF(D18="","Escoger UNIDAD ADMINISTRATIVA N4 (DIRECCIÓN TÉCNICA);",)&" "&(IF(F18="","Colocar DESCRIPCIÓN DE LA ACTIVIDAD;",)&" "&(IF(G18="","Colocar METAS;",)&" "&(IF(H18="","Colocar INDICADORES;",)&" "&(IF(I18="","Escoger OBJETIVO NACIONAL DE DESARROLLO - O.N.D.;",)&" "&(IF(J18="","Escoger OBJETIVO ESTRATÉGICO INSTITUCIONAL - O.E.I.;",)&" "&(IF(K18="","Escoger OBJETIVO ESPECÍFICO;",)&" "&(IF(L18="","Escoger IDENTIDAD OPERATIVA DESCONCENTRADA(EOD);",)&" "&(IF(N18="","Escoger PROGRAMA INSTITUCIONAL;",)&" "&(IF(O18="","Escoger PROYECTO;",)&" "&(IF(P18="","Escoger ACTIVIDAD INSTITUCIONAL;",)&" "&(IF(Q18="","Escoger NUEVO-ARRASTRE;",)&" "&(IF(S18="","Escoger CÓDIGO UNICO DE PROYECTO(CUP);",)&" "&(IF(V18="","Escoger FUENTE;",)&" "&(IF(W18=""," Escoger COD. ORG.;",)&" "&(IF(X18="","Escoger COD. CORRE.;",)&" "&(IF(Z18="","Escoger GRUPO GASTO;",)&" "&(IF(AB18="","Escoger ITEM;",)&" "&(IF(AD18="","Colocar TOTAL PROFORMA 2023;",)))))))))))))))))))))," ") -> Colocar DESCRIPCIÓN DE LA ACTIVIDAD; Colocar METAS; Colocar INDICADORES;
B19: Despacho_Ministerial | C19: Coordinación_General_de_Planificación_y_Gestión_Estratégica | D19: Dirección_de_Servicios,_Procesos_y_Cambio_y_Cultura | E19: =IF(D19="Programa_de_Reforma_Institucional_de_la_Gestion_Publica","Fortalecimiento del marco Institucional para la Reforma",IF(D19="Programa_de_Capacitacion_en_Gestion_del_Talento_Humano","Implimentar un Programa de Capacitación en Gestión del Talento Humano", "N/A")) -> N/A | I19: Fortalecer las capacidades del Estado con énfasis en la administración de justicia y eficiencia en los procesos de regulación y control, con independencia y autonomía. | J19: Fortalecer las capacidades institucionales | K19: Incrementar la excelencia y calidad de los servicios públicos en la gestión de las Entidades del Estado. | L19: 4-Dirección_Regional_de_Trabajo_y_Servicio_Público_de_Cuenca | M19: =IF(L19="2-Dirección_Regional_de_Trabajo_y_Servicio_Público_de_Guayaquil","901",IF(L19="3-Dirección_Regional_de_Trabajo_y_Servicio_Público_de_Ambato","1801",IF(L19="4-Dirección_Regional_de_Trabajo_y_Servicio_Público_de_Cuenca","101",IF(L19="10-Dirección_Regional_de_Trabajo_y_Servicio_Público_de_Ibarra","1001",IF(L19="11-Dirección_Regional_de_Trabajo_y_Servicio_Público_de_Loja","1101",IF(L19="13-Dirección_Regional_de_Trabajo_y_Servicio_Público_de_Portoviejo","1301","1701")))))) -> 101 | N19: 001-Administracion central | O19: 000-Sin proyecto | P19: 001-Fortalecimiento institucional | Q19: Nuevo | R19: SI | S19: N/A | T19: N/A | U19: N/A | V19: 202 | W19: 0 | X19: 0 | Y19: =IF(V19=1,"Recursos fiscales",IF(V19=2,"Recursos fiscales generados por las instituciones",IF(V19=202,"Préstamos externos"))) -> Préstamos externos | Z19: 99 | AA19: =VLOOKUP($Z19,'clacificaror presupuestario'!$K$2:$L$11,2,FALSE) -> Otros_pasivos | AB19: 570102 | AC19: =VLOOKUP($AB19,'clacificaror presupuestario'!$A$2:$C$506,3,FALSE) -> Tasas Generales, Impuestos, Contribuciones, Permisos, Licencias y Patentes. | AD19: 2011 | AG19: =+AD19+AE19-AF19 -> 2011 | AH19: 100 | AI19: 100 | AJ19: 100 | AK19: 100 | AL19: 100 | AM19: 100 | AN19: 100 | AO19: 100 | AP19: 100 | AQ19: 100 | AR19: 100 | AS19: 100 | AT19: =SUM(AH19:AS19) -> 1200 | AU19: =+AD19-AT19 -> 811 | AV19: =IF(B19<>"",IF(B19="","Escoger UNIDAD ADMINISTRATIVA N2 (VICEMINISTERIO / DESPACHO);",)&" "&(IF(C19="","Escoger UNIDAD ADMINISTRATIVA N3 (SUBSECRETARÍA / COORDINACIÓN);",)&" "&(IF(D19="","Escoger UNIDAD ADMINISTRATIVA N4 (DIRECCIÓN TÉCNICA);",)&" "&(IF(F19="","Colocar DESCRIPCIÓN DE LA ACTIVIDAD;",)&" "&(IF(G19="","Colocar METAS;",)&" "&(IF(H19="","Colocar INDICADORES;",)&" "&(IF(I19="","Escoger OBJETIVO NACIONAL DE DESARROLLO - O.N.D.;",)&" "&(IF(J19="","Escoger OBJETIVO ESTRATÉGICO INSTITUCIONAL - O.E.I.;",)&" "&(IF(K19="","Escoger OBJETIVO ESPECÍFICO;",)&" "&(IF(L19="","Escoger IDENTIDAD OPERATIVA DESCONCENTRADA(EOD);",)&" "&(IF(N19="","Escoger PROGRAMA INSTITUCIONAL;",)&" "&(IF(O19="","Escoger PROYECTO;",)&" "&(IF(P19="","Escoger ACTIVIDAD INSTITUCIONAL;",)&" "&(IF(Q19="","Escoger NUEVO-ARRASTRE;",)&" "&(IF(S19="","Escoger CÓDIGO UNICO DE PROYECTO(CUP);",)&" "&(IF(V19="","Escoger FUENTE;",)&" "&(IF(W19=""," Escoger COD. ORG.;",)&" "&(IF(X19="","Escoger COD. CORRE.;",)&" "&(IF(Z19="","Escoger GRUPO GASTO;",)&" "&(IF(AB19="","Escoger ITEM;",)&" "&(IF(AD19="","Colocar TOTAL PROFORMA 2023;",)))))))))))))))))))))," ") -> Colocar DESCRIPCIÓN DE LA ACTIVIDAD; Colocar METAS; Colocar INDICADORES;
B20: Despacho_Ministerial | C20: Coordinación_General_de_Planificación_y_Gestión_Estratégica | D20: Dirección_de_Servicios,_Procesos_y_Cambio_y_Cultura | E20: =IF(D20="Programa_de_Reforma_Institucional_de_la_Gestion_Publica","Fortalecimiento del marco Institucional para la Reforma",IF(D20="Programa_de_Capacitacion_en_Gestion_del_Talento_Humano","Implimentar un Programa de Capacitación en Gestión del Talento Humano", "N/A")) -> N/A | I20: Fortalecer las capacidades del Estado con énfasis en la administración de justicia y eficiencia en los procesos de regulación y control, con independencia y autonomía. | J20: Fortalecer las capacidades institucionales | K20: Incrementar la excelencia y calidad de los servicios públicos en la gestión de las Entidades del Estado. | L20: 4-Dirección_Regional_de_Trabajo_y_Servicio_Público_de_Cuenca | M20: =IF(L20="2-Dirección_Regional_de_Trabajo_y_Servicio_Público_de_Guayaquil","901",IF(L20="3-Dirección_Regional_de_Trabajo_y_Servicio_Público_de_Ambato","1801",IF(L20="4-Dirección_Regional_de_Trabajo_y_Servicio_Público_de_Cuenca","101",IF(L20="10-Dirección_Regional_de_Trabajo_y_Servicio_Público_de_Ibarra","1001",IF(L20="11-Dirección_Regional_de_Trabajo_y_Servicio_Público_de_Loja","1101",IF(L20="13-Dirección_Regional_de_Trabajo_y_Servicio_Público_de_Portoviejo","1301","1701")))))) -> 101 | N20: 001-Administracion central | O20: 000-Sin proyecto | P20: 001-Fortalecimiento institucional | Q20: Nuevo | R20: SI | S20: N/A | T20: N/A | U20: N/A | V20: 202 | W20: 0 | X20: 0 | Y20: =IF(V20=1,"Recursos fiscales",IF(V20=2,"Recursos fiscales generados por las instituciones",IF(V20=202,"Préstamos externos"))) -> Préstamos externos | Z20: 99 | AA20: =VLOOKUP($Z20,'clacificaror presupuestario'!$K$2:$L$11,2,FALSE) -> Otros_pasivos | AB20: 570102 | AC20: =VLOOKUP($AB20,'clacificaror presupuestario'!$A$2:$C$506,3,FALSE) -> Tasas Generales, Impuestos, Contribuciones, Permisos, Licencias y Patentes. | AD20: 2012 | AG20: =+AD20+AE20-AF20 -> 2012 | AH20: 100 | AI20: 100 | AJ20: 100 | AK20: 100 | AL20: 100 | AM20: 100 | AN20: 100 | AO20: 100 | AP20: 100 | AQ20: 100 | AR20: 100 | AS20: 100 | AT20: =SUM(AH20:AS20) -> 1200 | AU20: =+AD20-AT20 -> 812 | AV20: =IF(B20<>"",IF(B20="","Escoger UNIDAD ADMINISTRATIVA N2 (VICEMINISTERIO / DESPACHO);",)&" "&(IF(C20="","Escoger UNIDAD ADMINISTRATIVA N3 (SUBSECRETARÍA / COORDINACIÓN);",)&" "&(IF(D20="","Escoger UNIDAD ADMINISTRATIVA N4 (DIRECCIÓN TÉCNICA);",)&" "&(IF(F20="","Colocar DESCRIPCIÓN DE LA ACTIVIDAD;",)&" "&(IF(G20="","Colocar METAS;",)&" "&(IF(H20="","Colocar INDICADORES;",)&" "&(IF(I20="","Escoger OBJETIVO NACIONAL DE DESARROLLO - O.N.D.;",)&" "&(IF(J20="","Escoger OBJETIVO ESTRATÉGICO INSTITUCIONAL - O.E.I.;",)&" "&(IF(K20="","Escoger OBJETIVO ESPECÍFICO;",)&" "&(IF(L20="","Escoger IDENTIDAD OPERATIVA DESCONCENTRADA(EOD);",)&" "&(IF(N20="","Escoger PROGRAMA INSTITUCIONAL;",)&" "&(IF(O20="","Escoger PROYECTO;",)&" "&(IF(P20="","Escoger ACTIVIDAD INSTITUCIONAL;",)&" "&(IF(Q20="","Escoger NUEVO-ARRASTRE;",)&" "&(IF(S20="","Escoger CÓDIGO UNICO DE PROYECTO(CUP);",)&" "&(IF(V20="","Escoger FUENTE;",)&" "&(IF(W20=""," Escoger COD. ORG.;",)&" "&(IF(X20="","Escoger COD. CORRE.;",)&" "&(IF(Z20="","Escoger GRUPO GASTO;",)&" "&(IF(AB20="","Escoger ITEM;",)&" "&(IF(AD20="","Colocar TOTAL PROFORMA 2023;",)))))))))))))))))))))," ") -> Colocar DESCRIPCIÓN DE LA ACTIVIDAD; Colocar METAS; Colocar INDICADORES;
... B30: Despacho_Ministerial | C30: Coordinación_General_de_Planificación_y_Gestión_Estratégica | D30: Dirección_de_Servicios,_Procesos_y_Cambio_y_Cultura | E30: =IF(D30="Programa_de_Reforma_Institucional_de_la_Gestion_Publica","Fortalecimiento del marco Institucional para la Reforma",IF(D30="Programa_de_Capacitacion_en_Gestion_del_Talento_Humano","Implimentar un Programa de Capacitación en Gestión del Talento Humano", "N/A")) -> N/A | I30: Fortalecer las capacidades del Estado con énfasis en la administración de justicia y eficiencia en los procesos de regulación y control, con independencia y autonomía. | J30: Fortalecer las capacidades institucionales | K30: Incrementar la excelencia y calidad de los servicios públicos en la gestión de las Entidades del Estado. | L30: 4-Dirección_Regional_de_Trabajo_y_Servicio_Público_de_Cuenca | M30: =IF(L30="2-Dirección_Regional_de_Trabajo_y_Servicio_Público_de_Guayaquil","901",IF(L30="3-Dirección_Regional_de_Trabajo_y_Servicio_Público_de_Ambato","1801",IF(L30="4-Dirección_Regional_de_Trabajo_y_Servicio_Público_de_Cuenca","101",IF(L30="10-Dirección_Regional_de_Trabajo_y_Servicio_Público_de_Ibarra","1001",IF(L30="11-Dirección_Regional_de_Trabajo_y_Servicio_Público_de_Loja","1101",IF(L30="13-Dirección_Regional_de_Trabajo_y_Servicio_Público_de_Portoviejo","1301","1701")))))) -> 101 | N30: 001-Administracion central | O30: 000-Sin proyecto | P30: 001-Fortalecimiento institucional | Q30: Nuevo | R30: SI | S30: N/A | T30: N/A | U30: N/A | V30: 202 | W30: 0 | X30: 0 | Y30: =IF(V30=1,"Recursos fiscales",IF(V30=2,"Recursos fiscales generados por las instituciones",IF(V30=202,"Préstamos externos"))) -> Préstamos externos | Z30: 84 | AA30: =VLOOKUP($Z30,'clacificaror presupuestario'!$K$2:$L$11,2,FALSE) -> Bienes_de_larga_duración_propiedades_planta_y_equipo | AB30: 570102 | AC30: =VLOOKUP($AB30,'clacificaror presupuestario'!$A$2:$C$506,3,FALSE) -> Tasas Generales, Impuestos, Contribuciones, Permisos, Licencias y Patentes. | AD30: 2022 | AG30: =+AD30+AE30-AF30 -> 2022 | AH30: 100 | AI30: 100 | AJ30: 100 | AK30: 100 | AL30: 100 | AM30: 100 | AN30: 100 | AO30: 100 | AP30: 100 | AQ30: 100 | AR30: 100 | AS30: 100 | AT30: =SUM(AH30:AS30) -> 1200 | AU30: =+AD30-AT30 -> 822 | AV30: =IF(B30<>"",IF(B30="","Escoger UNIDAD ADMINISTRATIVA N2 (VICEMINISTERIO / DESPACHO);",)&" "&(IF(C30="","Escoger UNIDAD ADMINISTRATIVA N3 (SUBSECRETARÍA / COORDINACIÓN);",)&" "&(IF(D30="","Escoger UNIDAD ADMINISTRATIVA N4 (DIRECCIÓN TÉCNICA);",)&" "&(IF(F30="","Colocar DESCRIPCIÓN DE LA ACTIVIDAD;",)&" "&(IF(G30="","Colocar METAS;",)&" "&(IF(H30="","Colocar INDICADORES;",)&" "&(IF(I30="","Escoger OBJETIVO NACIONAL DE DESARROLLO - O.N.D.;",)&" "&(IF(J30="","Escoger OBJETIVO ESTRATÉGICO INSTITUCIONAL - O.E.I.;",)&" "&(IF(K30="","Escoger OBJETIVO ESPECÍFICO;",)&" "&(IF(L30="","Escoger IDENTIDAD OPERATIVA DESCONCENTRADA(EOD);",)&" "&(IF(N30="","Escoger PROGRAMA INSTITUCIONAL;",)&" "&(IF(O30="","Escoger PROYECTO;",)&" "&(IF(P30="","Escoger ACTIVIDAD INSTITUCIONAL;",)&" "&(IF(Q30="","Escoger NUEVO-ARRASTRE;",)&" "&(IF(S30="","Escoger CÓDIGO UNICO DE PROYECTO(CUP);",)&" "&(IF(V30="","Escoger FUENTE;",)&" "&(IF(W30=""," Escoger COD. ORG.;",)&" "&(IF(X30="","Escoger COD. CORRE.;",)&" "&(IF(Z30="","Escoger GRUPO GASTO;",)&" "&(IF(AB30="","Escoger ITEM;",)&" "&(IF(AD30="","Colocar TOTAL PROFORMA 2023;",)))))))))))))))))))))," ") -> Colocar DESCRIPCIÓN DE LA ACTIVIDAD; Colocar METAS; Colocar INDICADORES;

Sheet TABLAS
C1: UNIDAD_N3 | E1: UNIDADES_N4
A2: UNIDADES_N2 | C2: Viceministerio_del_Trabajo_y_Empleo | E2: Subsecretaría_de_Empleo_y_Salarios
A3: Viceministerio_del_Trabajo_y_Empleo | C3: Subsecretaría_de_Empleo_y_Salarios | E3: Coordinación_de_Empleo_y_Salarios
A4: Viceministerio_del_Servicio_Público | C4: Subsecretaría_de_Trabajo | E4: Dirección_de_Análisis_Salarial
A5: Despacho_Ministerial | E5: Dirección_de_Atención_a_Grupos_Prioritarios
C6: Viceministerio_del_Servicio_Público | E6: Dirección_de_Empleo_y_Reconversion_Laboral
C7: Subsecretaría_de_Calidad_en_el_Servicio_Público
C8: Subsecretaría_de_Evaluación_y_Control_del_Servicio_Público | E8: Subsecretaría_de_Trabajo
C9: Subsecretaría_de_Fortalecimiento_del_Servicio_Público | E9: Dirección_de_Control_de_Inspecciones | H9: OBJETIVO NACIONAL DE DESARROLLO - O.N.D. | I9: OBJETIVO ESTRATÉGICO INSTITUCIONAL - O.E.I. | J9: OBJETIVO ESPECÍFICO | N9: Programa | O9: Proyecto | P9: Actividad
C10: Subsecretaría_de_Meritocracia_y_Desarrollo_del_Talento_Humano | E10: Dirección_de_Mediacion_Laboral | H10: Incrementar y fomentar, de manera inclusiva, las oportunidades de empleo y las condiciones laborales. | I10: Incrementar el empleo adecuado en el Ecuador | J10: Incrementar el cumplimiento de los derechos y obligaciones de la ciudadanía labora | N10: 001-Administracion central | O10: 000-Sin proyecto | P10: 001-Fortalecimiento institucional
E11: Dirección_de_Organizaciones_Laborales | H11: Fortalecer las capacidades del Estado con énfasis en la administración de justicia y eficiencia en los procesos de regulación y control, con independencia y autonomía. | I11: Fortalecer las capacidades institucionales | J11: Mejorar los servicios institucionales, procesos y procedimientos internos. | N11: 055-Promocion de empleo verificación y control de derechos y obligaciones laborales | O11: 001-Mi Primer Empelo | P11: 001-Programa de reforma institucional de la gestión pública
C12: Despacho_Ministerial | E12: Dirección_de_Seguridad,_Salud_en_el_Trabajo_y_Gestión_Integral_de_Riesgos | J12: Incrementar el nivel de servicio de Tecnologías de Información y Telecomunicaciones | O12: 005-Programa de capacitación en gestión del talento humano | P12: 001-Promocion del empleo y control de los derechos y obligaciones laborales
C13: Subsecretaría_de_Cualificaciones_Profesionales | J13: Incrementar la excelencia y calidad de los servicios públicos en la gestión de las Entidades del Estado. | O13: 006-Empleo Joven | P13: 003-Fortalecimiento de la calidad del servicio publico
C14: Subsecretaría_de_Políticas_y_Normas | E14: Subsecretaría_de_Calidad_en_el_Servicio_Público | J14: Readecuar espacios físicos aprovechando la capacidad instalada con enfoque de accesibilidad | O14: 007-Compromiso por el Empleo | P14: 001-Capacitación en gestión del talento humano
C15: Subsecretaría_Interinstitucional_de_Servicio_Público_Trabajo_y_Empleo | E15: Dirección_de_Calidad_en_el_Servicio_Público | J15: Establecer un plan de desarrollo profesional para potenciar habilidades, competencias y destrezas del personal | O15: 008 Proyecto de Gestión del Subsistema de Empleo en el Servicio Público
C16: Coordinación_de_Inteligencia_de_Información_y_Estudios_del_Trabajo | E16: Dirección_de_Contacto_Ciudadano | J16: Incrementar el nivel de desempeño de los servidores de la institución
C17: Coordinación_General_Administrativa_Financiera | E17: Dirección_de_Control_y_Evaluación_de_la_Calidad_en_el_Servicio_Público | J17: Incrementar la calidad del gasto corriente e inversión
C18: Coordinación_General_de_Planificación_y_Gestión_Estratégica | E18: Dirección_de_Servicios_Procesos_e_Innovación
C19: Despacho_Ministerial.
C20: Direcciones_Regionales_de_Trabajo_y_Servicio_Público | E20: Subsecretaría_de_Evaluación_y_Control_del_Servicio_Público
E21: Dirección_de_Evaluación_y_Control_del_Servicio_Público
E22: Dirección_de_Recurso_y_Sumarios_Administrativos
E23: Dirección_de_Control_del_Servicio_Público | K23: PLURI | N23: ind | O23: FUENTE | P23: COD. ORG | Q23: COD. CORRE.
E24: Dirección_de_Control_Técnico_de_la_Gestión_del_Talento_Humano | K24: SI | N24: Nuevo | O24: 1 | P24: 0 | Q24: 0
K25: NO | N25: Arrastre | O25: 2 | P25: 9999 | Q25: 9999
E26: Subsecretaría_de_Fortalecimiento_del_Servicio_Público | O26: 202 | P26: 8888 | Q26: 8888
E27: Dirección_de_Análisis_y_Diseño_Organizacional
E28: Programa_de_Reforma_Institucional_de_la_Gestion_Publica
E29: Dirección_de_Fortalecimiento_Institucional
E30: Dirección_de_Planificación_y_Apoyo_a_la_Gestión_del_Talento_Humano
E32: Subsecretaría_de_Meritocracia_y_Desarrollo_del_Talento_Humano
E33: Dirección_de_Evaluación_del_Desempeño,_Capacitación_y_Desarrollo_del_Talento_Humano
E34: Dirección_de_Gestión_del_Cambio_y_Cultura_Organizacional
E35: Dirección_de_Meritocracia_y_Vinculación_del_Talento_Humano | J35: FUENTE
E36: Programa_de_Capacitacion_en_Gestion_del_Talento_Humano | J36: 1 | K36: Recursos fiscales | N36: Política de Ambiente | O36: NOMBRE ENTIDAD | P36: EOD | Q36: GEOGRÁFICO | R36: PROYECTO | S36: CUP | T36: Política de Igualdad
J37: 2 | K37: Recursos fiscales generados por las instituciones | N37: N/A | O37: MINISTERIO DEL TRABAJO DIRECCION REGIONAL DE TRABAJO Y SERVICIO PUBLICO DE CUENCA REGIONAL 6 | P37: 10-Dirección_Regional_de_Trabajo_y_Servicio_Público_de_Ibarra | Q37: 101 | R37: PROGRAMADE REFORMA INSTITUCIONAL DE LA GESTIÓN PÚBLICA | S37: 30400000.1780.7402. | T37: N/A
E38: Subsecretaría_de_Cualificaciones_Profesionales | J38: 3 | K38: Recursos provenientes de preasignaciones | N38: 02.01Cambio climático | O38: MINISTERIO DEL TRABAJO REGIONAL 2 LITORAL Y GALAPAGOS | P38: 11-Dirección_Regional_de_Trabajo_y_Servicio_Público_de_Loja | Q38: 901 | R38: PROGRAMA DE CAPACITACION EN GESTION DEL TALENTO HUMANO | S38: 113150000.0000.381389. | T38: 01.01 Género
E39: Dirección_de_Calificación,_Reconocimiento_y_Certificación_de_Operadores | J39: 6 | K39: Recursos provenientes de la ley orgánica de solidaridad | N39: 02.02Suelos, aguas subterráneas y superficiales | O39: DIRECCION REGIONAL DE TRABAJO 1 DE IBARRA | P39: 13-Dirección_Regional_de_Trabajo_y_Servicio_Público_de_Portoviejo | Q39: 1001 | R39: LOS DEMÁS | S39: N/A | T39: 01.02 Discapacidades
E40: Dirección_de_Competencias_y_Certificación | J40: 201 | K40: Colocaciones externas | N40: 02.03Aguas residuales | O40: DIRECCION REGIONAL DEL MINISTERIO DEL TRABAJO No 7 LOJA EL ORO Y ZAMORA | P40: 2-Dirección_Regional_de_Trabajo_y_Servicio_Público_de_Guayaquil | Q40: 1101 | T40: 01.03 Interculturalidad
J41: 202 | K41: Préstamos externos | N41: 02.04Sustancias químicas y residuos | O41: DIRECCION REGIONAL DE TRABAJO Y SERVICIO PUBLICO - DIRECCION REGIONAL MANTA | P41: 3-Dirección_Regional_de_Trabajo_y_Servicio_Público_de_Ambato | Q41: 1301 | T41: 01.04 Movilidad Humana
...

Sheet Act_Homologadas
A1: ACTIVIDADES HOMOLOGADAS
A2: Item | B2: Descripción del Item | C2: Concepto sugerido
