Workbook
Name Excel_BuiltIn__FilterDatabase_4: #REF!
Name Excel_BuiltIn_Print_Area_4_1: #REF!
Name OLE_LINK1_4: #REF!

Sheet FORMULARIO 1
A1: MINISTERIO DE ECONOMIA Y FINANZAS
A2: FORMULARIO 1: "FUENTES DE FINANCIAMIENTO DEL PROYECTO DE CONTRATO COLECTIVO"
A3: DETALLE DE INGRESOS
A5: GOBIERNO AUTÓNOMO DESCENTRALIZADO MUNICIPAL DE YANTZAZA
A6: Nº PROYECTO CONTRATO COLECTIVO: DECIMO CUARTO
A8: FUENTES DE FINANCIAMIENTO | C8: FINANCIAMIENTO CONTRATO COLECTIVO VIGENTE ENE - ABR 2015 | D8: FINANCIAMIENTO CONTRATO COLECTIVO PROPUESTO MAY - DIC 2015 | E8: FINANCIAMIENTO CONTRATO COLECTIVO PROPUESTO ENE - DIC 2016 | F8: FINANCIAMIENTO CONTRATO COLECTIVO PROPUESTO ENE - DIC 2017 | G8: FINANCIAMIENTO CONTRATO COLECTIVO PROPUESTO ENE - DIC 2018 | H8: OBSERVACIONES
A9: 11 | B9: IMPUESTOS
A10: 1101 | B10: Sobre la Renta, Utilidades y Ganancias de Capital | C10: =E10/3 -> 9533.3333 | D10: =C10*2 -> 19066.667 | E10: 28600 | F10: =E10*1.01 -> 28886 | G10: =F10*1.01 -> 29174.86
A11: 1102 | B11: Sobre la propiedad | C11: =E11/3 -> 78666.667 | D11: =C11*2 -> 157333.33 | E11: 236000 | F11: =E11*1.01 -> 238360 | G11: =F11*1.01 -> 240743.6
A12: 1107 | B12: Impuestos Diversos | C12: =E12/3 -> 39200 | D12: =C12*2 -> 78400 | E12: 117600 | F12: =E12*1.01 -> 118776 | G12: =F12*1.01 -> 119963.76
A13: 13 | B13: TASAS Y CONTRIBUCIONES
A14: 1301 | B14: Tasas generales | C14: =E14/3 -> 65800 | D14: =C14*2 -> 131600 | E14: 197400 | F14: =E14*1.01 -> 199374 | G14: =F14*1.01 -> 201367.74
A15: 14 | B15: VENTA DE BIENES Y SERVICIOS
A16: 1403 | B16: Ventas no Industriales | C16: =E16/3 -> 10866.667 | D16: =C16*2 -> 21733.333 | E16: 32600 | F16: =E16*1.01 -> 32926 | G16: =F16*1.01 -> 33255.26
A17: 18 | B17: TRANSFERENCIAS Y DONACIONES CORRIENTES
A18: 1801 | B18: Transferencias Corrientes del Sector Público | C18: ='FORMULARIO 2'!C27-(SUM(C9:C17)) -> 121423.01 | D18: ='FORMULARIO 2'!D27-(SUM(D9:D17)) -> 207669.06 | E18: ='FORMULARIO 2'!E27-(SUM(E9:E17)) -> 286493.06 | F18: ='FORMULARIO 2'!F27-(SUM(F9:F17)) -> 281100.06 | G18: ='FORMULARIO 2'!G27-(SUM(G9:G17)) -> 275807.84
A19: TOTAL | C19: =SUM(C9:C18) -> 325489.68 | D19: =SUM(D9:D18) -> 615802.4 | E19: =SUM(E9:E18) -> 898693.06 | F19: =SUM(F9:F18) -> 899422.06 | G19: =SUM(G9:G18) -> 900313.06
A20: NOTA.-
A21: Se cumple con la regla fiscal.
A28: Ing. Leonardo Heriberto Cueva Jimenez
A29: DIRECTOR FINANCIERO GADM YANTZAZA
A31: Yantzaza, 23 de abril de 2021

Sheet FORMULARIO 2
A1: ='FORMULARIO 1'!A1:H1 -> MINISTERIO DE ECONOMIA Y FINANZAS
A2: FORMULARIO 2: "COSTOS DEL PROYECTO DE CONTRATO COLECTIVO"
A3: DETALLE DE GASTOS
A5: ='FORMULARIO 1'!A5:H5 -> GOBIERNO AUTÓNOMO DESCENTRALIZADO MUNICIPAL DE YANTZAZA
A6: ='FORMULARIO 1'!A6:H6 -> Nº PROYECTO CONTRATO COLECTIVO: DECIMO CUARTO
A8: GASTO DEL PERSONAL | C8: COSTO CONTRATO COLECTIVO VIGENTE ENE - ABR 2015 | D8: COSTO CONTRATO COLECTIVO PROPUESTO MAY - DIC 2015 | E8: COSTO CONTRATO COLECTIVO PROPUESTO ENE - DIC 2016 | F8: COSTO CONTRATO COLECTIVO PROPUESTO ENE - DIC 2017 | G8: COSTO CONTRATO COLECTIVO PROPUESTO ENE - DIC 2018 | H8: OBSERVACIONES
A9: GASTO PERSONAL
A10: 5101 | B10: REMUNERACIONES BASICAS
A11: 510105 | B11: REMUNERACION UNIFICADA | C11: ='FORMULARIO 3'!F95 -> 202100.24 | D11: ='FORMULARIO 3'!G95 -> 415720.48 | E11: ='FORMULARIO 3'!H95 -> 623580.72 | F11: ='FORMULARIO 3'!I95 -> 623580.72 | G11: ='FORMULARIO 3'!J95 -> 623580.72
A12: 5102 | B12: REMUNERACIONES COMPLEMENTARIAS
A13: 510203 | B13: DECIMOTERCER SUELDO | C13: ='FORMULARIO 3'!F94 -> 50525.06 | D13: ='FORMULARIO 3'!G94 -> 51965.06 | E13: ='FORMULARIO 3'!H94 -> 51965.06 | F13: ='FORMULARIO 3'!I94 -> 51965.06 | G13: ='FORMULARIO 3'!J94 -> 51965.06
A14: 510204 | B14: DECIMOCUARTO SUELDO | C14: =(354*81)/3 -> 9558 | D14: =((354*81)/3)*2 -> 19116 | E14: =366*81 -> 29646 | F14: =375*81 -> 30375 | G14: =386*81 -> 31266
A15: 5103 | B15: REMUNERACIONES COMPENSATORIAS
A16: 510306 | B16: ALIMENTACION | C16: =((2*24)*4)*81 -> 15552 | D16: =((2*24)*8)*81 -> 31104 | E16: =((2*24)*12)*81 -> 46656 | F16: =((2*24)*12)*81 -> 46656 | G16: =((2*24)*12)*81 -> 46656
A17: 5104 | B17: SUBSIDIOS
A18: 510401 | B18: POR CARGAS FAMILIARES | C18: =C11*0.01 -> 2021.0024 | D18: =D11*0.01 -> 4157.2048 | E18: =E11*0.01 -> 6235.8072 | F18: =F11*0.01 -> 6235.8072 | G18: =G11*0.01 -> 6235.8072
A19: 510408 | B19: SUBSIDIO DE ANTIGUEDAD | C19: =C11*0.0025 -> 505.2506 | D19: =D11*0.0025 -> 1039.3012 | E19: =E11*0.0025 -> 1558.9518 | F19: =F11*0.0025 -> 1558.9518 | G19: =G11*0.0025 -> 1558.9518
A20: 5106 | B20: APORTES PATRONALES A LA SEGURIDAD SOCIAL
A21: 510601 | B21: APORTE PATRONAL | C21: =C11*0.1115 -> 22534.177 | D21: =D11*0.1115 -> 46352.834 | E21: =E11*0.1115 -> 69529.25 | F21: =F11*0.1115 -> 69529.25 | G21: =G11*0.1115 -> 69529.25
A22: 510602 | B22: FONDO DE RESERVA | C22: =C11*0.0833 -> 16834.95 | D22: =D11*0.0833 -> 34629.516 | E22: =E11*0.0833 -> 51944.274 | F22: =F11*0.0833 -> 51944.274 | G22: =G11*0.0833 -> 51944.274
A23: 5308 | B23: BIENES DE USO Y CONSUMO CORRIENTE
A24: 530802 | B24: VESTUARIO, LENCERIA, PRENDAS DE PROTECCION | C24: =(169*81)/3 -> 4563 | D24: =((169*81)/3)*2 -> 9126 | E24: =169*81 -> 13689 | F24: =169*81 -> 13689 | G24: =169*81 -> 13689
A25: 5702 | B25: SEGUROS, COSTOS FINANCIEROS Y OTROS GASTOS
A26: 570201 | B26: SEGUROS | C26: =(4*4)*81 -> 1296 | D26: =(4*8)*81 -> 2592 | E26: =(4*12)*81 -> 3888 | F26: =(4*12)*81 -> 3888 | G26: =(4*12)*81 -> 3888
A27: TOTAL DE GASTO | C27: =SUM(C10:C26) -> 325489.68 | D27: =SUM(D10:D26) -> 615802.4 | E27: =SUM(E10:E26) -> 898693.06 | F27: =SUM(F10:F26) -> 899422.06 | G27: =SUM(G10:G26) -> 900313.06
A28: NOTA.-
A29: El cálculo de remuneraciones compensatorias se realizó tomando como referancia 24 dias laborados al mes.
A36: ='FORMULARIO 1'!A28:H28 -> Ing. Leonardo Heriberto Cueva Jimenez
A37: ='FORMULARIO 1'!A29:H29 -> DIRECTOR FINANCIERO GADM YANTZAZA
A39: ='FORMULARIO 1'!A31:H31 -> Yantzaza, 23 de abril de 2021

Sheet CERTIFICACION
A1: CERTIFICACION PRESUPUESTARIA
A3: La Dirección Financiera del Gobierno Autónomo Descentralizado Municipal del Cantón Yantzaza, CERTIFICA, que los costos del Decimo Cuarto Contrato Colectivo de Trabajo a ser suscrito con el Sindicato Único de Trabajadores del GAD, están contemplados en los respectivos presupuestos y la diferecia de incremento sera cancelada en el presente ejercicio fiscal 2021, de acuerdo al siguiente detalle:
A9: GASTO DEL PERSONAL | C9: COSTO CONTRATO COLECTIVO MAY - DIC 2015 | D9: COSTO CONTRATO COLECTIVO ENE - DIC 2016 | E9: COSTO CONTRATO COLECTIVO ENE - DIC 2017 | F9: COSTO CONTRATO COLECTIVO ENE - DIC 2018
A10: GASTO PERSONAL
A11: 5101 | B11: REMUNERACIONES BASICAS
A12: 510105 | B12: REMUNERACION UNIFICADA | C12: ='FORMULARIO 2'!D11 -> 415720.48 | D12: ='FORMULARIO 2'!E11 -> 623580.72 | E12: ='FORMULARIO 2'!F11 -> 623580.72 | F12: ='FORMULARIO 2'!G11 -> 623580.72
A13: 5102 | B13: REMUNERACIONES COMPLEMENTARIAS
A14: 510203 | B14: DECIMOTERCER SUELDO | C14: ='FORMULARIO 2'!D13 -> 51965.06 | D14: ='FORMULARIO 2'!E13 -> 51965.06 | E14: ='FORMULARIO 2'!F13 -> 51965.06 | F14: ='FORMULARIO 2'!G13 -> 51965.06
A15: 510204 | B15: DECIMOCUARTO SUELDO | C15: ='FORMULARIO 2'!D14 -> 19116 | D15: ='FORMULARIO 2'!E14 -> 29646 | E15: ='FORMULARIO 2'!F14 -> 30375 | F15: ='FORMULARIO 2'!G14 -> 31266
A16: 5103 | B16: REMUNERACIONES COMPENSATORIAS
A17: 510306 | B17: ALIMENTACION | C17: ='FORMULARIO 2'!D16 -> 31104 | D17: ='FORMULARIO 2'!E16 -> 46656 | E17: ='FORMULARIO 2'!F16 -> 46656 | F17: ='FORMULARIO 2'!G16 -> 46656
A18: 5104 | B18: SUBSIDIOS
A19: 510401 | B19: POR CARGAS FAMILIARES | C19: ='FORMULARIO 2'!D18 -> 4157.2048 | D19: ='FORMULARIO 2'!E18 -> 6235.8072 | E19: ='FORMULARIO 2'!F18 -> 6235.8072 | F19: ='FORMULARIO 2'!G18 -> 6235.8072
A20: 510408 | B20: SUBSIDIO DE ANTIGUEDAD | C20: ='FORMULARIO 2'!D19 -> 1039.3012 | D20: ='FORMULARIO 2'!E19 -> 1558.9518 | E20: ='FORMULARIO 2'!F19 -> 1558.9518 | F20: ='FORMULARIO 2'!G19 -> 1558.9518
A21: 5106 | B21: APORTES PATRONALES A LA SEGURIDAD SOCIAL
A22: 510601 | B22: APORTE PATRONAL | C22: ='FORMULARIO 2'!D21 -> 46352.834 | D22: ='FORMULARIO 2'!E21 -> 69529.25 | E22: ='FORMULARIO 2'!F21 -> 69529.25 | F22: ='FORMULARIO 2'!G21 -> 69529.25
A23: 510602 | B23: FONDO DE RESERVA | C23: ='FORMULARIO 2'!D22 -> 34629.516 | D23: ='FORMULARIO 2'!E22 -> 51944.274 | E23: ='FORMULARIO 2'!F22 -> 51944.274 | F23: ='FORMULARIO 2'!G22 -> 51944.274
A24: 5308 | B24: BIENES DE USO Y CONSUMO CORRIENTE
A25: 530802 | B25: VESTUARIO, LENCERIA, PRENDAS DE PROTECCION | C25: ='FORMULARIO 2'!D24 -> 9126 | D25: ='FORMULARIO 2'!E24 -> 13689 | E25: ='FORMULARIO 2'!F24 -> 13689 | F25: ='FORMULARIO 2'!G24 -> 13689
A26: 5702 | B26: SEGUROS, COSTOS FINANCIEROS Y OTROS GASTOS
A27: 570201 | B27: SEGUROS | C27: ='FORMULARIO 2'!D26 -> 2592 | D27: ='FORMULARIO 2'!E26 -> 3888 | E27: ='FORMULARIO 2'!F26 -> 3888 | F27: ='FORMULARIO 2'!G26 -> 3888
A28: TOTAL DE GASTO | C28: =SUM(C11:C27) -> 615802.4 | D28: =SUM(D11:D27) -> 898693.06 | E28: =SUM(E11:E27) -> 899422.06 | F28: =SUM(F11:F27) -> 900313.06
A29: NOTA.-
A30: La presente certificacion es total responsabilidad del GADM ECHEANDÍA
A37: ='FORMULARIO 1'!A28:H28 -> Ing. Leonardo Heriberto Cueva Jimenez
A38: ='FORMULARIO 1'!A29:H29 -> DIRECTOR FINANCIERO GADM YANTZAZA
A40: ='FORMULARIO 1'!A31:H31 -> Yantzaza, 23 de abril de 2021

Sheet FORMULARIO 3
A2: ='FORMULARIO 1'!A1:H1 -> MINISTERIO DE ECONOMIA Y FINANZAS
A3: FORMULARIO 3: "COMPARATIVO ENTRE REMUNERACIÓN UNIFICADA Y PROPUESTA"
A4: DISTRIBUTIVO DE SALARIO UNIFICADO DESAGREGADO POR TRABAJADOR
A7: ='FORMULARIO 1'!A5:H5 -> GOBIERNO AUTÓNOMO DESCENTRALIZADO MUNICIPAL DE YANTZAZA
A8: ='FORMULARIO 1'!A6:H6 -> Nº PROYECTO CONTRATO COLECTIVO: DECIMO CUARTO
A11: CEDULA | B11: APELLIDOS Y NOMBRES | C11: No. TRBJ. | D11: GRADO DEL CARGO O PUESTO | E11: DENOMINACIÓN DEL PUESTO O CARGO DE OCUPACIÓN | F11: R.M.U. VIGENTE ENE - ABR 2015 | G11: R.M.U. PROPUESTA MAY - DIC 2015 | H11: R.M.U. PROPUESTA ENE - DIC 2016 | I11: R.M.U. PROPUESTA ENE - DIC 2017 | J11: R.M.U. PROPUESTA ENE - DIC 2018 | K11: OBSERVACIONES
A12: 1103055552 | B12: Aguinsaca Jaura José Pedro | C12: 1 | D12: 2 | E12: ALBAÑIL | F12: 548 | G12: 578 | H12: 578 | I12: 578 | J12: 578
A13: 1204917619 | B13: Anguisaca Campuzano Juan Carlos | C13: 2 | D13: 5 | E13: OPERADOR DE EXCAVADORA | F13: 708 | G13: 738 | H13: 738 | I13: 738 | J13: 738
A14: 1900284207 | B14: Arévalo Arévalo Mario Alcivar | C14: 3 | D14: 1 | E14: AYUDANTE DE EQUIPO CAMINERO | F14: 531 | G14: 561 | H14: 561 | I14: 561 | J14: 561
A15: 1105004830 | B15: Arévalo Correa David Waldimir | C15: 4 | D15: 3 | E15: POLICIA MUNICIPAL | F15: 566 | G15: 596 | H15: 596 | I15: 596 | J15: 596
A16: 1900457134 | B16: Armijos Godoy Franklin Hernán | C16: 5 | D16: 1 | E16: AYUDANTE DE EQUIPO CAMINERO | F16: 583.06 | G16: 583.06 | H16: 583.06 | I16: 583.06 | J16: 583.06
A17: 1900307941 | B17: Armijos González Richard Leonel | C17: 6 | D17: 8 | E17: TÉCNICO DE ELECTRICIDAD | F17: 703.83 | G17: 733.83 | H17: 733.83 | I17: 733.83 | J17: 733.83
A18: 1900310622 | B18: Armijos Puglla Henry José | C18: 7 | D18: 1 | E18: SOBRESTANTE DE HIGIENE AMBIENTAL | F18: 603.71 | G18: 603.71 | H18: 603.71 | I18: 603.71 | J18: 603.71
A19: 1900515329 | B19: Banegas Torres Bolívar Hernán | C19: 8 | D19: 5 | E19: OPERADOR DE EXCAVADORA | F19: 708 | G19: 738 | H19: 738 | I19: 738 | J19: 738
A20: 1102815279 | B20: Barba Cevallos José Reinaldo | C20: 9 | D20: 4 | E20: CHOFER DE VEHÍCULOS PESADOS | F20: 749.54 | G20: 749.54 | H20: 749.54 | I20: 749.54 | J20: 749.54
A21: 1104157688 | B21: Bastidas Galvez Lauro Miguel | C21: 10 | D21: 1 | E21: AYUDANTE DE RECOLECCIÓN DE ASEO | F21: 531 | G21: 561 | H21: 561 | I21: 561 | J21: 561
A22: 1900453224 | B22: Bautista Michay Víctor Patricio | C22: 11 | D22: 1 | E22: AYUDANTE DE EQUIPO Y/O MAQUINARIA PESADA | F22: 624.12 | G22: 624.12 | H22: 624.12 | I22: 624.12 | J22: 624.12
A23: 1900185057 | B23: Benitez Acaro Abel Mateo | C23: 12 | D23: 5 | E23: OPERADOR DE CARGADORA | F23: 921.65 | G23: 921.65 | H23: 921.65 | I23: 921.65 | J23: 921.65
... A26: 1900066695 | B26: Camacho Soto Aníbal Vidal | C26: 15 | D26: 3 | E26: POLICIA MUNICIPAL | F26: 610.36 | G26: 610.36 | H26: 610.36 | I26: 610.36 | J26: 610.36
A27: 0704860246 | B27: Cango Armijos Luis Eduardo | C27: 16 | D27: 2 | E27: SOLDADOR | F27: 548 | G27: 578 | H27: 578 | I27: 578 | J27: 578
A28: 1900406552 | B28: Cango Cuenca Fausto Lenín | C28: 17 | D28: 1 | E28: AUXILIAR DE SERVICIOS | F28: 531 | G28: 561 | H28: 561 | I28: 561 | J28: 561
A29: 1900333053 | B29: Castillo Castillo Edy Fausto | C29: 18 | D29: 1 | E29: AYUDANTE DE EQUIPO CAMINERO | F29: 567.19 | G29: 567.19 | H29: 567.19 | I29: 567.19 | J29: 567.19
A30: 1900451590 | B30: Chumapi Jumbo Walter Humberto | C30: 19 | D30: 1 | E30: JORNALERO | F30: 531 | G30: 561 | H30: 561 | I30: 561 | J30: 561
A31: 1900198589 | B31: Condolo Guaillas Pedro Francisco | C31: 20 | D31: 1 | E31: PEÓN | F31: 531 | G31: 561 | H31: 561 | I31: 561 | J31: 561
A32: 1900466721 | B32: Cuenca Cuenca César Augusto | C32: 21 | D32: 5 | E32: OPERADOR DE MAQUINARIA O EQUIPO PESADO | F32: 708 | G32: 738 | H32: 738 | I32: 738 | J32: 738
A33: 1900127752 | B33: Cueva Ochoa Vicente Medardo | C33: 22 | D33: 1 | E33: JORNALERO DE PARQUES Y JARDINES | F33: 594.11 | G33: 594.11 | H33: 594.11 | I33: 594.11 | J33: 594.11
A34: 1101576856 | B34: Curipoma Macas Manuel Salvador | C34: 23 | D34: 1 | E34: JORNALERO DE PARQUES Y JARDINES | F34: 531 | G34: 561 | H34: 561 | I34: 561 | J34: 561
A35: 1103226997 | B35: Espinosa Cumbicos Neli Esmeralda | C35: 24 | D35: 1 | E35: JORNALERO | F35: 603.68 | G35: 603.68 | H35: 603.68 | I35: 603.68 | J35: 603.68
A36: 1900668763 | B36: Godoy Mendoza Braulio Ricardo | C36: 25 | D36: 1 | E36: MENSAJERO | F36: 531 | G36: 561 | H36: 561 | I36: 561 | J36: 561
A37: 1900240050 | B37: González Cabrera Darwin Patricio | C37: 26 | D37: 4 | E37: CHOFER DE RECOLECTOR | F37: 584 | G37: 614 | H37: 614 | I37: 614 | J37: 614
A38: 1900334440 | B38: Gualán Caillagua Fredy Gustavo | C38: 27 | D38: 2 | E38: GASFITERO O PLOMERO | F38: 612.76 | G38: 612.76 | H38: 612.76 | I38: 612.76 | J38: 612.76
A39: 1103301725 | B39: Gualán Gualán Ángel Benigno | C39: 28 | D39: 5 | E39: OPERADOR RETROEXCAVADORA | F39: 708 | G39: 738 | H39: 738 | I39: 738 | J39: 738
... A54: 1900369560 | B54: Montalvan Gómez Jaime Rodrigo | C54: 43 | D54: 5 | E54: OPERADOR DE MOTONIVELADORA | F54: 708 | G54: 738 | H54: 738 | I54: 738 | J54: 738
A55: 1900411404 | B55: Montaño Márquez Roberto Carlos | C55: 44 | D55: 3 | E55: POLICIA MUNICIPAL | F55: 610.36 | G55: 610.36 | H55: 610.36 | I55: 610.36 | J55: 610.36
A56: 1900253558 | B56: Morales Cabrera José Efrén | C56: 45 | D56: 5 | E56: OPERADOR RETROEXCAVADORA | F56: 708 | G56: 738 | H56: 738 | I56: 738 | J56: 738
A57: 1101785986 | B57: Morocho Chamba Ángel Benigno | C57: 46 | D57: 4 | E57: CHOFER DE VEHÍCULOS PESADOS | F57: 584 | G57: 614 | H57: 614 | I57: 614 | J57: 614
A58: 1102603444 | B58: Morocho Salinas José Patricio | C58: 47 | D58: 4 | E58: CHOFER DE VEHÍCULOS PESADOS | F58: 630 | G58: 630 | H58: 630 | I58: 630 | J58: 630
A59: 1900359082 | B59: Mosquera Calero Manuel Agustín | C59: 48 | D59: 6 | E59: INSPECTOR DE MAQUINARIA Y TRABAJOS MUN | F59: 743 | G59: 773 | H59: 773 | I59: 773 | J59: 773
A60: 1900568534 | B60: Naula Montaño Marcelo Ismael | C60: 49 | D60: 5 | E60: OPERADOR DE EXCAVADORA | F60: 708 | G60: 738 | H60: 738 | I60: 738 | J60: 738
A61: 1900521939 | B61: Ochoa Rodríguez José Joaquin | C61: 50 | D61: 1 | E61: AYUDANTE DE EQUIPO CAMINERO | F61: 531 | G61: 561 | H61: 561 | I61: 561 | J61: 561
...

Sheet FORMULARIO 4
A1: MINISTERIO DE ECONOMIA Y FINANZAS
A2: FORMULARIO 4 "FLUJO PRESUPUESTARIO DE INGRESOS Y GASTOS"
A4: ='FORMULARIO 1'!A5:H5 -> GOBIERNO AUTÓNOMO DESCENTRALIZADO MUNICIPAL DE YANTZAZA
A6: DETALLE DE GRUPOS Y SUBGRUPOS | C6: FLUJO HISTORICO (USD) | I6: FLUJO PROYECTADO (USD) | M6: OBSERVACIONES
A7: Grupo y Subgrupo | B7: Descripción | C7: 2015 | D7: 2016 | E7: 2017 | F7: 2018 | G7: 2019 | H7: 2020 | I7: 2021 | J7: 2022 | K7: 2023 | L7: 2024
A8: TOTAL INGRESOS CORRIENTES (1) | C8: =SUM(C9,C13,C17:C20) -> 3247931 | D8: =SUM(D9,D13,D17:D20) -> 2846323.2 | E8: =SUM(E9,E13,E17:E20) -> 1349651.6 | F8: =SUM(F9,F13,F17:F20) -> 4733296.6 | G8: =SUM(G9,G13,G17:G20) -> 5081231.9 | H8: =SUM(H9,H13,H17:H20) -> 5725427.7 | I8: =SUM(I9,I13,I17:I20) -> 5868563.4 | J8: =SUM(J9,J13,J17:J20) -> 6015277.5 | ... L8: =SUM(L9,L13,L17:L20) -> 6319800.9
A9: 11 | B9: Impuestos | C9: =SUM(C10:C12) -> 967650.68 | D9: =SUM(D10:D12) -> 1033052.6 | E9: =SUM(E10:E12) -> 144135.56 | F9: =SUM(F10:F12) -> 1546509.2 | G9: =SUM(G10:G12) -> 2231453.2 | H9: =SUM(H10:H12) -> 2951059.8 | I9: =SUM(I10:I12) -> 3024836.3 | J9: =SUM(J10:J12) -> 3100457.2 | ... L9: =SUM(L10:L12) -> 3257417.9
A10: 1.1.01 | B10: Sobre la Renta, Utilidades y Ganancias de Capital | C10: 93116.3 | D10: 58723.33 | E10: 10235 | F10: 84797.2 | G10: 81474.7 | H10: 71749.69 | I10: =H10*1.025 -> 73543.432 | J10: =I10*1.025 -> 75382.018 | K10: =J10*1.025 -> 77266.569 | L10: =K10*1.025 -> 79198.233
A11: 1.1.02 | B11: Sobre la propiedad | C11: 636882.69 | D11: 751767.77 | E11: 96157.93 | F11: 1189771.8 | G11: 1804598.1 | H11: 2388529.2 | I11: =H11*1.025 -> 2448242.4 | J11: =I11*1.025 -> 2509448.4 | K11: =J11*1.025 -> 2572184.7 | L11: =K11*1.025 -> 2636489.3
A12: 1.1.07 | B12: Impuestos Diversos | C12: 237651.69 | D12: 222561.54 | E12: 37742.63 | F12: 271940.24 | G12: 345380.36 | H12: 490780.97 | I12: =H12*1.025 -> 503050.49 | J12: =I12*1.025 -> 515626.76 | K12: =J12*1.025 -> 528517.43 | L12: =K12*1.025 -> 541730.36
A13: 13 | B13: Tasas y contribuciones | C13: =SUM(C14:C16) -> 456174.06 | D13: =SUM(D14:D16) -> 449225.21 | E13: =SUM(E14:E16) -> 168544.68 | F13: =SUM(F14:F16) -> 1474118.4 | G13: =SUM(G14:G16) -> 1044660.4 | H13: =SUM(H14:H16) -> 1259095.9 | I13: =SUM(I14:I16) -> 1290573.3 | J13: =SUM(J14:J16) -> 1322837.7 | ... L13: =SUM(L14:L16) -> 1389806.3
A14: 1.3.01 | B14: Tasas generales | C14: 416523.72 | D14: 418858.69 | E14: 168544.68 | F14: 1439364.9 | G14: 641076.19 | H14: 673566.46 | I14: =H14*1.025 -> 690405.62 | J14: =I14*1.025 -> 707665.76 | K14: =J14*1.025 -> 725357.41 | L14: =K14*1.025 -> 743491.34
A15: 1.3.03 | B15: Tasas Diversas | C15: 0 | D15: 0 | E15: 0 | F15: 20457.23 | G15: 389896.61 | H15: 573492.86 | I15: =H15*1.025 -> 587830.18 | J15: =I15*1.025 -> 602525.94 | K15: =J15*1.025 -> 617589.08 | L15: =K15*1.025 -> 633028.81
A16: 1.3.04 | B16: Contribuciones | C16: 39650.34 | D16: 30366.52 | E16: 0 | F16: 14296.25 | G16: 13687.6 | H16: 12036.62 | I16: =H16*1.025 -> 12337.535 | J16: =I16*1.025 -> 12645.974 | K16: =J16*1.025 -> 12962.123 | L16: =K16*1.025 -> 13286.176
A17: 14 | B17: Venta de Bienes y Servicios | C17: 287488.94 | D17: 276620.11 | E17: 123075.91 | F17: 356681.46 | G17: 409549.71 | H17: 422844.29 | I17: =H17*1.025 -> 433415.4 | J17: =I17*1.025 -> 444250.78 | K17: =J17*1.025 -> 455357.05 | L17: =K17*1.025 -> 466740.98
A18: 17 | B18: Rentas de Invesiones y Multas | C18: 118099.83 | D18: 132498.15 | E18: 41797.31 | F18: 193331.48 | G18: 212876.27 | H18: 165895.67 | I18: =H18*1.025 -> 170043.06 | J18: =I18*1.025 -> 174294.14 | K18: =J18*1.025 -> 178651.49 | L18: =K18*1.025 -> 183117.78
A19: 18 | B19: Transferencias y Donaciones Corrientes | C19: 1392333 | D19: 925597.74 | E19: 857961.67 | F19: 1139993.9 | G19: 1039488.3 | H19: 864136.38 | I19: =H19*1.025 -> 885739.79 | J19: =I19*1.025 -> 907883.28 | K19: =J19*1.025 -> 930580.37 | L19: =K19*1.025 -> 953844.88
A20: 19 | B20: Otros ingresos | C20: =SUM(C21:C21) -> 26184.41 | D20: =SUM(D21:D21) -> 29329.4 | E20: =SUM(E21:E21) -> 14136.47 | F20: =SUM(F21:F21) -> 22662.23 | G20: =SUM(G21:G21) -> 143204.03 | H20: =SUM(H21:H21) -> 62395.62 | I20: =SUM(I21:I21) -> 63955.51 | J20: =SUM(J21:J21) -> 65554.398 | ... L20: =SUM(L21:L21) -> 68873.09
A21: 1.9.04 | B21: Otros no Operacionales | C21: 26184.41 | D21: 29329.4 | E21: 14136.47 | F21: 22662.23 | G21: 143204.03 | H21: 62395.62 | I21: =H21*1.025 -> 63955.51 | J21: =I21*1.025 -> 65554.398 | K21: =J21*1.025 -> 67193.258 | L21: =K21*1.025 -> 68873.09
A22: TOTAL GASTOS CORRIENTES (2) | C22: =SUM(C23,C40,C50,C53,C56) -> 2774531.2 | D22: =SUM(D23,D40,D50,D53,D56) -> 2286649.7 | E22: =SUM(E23,E40,E50,E53,E56) -> 2236453.9 | F22: =SUM(F23,F40,F50,F53,F56) -> 2458555.1 | G22: =SUM(G23,G40,G50,G53,G56) -> 2935706.6 | H22: =SUM(H23,H40,H50,H53,H56) -> 2718089.2 | I22: =SUM(I23,I40,I50,I53,I56) -> 2786041.4 | J22: =SUM(J23,J40,J50,J53,J56) -> 2855692.4 | ... L22: =SUM(L23,L40,L50,L53,L56) -> 3000261.9
A23: 51 | B23: Gastos en personal | C23: =SUM(C24:C39) -> 2165295.4 | D23: =SUM(D24:D39) -> 1713301.6 | E23: =SUM(E24:E39) -> 1677904.9 | F23: =SUM(F24:F39) -> 1962304.9 | G23: =SUM(G24:G39) -> 2097424.3 | H23: =SUM(H24:H39) -> 2049503.3 | I23: =SUM(I24:I39) -> 2100740.9 | J23: =SUM(J24:J39) -> 2153259.4 | ... L23: =SUM(L24:L39) -> 2262268.2
A24: 5.1.01.05 | B24: Remuneraciones Unificadas | C24: 747880.52 | D24: 544874.28 | E24: 592199.5 | F24: 768452.03 | G24: 852272.51 | H24: 839204.25 | I24: =H24*1.025 -> 860184.36 | J24: =I24*1.025 -> 881688.97 | K24: =J24*1.025 -> 903731.19 | L24: =K24*1.025 -> 926324.47
A25: 5.1.01.06 | B25: Salazarios Unificados | C25: 456277.38 | D25: 310149.81 | E25: 289597.25 | F25: 299573.99 | G25: 285234.1 | H25: 272492.22 | I25: =H25*1.025 -> 279304.53 | J25: =I25*1.025 -> 286287.14 | K25: =J25*1.025 -> 293444.32 | L25: =K25*1.025 -> 300780.43
A26: 5.1.02.03 | B26: Décimo tercer sueldo | C26: 126845.23 | D26: 103933.71 | E26: 101155.03 | F26: 110074.82 | G26: 122723.23 | H26: 129560.59 | I26: =H26*1.025 -> 132799.6 | J26: =I26*1.025 -> 136119.59 | K26: =J26*1.025 -> 139522.58 | L26: =K26*1.025 -> 143010.65
A27: 5.1.02.04 | B27: Décimo cuarto sueldo | C27: 65210.24 | D27: 48696.68 | E27: 43370.02 | F27: 50950.38 | G27: 55003.34 | H27: 71441.19 | I27: =H27*1.025 -> 73227.22 | J27: =I27*1.025 -> 75057.9 | K27: =J27*1.025 -> 76934.348 | L27: =K27*1.025 -> 78857.706
A28: 5.1.04.01 | B28: Por Cargas Familiares | C28: 2981.76 | D28: 1795.86 | E28: 1995 | F28: 2066.01 | G28: 1924.95 | H28: 2182.08 | I28: =H28*1.025 -> 2236.632 | J28: =I28*1.025 -> 2292.5478 | K28: =J28*1.025 -> 2349.8615 | L28: =K28*1.025 -> 2408.608
A29: 5.1.04.08 | B29: Subsidio De Antiguedad | C29: 10724.4 | D29: 5730.79 | E29: 4503.24 | F29: 8296.5 | G29: 7108.86 | H29: 6942.24 | I29: =H29*1.025 -> 7115.796 | J29: =I29*1.025 -> 7293.6909 | K29: =J29*1.025 -> 7476.0332 | L29: =K29*1.025 -> 7662.934
A30: 5.1.05.07 | B30: Honorarios | C30: 0 | D30: 6955.73 | E30: 10653.19 | F30: 9113.8 | G30: 5634.91 | H30: 0 | I30: =H30*1.025 -> 0 | J30: =I30*1.025 -> 0 | K30: =J30*1.025 -> 0 | L30: =K30*1.025 -> 0
A31: 5.1.05.09 | B31: Horas Extraordinarias Y Suplementarias | C31: 8048.51 | D31: 11381.86 | E31: 8113.44 | F31: 4977.34 | G31: 6658.32 | H31: 7679.05 | I31: =H31*1.025 -> 7871.0262 | J31: =I31*1.025 -> 8067.8019 | K31: =J31*1.025 -> 8269.497 | L31: =K31*1.025 -> 8476.2344
A32: 5.1.05.10 | B32: Servicios personales por contrato | C32: 297257.53 | D32: 365792.49 | E32: 337975.29 | F32: 287487.04 | G32: 365918.46 | H32: 436762.97 | I32: =H32*1.025 -> 447682.04 | J32: =I32*1.025 -> 458874.1 | K32: =J32*1.025 -> 470345.95 | L32: =K32*1.025 -> 482104.6
A33: 5.1.05.12 | B33: Subrogacion | C33: 3500.52 | D33: 3695.8 | E33: 5586.02 | F33: 4748.28 | G33: 555.67 | H33: 1681.62 | I33: =H33*1.025 -> 1723.6605 | J33: =I33*1.025 -> 1766.752 | K33: =J33*1.025 -> 1810.9208 | L33: =K33*1.025 -> 1856.1938
A34: 5.1.06.01 | B34: Aporte patronal | C34: 185023.35 | D34: 148337.2 | E34: 142720.14 | F34: 171295.01 | G34: 177198.17 | H34: 183028.94 | I34: =H34*1.025 -> 187604.66 | J34: =I34*1.025 -> 192294.78 | K34: =J34*1.025 -> 197102.15 | L34: =K34*1.025 -> 202029.7
A35: 5.1.06.02 | B35: Fondo de reserva | C35: 82164.59 | D35: 79192.49 | E35: 80193.66 | F35: 85302.88 | G35: 71487.11 | H35: 81269.99 | I35: =H35*1.025 -> 83301.74 | J35: =I35*1.025 -> 85384.283 | K35: =J35*1.025 -> 87518.89 | L35: =K35*1.025 -> 89706.863
... A39: 5.1.07.11 | B39: Indemnizaciones Laborales | C39: 160610.76 | D39: 52911.45 | E39: 46168.6 | F39: 15546.78 | G39: 0 | H39: 0 | I39: =H39*1.025 -> 0 | J39: =I39*1.025 -> 0 | K39: =J39*1.025 -> 0 | L39: =K39*1.025 -> 0
A40: 53 | B40: Bienes y servicios de consumo | C40: =SUM(C41:C49) -> 360968.99 | D40: =SUM(D41:D49) -> 271170.83 | E40: =SUM(E41:E49) -> 287599.06 | F40: =SUM(F41:F49) -> 265578.02 | G40: =SUM(G41:G49) -> 296706.27 | H40: =SUM(H41:H49) -> 291358.46 | I40: =SUM(I41:I49) -> 298642.42 | J40: =SUM(J41:J49) -> 306108.48 | ... L40: =SUM(L41:L49) -> 321605.22
A41: 5.3.01 | B41: Servicios Básicos | C41: 62635.16 | D41: 55218.28 | E41: 74825.63 | F41: 62677.8 | G41: 73223.15 | H41: 68926.92 | I41: =H41*1.025 -> 70650.093 | J41: =I41*1.025 -> 72416.345 | K41: =J41*1.025 -> 74226.754 | L41: =K41*1.025 -> 76082.423
A42: 5.3.02 | B42: Servicios Generales | C42: 32852.1 | D42: 60091.74 | E42: 24938.13 | F42: 14097.48 | G42: 18708.03 | H42: 28648.68 | I42: =H42*1.025 -> 29364.897 | J42: =I42*1.025 -> 30099.019 | K42: =J42*1.025 -> 30851.495 | L42: =K42*1.025 -> 31622.782
A43: 5.3.03 | B43: Traslados, Instalaciones, Viáticos y Subsistencias | C43: 13898.33 | D43: 9192.44 | E43: 13988.42 | F43: 13189.28 | G43: 14036.67 | H43: 3692.75 | I43: =H43*1.025 -> 3785.0687 | J43: =I43*1.025 -> 3879.6955 | K43: =J43*1.025 -> 3976.6879 | L43: =K43*1.025 -> 4076.1051
A44: 5.3.04 | B44: Instalación, Mantenimiento y Reparaciones | C44: 17862.26 | D44: 8776.53 | E44: 15052 | F44: 27997.7 | G44: 18933.22 | H44: 33178.08 | I44: =H44*1.025 -> 34007.532 | J44: =I44*1.025 -> 34857.72 | K44: =J44*1.025 -> 35729.163 | L44: =K44*1.025 -> 36622.392
A45: 5.3.05 | B45: Arrendamientos de Bienes | C45: 26.88 | D45: 1209.44 | E45: 2722.88 | F45: 6666.24 | G45: 4898.73 | H45: 7020 | I45: =H45*1.025 -> 7195.5 | J45: =I45*1.025 -> 7375.3875 | K45: =J45*1.025 -> 7559.7722 | L45: =K45*1.025 -> 7748.7665
...
