Workbook

Sheet FORMULARIO 1
A1: MINISTERIO DE FINANZAS
A2: FORMULARIO 1: "FUENTES DE FINANCIAMIENTO DEL PROYECTO DE CONTRATO COLECTIVO"
A3: DETALLE DE INGRESOS
A5: EMPRESA PUBLICA DE VIALIDAD DEL SUR
A6: Nº PROYECTO CONTRATO COLECTIVO PROYECTO DECIMO NOVENO
A7: Nº ACTA TRANSACCIONAL ___________________________
A9: FUENTES DE FINANCIAMIENTO | C9: FINANCIAMIENTO REAL DEL CONTRATO COLECTIVO VIGENTE USD 2014 | D9: FINANCIAMIENTO REAL DEL CONTRATO COLECTIVO PROPUESTO USD 2015 | E9: FINANCIAMIENTO REAL DEL CONTRATO COLECTIVO PROPUESTO USD 2016 | F9: FINANCIAMIENTO REAL DEL CONTRATO COLECTIVO PROPUESTO USD 2017 | G9: FINANCIAMIENTO REAL DEL CONTRATO COLECTIVO PROPUESTO USD 2018 | H9: FINANCIAMIENTO REAL DEL CONTRATO COLECTIVO PROPUESTO USD 2019 | I9: OBSERVACIONES
A10: INGRESOS CORRIENTES Y PERMANENTES
A11: 11 | B11: POR IMPUESTOS
A12: 1101 | B12: Sobre la Renta, Utilidades y Ganancias de Capital
A13: 1102 | B13: Sobre la propiedad
A14: 1103 | B14: Al consumo de Bienes y Servicios
A15: 1107 | B15: Impuestos Diversos
A17: 13 | B17: TASAS Y CONTRIBUCIONES
A18: 1301 | B18: Tasas generales
A19: 1302 | B19: Tasas portuarias y aeroportuarias
A20: 1303 | B20: Tasas diversas
A21: 1304 | B21: Contribuciones
A23: 14 | B23: VENTA DE BIENES Y SERVICIOS
A25: 17 | B25: RENTAS DE INVERSIONES Y MULTAS
A27: 28 | B27: TRANSFERENCIAS Y DONACIONES CORRIENTES
B28: GOBIERNO PROVINCIAL DE LOJA | C28: ='FORMULARIO 2'!C36 -> 3899938.3 | D28: ='FORMULARIO 2'!D36 -> 4053864.5 | E28: ='FORMULARIO 2'!E36 -> 3751997.6 | F28: ='FORMULARIO 2'!F36 -> 3014753.1 | G28: ='FORMULARIO 2'!G36 -> 3056346 | H28: ='FORMULARIO 2'!H36 -> 3131602.4 | I28: PROGRAMA MANTENIMIENTO Y MEJORAMIENTO VIAL
B29: TOTAL | C29: =C28 -> 3899938.3 | D29: =D28 -> 4053864.5 | E29: =E28 -> 3751997.6 | F29: =F28 -> 3014753.1 | G29: =G28 -> 3056346 | H29: =H28 -> 3131602.4
B30: INCREMENTO PORCENTUAL | D30: =(D29/C29-1)*100 -> 3.9468897 | E30: =(E29/C29-1)*100 -> -3.793409 | F30: =(F29/C29-1)*100 -> -22.697414 | G30: =(G29/C29-1)*100 -> -21.630912 | H30: =(H29/C29-1)*100 -> -19.70123
A32: * De ser el caso, se deberá incluir filas adicionales, para detallar los subgrupos o items correspondientes.
A33: * En caso de que en el contrato colectivo se negocie algún beneficio adicional a los expuestos favor incluir el item correspondiente.
A34: * La información de los formularios deberá remitirse en medio magnético (Excel) e impreso con las respectivas firmas de responsabilidad.
B39: FIRMA DIRECTOR (A) FINANCIERO (A)
B41: Nombre: Ing. Roberto Astudillo Medina
B43: Lugar y Fecha: 26 Noviembre 2019
B44: Sello Institucional

Sheet FORMULARIO 2
A1: FORMULARIO 2: "COSTOS DEL PROYECTO DE CONTRATO COLECTIVO"
A2: EMPRESA PUBLICA DE VIALIDAD DEL SUR
A3: Nº PROYECTO CONTRATO COLECTIVO DECIMO NOVENO
A4: Nº ACTA TRANSACCIONAL ___________________________
A6: CLASIFICADOR PRESUPUESTARIO | B6: GASTO DEL PERSONAL | C6: COSTO REAL DEL CONTRATO COLECTIVO VIGENTE USD 2014 | D6: COSTO REAL DEL CONTRATO COLECTIVO PROPUESTO USD 2015 | E6: COSTO REAL DEL CONTRATO COLECTIVO PROPUESTO USD 2016 | F6: COSTO REAL DEL CONTRATO COLECTIVO PROPUESTO USD 2017 | G6: COSTO REAL DEL CONTRATO COLECTIVO PROPUESTO USD 2018 | H6: COSTO ESTIMADO DEL CONTRATO COLECTIVO PROPUESTO USD 2019 | I6: OBSERVACIONES
A7: GASTO PERSONAL
A8: 7101 | B8: REMUNERACIONES BASICAS
A9: 710106 | B9: SALARIOS UNIFICADOS | C9: 1988598 | D9: 1953895.4 | E9: 1948134.2 | F9: 1906754.9 | G9: 1899780.2 | H9: 1801684 | I9: PROGRAMA MANTENIMIENTO Y MEJORAMIENTO VIAL
A11: 7102 | B11: REMUNERACIONES COMPLEMENTARIAS
A12: 710203 | B12: DECIMOTERCER SUELDO | C12: 165716.5 | D12: 162824.62 | E12: 162344.52 | F12: 158896.24 | G12: 158315.02 | H12: 150140.33
A13: 710204 | B13: DECIMOCUARTO SUELDO | C13: 86020 | D13: 89562 | E13: 90036 | F13: 93375 | G13: 95480 | H13: 97712
A15: 7103 | B15: REMUNERACIONES COMPENSATORIAS
A16: 710304 | B16: COMPENSACION POR TRANSPORTE | C16: 33396 | D16: 33187 | E16: 32472 | F16: 32868 | G16: 32736 | H16: 32736
A17: 710306 | B17: ALIMENTACION | C17: 267168 | D17: 265496 | E17: 259776 | F17: 262944 | G17: 261888 | H17: 261888
A19: 7104 | B19: SUBSIDIOS
A20: 710401 | B20: POR CARGAS FAMILIARES | C20: 8690.4 | D20: 13211 | E20: 13395.6 | F20: 13606.92 | G20: 13305.6 | H20: 11873.4
A21: 710408 | B21: SUBSIDIO POR ANTIGÜEDAD | C21: 19818.72 | D21: 23006.52 | E21: 27226.2 | F21: 32561.529 | G21: 38146.486 | H21: 40515.893
A22: 7105 | B22: REMUNERACIONES TEMPORALES
A23: 710509 | B23: HORAS EXTRAORDINARIAS Y SUPLEMENTARIAS | C23: 0 | D23: 0 | E23: 0
A25: 7106 | B25: APORTES A LA SEGURIDAD SOCIAL
A26: 710601 | B26: APORTE PATRONAL | C26: 240854.31 | D26: 240149.82 | E26: 235850.89 | F26: 239226.21 | G26: 238378.79 | H26: 238575.62
A27: 710602 | B27: FONDO DE RESERVA | C27: 165716.5 | D27: 162824.62 | E27: 162344.52 | F27: 158896.24 | G27: 158315.02 | H27: 150140.33
A28: 710603 | B28: FONDO DE JUBILACION PATRONAL | C28: 39230.65 | D28: 46911.25 | E28: 44318.96 | F28: 11828.942 | G28: 11010.82 | H28: 62506.006
A30: 7107 | B30: INDEMNIZACIONES
A31: 710704 | B31: COMPENSACION POR DESAHUCIO | C31: 0 | D31: 0 | E31: 0
A32: 710705 | B32: POR JUBILACIÓN | C32: 716036.22 | D32: 851819.38 | E32: 736502.9 | F32: 95139.467 | G32: 141430.67 | H32: 258344.61
A33: 730802 | B33: VESTUARIO, LENCERIA Y PRENDAS DE PROTECCION | C33: 168692.95 | D33: 201861.48 | E33: 30940.11 | F33: 0 | G33: 0 | H33: 20776.48
A34: 770201 | B34: SEGUROS | C34: 0 | D34: 9115.38 | E34: 8655.7 | F34: 8655.7 | G34: 7559.4 | H34: 4709.8
B36: TOTAL | C36: =SUM(C8:C35) -> 3899938.3 | D36: =SUM(D9:D35) -> 4053864.5 | E36: =SUM(E8:E35) -> 3751997.6 | F36: =SUM(F9:F35) -> 3014753.1 | G36: =SUM(G9:G35) -> 3056346 | H36: =SUM(H9:H35) -> 3131602.4
D37: =(D36/C36-1)*100 -> 3.9468897 | E37: =(E36/C36-1)*100 -> -3.793409 | F37: =(F36/C36-1)*100 -> -22.697414 | G37: =(G36/C36-1)*100 -> -21.630912 | H37: =(H36/C36-1)*100 -> -19.70123
A38: * De ser el caso, se deberá incluir filas adicionales, para detallar los subgrupos o items correspondientes.
A39: * En caso de que en el contrato colectivo se negocie algún beneficio adicional a los expuestos favor incluir el item correspondiente.
A40: * La información de los formularios deberá remitirse en medio magnético (Excel) e impreso con las respectivas firmas de responsabilidad.
B44: FIRMA DIRECTOR (A) FINANCIERO (A)
B46: Nombre: Ing. Roberto Astudillo Medina
B47: Lugar y Fecha: 26 Noviembre 2019
B48: Sello Institucional

Sheet FORMULARIO 3
A1: MINISTERIO DE FINANZAS
A2: FORMULARIO 3: "COMPARATIVO ENTRE REMUNERACIÓN UNIFICADA Y PROPUESTA"
A3: DISTRIBUTIVO DE SALARIO UNIFICADO DESAGREGADO POR TRABAJADOR
A5: EMPRESA PÚBLICA DE VIALIDAD DEL SUR
A6: Nº PROYECTO CONTRATO COLECTIVO: DECIMO NOVENO
A7: Nº ACTA TRANSACCIONAL ___________________________
F8: 2014 | G8: 2015 | H8: 2016 | I8: 2017 | J8: 2018 | K8: 2019
A9: CEDULA | B9: APELLIDOS Y NOMBRES | C9: No. TRABAJADOR | D9: GRADO DEL CARGO O PUESTO | E9: DENOMINACIÓN DEL PUESTO O CARGO DE OCUPACIÓN | F9: REMUNERACIÓN UNIFICADA 2014 | G9: REMUNERACIÓN UNIFICADA CONTRATO COLECTIVO PROPUESTO USD $ | H9: REMUNERACIÓN UNIFICADA CONTRATO COLECTIVO PROPUESTO USD $ | I9: REMUNERACIÓN UNIFICADA CONTRATO COLECTIVO PROPUESTO USD $ | J9: REMUNERACIÓN UNIFICADA CONTRATO COLECTIVO PROPUESTO USD $ | K9: REMUNERACIÓN UNIFICADA CONTRATO COLECTIVO PROPUESTO USD $ | L9: OBSERVACIONES | M9: FECHA DE INGRESO A VIALSUR E.P.
A10: 1101414793 | B10: ABRIGO DIAZ MARCO ALBERTO | C10: 1 | D10: 1 | E10: GUARDIAN | F10: 565.22 | G10: 565.22 | H10: 565.22 | I10: 565.22 | J10: 565.22 | K10: 565.22 | L10: SOBREVALORADO | M10: 40909
A11: 1101891743 | B11: ABRIGO ORTEGA ANGEL BOLIVAR | C11: 2 | D11: 5 | E11: OPERADOR DE MOTONIVELADORA | F11: 889.33 | G11: 889.33 | H11: 889.33 | I11: 889.33 | J11: 889.33 | K11: 889.33 | L11: SOBREVALORADO | M11: 40909
A12: 1102409362 | B12: AGILA VASQUEZ JOSE ARMANDO | C12: 3 | D12: 1 | E12: AYUDANTE DE EQUIPO Y/O MAQUINARIA PESADA | F12: 565.22 | G12: 565.22 | H12: 565.22 | I12: 565.22 | J12: 565.22 | K12: 565.22 | L12: SOBREVALORADO | M12: 40909
A13: 1102462072 | B13: AGUIRRE GUZMAN JORGE ROLANDO | C13: =+C12+1 -> 4 | D13: 5 | E13: OPERADOR DE MAQUINARIA O EQUIPO PESADO | F13: 733 | G13: 733 | H13: 733 | I13: 733 | J13: 733 | K13: 733 | L13: SOBREVALORADO | M13: 41640
A14: 1104225295 | B14: AGUIRRE PAZ RAMIRO GABRIEL | C14: =+C13+1 -> 5 | D14: 1 | E14: AYUDANTE DE EQUIPO Y/O MAQUINARIA PESADA | F14: 565.22 | G14: 565.22 | H14: 565.22 | I14: 565.22 | J14: 565.22 | K14: 565.22 | L14: SOBREVALORADO | M14: 40909
A15: 1101977617 | B15: AGURTO ERIQUE VICTOR VICENTE | C15: =+C14+1 -> 6 | D15: 4 | E15: CHOFER DE VEHÍCULO PESADO | F15: 615.22 | G15: 615.22 | H15: 615.22 | I15: 615.22 | J15: 615.22 | K15: 615.22 | L15: SOBREVALORADO | M15: 40909
A16: 0101325512 | B16: ALARCON HUGO ANIBAL | C16: =+C15+1 -> 7 | D16: 9 | E16: SUPERVISOR MANTENIMIENTO, EQUIPO PESADO Y AUTOMOTRIZ | F16: 1067.86 | G16: 1067.86 | H16: 1067.86 | I16: 1067.86 | J16: 1067.86 | K16: 1067.86 | L16: SOBREVALORADO | M16: 40909
A17: 1101705117 | B17: ALBERCA ARMIJOS CESARIO AGUSTIN | C17: =+C16+1 -> 8 | D17: 1 | E17: CADENERO | F17: 565.22 | G17: 565.22 | H17: 565.22 | I17: 565.22 | J17: 565.22 | K17: 565.22 | L17: SOBREVALORADO | M17: 40909
A18: 1101740460 | B18: ALVARADO ALVARADO MANUEL IGNACIO | C18: =+C17+1 -> 9 | D18: 5 | E18: OPERADOR DE DISTRIBUIDOR DE AGREGADOS | F18: 733.22 | G18: 733.22 | H18: 733.22 | I18: 733.22 | J18: 733.22 | K18: 733.22 | L18: SOBREVALORADO | M18: 40909
A19: 1102957576 | B19: ALVARADO JARAMILLO JUAN CARLOS | C19: =+C18+1 -> 10 | D19: 1 | E19: GUARDIAN | F19: 565.22 | G19: 565.22 | H19: 565.22 | I19: 565.22 | J19: 565.22 | K19: 565.22 | L19: SOBREVALORADO | M19: 40909
A20: 1100202439 | B20: ALVARADO LEON ELEUTERIO | C20: =+C19+1 -> 11 | D20: 5 | E20: OPERADOR DE EXCAVADORA | F20: 733.22 | G20: 733.22 | H20: 733.22 | I20: 733.22 | J20: 733.22 | K20: 733.22 | L20: SOBREVALORADO | M20: 40909
A21: 1104163082 | B21: ALVAREZ CHAVEZ JUAN PABLO | C21: =+C20+1 -> 12 | D21: 1 | E21: AYUDANTE DE MECÁNICA DE EQUIPO Y/O MAQUINARIA | F21: 565.22 | G21: 565.22 | H21: 565.22 | I21: 565.22 | J21: 565.22 | K21: 565.22 | L21: SOBREVALORADO | M21: 40909
A22: 1102165659 | B22: APOLO PINZA ELSA | C22: =+C21+1 -> 13 | D22: 2 | E22: COCINERO-PROVEEDORA | F22: 581.22 | G22: 581.22 | H22: 581.22 | I22: 581.22 | J22: 581.22 | K22: 581.22 | L22: SOBREVALORADO | M22: 40909
A23: 1703633683 | B23: ARBOLEDA ORDOÑEZ MODESTO LOSTICO | C23: =+C22+1 -> 14 | D23: 1 | E23: DESPACHADOR DE MATERIALES | F23: 565.22 | G23: 565.22 | H23: 565.22 | I23: 565.22 | J23: 565.22 | K23: 0 | L23: RETIRO VOLUNTARIO PARA ACOGERSE A LA JUBILACION 2018. | M23: 40909
A24: 1102863857 | B24: AREVALO SUCUNUTA VICTOR ALFREDO | C24: =+C23+1 -> 15 | D24: 4 | E24: CHOFER DE VEHÍCULO PESADO | F24: 615.22 | G24: 615.22 | H24: 615.22 | I24: 615.22 | J24: 615.22 | K24: 615.22 | L24: SOBREVALORADO | M24: 40909
A25: 1102175229 | B25: AREVALO VALDIVIESO RICHARD SONY | C25: =+C24+1 -> 16 | D25: 1 | E25: AYUDANTE DE MECÁNICA | F25: 565 | G25: 565 | H25: 565 | I25: 565 | J25: 565 | K25: 565 | L25: SOBREVALORADO | M25: 41640
A26: 1103403760 | B26: ARIAS VIVANCO ESTEBAN MANUEL | C26: =+C25+1 -> 17 | D26: 4 | E26: CHOFER DE VEHÍCULO PESADO | F26: 615.22 | G26: 615.22 | H26: 615.22 | I26: 615.22 | J26: 615.22 | K26: 615.22 | L26: SOBREVALORADO | M26: 40909
A27: 1102980826 | B27: ARMIJOS VICENTE ARIELITO | C27: =+C26+1 -> 18 | D27: 1 | E27: AYUDANTE DE EQUIPO Y/O MAQUINARIA PESADA | F27: 615.22 | G27: 0 | H27: 0 | I27: 0 | J27: 0 | K27: 0 | L27: TRASPASO AL GPL EL 01 ENERO 2015 | M27: 40909
A28: 1104398951 | B28: ARMIJOS CABRERA JUNIOR ONOFRE | C28: =+C27+1 -> 19 | D28: 5 | E28: OPERADOR DE EXCAVADORA | F28: 733.22 | G28: 733.22 | H28: 733.22 | I28: 733.22 | J28: 733.22 | K28: 733.22 | L28: SOBREVALORADO | M28: 40909
A29: 0701074031 | B29: ARMIJOS TORO HARALDO ONOFRE | C29: =+C28+1 -> 20 | D29: 4 | E29: CHOFER DE VEHÍCULO PESADO | F29: 615.22 | G29: 615.22 | H29: 615.22 | I29: 615.22 | J29: 615.22 | K29: 615.22 | L29: SOBREVALORADO | M29: 40909
A30: 1804035937 | B30: BALLESTEROS CAIZA ALVARO RENATO | C30: =+C29+1 -> 21 | D30: 2 | E30: VULCANIZADOR | F30: 581.22 | G30: 581.22 | H30: 581.22 | I30: 581.22 | J30: 581.22 | K30: 581.22 | L30: SOBREVALORADO | M30: 40909
A31: 1103015093 | B31: BANEGAS CARAGUAY LORGIO EDLIDER | C31: =+C30+1 -> 22 | D31: 8 | E31: TÉCNICO MANTENIMIENTO AUTOMOTRIZ | F31: 816.22 | G31: 816.22 | H31: 816.22 | I31: 816.22 | J31: 816.22 | K31: 816.22 | L31: SOBREVALORADO | M31: 40909
A32: 1703099513 | B32: BARAJA JOSÉ HOMERO | C32: =+C31+1 -> 23 | D32: 5 | E32: OPERADOR DE EXCAVADORA | F32: 733.22 | G32: 733.22 | H32: 733.22 | I32: 733.22 | J32: 733.22 | K32: 0 | L32: RETIRO VOLUNTARIO PARA ACOGERSE A LA JUBILACION 2018. | M32: 40909
A33: 1100587060 | B33: BARBA GORDILLO ESTEBAN NOE | C33: =+C32+1 -> 24 | D33: 4 | E33: CHOFER DE VEHÍCULO PESADO | F33: 615.22 | G33: 615.22 | H33: 615.22 | I33: 615.22 | J33: 615.22 | K33: 615.22 | L33: SOBREVALORADO | M33: 40909
A34: 1105035883 | B34: BECERRA LOPEZ LUIS MIGUEL | C34: =+C33+1 -> 25 | D34: 1 | E34: AYUDANTE DE EQUIPO Y/O MAQUINARIA PESADA | F34: 565 | G34: 565 | H34: 565 | I34: 565 | J34: 565 | K34: 565 | L34: SOBREVALORADO | M34: 41640
A35: 1900383090 | B35: BECERRA SANCHEZ HECTOR GENARO | C35: =+C34+1 -> 26 | D35: 5 | E35: OPERADOR DE MOTONIVELADORA | F35: 733.22 | G35: 733.22 | H35: 733.22 | I35: 733.22 | J35: 733.22 | K35: 733.22 | L35: SOBREVALORADO | M35: 40909
A36: 1103650055 | B36: BENALCAZAR CASTILLO WILSON PATRICIO | C36: =+C35+1 -> 27 | D36: 6 | E36: TOPÓGRAFO | F36: 615.22 | G36: 615.22 | H36: 709 | I36: 709 | J36: 709 | K36: 709 | L36: SIN NOTA | M36: 40909
A37: 1103812838 | B37: BENITEZ QUEZADA VINICIO LEONARDO | C37: =+C36+1 -> 28 | D37: 4 | E37: CHOFER DE VEHÍCULO PESADO | F37: 615.22 | G37: 615.22 | H37: 615.22 | I37: 615.22 | J37: 615.22 | K37: 615.22 | L37: SOBREVALORADO | M37: 40909
A38: 1103632095 | B38: BERMEO YAGUACHE CARLOS VICENTE | C38: =+C37+1 -> 29 | D38: 1 | E38: GUARDIAN | F38: 565.22 | G38: 565.22 | H38: 565.22 | I38: 565.22 | J38: 565.22 | K38: 565.22 | L38: SOBREVALORADO | M38: 40909
A39: 1104565468 | B39: BRAVO SANMARTIN STALIN ARMANDO | C39: =+C38+1 -> 30 | D39: 1 | E39: AYUDANTE DE MECÁNICA | F39: 565 | G39: 565 | H39: 565 | I39: 565 | J39: 565 | K39: 565 | L39: SOBREVALORADO | M39: 41640
A40: 1102803457 | B40: BRAVO YANANGOMEZ CRISTOBAL FERNANDO | C40: =+C39+1 -> 31 | D40: 1 | E40: AUXILIAR DE LABORATORIO DE SUELOS | F40: 565.22 | G40: 565.22 | H40: 565.22 | I40: 565.22 | J40: 565.22 | K40: 565.22 | L40: SOBREVALORADO | M40: 40909
A41: 1104063274 | B41: BRICEÑO CALVA FREDY WILLAN | C41: =+C40+1 -> 32 | D41: 1 | E41: AYUDANTE DE MECÁNICA | F41: 565 | G41: 565 | H41: 565 | I41: 565 | J41: 565 | K41: 565 | L41: SOBREVALORADO | M41: 41640
...

Sheet FORMULARIO 4.
A1: FORMULARIO 4
A2: FLUJO PRESUPUESTARIO DE INGRESOS Y GASTOS
A3: EMPRESA PÚBLICA DE VIALIDAD DEL SUR
A5: DETALLE DE GRUPOS Y SUBGRUPOS | C5: FLUJO HISTÓRICO (USD) | F5: FLUJO PROYECTADO (USD) | J5: OBSERVACIONES
A7: Grupo y Subgrupo | B7: Descripción | C7: 2015 | D7: 2016 | E7: 2017 | F7: AÑO (2018) | G7: AÑO 1 (2019) | H7: AÑO 2 (2020) | I7: AÑO 3 (2021)
A8: TOTAL INGRESOS CORRIENTES (1) | C8: =+C9+C14+C19+C20+C21+C22 -> 96363.44 | D8: =+D9+D14+D19+D20+D21+D22 -> 40401.32 | E8: =+E9+E14+E19+E20+E21+E22 -> 2878494.6 | F8: =+F9+F14+F19+F20+F21+F22 -> 3159453.3 | G8: =+G9+G14+G19+G20+G21+G22 -> 728391.16 | H8: =+H9+H14+H19+H20+H21+H22 -> 89063.676 | I8: =+I9+I14+I19+I20+I21+I22 -> 89954.312
A9: 11 | B9: Impuestos
A10: 1101 | B10: Sobre la Renta, Utilidades y Ganancias de Capital
A11: 1102 | B11: Sobre la propiedad
A12: 1103 | B12: Al consumo de Bienes y Servicios
A13: 1107 | B13: Impuestos Diversos
A14: 13 | B14: Tasas y contribuciones | C14: =SUM(C15:C18) -> 2300 | D14: =SUM(D15:D18) -> 2100 | E14: =SUM(E15:E18) -> 2050 | F14: =SUM(F15:F18) -> 4758 | G14: =SUM(G15:G18) -> 2415.43 | H14: =SUM(H15:H18) -> 2451.6614 | I14: 2476.1781
A15: 1301 | B15: Tasas generales | C15: 2300 | D15: 2100 | E15: 2050 | F15: 4758 | G15: 2415.43 | H15: 2451.6614 | I15: 2476.1781
A16: 1302 | B16: Tasas portuarias y aeroportuarias | H16: 0 | I16: 0
A17: 1303 | B17: Tasas diversas | H17: 0 | I17: 0
A18: 1304 | B18: Contribuciones | H18: 0 | I18: 0
A19: 14 | B19: Venta de Bienes y Servicios | E19: 2855303.1 | F19: 3010466.2 | G19: 689904.78 | H19: 50000 | I19: 50500
A20: 17 | B20: Rentas de Invesiones y Multas | C20: 1696.9 | D20: 4332.27 | E20: 1225.8 | F20: 11010.78 | G20: 14811.08 | H20: 15033.246 | I20: 15183.579
A21: 18 | B21: Transferencias y Donaciones Corrientes
A22: 19 | B22: Otros ingresos | C22: =SUM(C23:C25) -> 92366.54 | D22: =SUM(D23:D25) -> 33969.05 | E22: =SUM(E23:E25) -> 19915.75 | F22: =SUM(F23:F25) -> 133218.34 | G22: 21259.87 | H22: 21578.768 | I22: 21794.556
A23: 1901 | B23: Garantías y Fianzas | I23: 0
A24: 1902 | B24: Indemnizaciones y valores no reclamados | C24: 61492.62 | D24: 5070.34 | E24: 0 | F24: 85756.77 | G24: 0 | H24: 0 | I24: 0
A25: 1904 | B25: Otros no Operacionales | C25: 30873.92 | D25: 28898.71 | E25: 19915.75 | F25: 47461.57 | G25: 21259.87 | H25: 21578.768 | I25: 21794.556
A26: TOTAL GASTOS CORRIENTES (2) | C26: =+C27+C36+C37+C38+C39+C40 -> 31020 | D26: =+D27+D36+D37+D38+D39+D40 -> 33951.76 | E26: =+E27+E36+E37+E38+E39+E40 -> 11748.84 | F26: =+F27+F36+F37+F38+F39+F40 -> 75173.68 | G26: =+G27+G36+G37+G38+G39+G40 -> 3019.31 | H26: 2547.8023 | I26: 2573.2803
A27: 51 | B27: Gastos en personal | H27: 0 | I27: 0
A28: 5101 | B28: Remuneraciones Básicas | H28: 0 | I28: 0
A29: 5102 | B29: Remuneraciones Complementarias | H29: 0 | I29: 0
A30: 5103 | B30: Remuneraciones Compensatorias | H30: 0 | I30: 0
A31: 5104 | B31: Subsidios | H31: 0 | I31: 0
A32: 5105 | B32: Remuneraciones Temporales | H32: 0 | I32: 0
A33: 5106 | B33: Aportes Patronales a la Seguridad Social | H33: 0 | I33: 0
A34: 5107 | B34: Indemnizaciones | H34: 0 | I34: 0
A35: 5199 | B35: Asignaciones a distribuir | H35: 0 | I35: 0
A36: 53 | B36: Bienes y servicios de consumo | H36: 0 | I36: 0
A37: 56 | B37: Gastos Financieros | H37: 0 | I37: 0
A38: 57 | B38: Otros gastos corrientes | F38: 71658.66 | H38: 0 | I38: 0
A39: 58 | B39: Transferencias y donaciones corrientes | C39: 31020 | D39: 33951.76 | E39: 11748.84 | F39: 3515.02 | G39: 3019.31 | H39: 12219.84 | I39: 12342.038
A40: 59 | B40: Previsiones para reasignaciones | K40: =+H40*1/100 -> 0
A41: SUPERAVIT/DEFICIT CORRIENTE (1) - (2) = (3) | C41: =+C8-C26 -> 65343.44 | D41: =+D8-D26 -> 6449.56 | E41: =+E8-E26 -> 2866745.8 | F41: =+F8-F26 -> 3084279.7 | G41: =+G8-G26 -> 725371.85 | H41: =+H8-H26 -> 86515.873 | I41: =+I8-I26 -> 87381.032
A42: INGRESOS DE CAPITAL E INVERSIÓN (4) | C42: =+C44 -> 7425936.1 | D42: =SUM(D43:D44) -> 10247254 | E42: =SUM(E43:E44) -> 7130371.3 | F42: =SUM(F43:F44) -> 8097694.1 | G42: =SUM(G43:G44) -> 6927446.8 | H42: =SUM(H43:H44) -> 6325710.7 | I42: =SUM(I43:I44) -> 6388967.8
...
