Workbook
Name OLE_LINK22: 'CONTROL DE VACACIONES'!#REF!

Sheet CRONOGRAMA EJECUTADO
E1: ANÁLISIS DEL CRONOGRAMA EJECUTADO
A3: INSTITUCIÓN EVALUADA:
A4: RESPONSABLE DE LA EVALUACIÓN:
A6: Nº | B6: APELLIDOS Y NOMBRES | C6: CRONOGRAMA PLANIFICADO | E6: CRONOGRAMA EJECUTADO | G6: JUSTIFICACIÓN DE REPROGRAMACIÓN | H6: OBSERVACIÓN
C7: FECHA DE INICIO (DIA/MES/AÑO) | D7: FECHA DE FIN (DIA/MES/AÑO) | E7: FECHA DE INICIO (DIA/MES/AÑO) | F7: FECHA DE FIN (DIA/MES/AÑO)

Sheet ESTUDIOS PREVIOS
E1: ANÁLISIS DE HERRAMIENTAS DE INSTITUCIONALIDAD ESTUDIOS PREVIOS
A3: ENTIDAD EVALUADA:
A4: FECHA DE CORTE:
A7: BASE LEGAL
A8: - Informes de estudios de control efectuados en períodos previos desde el año 2017. - Comunicación de resultados finales de los estudios de control efectuados en períodos previos desde el año 2017. - Matriz final de seguimiento a las acciones de mejoramiento efectuadas respecto de los hallagos determinados en los estudios de control ejecutados desde el año 2017. - Comunicación de resultados finales del seguimiento a las acciones de mejoramiento efctuadas respecto de los hallagos determinados desde el año 2017.
A11: ANÁLISIS HISTÓRICO
A13: ¿Se realizaron estudios previos ? En caso de ser afirmativa la respuesta, realizar el siguiente cuadro comparativo, caso contrario continuar con la etapa de Análisis Actual | C13: ELIJA: | D13: SI | E13: NO | F13: OBSERVACIÓN MDT
A16: Si su respuesta fue afirmativa, realizar el siguiente análisis:
A18: INFORMACIÓN DEL ESTUDIO DE CONTROL PREVIAMENTE REALIZADO | E18: INFORMACIÓN DE LAS ACTIVIDADES ESTABLECIDAS EN EL PLAN DE MEJORA
A19: VARIABLE | B19: AÑO EN QUE SE EJECUTÓ EL ESTUDIO | C19: PERÍODO ANALIZADO (MES/AÑO - MES/AÑO) | D19: CUMPLIMIENTO (SI/NO) | E19: SE PLANTEARON ACCIONES DE MEJORAMIENTO (SI/NO) | F19: % DE CUMPLIMIENTO QUE ALCANZÓ ESTA VARIABLE DURANTE EL PLAN DE MEJORA | G19: ¿SE REALIZARON ACCIONES POSTERIORES PARA CULMINAR LO CONTEMPLADO EN EL PLAN DE MEJORA O PARA SOLVENTAR EL HALLAZGO?
A20: APROBACIÓN DEL PLAN DE VACACIONES
A21: IMPLEMENTACIÓN DEL PLAN
A22: CONTROL DE JORNADA LABORAL
A23: SALDOS DE VACACIONES
A24: TELETRABAJO

Sheet REGLAMENTO-PROCEDIMIENTO
D1: VERIFICACION DE PROCEDIMIENTO O REGLAMENTO INTERNO DE PERMISOS Y VACACIONES
A3: INSTITUCIÓN EVALUADA: | C3: ='JORNADA LABORAL '!C4:I4 -> MINISTERIO DE SALUD PUBLICA COORDINACIÓN ZONA 7 SALUD
A4: No. | B4: CUESTIONARIO | C4: SI/NO/NO APLICA | D4: NO. DE DOCUMENTO | E4: OBSERVACIÓN
A5: 1 | B5: La entidad dispone de reglamento interno o procedimiento que regule la gestion de permisos y vacaciones? | C5: SI | D5: RESOLUCIÓN MSP-C7-SALUD-2017-0026-RA | E5: REGLAMENTO INTERNO DE TALENTO HUMANO
A6: 2 | B6: La entidad dispone de un horario establecido y aprobado por la maxima autoridad o su delegado? | C6: SI | D6: RESOLUCIÓN MSP-C7-SALUD-2017-0026-RA
A7: 3 | B7: El procedimiento o reglamento establece la forma de calculo de vacaciones partiendo de los permisos y vacaciones solicitadas por el servidor? | C7: SI | D7: RESOLUCIÓN MSP-C7-SALUD-2017-0026-RA
A8: 4 | B8: El procedimiento o reglamento incluye descuentos al saldo de vacaciones no establecidos en la LOSEP como atrasos u otro similar? | C8: SI | D8: RESOLUCIÓN MSP-C7-SALUD-2017-0026-RA
A9: 5 | B9: El procedimiento o reglamento establece tiempos de gracia para el ingreso a la jornada laboral? | C9: NO
B12: MINISTERIO DE SALUD PÚBLICA | D12: MINISTERIO DEL TRABAJO
B13: Coordinación Zonal 7 Salud
B20: Dra. Laura Cecilia Mogrovejo Leon | D20: Ing. Maria Cumandá Nole Nole
B21: Responsable de la Gestión Interna Zonal Administración de Talento Humano | D21: Analista Regional de Control y Servicio Público

Sheet CONTROL DE VACACIONES
E1: ANÁLISIS DEL CRONOGRAMA EJECUTADO VS PLANIFICADO
A3: INSTITUCIÓN EVALUADA: | C3: MINISTERIO DE SALUD PUBLICA COORDINACIÓN ZONA 7 SALUD
A4: PERIODO | C4: al 31-03-2023
A6: Nº | B6: NOMBRES Y APELLIDOS | C6: CRONOGRAMA PLANIFICADO | E6: CRONOGRAMA EJECUTADO | G6: JUSTIFICACIÓN DE REPROGRAMACIÓN SI /NO | H6: OBSERVACIÓN
C7: FECHA DE INICIO (DIA/MES/AÑO) | D7: FECHA DE FIN (DIA/MES/AÑO) | E7: FECHA DE INICIO (DIA/MES/AÑO) | F7: FECHA DE FIN (DIA/MES/AÑO)
A8: 1 | B8: RIVADENEIRA VILLARREAL DARWIN DANIEL | C8: NO TIENE | D8: NO TIENE | E8: NO TIENE | F8: NO TIENE | G8: NO | H8: No existe información del Servidor en los kardex remitidos por la insttución.
A9: 2 | B9: PEREZ GONZALEZ CRISTINA ELIZABETH | C9: NO TIENE | D9: NO TIENE | E9: NO TIENE | F9: NO TIENE | G9: NO | H9: De acuerdo al Cronograma, remito por la Institución se evidencia que no esta claro los tiempos planificados por no tienen fecha de fin y tampoco se puede verificar si las vacaciones planificadas fueron replanificadas-
A10: 3 | B10: GUACHON MEDINA TANIA CECILIA | C10: 16/03/2022; 12/09/2022; 14/09/2022;15/3/2023; 15/03/2021; 14/09/2021 | D10: 28/9/2021 29/03/2023 | E10: 15/3/2023; 12/09/2022; 14/09/2021; 15/03/021 | F10: 29/3/2023; 27/09/2022; 28/09/2021; 04/04/2021 | G10: NO APLICA | H10: De acuerdo al Cronograma Remitido por la Institución tiene fecha de inicio y no tiene fecha de fin | I10: 2023 | J10: 15 | K10: 16-29 -03-2023 no se realizo las vacaciones
A11: 4 | B11: CAMPUZANO VILLAFUERTE JOSE JAVIER | C11: 1/6/2021/15 DIAS | D11: 17/7/2022/ 15 DIAS; 01/09-2022-15 DIAS ; 01/02-2022-5 DIAS | E11: 15/11/2022; 01/07/2022;01/11/2022; 16/04/2022; 01/12/2021; 01/09/2021;16/07/2021 | F11: 29/11/2022; 15/07/2022; 05/11/2022; 30/04/2022; 15/12/2021; 15/09/2021;30/07/2021 | G11: NO | H11: Existen vacaciones planificadas del año 2022, que no se evidencia el documento de sustento de la Replanificación, y tampoco se puede verificar en el cronograma del año 2022 y 2023 las vacaciones planificadas. | I11: 2022 | J11: 4
A12: 5 | B12: GUAMAN QUITUIZACA MARIA AUGUSTA | C12: 10-01-2021/ 15 dias ; 06-09-2021 / 15 dias | D12: 01-06-2022 / 15 dias ; 15-08-2022 / 15 dias; 15-12-2022 / 15 dias | E12: 44986 | F12: 45000 | G12: NO | H12: La institución no remite las acciones de personal para verificar el cumplimiento de las vacaciones del año 2021 y 2022.
C18: MINISTERIO DE SALUD PÚBLICA | E18: MINISTERIO DEL TRABAJO
C19: Coordinación Zonal 7 Salud
C26: Dra. Laura Cecilia Mogrovejo Leon | E26: Ing. Maria Cumandá Nole Nole
C27: Responsable de la Gestión Interna Zonal Administración de Talento Humano | E27: Analista Regional de Control y Servicio Público

Sheet MUESTRA SALDO DE VACACIONES
A2: MUESTRA DE SALDOS DE VACACIONES PROPORCIONADOS POR LA UATH
A4: INSTITUCIÓN EVALUADA: | C4: ='CONTROL DE VACACIONES'!C3:F3 -> MINISTERIO DE SALUD PUBLICA COORDINACIÓN ZONA 7 SALUD
A5: FECHA DE CORTE: | C5: 45016
A7: No. | B7: CÉDULA | C7: NOMBRES Y APELLIDOS | D7: FECHA DE INGRESO A LA INSTITUCION | E7: PERMISOS SOLICITADOS (DÍAS) | F7: VACACIONES SOLICITADAS (DÍAS) | G7: SALDO DE VACACIONES (DÍAS)
A8: 1 | B8: 1725694341 | C8: RIVADENEIRA VILLARREAL DARWIN DANIEL | D8: 44287 | E8: 0 | F8: 30 | G8: 30
A9: 2 | B9: 0706858347 | C9: PEREZ GONZALEZ CRISTINA ELIZABETH | D9: 44713 | E9: 0 | F9: 30 | G9: 30
A10: 3 | B10: 1104739709 | C10: GUACHON MEDINA TANIA CECILIA | D10: 42767 | E10: 0.63 | F10: 30 | G10: 29.37
A11: 4 | B11: 0930243753 | C11: CAMPUZANO VILLAFUERTE JOSE JAVIER | D11: 43952 | E11: 0 | F11: 30 | G11: 30
A12: 5 | B12: 1104806730 | C12: TORRES CALBA MAIRA ESPERANZA | D12: 44562 | E12: 0 | F12: 6.25 | G12: 6.25
C15: MINISTERIO DE SALUD PÚBLICA | E15: MINISTERIO DEL TRABAJO
C16: Coordinación Zonal 7 Salud
C23: Dra. Laura Cecilia Mogrovejo Leon | E23: Ing. Maria Cumandá Nole Nole
C24: Responsable de la Gestión Interna Zonal Administración de Talento Humano | E24: Analista Regional de Control y Servicio Público

Sheet DETALLE PERMISOS
C1: VALIDACIÓN Y CÁLCULO DEL TOTAL DE PERMISOS
A5: INSTITUCIÓN EVALUADA: | C5: ='MUESTRA SALDO DE VACACIONES'!C4 -> MINISTERIO DE SALUD PUBLICA COORDINACIÓN ZONA 7 SALUD
A7: CÉDULA | B7: NOMBRES Y APELLIDOS | C7: FECHA (DD/MM/AA) | D7: DÍAS | E7: HORAS | F7: MINUTOS | G7: TIEMPO (DÍAS) | H7: OBSERVACIÓN | I7: TOTAL
A8: ='MUESTRA SALDO DE VACACIONES'!B8 -> 1725694341 | B8: ='MUESTRA SALDO DE VACACIONES'!C8 -> RIVADENEIRA VILLARREAL DARWIN DANIEL | G8: =D8+(E8/8)+(F8/480) -> 0 | H8: No tiene permisos solicitados | I8: =SUM(G8:G12) -> 0
G9: =D9+(E9/8)+(F9/480) -> 0
G10: =D10+(E10/8)+(F10/480) -> 0
G11: =D11+(E11/8)+(F11/480) -> 0
G12: =D12+(E12/8)+(F12/480) -> 0
A13: ='MUESTRA SALDO DE VACACIONES'!B9 -> 0706858347 | B13: ='MUESTRA SALDO DE VACACIONES'!C9 -> PEREZ GONZALEZ CRISTINA ELIZABETH | G13: =D13+(E13/8)+(F13/480) -> 0 | H13: No tiene permisos solicitados | I13: =SUM(G13:G17) -> 0
G14: =D14+(E14/8)+(F14/480) -> 0
G15: =D15+(E15/8)+(F15/480) -> 0
G16: =D16+(E16/8)+(F16/480) -> 0
G17: =D17+(E17/8)+(F17/480) -> 0
A18: ='MUESTRA SALDO DE VACACIONES'!B10 -> 1104739709 | B18: ='MUESTRA SALDO DE VACACIONES'!C10 -> GUACHON MEDINA TANIA CECILIA | C18: 44547 | E18: 0 | F18: 30 | G18: =D18+(E18/8)+(F18/480) -> 0.0625 | H18: Los permisos varian de acuerdo a lo reportado por la insitutición 2021 = 1,11 2022 = 1,16 2023 = 0,56 total 2,83 | I18: =SUM(G18:G38) -> 2.8333333
C19: 44490 | E19: 3 | G19: =D19+(E19/8)+(F19/480) -> 0.375
C20: 44494 | E20: 1 | G20: =D20+(E20/8)+(F20/480) -> 0.125
C21: 44480 | E21: 1 | G21: =D21+(E21/8)+(F21/480) -> 0.125
C22: 44439 | F22: 30 | G22: =D22+(E22/8)+(F22/480) -> 0.0625
C23: 44323 | E23: 2 | F23: 55 | G23: =D23+(E23/8)+(F23/480) -> 0.36458333
C24: 44791 | F24: 30 | G24: =D24+(E24/8)+(F24/480) -> 0.0625
C25: 44721 | F25: 30 | G25: =D25+(E25/8)+(F25/480) -> 0.0625
C26: 44601 | E26: 1 | G26: =D26+(E26/8)+(F26/480) -> 0.125
C27: 44637 | F27: 30 | G27: =D27+(E27/8)+(F27/480) -> 0.0625
C28: 44757 | F28: 30 | G28: =D28+(E28/8)+(F28/480) -> 0.0625
C29: 44784 | E29: 3 | G29: =D29+(E29/8)+(F29/480) -> 0.375
C30: 44873 | E30: 1 | G30: =D30+(E30/8)+(F30/480) -> 0.125
C31: 44879 | F31: 45 | G31: =D31+(E31/8)+(F31/480) -> 0.09375
C32: 44893 | E32: 1 | F32: 30 | G32: =D32+(E32/8)+(F32/480) -> 0.1875
C33: 44993 | F33: 30 | G33: =D33+(E33/8)+(F33/480) -> 0.0625
C34: 44981 | E34: 1 | G34: =D34+(E34/8)+(F34/480) -> 0.125
C35: 44946 | E35: 3 | G35: =D35+(E35/8)+(F35/480) -> 0.375
G36: =D36+(E36/8)+(F36/480) -> 0
G37: =D37+(E37/8)+(F37/480) -> 0
G38: =D38+(E38/8)+(F38/480) -> 0
A39: ='MUESTRA SALDO DE VACACIONES'!B11 -> 0930243753 | B39: ='MUESTRA SALDO DE VACACIONES'!C11 -> CAMPUZANO VILLAFUERTE JOSE JAVIER | C39: 44461 | E39: 1 | G39: =D39+(E39/8)+(F39/480) -> 0.125 | I39: =SUM(G39:G46) -> 0.625
C40: 44424 | E40: 1 | G40: =D40+(E40/8)+(F40/480) -> 0.125
C41: 44358 | E41: 1 | G41: =D41+(E41/8)+(F41/480) -> 0.125
C42: 44337 | E42: 1 | G42: =D42+(E42/8)+(F42/480) -> 0.125
C43: 44323 | E43: 1 | G43: =D43+(E43/8)+(F43/480) -> 0.125
G46: =D46+(E46/8)+(F46/480) -> 0
...

Sheet DETALLE VACACIONES
C1: VALIDACIÓN Y CÁLCULO DEL TOTAL DE VACACIONES
A5: INSTITUCIÓN EVALUADA: | C5: ='DETALLE PERMISOS'!C5:H5 -> MINISTERIO DE SALUD PUBLICA COORDINACIÓN ZONA 7 SALUD
A7: CÉDULA | B7: NOMBRES Y APELLIDOS | C7: FECHA (DD/MM/AAAA) | D7: DÍAS | E7: HORAS | F7: MINUTOS | G7: TIEMPO (DÍAS) | H7: OBSERVACIÓN | I7: TOTAL
A8: ='DETALLE PERMISOS'!A8:A12 -> 1725694341 | B8: ='DETALLE PERMISOS'!B8:B12 -> RIVADENEIRA VILLARREAL DARWIN DANIEL | G8: =D8+(E8/8)+(F8/480) -> 0 | H8: En el expediente remitido por la institución no tiene acciones de personal por ejecución de vacaciones, ni documentos que justifiquen la reprogración de vacaciones. | I8: =SUM(G8:G12) -> 0
G9: =D9+(E9/8)+(F9/480) -> 0
G10: =D10+(E10/8)+(F10/480) -> 0
G11: =D11+(E11/8)+(F11/480) -> 0
G12: =D12+(E12/8)+(F12/480) -> 0
A13: ='DETALLE PERMISOS'!A13:A17 -> 0706858347 | B13: ='DETALLE PERMISOS'!B13:B17 -> PEREZ GONZALEZ CRISTINA ELIZABETH | G13: =D13+(E13/8)+(F13/480) -> 0 | H13: No aplica | I13: =SUM(G13:G17) -> 0
G14: =D14+(E14/8)+(F14/480) -> 0
G15: =D15+(E15/8)+(F15/480) -> 0
G16: =D16+(E16/8)+(F16/480) -> 0
G17: =D17+(E17/8)+(F17/480) -> 0
A18: ='DETALLE PERMISOS'!A18:A38 -> 1104739709 | B18: ='DETALLE PERMISOS'!B14:B22 -> GUACHON MEDINA TANIA CECILIA | C18: 45000 | D18: 15 | G18: =D18+(E18/8)+(F18/480) -> 15 | I18: =SUM(G18:G22) -> 54
C19: 44816 | D19: 4 | G19: =D19+(E19/8)+(F19/480) -> 4
C20: 44453 | D20: 14 | G20: =D20+(E20/8)+(F20/480) -> 14
C21: 44270 | D21: 21 | G21: =D21+(E21/8)+(F21/480) -> 21 | H21: periodo febrero 2019-enero 2020
G22: =D22+(E22/8)+(F22/480) -> 0
A23: 0930243753 | B23: CAMPUZANO VILLAFUERTE JOSE JAVIER | C23: 44866 | D23: 5 | G23: =D23+(E23/8)+(F23/480) -> 5 | I23: =SUM(G23:G27) -> 65
C24: 44743 | D24: 15 | G24: =D24+(E24/8)+(F24/480) -> 15
C25: 44667 | D25: 15 | G25: =D25+(E25/8)+(F25/480) -> 15
C26: 44531 | D26: 15 | G26: =D26+(E26/8)+(F26/480) -> 15
C27: 44440 | D27: 15 | G27: =D27+(E27/8)+(F27/480) -> 15
C28: 44393 | D28: 15 | G28: =D28+(E28/8)+(F28/480) -> 15
A29: 1104806730 | B29: TORRES CALBA MAIRA ESPERANZA | C29: 44986 | D29: 15 | G29: =D29+(E29/8)+(F29/480) -> 15 | H29: SI CUMPLE | I29: =SUM(G29:G33) -> 15
G30: =D30+(E30/8)+(F30/480) -> 0
G31: =D31+(E31/8)+(F31/480) -> 0
G32: =D32+(E32/8)+(F32/480) -> 0
G33: =D33+(E33/8)+(F33/480) -> 0
C36: MINISTERIO DE SALUD PÚBLICA | E36: MINISTERIO DEL TRABAJO
C37: Coordinación Zonal 7 Salud
C44: Dra. Laura Cecilia Mogrovejo Leon | E44: Ing. Maria Cumandá Nole Nole
C45: Responsable de la Gestión Interna Zonal Administración de Talento Humano | E45: Analista Regional de Control y Servicio Público

Sheet SALDO DE VACACIONES MDT
D1: ANÁLISIS DEL SALDO DE VACACIONES SEGÚN MDT
A2: PAPEL DE TRABAJO
A4: INSTITUCIÓN EVALUADA: | D4: ='DETALLE VACACIONES'!C5:H5 -> 0
A5: FACTOR: | D5: =2.5/30 -> 0.083333333
A6: FECHA DE CORTE: | D6: 45016
A7: CALCULO DE VACACIONES MINISTERIO DEL TRABAJO
A8: INFORMACION DEL PERSONAL | F8: SALDO DE VACACIONES INICIAL | I8: SALDO DE VACACIONES FINAL MDT | N8: OBSERVACIONES
A9: No. | B9: CÉDULA | C9: NOMBRES Y APELLIDOS | D9: FECHA DE INGRESO A LA INSTITUCIÓN | E9: DÍAS | F9: CÁLCULO DE SALDO DE VACACIONES SIN DESCUENTOS | G9: DIAS LABORABLES | H9: DIAS NO LABORABLES | I9: TOTAL PERMISOS | J9: TOTAL VACACIONES | K9: SALDO FINAL MDT | L9: SALDO LABORABLES | M9: SALDO NO LABORABLES
A10: 1 | B10: ='MUESTRA SALDO DE VACACIONES'!B8 -> 1725694341 | C10: =VLOOKUP(B10,'MUESTRA SALDO DE VACACIONES'!$B$7:E61,2,0) -> RIVADENEIRA VILLARREAL DARWIN DANIEL | D10: ='MUESTRA SALDO DE VACACIONES'!D8 -> 44287 | E10: =(ROUND(DAYS360((EOMONTH(D10,-1)+1),(IF(EOMONTH($D$6,0)=$D$6,EOMONTH($D$6,0),EOMONTH($D$6,-1))))/30,0)*30+(IF(EOMONTH($D$6,0)=$D$6,0,DAY($D$6))-DAY(D10)))+1 -> 720 | F10: =+E10*$D$5 -> 60 | G10: =F10*(22/30) -> 44 | H10: =F10*(8/30) -> 16 | I10: ='DETALLE PERMISOS'!I8 -> 0 | J10: ='DETALLE VACACIONES'!I8 -> 0 | K10: =+F10-I10-J10 -> 60 | N10: De acuerdo a la revisión de la información remitida por la institución y a la reportada en la matriz del mdt, existe variación en el saldo de las vacaciones por lo que no se encuentran todos los sustentos para la verificación
A11: 2 | B11: ='MUESTRA SALDO DE VACACIONES'!B9 -> 0706858347 | C11: =VLOOKUP(B11,'MUESTRA SALDO DE VACACIONES'!$B$7:E62,2,0) -> PEREZ GONZALEZ CRISTINA ELIZABETH | D11: ='MUESTRA SALDO DE VACACIONES'!D9 -> 44713 | E11: =(ROUND(DAYS360((EOMONTH(D11,-1)+1),(IF(EOMONTH($D$6,0)=$D$6,EOMONTH($D$6,0),EOMONTH($D$6,-1))))/30,0)*30+(IF(EOMONTH($D$6,0)=$D$6,0,DAY($D$6))-DAY(D11)))+1 -> 300 | F11: =+E11*$D$5 -> 25 | G11: =F11*(22/30) -> 18.333333 | H11: =F11*(8/30) -> 6.6666667 | I11: ='DETALLE PERMISOS'!I13 -> 0 | J11: ='DETALLE VACACIONES'!I13 -> 0 | K11: =+F11-I11-J11 -> 25
A12: 3 | B12: ='MUESTRA SALDO DE VACACIONES'!B10 -> 1104739709 | C12: =VLOOKUP(B12,'MUESTRA SALDO DE VACACIONES'!$B$7:E63,2,0) -> GUACHON MEDINA TANIA CECILIA | D12: ='MUESTRA SALDO DE VACACIONES'!D10 -> 42767 | E12: =(ROUND(DAYS360((EOMONTH(D12,-1)+1),(IF(EOMONTH($D$6,0)=$D$6,EOMONTH($D$6,0),EOMONTH($D$6,-1))))/30,0)*30+(IF(EOMONTH($D$6,0)=$D$6,0,DAY($D$6))-DAY(D12)))+1 -> 2220 | F12: =+E12*$D$5 -> 185 | G12: =F12*(22/30) -> 135.66667 | H12: =F12*(8/30) -> 49.333333 | I12: ='DETALLE PERMISOS'!I18 -> 2.8333333 | J12: ='DETALLE VACACIONES'!I18 -> 54 | K12: =+F12-I12-J12 -> 128.16667
A13: 4 | B13: ='MUESTRA SALDO DE VACACIONES'!B11 -> 0930243753 | C13: =VLOOKUP(B13,'MUESTRA SALDO DE VACACIONES'!$B$7:E64,2,0) -> CAMPUZANO VILLAFUERTE JOSE JAVIER | D13: ='MUESTRA SALDO DE VACACIONES'!D11 -> 43952 | E13: =(ROUND(DAYS360((EOMONTH(D13,-1)+1),(IF(EOMONTH($D$6,0)=$D$6,EOMONTH($D$6,0),EOMONTH($D$6,-1))))/30,0)*30+(IF(EOMONTH($D$6,0)=$D$6,0,DAY($D$6))-DAY(D13)))+1 -> 1050 | F13: =+E13*$D$5 -> 87.5 | G13: =F13*(22/30) -> 64.166667 | H13: =F13*(8/30) -> 23.333333 | I13: ='DETALLE PERMISOS'!I39 -> 0.625 | J13: ='DETALLE VACACIONES'!I23 -> 65 | K13: =+F13-I13-J13 -> 21.875
A14: 5 | B14: ='MUESTRA SALDO DE VACACIONES'!B12 -> 1104806730 | C14: =VLOOKUP(B14,'MUESTRA SALDO DE VACACIONES'!$B$7:E65,2,0) -> TORRES CALBA MAIRA ESPERANZA | D14: ='MUESTRA SALDO DE VACACIONES'!D12 -> 44562 | E14: =(ROUND(DAYS360((EOMONTH(D14,-1)+1),(IF(EOMONTH($D$6,0)=$D$6,EOMONTH($D$6,0),EOMONTH($D$6,-1))))/30,0)*30+(IF(EOMONTH($D$6,0)=$D$6,0,DAY($D$6))-DAY(D14)))+1 -> 450 | F14: =+E14*$D$5 -> 37.5 | G14: =F14*(22/30) -> 27.5 | H14: =F14*(8/30) -> 10 | I14: ='DETALLE PERMISOS'!I47 -> 0 | J14: ='DETALLE VACACIONES'!I29 -> 15 | K14: =+F14-I14-J14 -> 22.5
D18: MINISTERIO DE SALUD PÚBLICA | F18: MINISTERIO DEL TRABAJO
D19: Coordinación Zonal 7 Salud
D26: Dra. Laura Cecilia Mogrovejo Leon | F26: Ing. Maria Cumandá Nole Nole
D27: Responsable de la Gestión Interna Zonal Administración de Talento Humano | F27: Analista Regional de Control y Servicio Público

Sheet COMPARACIÓN DE SALDOS
D1: COMPARACIÓN DE SALDOS DE VACACIONES
A2: PAPEL DE TRABAJO
A4: INSTITUCIÓN:
A5: PERÍODO ANALIZADO:
A6: VARIABLE :
A8: INSTITUCIÓN EVALUADA: | D8: ='DETALLE VACACIONES'!C5:H5 -> 0
B9: CÁLCULO DE MUESTRA | K9: NOTA:
B10: PARÁMETROS | I10: VALORES | K10: =5*1.4 -> 7
B11: POBLACIÓN (Personal LOSEP, CSO, ETC que trabajan en Planta Central) | I11: 200
B12: TOTAL ELEMENTOS DE LA MUESTRA A CONSIDERAR | I12: =IF(I11<200,5,10) -> 10
A16: INFORMACION PERSONAL | E16: INFORMACIÓN PROPORCIONADA POR LA UATH INSTITUCIONAL | I16: VERIFICACIÓN MDT | M16: DIFERENCIA
A17: No. | B17: CÉDULA | C17: NOMBRS Y APELLIDOS | D17: FECHA DE INGRESO | E17: SALDO DE VACACIONES SIN DESCONTAR | F17: VACACIONES | G17: PERMISOS IMPUTABLES A VACACIONES | H17: SALDO FINAL DE VACACIONES | I17: SALDO DE VACACIONES SIN DESCONTAR PERMISOS NI VACACIONES | J17: VACACIONES GOZADAS | K17: PERMISOS IMPUTABLES A VACACIONES | L17: SALDO FINAL DE VACACIONES
A18: 1 | B18: ='SALDO DE VACACIONES MDT'!B10 -> 1725694341 | C18: ='SALDO DE VACACIONES MDT'!C10 -> RIVADENEIRA VILLARREAL DARWIN DANIEL | D18: ='MUESTRA SALDO DE VACACIONES'!D8 -> 44287 | E18: =+H18+G18+F18 -> 60 | F18: ='MUESTRA SALDO DE VACACIONES'!E8 -> 0 | G18: ='MUESTRA SALDO DE VACACIONES'!F8 -> 30 | H18: ='MUESTRA SALDO DE VACACIONES'!G8 -> 30 | I18: ='SALDO DE VACACIONES MDT'!F10 -> 60 | J18: ='SALDO DE VACACIONES MDT'!J10 -> 0 | K18: ='SALDO DE VACACIONES MDT'!I10 -> 0 | L18: =+I18-J18-K18 -> 60 | M18: =+H18-L18 -> -30
A19: 2 | B19: ='SALDO DE VACACIONES MDT'!B11 -> 0706858347 | C19: ='SALDO DE VACACIONES MDT'!C11 -> PEREZ GONZALEZ CRISTINA ELIZABETH | D19: ='MUESTRA SALDO DE VACACIONES'!D9 -> 44713 | E19: =+H19+G19+F19 -> 60 | F19: ='MUESTRA SALDO DE VACACIONES'!E9 -> 0 | G19: ='MUESTRA SALDO DE VACACIONES'!F9 -> 30 | H19: ='MUESTRA SALDO DE VACACIONES'!G9 -> 30 | I19: ='SALDO DE VACACIONES MDT'!F11 -> 25 | J19: ='SALDO DE VACACIONES MDT'!J11 -> 0 | K19: ='SALDO DE VACACIONES MDT'!I11 -> 0 | L19: =+I19-J19-K19 -> 25 | M19: =+H19-L19 -> 5
A20: 3 | B20: ='SALDO DE VACACIONES MDT'!B12 -> 1104739709 | C20: ='SALDO DE VACACIONES MDT'!C12 -> GUACHON MEDINA TANIA CECILIA | D20: ='MUESTRA SALDO DE VACACIONES'!D10 -> 42767 | E20: =+H20+G20+F20 -> 60 | F20: ='MUESTRA SALDO DE VACACIONES'!E10 -> 0.63 | G20: ='MUESTRA SALDO DE VACACIONES'!F10 -> 30 | H20: ='MUESTRA SALDO DE VACACIONES'!G10 -> 29.37 | I20: ='SALDO DE VACACIONES MDT'!F12 -> 185 | J20: ='SALDO DE VACACIONES MDT'!J12 -> 54 | K20: ='SALDO DE VACACIONES MDT'!I12 -> 2.8333333 | L20: =+I20-J20-K20 -> 128.16667 | M20: =+H20-L20 -> -98.796667
A21: 4 | B21: ='SALDO DE VACACIONES MDT'!B13 -> 0930243753 | C21: ='SALDO DE VACACIONES MDT'!C13 -> CAMPUZANO VILLAFUERTE JOSE JAVIER | D21: ='MUESTRA SALDO DE VACACIONES'!D11 -> 43952 | E21: =+H21+G21+F21 -> 60 | F21: ='MUESTRA SALDO DE VACACIONES'!E11 -> 0 | G21: ='MUESTRA SALDO DE VACACIONES'!F11 -> 30 | H21: ='MUESTRA SALDO DE VACACIONES'!G11 -> 30 | I21: ='SALDO DE VACACIONES MDT'!F13 -> 87.5 | J21: ='SALDO DE VACACIONES MDT'!J13 -> 65 | K21: ='SALDO DE VACACIONES MDT'!I13 -> 0.625 | L21: =+I21-J21-K21 -> 21.875 | M21: =+H21-L21 -> 8.125
A22: 5 | B22: ='SALDO DE VACACIONES MDT'!B14 -> 1104806730 | C22: ='SALDO DE VACACIONES MDT'!C14 -> TORRES CALBA MAIRA ESPERANZA | D22: ='MUESTRA SALDO DE VACACIONES'!D12 -> 44562 | E22: =+H22+G22+F22 -> 12.5 | F22: ='MUESTRA SALDO DE VACACIONES'!E12 -> 0 | G22: ='MUESTRA SALDO DE VACACIONES'!F12 -> 6.25 | H22: ='MUESTRA SALDO DE VACACIONES'!G12 -> 6.25 | I22: ='SALDO DE VACACIONES MDT'!F14 -> 37.5 | J22: ='SALDO DE VACACIONES MDT'!J14 -> 15 | K22: ='SALDO DE VACACIONES MDT'!I14 -> 0 | L22: =+I22-J22-K22 -> 22.5 | M22: =+H22-L22 -> -16.25
E24: MINISTERIO DE SALUD PÚBLICA | G24: MINISTERIO DEL TRABAJO
E25: Coordinación Zonal 7 Salud
E32: Dra. Laura Cecilia Mogrovejo Leon | G32: Ing. Maria Cumandá Nole Nole
E33: Responsable de la Gestión Interna Zonal Administración de Talento Humano | G33: Analista Regional de Control y Servicio Público

Sheet JORNADA LABORAL 
E1: ANÁLISIS DE CUMPLIMIENTO DE JORNADA LABORAL
A4: INSTITUCIÓN EVALUADA: | C4: ='CONTROL DE VACACIONES'!C3:F3 -> MINISTERIO DE SALUD PUBLICA COORDINACIÓN ZONA 7 SALUD
A6: No. | B6: NOMBRES Y APELLIDOS | C6: FECHA (DD/MM/AA) | D6: DÍA | E6: JORNADA LABORAL | G6: HORARIO DE ALMUERZO | I6: OBSERVACIONES
E7: INGRESO | F7: SALIDA | G7: SALIDA | H7: RETORNO
A8: 1 | B8: SARANGO RIVERA FRANCIS DAVID | C8: 44217 | D8: =TEXT(C8,"DDDD") -> jueves | E8: 07H51 | I8: La instirución no indica si el servidor mantiene turnos rotativos, lo que no se puede verificar el cumplimiento de la Jornada Laboral
C9: 44224 | D9: =TEXT(C9,"DDDD") -> jueves | E9: NO TIENE | F9: 16H48
C10: 44214 | D10: =TEXT(C10,"DDDD") -> lunes | E10: NO TIENE | F10: NO TIENE
C11: 44200 | D11: =TEXT(C11,"DDDD") -> lunes | E11: 7H50 | F11: 16H28
C12: 44202 | D12: =TEXT(C12,"DDDD") -> miércoles | E12: 7H54 | F12: 16H19
C13: 44203 | D13: =TEXT(C13,"DDDD") -> jueves | E13: 7h48 | F13: 16h24
C14: 44934 | D14: =TEXT(C14,"DDDD") -> domingo | E14: 7h50 | F14: 16h50
C15: 44940 | D15: =TEXT(C15,"DDDD") -> sábado | E15: 7h50 | F15: 16h10
C16: 44581 | D16: =TEXT(C16,"DDDD") -> jueves | E16: 8H04 | F16: 17H02
C17: 44585 | D17: =TEXT(C17,"DDDD") -> lunes | E17: 7H59 | F17: 16H04
C18: 44588 | D18: =TEXT(C18,"DDDD") -> jueves | E18: 7H52 | F18: 16H04
C19: 44995 | D19: =TEXT(C19,"DDDD") -> viernes | E19: 7h57 | F19: NO TIENE
C20: 45005 | D20: =TEXT(C20,"DDDD") -> lunes | E20: NO TIENE | F20: 17h21
C21: 45006 | D21: =TEXT(C21,"DDDD") -> martes | E21: 7h39 | F21: NO TIENE
A25: 2 | B25: JARAMILLO CASTILLO ROMEO JAVIER | C25: 44547 | D25: =TEXT(C25,"DDDD") -> viernes | E25: 7H43 | F25: NO TIENE | I25: se verifica que el servidor mantiene marcaciones recurrentes fuera del horario establecido , la institución no remite los justificativos.
C26: 44566 | D26: =TEXT(C26,"DDDD") -> miércoles | E26: 7H51 | F26: 13H55
C27: 44572 | D27: =TEXT(C27,"DDDD") -> martes | E27: 7H50 | F27: 16H03
C28: 44585 | D28: =TEXT(C28,"DDDD") -> lunes | E28: 8H01 | F28: 16H10
C29: 44588 | D29: =TEXT(C29,"DDDD") -> jueves | E29: 7H42 | F29: 16H10
C30: 44986 | D30: =TEXT(C30,"DDDD") -> miércoles | E30: 10h01 | F30: 17h01
A34: 3 | B34: CASTILLO VALAREZO JANETH LUCIA | C34: 44536 | D34: =TEXT(C34,"DDDD") -> lunes | E34: 8h01 | F34: NO TIENE | I34: se verifica que el servidor mantiene marcaciones recurrentes fuera del horario establecido , la institución no remite los justificativos.
C35: 44539 | D35: =TEXT(C35,"DDDD") -> jueves | E35: 7h03 | F35: 15h36
C36: 44544 | D36: =TEXT(C36,"DDDD") -> martes | E36: 8h01 | F36: 17h43
C37: 44545 | D37: =TEXT(C37,"DDDD") -> miércoles | E37: 8h03 | F37: 17h30
C38: 44565 | D38: =TEXT(C38,"DDDD") -> martes | E38: 8H05 | F38: 17H39
C39: 44566 | D39: =TEXT(C39,"DDDD") -> miércoles | E39: 8H01 | F39: 17H20
C40: 44567 | D40: =TEXT(C40,"DDDD") -> jueves | E40: 8H02 | F40: 17H25
C41: 44572 | D41: =TEXT(C41,"DDDD") -> martes | E41: 7H59 | F41: 16H14
C42: 44575 | D42: =TEXT(C42,"DDDD") -> viernes | E42: 8H02 | F42: 17H56
C43: 44578 | D43: =TEXT(C43,"DDDD") -> lunes | E43: 8H06 | F43: 17H28
C44: 44580 | D44: =TEXT(C44,"DDDD") -> miércoles | E44: 9H31 | F44: 17H13
C45: 44585 | D45: =TEXT(C45,"DDDD") -> lunes | E45: 8H01 | F45: 16H17
C46: 44951 | D46: =TEXT(C46,"DDDD") -> miércoles | E46: 8H03 | F46: 17H05
... C51: 45016 | D51: =TEXT(C51,"DDDD") -> viernes | E51: 8h01 | F51: 18h01
A52: 4 | B52: ROJAS BETANCOURT RAMIRO PATRICIO | C52: 44553 | D52: =TEXT(C52,"DDDD") -> jueves | E52: NO TIENE | F52: 18H13 | I52: se verifica que el servidor mantiene marcaciones recurrentes fuera del horario establecido , la institución no remite los justificativos.
C53: 44532 | D53: =TEXT(C53,"DDDD") -> jueves
...

Sheet TELETRABAJO
E1: ANÁLISIS DE CUMPLIMIENTO DE JORNADA LABORAL | K1: SI
K2: NO
D3: FORMULARIO DE REGISTRO DE TELETRABAJADORES | I3: SI
A4: INSTITUCIÓN EVALUADA: | C4: ='CONTROL DE VACACIONES'!C3:F3 -> MINISTERIO DE SALUD PUBLICA COORDINACIÓN ZONA 7 SALUD
A5: RESPONSABLE DE LA EVALUACIÓN: | C5: ='CONTROL DE VACACIONES'!#REF! -> #REF!
A7: No.A7:H33A7:H38A7:H43A57A7:H28 | B7: NOMBRES Y APELLIDOS | C7: FECHA (DD/MM/AA) | D7: DÍA | E7: JORNADA LABORAL | G7: HORARIO DE ALMUERZO | I7: OBSERVACIONES
E8: INGRESO | F8: SALIDA | G8: SALIDA | H8: RETORNO
A9: 1 | B9: CARDENAS SANCHEZ DOLORES CECILIA | C9: 44200 | D9: =TEXT(C9,"DDDD") -> lunes | E9: 8H00 | F9: 17H00 | G9: 13H00 | H9: 14H00 | I9: La Institución remito la matriz de los servidores bajo la modalidad de Teletrabajo sin embargo no remiten documentación que sustente el procedimiento
A14: 2 | B14: LEON CONTENTO MARIA SOLEDAD | C14: 04/01/2021 hasta 28/02/2022 | E14: 8H00 | F14: 17H00 | G14: 13H00 | H14: 14H00
A19: 3 | B19: SEVERINO CORREA CARMELINA ESPERANZA | C19: 04/01/2021 hasta 28/02/2022 | E19: 8H00 | F19: 17H00 | G19: 13H00 | H19: 14H00
A24: 4 | B24: CORONEL CELI CECILIA MARGARITA | C24: 04/01/2021 hasta 22/09/2021 | E24: 8H00 | F24: 17H00 | G24: 13H00 | H24: 14H00
A29: 5 | B29: VILLACIS VILLA DIANA GABRIELA | C29: 09/03/2021 hasta 31/08/2021 | E29: 8H00 | F29: 17H00 | G29: 13H00 | H29: 14H00
A34: 6 | B34: LEON CONTENTO MARIA SOLEDAD | C34: 04/01/2021 hasta 28/02/2022 | E34: 8H00 | F34: 17H00 | G34: 13H00 | H34: 14H00
A39: 7 | B39: GALVEZ ALVAREZ ALEX FERNANDO | C39: 30/08/2022 hasta 08/12/2022 | E39: 8H00 | F39: 17H00 | G39: 13H00 | H39: 14H00
A44: 8 | B44: MALDONADO ORTEGA JASMIN MARINA | C44: 18/05/2021 HASTA 22/09/2021 | E44: 8H00 | F44: 17H00 | G44: 13H00 | H44: 14H00
A49: 9 | B49: PINEDA LOPEZ LIVIA GLADYS | C49: 24/01/2022 HASTA 20/12/2022 | E49: 8H00 | F49: 17H00 | G49: 13H00 | H49: 14H00
A55: OBSERVACIONES GENERALES
A57: La Institución remitio la matriz de los servidores bajo la modalidad de Teletrabajo, Mediante Memorando Nro. CZ7-2023 de fech 30 de junio del 2023, justifica las actividades realizadas por los teletrabajadores sin embargo no remite documentación para la verificación del cumplimiento de la Jornada Laboral.
C64: MINISTERIO DE SALUD PÚBLICA | E64: MINISTERIO DEL TRABAJO
C65: Coordinación Zonal 7 Salud
C72: Dra. Laura Cecilia Mogrovejo Leon | E72: Ing. Maria Cumandá Nole Nole
C73: Responsable de la Gestión Interna Zonal Administración de Talento Humano | E73: Analista Regional de Control y Servicio Público

Sheet MUESTRA ANTICIPO DE VACACIONES
D1: ANTICIPO DE VACACIONES Y PERMISOS
A3: INSTITUCIÓN EVALUADA: | C3: ='JORNADA LABORAL '!C4:I4 -> MINISTERIO DE SALUD PUBLICA COORDINACIÓN ZONA 7 SALUD
A5: No. | B5: CÉDULA | C5: NOMBRES Y APELLIDOS | D5: FECHA DE INGRESO A LA INSTITUCION | E5: SALDO DE VACACIONES (DÍAS)
A6: 1
A7: 2
A8: 3
A9: 4
A10: 5
A38: MINISTERIO DE SALUD PÚBLICA | C38: MINISTERIO DEL TRABAJO
A39: Coordinación Zonal 7 Salud
A46: Dra. Laura Cecilia Mogrovejo Leon | C46: Ing. Maria Cumandá Nole Nole
A47: Responsable de la Gestión Interna Zonal Administración de Talento Humano | C47: Analista Regional de Control y Servicio Público
