Workbook

Sheet FORMULARIO 1
A1: MINISTERIO DE FINANZAS
A2: FORMULARIO 1: "FUENTES DE FINANCIAMIENTO DEL PROYECTO DE CONTRATO COLECTIVO"
A3: DETALLE DE INGRESOS
A5: GOBIERNO AUTÓNOMO DESCENTRALIZADO MUNICIPAL DE CATAMAYO
A6: Nº PROYECTO CONTRATO COLECTIVO: DÉCIMO SEGUNDO
A7: Nº ACTA TRANSACCIONAL ___________________________
A9: FUENTES DE FINANCIAMIENTO | C9: FINANCIAMIENTO REAL DEL CONTRATO COLECTIVO VIGENTE USD (2015) | D9: FINANCIAMIENTO ESTIMADO DEL CONTRATO COLECTIVO PROPUESTO USD (2016) | E9: OBSERVACIONES
A10: INGRESOS CORRIENTES Y PERMANENTES
A11: 11 | B11: POR IMPUESTOS
A12: 1101 | B12: Sobre la Renta, Utilidades y Ganancias de Capital
A13: 1102 | B13: Sobre la propiedad
A14: 1103 | B14: Al consumo de Bienes y Servicios
A15: 1107 | B15: Impuestos Diversos
A17: 13 | B17: TASAS Y CONTRIBUCIONES
A18: 1301 | B18: Tasas generales
A19: 1302 | B19: Tasas portuarias y aeroportuarias
A20: 1303 | B20: Tasas diversas
A21: 1304 | B21: Contribuciones
A23: 14 | B23: VENTA DE BIENES Y SERVICIOS
A25: 17 | B25: RENTAS DE INVERSIONES Y MULTAS
A27: 18 | B27: TRANSFERENCIAS Y DONACIONES CORRIENTES
B28: COOTAD
A29: 19 | B29: OTROS INGRESOS
A30: 1901 | B30: Garantías y Fianzas
A31: 1902 | B31: Indemnizaciones y valores no reclamados
A32: 1904 | B32: Otros no Operacionales
A33: 28 | B33: INGRESOS DE CAPITAL E INVERSIÓN (4)
A34: 2806 | B34: Transferencias y donaciones de capital e inversión | C34: ='FORMULARIO 2'!C40 -> 1995934.9 | D34: ='FORMULARIO 2'!D40 -> 2260664.8
B35: TOTAL | C35: =C34 -> 1995934.9 | D35: =D34 -> 2260664.8
B36: INCREMENTO PORCENTUAL % | D36: =SUM(D35-C35)/C35*100 -> 13.263457
A38: * De ser el caso, se deberá incluir filas adicionales, para detallar los subgrupos o items correspondientes.
A39: * En caso de que en el contrato colectivo se negocie algún beneficio adicional a los expuestos favor incluir el item correspondiente.
A40: * La información de los formularios deberá remitirse en medio magnético (Excel) e impreso con las respectivas firmas de responsabilidad.
B45: FIRMA DIRECTOR (A) FINANCIERO (A) DEL GAD
B46: Dr. C.P.A. Julio Farinango Benalcázar
B48: Lugar y Fecha: Catamayo, 01/12/2016
B49: Sello Institucional

Sheet FORMULARIO 2
A1: MINISTERIO DE FINANZAS
A2: FORMULARIO 2: "COSTOS DEL PROYECTO DE CONTRATO COLECTIVO"
A4: GOBIERNO AUTÓNOMO DESCENTRALIZADO MUNICIPAL DE CATAMAYO
A5: Nº PROYECTO CONTRATO COLECTIVO: DÉCIMO SEGUNDO
A6: Nº ACTA TRANSACCIONAL ___________________________
A8: CLASIFICADOR PRESUPUESTARIO | B8: GASTO DEL PERSONAL | C8: COSTO REAL DEL CONTRATO COLECTIVO VIGENTE USD (2015) | D8: COSTO ESTIMADO DEL CONTRATO COLECTIVO PROPUESTO USD (2016) | E8: OBSERVACIONES
A9: GASTO PERSONAL
A10: 7101 | B10: REMUNERACIONES BASICAS
A11: 710106 | B11: SALARIOS UNIFICADOS | C11: =(100514)*12 -> 1206168 | D11: ='FORMULARIO 3'!G185*12 -> 1226760
A13: 7102 | B13: REMUNERACIONES COMPLEMENTARIAS
A14: 710203 | B14: DECIMOTERCER SUELDO | C14: =144255.99 -> 144255.99 | D14: ='FORMULARIO 3'!G185 -> 102230
A15: 710204 | B15: DECIMOCUARTO SUELDO | C15: =66966.5 -> 66966.5 | D15: =174*366 -> 63684
A17: 7103 | B17: REMUNERACIONES COMPENSATORIAS
A18: 710304 | B18: COMPENSACION POR TRANSPORTE | C18: =23232 -> 23232 | D18: =22968 -> 22968 | E18: 174 trabajadores
A19: 710306 | B19: ALIMENTACION | C19: =139392 -> 139392 | D19: =183744 -> 183744 | E19: 174 trabajadores
A20: 710307 | B20: COMISARIATO | C20: 0 | D20: 0
A22: 7104 | B22: SUBSIDIOS
A23: 710401 | B23: POR CARGAS FAMILIARES | C23: =102.66 -> 102.66 | D23: =(10.62*12) -> 127.44
A25: 7105 | B25: REMUNERACIONES TEMPORALES
A26: 710509 | B26: HORAS EXTRAORDINARIAS Y SUPLEMENTARIAS | C26: =(10026.96+12790.16+13122.45+10123.66+13608.86+10728.94+11487.59+13784.5+10493.81+13113.98+8428.74+8934.64) -> 136644.29 | D26: =C26*10%+C26 -> 150308.72
A28: 7106 | B28: APORTES A LA SEGURIDAD SOCIAL
A29: 710601 | B29: APORTE PATRONAL | C29: =C11*12.15% -> 146549.41 | D29: =D11*12.15% -> 149051.34
A30: 710602 | B30: FONDO DE RESERVA | C30: =C11/12 -> 100514 | D30: =D11/12 -> 102230
A31: 710603 | B31: FONDO DE JUBILACION PATRONAL | C31: 0 | D31: 0
A33: 7107 | B33: INDEMNIZACIONES
A34: 710704 | B34: COMPENSACION POR DESAHUCIO | C34: 0 | D34: 0
A35: 710705 | B35: POR JUBILACIÓN | C35: 0 | D35: 230155.31
A37: 7308 | B37: BIENES DE USO Y CONUSMO DE INVERSIÓN
A38: 730802 | B38: VESTUARIO, LENCERÍA Y PRENDAS DE PROTECCIÓN | C38: =190*169 -> 32110 | D38: =174*169 -> 29406 | E38: 174 trabajadores
B40: TOTAL | C40: =SUM(C10:C39) -> 1995934.9 | D40: =SUM(D10:D39) -> 2260664.8
B41: INCREMENTO PORCENTUAL % | D41: =SUM(D40-C40)/C40*100 -> 13.263457
A42: NOTA: | B42: Las partidas de inversión corresponden al PROGRAMA OTROS SERVICIOS COMUNALES
A43: * De ser el caso, se deberá incluir filas adicionales, para detallar los subgrupos o items correspondientes.
A44: * En caso de que en el contrato colectivo se negocie algún beneficio adicional a los expuestos favor incluir el item correspondiente.
A45: * La información de los formularios deberá remitirse en medio magnético (Excel) e impreso con las respectivas firmas de responsabilidad.
B50: FIRMA DIRECTOR (A) FINANCIERO (A) DEL GAD
B51: Dr. C.P.A. Julio Farinango Benalcázar
B53: Lugar y Fecha: Catamayo, 01/12/2016
B54: Sello Institucional
E79: ='FORMULARIO 2'!C185 -> 0

Sheet FORMULARIO 3
A1: MINISTERIO DE FINANZAS
A2: FORMULARIO 3: "COMPARATIVO ENTRE REMUNERACIÓN UNIFICADA Y PROPUESTA"
A3: DISTRIBUTIVO DE SALARIO UNIFICADO DESAGREGADO POR TRABAJADOR
A5: GOBIERNO AUTÓNOMO DESCENTRALIZADO MUNICIPAL DE CATAMAYO
A6: Nº PROYECTO CONTRATO COLECTIVO: DÉCIMO SEGUNDO
A7: Nº ACTA TRANSACCIONAL ___________________________
A9: CEDULA | B9: APELLIDOS Y NOMBRES | C9: No. TRABAJADOR | D9: GRADO DEL CARGO O PUESTO | E9: DENOMINACIÓN DEL PUESTO O CARGO DE OCUPACIÓN | F9: REMUNERACIÓN UNIFICADA CONTRATO COLECTIVO VIGENTE USD (2015) | G9: REMUNERACIÓN UNIFICADA 2016 CONTRATO COLECTIVO PROPUESTO USD | H9: OBSERVACIONES
A10: 1103017040 | B10: CARREÑO MARIN IVAN PATRICIO | C10: 1 | D10: 1 | E10: AUXILIAR DE SERV. MUNICIPALES | F10: =531 -> 531 | G10: =549 -> 549
A11: 1101175709 | B11: CUESTA JIMENEZ MARCO ANTONIO | C11: 2 | D11: 1 | E11: JORNALERO DE PARQUES Y JARDINES | F11: =531 -> 531 | G11: =549 -> 549
A12: 1103654313 | B12: MARIN SOLORZANO LEONARDO EZEQUIEL | C12: 3 | D12: 1 | E12: AUXILIAR ADM. DE TRAMITES | F12: =531 -> 531 | G12: =549 -> 549
A13: 1105156853 | B13: MAZA GUAMAN GUIDO RENE | C13: 4 | D13: 1 | E13: AYUDANTE DE ALBAÑIL | F13: =531 -> 531 | G13: =549 -> 549
A14: 1101628483 | B14: SACAPI LUIS ENRIQUE | C14: 5 | D14: 1 | E14: GUARDIAN ADMINISTRATIVO | F14: =531 -> 531 | G14: =549 -> 549
A15: 1100809993 | B15: BALCAZAR RAMIREZ ANGEL TORIBIO | C15: 6 | D15: 1 | E15: GUARDIAN ADMINISTRATIVO | F15: =531 -> 531 | G15: =549 -> 549
A16: 1103256374 | B16: BARRERA POLO HECTOR ENRIQUE | C16: 7 | D16: 1 | E16: AUXILIAR ADMINISTRATIVO 111 | F16: =531 -> 531 | G16: =549 -> 549
A17: 1104721384 | B17: BRICEÑO BRICEÑO DIEGO FERNANDO | C17: 8 | D17: 1 | E17: GUARDIAN ADMINISTRATIVO | F17: =531 -> 531 | G17: =549 -> 549
A18: 1102914007 | B18: CABRERA GONZALEZ MANUEL IGNACIO | C18: 9 | D18: 1 | E18: GUARDIAN ADMINISTRATIVO | F18: =531 -> 531 | G18: =549 -> 549
A19: 1101055463 | B19: CABRERA MACAS EFRAIN | C19: 10 | D19: 1 | E19: GUARDIAN ADMINISTRATIVO | F19: =531 -> 531 | G19: =549 -> 549
A20: 1101060588 | B20: CARRION ENCALADA ELICEO | C20: 11 | D20: 1 | E20: GUARDIAN ADMINISTRATIVO | F20: =531 -> 531 | G20: =549 -> 549
A21: 1101431839 | B21: CASTILLO FRANCO VICENTE | C21: 12 | D21: 1 | E21: GUARDIAN ADMINISTRATIVO | F21: =531 -> 531 | G21: =549 -> 549
... A117: 1100765989 | B117: YAGUANA POGO CESAR AMABLE | C117: 108 | D117: 1 | E117: AYUDANTE DE ALBAÑIL | F117: =531 -> 531 | G117: =549 -> 549
A118: 1104395007 | B118: JARAMILLO JARAMILLO DIEGO ARMANDO | C118: 109 | D118: 2 | E118: CONTROLADOR MANTENIMIENTO AGUA | F118: =548 -> 548 | G118: =566 -> 566
A119: 0701942575 | B119: MACAS CHUNCHO FLORESMILO ADRIANO | C119: 110 | D119: 2 | E119: CONTROLADOR MANTENIMIENTO AGUA | F119: =548 -> 548 | G119: =566 -> 566
A120: 1103141899 | B120: NAVARRO CHIRIBOGA NILO ALBERTO | C120: 111 | D120: 2 | E120: GASFITERO | F120: =548 -> 548 | G120: =566 -> 566
A121: 1102135652 | B121: AGUIRRE GONZAGA WILMAN ORLANDO | C121: 112 | D121: 2 | E121: MAESTRO ALBAÑIL | F121: =548 -> 548 | G121: =566 -> 566
A122: 1101963427 | B122: CASTILLO CUENCA JORGE ENRIQUE | C122: 113 | D122: 2 | E122: MAESTRO ALBAÑIL | F122: =548 -> 548 | G122: =566 -> 566
A123: 1102997705 | B123: CHAMBA CUENCA OLGER EDUARDO | C123: 114 | D123: 2 | E123: MAESTRO ALBAÑIL | F123: =548 -> 548 | G123: =566 -> 566
A124: 1103292759 | B124: JIMENEZ CHAMBA JORGE FELICITO | C124: 115 | D124: 2 | E124: MAESTRO ALBAÑIL | F124: =548 -> 548 | G124: =566 -> 566
A125: 1718055542 | B125: RIVAS ALVAREZ LUIS RODRIGO | C125: 116 | D125: 2 | E125: MECANICO INDUSTRIAL | F125: =548 -> 548 | G125: =566 -> 566
A126: 0701121519 | B126: RODRIGUEZ RODRIGUEZ ROBERT RAUL | C126: 117 | D126: 2 | E126: PINTOR AUTOMOTRIZ | F126: =548 -> 548 | G126: =566 -> 566
A127: 1102740154 | B127: VASQUEZ FERNÁNDEZ HONORATO | C127: 118 | D127: 2 | E127: PINTOR | F127: =548 -> 548 | G127: =566 -> 566
A128: 1102773775 | B128: VEGA VIÑAGUAZO JOSE AUGUSTO | C128: 119 | D128: 2 | E128: MAESTRO ALBAÑIL | F128: =548 -> 548 | G128: =566 -> 566
A129: 1100255023 | B129: VILLALTA TORRES LEONARDO AMADEO | C129: 120 | D129: 2 | E129: MAESTRO ALBAÑIL | F129: =548 -> 548 | G129: =566 -> 566
... A133: 1101797171 | B133: YAGUANA HERRERA FRANCISCO JAVIER | C133: 124 | D133: 2 | E133: MAESTRO ALBAÑIL | F133: =548 -> 548 | G133: =566 -> 566
A134: 1103230585 | B134: SOLANO SOLANO JOSÉ RAMIRO | C134: 125 | D134: 3 | E134: CHOFER VEHICULOS LIVIANOS | F134: =566 -> 566 | G134: =584 -> 584
A135: 1103245146 | B135: CHUBA QUITO CÉSAR ROLANDO | C135: 126 | D135: 3 | E135: CHOFER VEHICULOS LIVIANOS | F135: =566 -> 566 | G135: =584 -> 584
A136: 1101347506 | B136: GONZALEZ AYORA JUAN IGNACIO | C136: 127 | D136: 3 | E136: CHOFER VEHICULOS LIVIANOS | F136: =566 -> 566 | G136: =584 -> 584
A137: 0101510477 | B137: QUITO ENRIQUEZ LUIS MIGUEL | C137: 128 | D137: 3 | E137: MAESTRO ALBAÑIL 11 | F137: =560 -> 560 | G137: =578 -> 578
A138: 1101673034 | B138: VACA TAMAYO ANGEL SALVADOR | C138: 129 | D138: 4 | E138: CHOFER VEHICULOS PESADOS | F138: =584 -> 584 | G138: =602 -> 602
A139: 1101879482 | B139: CARRILLO MARÍN JORGE NICOLÁS | C139: 130 | D139: 4 | E139: CHOFER VEHICULOS PESADOS | F139: =584 -> 584 | G139: =602 -> 602
A140: 1104412398 | B140: CRUZ VALDIVIEZO DIEGO FERNANDO | C140: 131 | D140: 4 | E140: CHOFER VEHICULOS PESADOS | F140: =584 -> 584 | G140: =602 -> 602
...

Sheet FORMULARIO 4
A1: FORMULARIO 4
A2: FLUJO PRESUPUESTARIO DE INGRESOS Y GASTOS
A4: GOBIERNO AUTÓNOMO DESCENTRALIZADO MUNICIPAL DE CATAMAYO
A6: DETALLE DE GRUPOS Y SUBGRUPOS | C6: FLUJO HISTÓRICO (USD) | F6: FLUJO PROYECTADO (USD) | J6: OBSERVACIONES
A8: Grupo y Subgrupo | B8: Descripción | C8: 2013 | D8: 2014 | E8: 2015 | F8: AÑO 1 | G8: AÑO 2 | H8: AÑO 3 | I8: AÑO 4
A9: TOTAL INGRESOS CORRIENTES (1) | C9: =SUM(C11:C32) -> 3297110.5 | D9: =SUM(D11:D32) -> 3380227.1 | E9: =SUM(E11:E32) -> 3156612.3 | F9: =SUM(F11:F32) -> 3219744.5 | G9: =SUM(G11:G32) -> 3284139.4 | H9: =SUM(H11:H32) -> 3316980.8 | I9: =SUM(I11:I32) -> 3350150.6
A10: 11 | B10: Impuestos
A11: 1101 | B11: Sobre la Renta, Utilidades y Ganancias de Capital | C11: 111045.83 | D11: =146142.35 -> 146142.35 | E11: =99217.63 -> 99217.63 | F11: =SUM(E11*0.02)+E11 -> 101201.98 | G11: =SUM(F11*0.02)+F11 -> 103226.02 | H11: =SUM(G11*0.01)+G11 -> 104258.28 | I11: =SUM(H11*0.01)+H11 -> 105300.87
A12: 1102 | B12: Sobre la propiedad | C12: =167202.17+12114.77+196402.45+166707.73+46095.16 -> 588522.28 | D12: =173338.9+13645.16+182591.57+138360.88+63500.18 -> 571436.69 | E12: =175676.27+13653.89+164394.88+123512.11+53463.72 -> 530700.87 | F12: =SUM(E12*0.02)+E12 -> 541314.89 | G12: =SUM(F12*0.02)+F12 -> 552141.19 | H12: =SUM(G12*0.01)+G12 -> 557662.6 | I12: =SUM(H12*0.01)+H12 -> 563239.22
A13: 1103 | B13: Al consumo de Bienes y Servicios | C13: 234 | D13: 250 | E13: 184 | F13: =SUM(E13*0.02)+E13 -> 187.68 | G13: =SUM(F13*0.02)+F13 -> 191.4336 | H13: =SUM(G13*0.01)+G13 -> 193.34794 | I13: =SUM(H13*0.01)+H13 -> 195.28142
A14: 1107 | B14: Impuestos Diversos | C14: =128387 -> 128387 | D14: =193144.23 -> 193144.23 | E14: 87304.47 | F14: =SUM(E14*0.02)+E14 -> 89050.559 | G14: =SUM(F14*0.02)+F14 -> 90831.571 | H14: =SUM(G14*0.01)+G14 -> 91739.886 | I14: =SUM(H14*0.01)+H14 -> 92657.285
A15: 13 | B15: Tasas y contribuciones
A16: 1301 | B16: Tasas generales | C16: =122450.83+59887.04+16025+6906.4+46921.35+11581.7+2955+62158.82+54281.68+9367.31+7982.32+64673.63 -> 465191.08 | D16: =126810.25+52132.71+16403+5639+51161.77+3100+63210.49+27807.4+6855.44+9235+64125.13 -> 426480.19 | E16: =133949.71+50030.13+10596.5+6590.52+50521.26+4440+67357.58+47667.92+7554.51+7410+63037.53 -> 449155.66 | F16: =SUM(E16*0.02)+E16 -> 458138.77 | G16: =SUM(F16*0.02)+F16 -> 467301.55 | H16: =SUM(G16*0.01)+G16 -> 471974.56 | I16: =SUM(H16*0.01)+H16 -> 476694.31
A17: 1302 | B17: Tasas portuarias y aeroportuarias
A18: 1303 | B18: Tasas diversas
A19: 1304 | B19: Contribuciones | C19: =28963.58+32272.69+30065.14+231399.67 -> 322701.08 | D19: =1755.94+10980.13+9180.3+219599.83+1089.48 -> 242605.68 | E19: =7185.35+3371.76+19676.54+316687.34 -> 346920.99 | F19: =SUM(E19*0.02)+E19 -> 353859.41 | G19: =SUM(F19*0.02)+F19 -> 360936.6 | H19: =SUM(G19*0.01)+G19 -> 364545.96 | I19: =SUM(H19*0.01)+H19 -> 368191.42
A20: 14 | B20: Venta de Bienes y Servicios
A21: 1402 | B21: Ventas de productos y materiales | C21: =17626.62+230.5 -> 17857.12 | D21: =18974.2+289 -> 19263.2 | E21: =16727.85+182 -> 16909.85 | F21: =SUM(E21*0.02)+E21 -> 17248.047 | G21: =SUM(F21*0.02)+F21 -> 17593.008 | H21: =SUM(G21*0.01)+G21 -> 17768.938 | I21: =SUM(H21*0.01)+H21 -> 17946.627
A22: 1403 | B22: Ventas no industriales | C22: =154831.61+55623.07 -> 210454.68 | D22: =156344.71+56417.14 -> 212761.85 | E22: =168348.81+63825.22 -> 232174.03 | F22: =SUM(E22*0.02)+E22 -> 236817.51 | G22: =SUM(F22*0.02)+F22 -> 241553.86 | H22: =SUM(G22*0.01)+G22 -> 243969.4 | I22: =SUM(H22*0.01)+H22 -> 246409.09
A23: 17 | B23: Rentas de Invesiones y Multas
A24: 1701 | B24: Rentas de inversiones | C24: 15.34
A25: 1702 | B25: Rentas por arrendamientos de bienes | C25: =32905.95+5018.8+7444.94 -> 45369.69 | D25: =6160+324.43+12876.9 -> 19361.33 | E25: =6619+635.24+14203.27 -> 21457.51 | F25: =SUM(E25*0.02)+E25 -> 21886.66 | G25: =SUM(F25*0.02)+F25 -> 22324.393 | H25: =SUM(G25*0.01)+G25 -> 22547.637 | I25: =SUM(H25*0.01)+H25 -> 22773.114
A26: 1704 | B26: Multas | C26: =29987.36+1911+31589.63+7493.6 -> 70981.59 | D26: =39512.92+3234.5+9243.35+55528.12 -> 107518.89 | E26: =35726.56+3103.28+40315.74 -> 79145.58 | F26: =SUM(E26*0.02)+E26 -> 80728.492 | G26: =SUM(F26*0.02)+F26 -> 82343.061 | H26: =SUM(G26*0.01)+G26 -> 83166.492 | I26: =SUM(H26*0.01)+H26 -> 83998.157
A27: 18 | B27: Transferencias y Donaciones Corrientes
A28: 1806 | B28: Aporte y participación cooriente del Régimen Seccional Autónomo | C28: =1336334.83 -> 1336334.8 | D28: =1441262.68 -> 1441262.7 | E28: =1293441.69 -> 1293441.7 | F28: =SUM(E28*0.02)+E28 -> 1319310.5 | G28: =SUM(F28*0.02)+F28 -> 1345696.7 | H28: =SUM(G28*0.01)+G28 -> 1359153.7 | I28: =SUM(H28*0.01)+H28 -> 1372745.2
A29: 19 | B29: Otros ingresos
A30: 1901 | B30: Garantías y Fianzas
A31: 1902 | B31: Indemnizaciones y valores no reclamados
A32: 1904 | B32: Otros no Operacionales | C32: 16.01
A33: TOTAL GASTOS CORRIENTES (2) | C33: =SUM(C35:C62) -> 1837469.1 | D33: =SUM(D35:D62) -> 2461219.6 | E33: =SUM(E35:E62) -> 1158025.5 | F33: =SUM(F35:F62) -> 1181186 | G33: =SUM(G35:G62) -> 1204809.7 | H33: =SUM(H35:H62) -> 1216857.8 | I33: =SUM(I35:I62) -> 1229026.4
A34: 51 | B34: Gastos en personal
A35: 5101 | B35: Remuneraciones Básicas | C35: =230789.6+127969.71+24766.45+47047.6+13917.85+145583.42+199274.3+41710.83+49888.2+41132.2 -> 922080.16 | D35: =239851.96+147437.21+24779.43+47915.88+18473.65+172625.23+249463.04+53470.6+54306.63+49029.36 -> 1057353 | E35: =171120.6+117780.28+24285.62+38590.78+120629.16 -> 472406.44 | F35: =SUM(E35*0.02)+E35 -> 481854.57 | G35: =SUM(F35*0.02)+F35 -> 491491.66 | H35: =SUM(G35*0.01)+G35 -> 496406.58 | I35: =SUM(H35*0.01)+H35 -> 501370.64
A36: 5102 | B36: Remuneraciones Complementarias | C36: =3869.89+4329.42+237.62+1590+287.08+5939+13557.89+2186.25+1590+1271.12 -> 34858.27 | D36: =19116.45+16508.46+2508.76+4048.9+1781.48+22487.66+38719.95+7082.81+6474.25+5003.48 -> 123732.2 | E36: =18148.42+16643.22+3440.24+5221.57+16624.89 -> 60078.34 | F36: =SUM(E36*0.02)+E36 -> 61279.907 | G36: =SUM(F36*0.02)+F36 -> 62505.505 | H36: =SUM(G36*0.01)+G36 -> 63130.56 | I36: =SUM(H36*0.01)+H36 -> 63761.866
A37: 5103 | B37: Remuneraciones Compensatorias
A38: 5104 | B38: Subsidios
A39: 5105 | B39: Remuneraciones Temporales | C39: =46003.36+28482.67+3400.58+5595.63+15202.94+63812.94+1205.2+80217.39+697.84 -> 244618.55 | D39: =17759.87+24793.51+7490.75+8067.13+19557.02+78596.78+577.38+77576.05 -> 234418.49 | E39: =3660+108099.22+12589.07+35727.22 -> 160075.51 | F39: =SUM(E39*0.02)+E39 -> 163277.02 | G39: =SUM(F39*0.02)+F39 -> 166542.56 | H39: =SUM(G39*0.01)+G39 -> 168207.99 | I39: =SUM(H39*0.01)+H39 -> 169890.07
A40: 5106 | B40: Aportes Patronales a la Seguridad Social | C40: =44859.78+21485.36+3528.08+9400.2+1660.72+27991.27+40317.4+8687.54+9563.45+7151.93 -> 174645.73 | D40: =39571.04+24921.14+4583.57+9599.98+2270.35+32133.8+54763.57+10314.38+9669.84+7958.08 -> 195785.75 | E40: =33686.24+23804.1+5321.41+8579.89+27368.88 -> 98760.52 | F40: =SUM(E40*0.02)+E40 -> 100735.73 | G40: =SUM(F40*0.02)+F40 -> 102750.45 | H40: =SUM(G40*0.01)+G40 -> 103777.95 | I40: =SUM(H40*0.01)+H40 -> 104815.73
A41: 5107 | B41: Indemnizaciones | C41: =54416.72 -> 54416.72 | D41: =163813.55 -> 163813.55 | E41: =86010.09 -> 86010.09 | F41: =SUM(E41*0.02)+E41 -> 87730.292 | G41: =SUM(F41*0.02)+F41 -> 89484.898 | H41: =SUM(G41*0.01)+G41 -> 90379.747 | I41: =SUM(H41*0.01)+H41 -> 91283.544
A42: 5199 | B42: Asignaciones a distribuir
A43: 53 | B43: Bienes y servicios de consumo
...

Sheet Hoja2
B1: 2014 | C1: 2015 | E1: 2016 | F1: 2017
A2: total mensual salarios | B2: 88370.42 | C2: 100514 | D2: 99098 | E2: 102230 | F2: 104318
A3: Decimo tercer sueldo | B3: 84911.16 | C3: 129936.74
C4: =2184.94+1964.14+112.82+1964.14+137.66+1827.03+131.47+1827.03+154.35+1827.03+196.11+1827.03+165.5 -> 14319.25
A6: Decimo cuarto | B6: 53380 | C6: =63248+3718.5 -> 66966.5
A11: Decimo Cuarto 2016 | B11: =174*366 -> 63684 | D11: se toma en cuenta 174 trabajadores por 366 que es el salario minimo unificado
A12: Decimo Cuarto 2017 | B12: =174*380 -> 66120 | D12: se toma en cuenta 174 trabajadores por 380 que es el salario minimo unificado
A15: Decimo Tercer 2016 | B15: ='FORMULARIO 3'!G185/12 -> 8519.1667
A16: Decimo Tercer 2017 | B16: ='FORMULARIO 3'!#REF!/12 -> #REF!
A19: Alimentacion 2014 | B19: =(((3*22)*12)*188) -> 148896 | D19: la alimentacion se considera 3 dola diarios por 22 dias del mes por 12 meses y por 188 trabajadores permanentes
A20: Alimentacion 2015 | B20: =(((3*22)*12)*176) -> 139392 | D20: la alimentacion se considera 3 dola diarios por 22 dias del mes por 12 meses y por 176 trabajadores permanentes
A23: Alimentacion 2016 | B23: =(((4*22)*12)*174) -> 183744 | D23: la alimentacion se considera 4 dola diarios por 22 dias del mes por 12 meses y por 174 trabajadores permanentes
A24: Alimentacion 2017 | B24: =(((4*22)*12)*174) -> 183744 | D24: la alimentacion se considera 4 dola diarios por 22 dias del mes por 12 meses y por 174 trabajadores permanentes
A26: transporte 2014 | B26: =(((0.5*22)*12)*188) -> 24816 | D26: la alimentacion se considera 0.5 dola diarios por 22 dias del mes por 12 meses y por 188 trabajadores permanentes
A27: transporte 2015 | B27: =(((0.5*22)*12)*176) -> 23232 | D27: la alimentacion se considera 0.5 dola diarios por 22 dias del mes por 12 meses y por 176 trabajadores permanentes
A29: transporte 2016 | B29: =(((0.5*22)*12)*174) -> 22968 | D29: la alimentacion se considera 0.5 dola diarios por 22 dias del mes por 12 meses y por 174 trabajadores permanentes
A30: transporte 2017 | B30: =(((0.5*22)*12)*174) -> 22968 | D30: la alimentacion se considera 0.5 dola diarios por 22 dias del mes por 12 meses y por 174 trabajadores permanentes
A33: subs. Familiar | B33: 102.66 | D33: solo de marzo a diciembre 2015 7.08 de marzo y 10.62 de abril a diciembre de 2015
