Workbook

Sheet ENERO
A1: Zona | B1: provincia | C1: canton | D1: distrito | E1: unicodigo | F1: uni_nombre | G1: nivel | H1: tipo | I1: int_msp | J1: ext_CNH | K1: ext_cibv | L1: ext_educ_gene_basic | M1: ext_bachillerato | N1: ext_visita_domi | O1: ext_comuni | P1: ext_otros | Q1: sexo_h | R1: sexo_m | S1: pertenece_ES | T1: No_pertenece_ES | U1: ecuatoriano | V1: colombiano | W1: peruano | X1: cubano | Y1: venezolano | Z1: otros | AA1: indigena | AB1: afro | AC1: negro | AD1: mulato | AE1: montubio | AF1: mestizo | AG1: blanco | AH1: otro | AI1: Achuar | AJ1: Andoa | AK1: Awa | AL1: Chachi | AM1: Cofan | AN1: Epera | AO1: Huancavilca | AP1: Kichwa | AQ1: Manta | AR1: Secoya | AS1: Shiwiar | AT1: Shuar | AU1: Siona | AV1: Tsáchila | AW1: Waorani | AX1: Zapara | AY1: Chibuleo | AZ1: Kañari | BA1: Karanki | BB1: Kayambi | BC1: Kichwa Amazónico | BD1: Kisapincha | BE1: Kitukara | BF1: Natabuela | BG1: Otavalo | BH1: Paltas | BI1: Panzaleo | BJ1: Pastos | BK1: Puruha | BL1: Salasaka | BM1: Saraguro | BN1: Tomabela | BO1: Waramka | BP1: BCG_24 | BQ1: HB_24 | BR1: BCG_365 | BS1: rota_1 | BT1: fIPV_1 | BU1: neumo_1 | BV1: penta_1 | BW1: rota_2 | BX1: fIPV_2 | BY1: neumo_2 | BZ1: penta_2 | CA1: bopv_3 | CB1: neumo_3 | CC1: penta_3 | CD1: srp_1 | CE1: fa | CF1: varicela | CG1: srp_2 | CH1: bopv_4 | CI1: dpt_4 | CJ1: bopv_5 | CK1: dpt_5 | CL1: hpv_9a_1d | CM1: hpv_9a_2d | CN1: hpv_10a_2d | CO1: dt_3
A2: Z07 | B2: EL ORO | C2: ARENILLAS | D2: 07D05 | E2: 000541 | F2: SAN VICENTE | G2: NIVEL 1 | H2: CENTRO DE SALUD TIPO A
A3: Z07 | B3: EL ORO | C3: ARENILLAS | D3: 07D05 | E3: 000542 | F3: SAN ISIDRO URBANO | G3: NIVEL 1 | H3: CENTRO DE SALUD TIPO B
A4: Z07 | B4: EL ORO | C4: ARENILLAS | D4: 07D05 | E4: 000543 | F4: CAÑAS | G4: NIVEL 1 | H4: PUESTO DE SALUD
A5: Z07 | B5: EL ORO | C5: ARENILLAS | D5: 07D05 | E5: 000544 | F5: LA CUCA | G5: NIVEL 1 | H5: CENTRO DE SALUD TIPO A
A6: Z07 | B6: EL ORO | C6: ARENILLAS | D6: 07D05 | E6: 000545 | F6: CARCABON | G6: NIVEL 1 | H6: CENTRO DE SALUD TIPO A
A7: Z07 | B7: EL ORO | C7: ARENILLAS | D7: 07D05 | E7: 000546 | F7: CHACRAS | G7: NIVEL 1 | H7: CENTRO DE SALUD TIPO A
A8: Z07 | B8: EL ORO | C8: ARENILLAS | D8: 07D05 | E8: 000547 | F8: PALMALES | G8: NIVEL 1 | H8: CENTRO DE SALUD TIPO A
A9: Z07 | B9: EL ORO | C9: ARENILLAS | D9: 07D05 | E9: 000548 | F9: MANABI DE EL ORO | G9: NIVEL 1 | H9: PUESTO DE SALUD
A10: Z07 | B10: EL ORO | C10: ARENILLAS | D10: 07D05 | E10: 000591 | F10: HOSPITAL BASICO DE ARENILLAS | G10: NIVEL 2 | H10: HOSPITAL BASICO
A11: Z07 | B11: EL ORO | C11: ARENILLAS | D11: 07D05 | E11: 002763 | F11: EL JOBO SAN VICENTE | G11: NIVEL 1 | H11: PUESTO DE SALUD
A12: Z07 | B12: EL ORO | C12: ARENILLAS | D12: 07D05 | E12: 002900 | F12: CENTRO DE SALUD ARENILLAS | G12: NIVEL 1 | H12: CENTRO DE SALUD TIPO A
A13: Z07 | B13: EL ORO | C13: ATAHUALPA | D13: 07D03 | E13: 000576 | F13: AYAPAMBA | G13: NIVEL 1 | H13: CENTRO DE SALUD TIPO A
... A256: Z07 | B256: ZAMORA CHINCHIPE | C256: CENTINELA DEL CONDOR | D256: 19D02 | E256: 001900 | F256: ZUMBI | G256: NIVEL 1 | H256: CENTRO DE SALUD TIPO A
A257: Z07 | B257: ZAMORA CHINCHIPE | C257: CHINCHIPE | D257: 19D03 | E257: 001901 | F257: LA CHONTA | G257: NIVEL 1 | H257: CENTRO DE SALUD TIPO A | I257: 3 | Q257: 1 | R257: 2 | S257: 2 | T257: 1 | U257: 3 | AF257: 3 | CD257: 1 | CE257: 1 | CF257: 1 | CG257: 1 | CO257: 1
A258: Z07 | B258: ZAMORA CHINCHIPE | C258: CHINCHIPE | D258: 19D03 | E258: 001902 | F258: EL CHORRO | G258: NIVEL 1 | H258: PUESTO DE SALUD
A259: Z07 | B259: ZAMORA CHINCHIPE | C259: CHINCHIPE | D259: 19D03 | E259: 001903 | F259: CHITO | G259: NIVEL 1 | H259: CENTRO DE SALUD TIPO A | I259: 15 | N259: 2 | Q259: 9 | R259: 8 | S259: 16 | T259: 1 | U259: 15 | W259: 1 | X259: 1 | AF259: 15 | AH259: 2 | BP259: 1 | BQ259: 1 | BS259: 1 | BT259: 1 | BU259: 1 | BV259: 1 | BW259: 4 | BX259: 4 | BY259: 4 | BZ259: 4 | CA259: 1 | CB259: 1 | CC259: 1 | CD259: 1 | CE259: 1 | CF259: 4 | CG259: 4 | CH259: 4 | CI259: 4 | CL259: 1
A260: Z07 | B260: ZAMORA CHINCHIPE | C260: CHINCHIPE | D260: 19D03 | E260: 001921 | F260: LA GUAYUZA | G260: NIVEL 1 | H260: PUESTO DE SALUD | I260: 3 | Q260: 2 | R260: 1 | S260: 3 | U260: 3 | AF260: 3 | BS260: 1 | BT260: 1 | BU260: 1 | BV260: 1 | BW260: 1 | BX260: 1 | BY260: 1 | BZ260: 1 | CG260: 1 | CH260: 1 | CI260: 1
A261: Z07 | B261: ZAMORA CHINCHIPE | C261: CHINCHIPE | D261: 19D03 | E261: 001922 | F261: LA DIVERSION | G261: NIVEL 1 | H261: CENTRO DE SALUD TIPO A | I261: 3 | L261: 4 | M261: 8 | N261: 3 | Q261: 8 | R261: 10 | S261: 18 | U261: 18 | AF261: 18 | BS261: 2 | BT261: 2 | BU261: 2 | BV261: 2 | CA261: 2 | CB261: 2 | CC261: 2 | CD261: 1 | CE261: 1 | CF261: 1 | CJ261: 2 | CK261: 2 | CL261: 2 | CO261: 8
A262: Z07 | B262: ZAMORA CHINCHIPE | C262: CHINCHIPE | D262: 19D03 | E262: 001923 | F262: SAN ANDRES | G262: NIVEL 1 | H262: PUESTO DE SALUD | I262: 3 | N262: 1 | Q262: 3 | R262: 1 | S262: 4 | U262: 4 | AF262: 4 | BS262: 1 | BT262: 1 | BU262: 1 | BV262: 1 | BW262: 1 | BX262: 1 | BY262: 1 | BZ262: 1 | CD262: 1 | CE262: 1 | CL262: 1
A263: Z07 | B263: ZAMORA CHINCHIPE | C263: CHINCHIPE | D263: 19D03 | E263: 001949 | F263: HOSPITAL BASICO DE ZUMBA | G263: NIVEL 2 | H263: HOSPITAL BASICO | I263: 9 | Q263: 8 | R263: 1 | S263: 4 | T263: 5 | U263: 9 | AF263: 9 | BP263: 8 | BQ263: 8 | BR263: 1
A264: Z07 | B264: ZAMORA CHINCHIPE | C264: CHINCHIPE | D264: 19D03 | E264: 002846 | F264: CENTRO DE SALUD DE ZUMBA | G264: NIVEL 1 | H264: CENTRO DE SALUD TIPO A | I264: 83 | N264: 3 | Q264: 32 | R264: 54 | S264: 86 | U264: 86 | AF264: 86 | BS264: 11 | BT264: 11 | BU264: 11 | BV264: 11 | BW264: 12 | BX264: 12 | BY264: 12 | BZ264: 12 | CA264: 14 | CB264: 14 | CC264: 14 | CD264: 10 | CE264: 11 | CF264: 7 | CG264: 8 | CH264: 8 | CI264: 9 | CJ264: 8 | CK264: 8 | CL264: 10 | CM264: 1 | CO264: 3
A265: Z07 | B265: ZAMORA CHINCHIPE | C265: EL PANGUI | D265: 19D04 | E265: 001912 | F265: PACHICUTZA | G265: NIVEL 1 | H265: PUESTO DE SALUD
A266: Z07 | B266: ZAMORA CHINCHIPE | C266: EL PANGUI | D266: 19D04 | E266: 001913 | F266: EL PANGUI | G266: NIVEL 1 | H266: CENTRO DE SALUD TIPO B
A267: Z07 | B267: ZAMORA CHINCHIPE | C267: EL PANGUI | D267: 19D04 | E267: 001914 | F267: TUNDAYME | G267: NIVEL 1 | H267: PUESTO DE SALUD
A268: Z07 | B268: ZAMORA CHINCHIPE | C268: EL PANGUI | D268: 19D04 | E268: 001933 | F268: EL GUISMI | G268: NIVEL 1 | H268: PUESTO DE SALUD
A269: Z07 | B269: ZAMORA CHINCHIPE | C269: EL PANGUI | D269: 19D04 | E269: 001934 | F269: CHUCHUMBLETZA | G269: NIVEL 1 | H269: PUESTO DE SALUD
A270: Z07 | B270: ZAMORA CHINCHIPE | C270: NANGARITZA | D270: 19D02 | E270: 001906 | F270: NUEVO PARAISO | G270: NIVEL 1 | H270: PUESTO DE SALUD
A271: Z07 | B271: ZAMORA CHINCHIPE | C271: NANGARITZA | D271: 19D02 | E271: 001907 | F271: SHAIMI | G271: NIVEL 1 | H271: PUESTO DE SALUD
A272: Z07 | B272: ZAMORA CHINCHIPE | C272: NANGARITZA | D272: 19D02 | E272: 001908 | F272: GERANIOS | G272: NIVEL 1 | H272: PUESTO DE SALUD
A273: Z07 | B273: ZAMORA CHINCHIPE | C273: NANGARITZA | D273: 19D02 | E273: 001909 | F273: ZURMI | G273: NIVEL 1 | H273: PUESTO DE SALUD
A274: Z07 | B274: ZAMORA CHINCHIPE | C274: NANGARITZA | D274: 19D02 | E274: 001925 | F274: SANTA ELENA | G274: NIVEL 1 | H274: PUESTO DE SALUD
A275: Z07 | B275: ZAMORA CHINCHIPE | C275: NANGARITZA | D275: 19D02 | E275: 001926 | F275: GUAYZIMI | G275: NIVEL 1 | H275: CENTRO DE SALUD TIPO A
A276: Z07 | B276: ZAMORA CHINCHIPE | C276: PALANDA | D276: 19D03 | E276: 001904 | F276: SAN FRANCISCO DEL VERGEL | G276: NIVEL 1 | H276: PUESTO DE SALUD | I276: 24 | Q276: 13 | R276: 11 | S276: 20 | T276: 4 | U276: 24 | AF276: 24 | BS276: 2 | BT276: 2 | BU276: 2 | BV276: 2 | BW276: 6 | BX276: 5 | BY276: 6 | BZ276: 6 | CA276: 6 | CB276: 6 | CC276: 6 | CD276: 4 | CE276: 4 | CF276: 4 | CG276: 1 | CH276: 1 | CL276: 1
A277: Z07 | B277: ZAMORA CHINCHIPE | C277: PALANDA | D277: 19D03 | E277: 001937 | F277: EL PORVENIR DEL CARMEN | G277: NIVEL 1 | H277: PUESTO DE SALUD | I277: 7 | Q277: 4 | R277: 3 | S277: 7 | U277: 7 | AF277: 7 | BR277: 2 | BW277: 1 | BX277: 1 | BY277: 1 | BZ277: 1 | CF277: 2 | CJ277: 2 | CK277: 2
A278: Z07 | B278: ZAMORA CHINCHIPE | C278: PALANDA | D278: 19D03 | E278: 001944 | F278: PALANDA | G278: NIVEL 1 | H278: CENTRO DE SALUD TIPO B | I278: 54 | L278: 8 | Q278: 27 | R278: 35 | S278: 54 | T278: 8 | U278: 62 | AF278: 62 | BP278: 2 | BQ278: 4 | BS278: 8 | BT278: 8 | BU278: 8 | BV278: 8 | BW278: 7 | BX278: 7 | BY278: 7 | BZ278: 7 | CA278: 5 | CB278: 5 | CC278: 5 | CD278: 10 | CE278: 10 | CF278: 6 | CG278: 10 | CH278: 10 | CI278: 10 | CL278: 11 | CN278: 1
A279: Z07 | B279: ZAMORA CHINCHIPE | C279: PALANDA | D279: 19D03 | E279: 001945 | F279: VALLADOLID | G279: NIVEL 1 | H279: CENTRO DE SALUD TIPO A | I279: 13 | M279: 22 | Q279: 13 | R279: 22 | S279: 35 | U279: 35 | AF279: 35 | BS279: 1 | BT279: 1 | BU279: 1 | BV279: 1 | BW279: 1 | BX279: 1 | BY279: 1 | BZ279: 1 | CD279: 4 | CE279: 4 | CF279: 2 | CG279: 2 | CH279: 2 | CI279: 2 | CL279: 3 | CO279: 22
A280: Z07 | B280: ZAMORA CHINCHIPE | C280: PALANDA | D280: 19D03 | E280: 001946 | F280: LA CANELA | G280: NIVEL 1 | H280: PUESTO DE SALUD | I280: 3 | Q280: 2 | R280: 1 | S280: 3 | U280: 3 | AF280: 3 | BP280: 2 | CF280: 1
A281: Z07 | B281: ZAMORA CHINCHIPE | C281: PAQUISHA | D281: 19D02 | E281: 001899 | F281: PAQUISHA | G281: NIVEL 1 | H281: CENTRO DE SALUD TIPO B
A282: Z07 | B282: ZAMORA CHINCHIPE | C282: PAQUISHA | D282: 19D02 | E282: 001941 | F282: BELLAVISTA | G282: NIVEL 1 | H282: PUESTO DE SALUD
...

Sheet FEBRERO
A1: Zona | B1: provincia | C1: canton | D1: distrito | E1: unicodigo | F1: uni_nombre | G1: nivel | H1: tipo | I1: int_msp | J1: ext_CNH | K1: ext_cibv | L1: ext_educ_gene_basic | M1: ext_bachillerato | N1: ext_visita_domi | O1: ext_comuni | P1: ext_otros | Q1: sexo_h | R1: sexo_m | S1: pertenece_ES | T1: No_pertenece_ES | U1: ecuatoriano | V1: colombiano | W1: peruano | X1: cubano | Y1: venezolano | Z1: otros | AA1: indigena | AB1: afro | AC1: negro | AD1: mulato | AE1: montubio | AF1: mestizo | AG1: blanco | AH1: otro | AI1: Achuar | AJ1: Andoa | AK1: Awa | AL1: Chachi | AM1: Cofan | AN1: Epera | AO1: Huancavilca | AP1: Kichwa | AQ1: Manta | AR1: Secoya | AS1: Shiwiar | AT1: Shuar | AU1: Siona | AV1: Tsáchila | AW1: Waorani | AX1: Zapara | AY1: Chibuleo | AZ1: Kañari | BA1: Karanki | BB1: Kayambi | BC1: Kichwa Amazónico | BD1: Kisapincha | BE1: Kitukara | BF1: Natabuela | BG1: Otavalo | BH1: Paltas | BI1: Panzaleo | BJ1: Pastos | BK1: Puruha | BL1: Salasaka | BM1: Saraguro | BN1: Tomabela | BO1: Waramka | BP1: BCG_24 | BQ1: HB_24 | BR1: BCG_365 | BS1: rota_1 | BT1: fIPV_1 | BU1: neumo_1 | BV1: penta_1 | BW1: rota_2 | BX1: fIPV_2 | BY1: neumo_2 | BZ1: penta_2 | CA1: bopv_3 | CB1: neumo_3 | CC1: penta_3 | CD1: srp_1 | CE1: fa | CF1: varicela | CG1: srp_2 | CH1: bopv_4 | CI1: dpt_4 | CJ1: bopv_5 | CK1: dpt_5 | CL1: hpv_9a_1d | CM1: hpv_9a_2d | CN1: hpv_10a_2d | CO1: dt_3
A2: Z07 | B2: EL ORO | C2: ARENILLAS | D2: 07D05 | E2: 000541 | F2: SAN VICENTE | G2: NIVEL 1 | H2: CENTRO DE SALUD TIPO A
A3: Z07 | B3: EL ORO | C3: ARENILLAS | D3: 07D05 | E3: 000542 | F3: SAN ISIDRO URBANO | G3: NIVEL 1 | H3: CENTRO DE SALUD TIPO B
A4: Z07 | B4: EL ORO | C4: ARENILLAS | D4: 07D05 | E4: 000543 | F4: CAÑAS | G4: NIVEL 1 | H4: PUESTO DE SALUD
A5: Z07 | B5: EL ORO | C5: ARENILLAS | D5: 07D05 | E5: 000544 | F5: LA CUCA | G5: NIVEL 1 | H5: CENTRO DE SALUD TIPO A
A6: Z07 | B6: EL ORO | C6: ARENILLAS | D6: 07D05 | E6: 000545 | F6: CARCABON | G6: NIVEL 1 | H6: CENTRO DE SALUD TIPO A
A7: Z07 | B7: EL ORO | C7: ARENILLAS | D7: 07D05 | E7: 000546 | F7: CHACRAS | G7: NIVEL 1 | H7: CENTRO DE SALUD TIPO A
A8: Z07 | B8: EL ORO | C8: ARENILLAS | D8: 07D05 | E8: 000547 | F8: PALMALES | G8: NIVEL 1 | H8: CENTRO DE SALUD TIPO A
A9: Z07 | B9: EL ORO | C9: ARENILLAS | D9: 07D05 | E9: 000548 | F9: MANABI DE EL ORO | G9: NIVEL 1 | H9: PUESTO DE SALUD
A10: Z07 | B10: EL ORO | C10: ARENILLAS | D10: 07D05 | E10: 000591 | F10: HOSPITAL BASICO DE ARENILLAS | G10: NIVEL 2 | H10: HOSPITAL BASICO
A11: Z07 | B11: EL ORO | C11: ARENILLAS | D11: 07D05 | E11: 002763 | F11: EL JOBO SAN VICENTE | G11: NIVEL 1 | H11: PUESTO DE SALUD
A12: Z07 | B12: EL ORO | C12: ARENILLAS | D12: 07D05 | E12: 002900 | F12: CENTRO DE SALUD ARENILLAS | G12: NIVEL 1 | H12: CENTRO DE SALUD TIPO A
A13: Z07 | B13: EL ORO | C13: ATAHUALPA | D13: 07D03 | E13: 000576 | F13: AYAPAMBA | G13: NIVEL 1 | H13: CENTRO DE SALUD TIPO A
... A256: Z07 | B256: ZAMORA CHINCHIPE | C256: CENTINELA DEL CONDOR | D256: 19D02 | E256: 001900 | F256: ZUMBI | G256: NIVEL 1 | H256: CENTRO DE SALUD TIPO A
A257: Z07 | B257: ZAMORA CHINCHIPE | C257: CHINCHIPE | D257: 19D03 | E257: 001901 | F257: LA CHONTA | G257: NIVEL 1 | H257: CENTRO DE SALUD TIPO A | I257: 2 | N257: 1 | O257: 1 | Q257: 1 | R257: 3 | S257: 4 | U257: 4 | AF257: 4 | CD257: 1 | CE257: 1 | CF257: 1 | CG257: 2 | CH257: 1 | CI257: 1 | CL257: 1
A258: Z07 | B258: ZAMORA CHINCHIPE | C258: CHINCHIPE | D258: 19D03 | E258: 001902 | F258: EL CHORRO | G258: NIVEL 1 | H258: PUESTO DE SALUD | I258: 2 | Q258: 1 | R258: 1 | S258: 2 | U258: 2 | AF258: 2 | CA258: 1 | CB258: 1 | CC258: 1 | CD258: 1 | CE258: 1
A259: Z07 | B259: ZAMORA CHINCHIPE | C259: CHINCHIPE | D259: 19D03 | E259: 001903 | F259: CHITO | G259: NIVEL 1 | H259: CENTRO DE SALUD TIPO A | I259: 17 | N259: 7 | Q259: 13 | R259: 11 | S259: 24 | U259: 24 | AF259: 24 | BS259: 5 | BT259: 5 | BU259: 5 | BV259: 5 | BW259: 2 | BX259: 2 | BY259: 2 | BZ259: 2 | CA259: 3 | CB259: 3 | CC259: 3 | CD259: 3 | CE259: 3 | CF259: 5 | CG259: 3 | CH259: 3 | CI259: 3 | CL259: 3
A260: Z07 | B260: ZAMORA CHINCHIPE | C260: CHINCHIPE | D260: 19D03 | E260: 001921 | F260: LA GUAYUZA | G260: NIVEL 1 | H260: PUESTO DE SALUD | I260: 0 | O260: 2 | Q260: 1 | R260: 1 | S260: 2 | U260: 2 | AF260: 2 | BS260: 1 | BT260: 1 | BU260: 1 | BV260: 1 | BW260: 0 | BX260: 0 | BY260: 0 | BZ260: 0 | CG260: 0 | CI260: 1 | CJ260: 0 | CK260: 0
A261: Z07 | B261: ZAMORA CHINCHIPE | C261: CHINCHIPE | D261: 19D03 | E261: 001922 | F261: LA DIVERSION | G261: NIVEL 1 | H261: CENTRO DE SALUD TIPO A | I261: 1 | N261: 3 | Q261: 1 | R261: 3 | S261: 3 | T261: 1 | U261: 4 | AF261: 4 | CF261: 1 | CJ261: 3 | CK261: 3
A262: Z07 | B262: ZAMORA CHINCHIPE | C262: CHINCHIPE | D262: 19D03 | E262: 001923 | F262: SAN ANDRES | G262: NIVEL 1 | H262: PUESTO DE SALUD | I262: 3 | N262: 1 | Q262: 2 | R262: 2 | S262: 4 | U262: 4 | AF262: 4 | BS262: 1 | BT262: 1 | BU262: 1 | BV262: 1 | CF262: 1 | CG262: 1 | CH262: 1 | CI262: 1 | CJ262: 1 | CK262: 1
A263: Z07 | B263: ZAMORA CHINCHIPE | C263: CHINCHIPE | D263: 19D03 | E263: 001949 | F263: HOSPITAL BASICO DE ZUMBA | G263: NIVEL 2 | H263: HOSPITAL BASICO | I263: 12 | Q263: 7 | R263: 5 | S263: 7 | T263: 5 | U263: 12 | AF263: 12 | BP263: 12 | BQ263: 12
A264: Z07 | B264: ZAMORA CHINCHIPE | C264: CHINCHIPE | D264: 19D03 | E264: 002846 | F264: CENTRO DE SALUD DE ZUMBA | G264: NIVEL 1 | H264: CENTRO DE SALUD TIPO A | I264: 53 | N264: 8 | Q264: 32 | R264: 29 | S264: 61 | U264: 61 | AF264: 61 | BS264: 11 | BT264: 11 | BU264: 11 | BV264: 11 | BW264: 8 | BX264: 9 | BY264: 7 | BZ264: 7 | CA264: 8 | CB264: 8 | CC264: 8 | CD264: 10 | CE264: 10 | CF264: 11 | CG264: 6 | CH264: 6 | CI264: 6 | CJ264: 2 | CK264: 2 | CL264: 1 | CM264: 1 | CN264: 1 | CO264: 1
A265: Z07 | B265: ZAMORA CHINCHIPE | C265: EL PANGUI | D265: 19D04 | E265: 001912 | F265: PACHICUTZA | G265: NIVEL 1 | H265: PUESTO DE SALUD
A266: Z07 | B266: ZAMORA CHINCHIPE | C266: EL PANGUI | D266: 19D04 | E266: 001913 | F266: EL PANGUI | G266: NIVEL 1 | H266: CENTRO DE SALUD TIPO B
A267: Z07 | B267: ZAMORA CHINCHIPE | C267: EL PANGUI | D267: 19D04 | E267: 001914 | F267: TUNDAYME | G267: NIVEL 1 | H267: PUESTO DE SALUD
A268: Z07 | B268: ZAMORA CHINCHIPE | C268: EL PANGUI | D268: 19D04 | E268: 001933 | F268: EL GUISMI | G268: NIVEL 1 | H268: PUESTO DE SALUD
A269: Z07 | B269: ZAMORA CHINCHIPE | C269: EL PANGUI | D269: 19D04 | E269: 001934 | F269: CHUCHUMBLETZA | G269: NIVEL 1 | H269: PUESTO DE SALUD
A270: Z07 | B270: ZAMORA CHINCHIPE | C270: NANGARITZA | D270: 19D02 | E270: 001906 | F270: NUEVO PARAISO | G270: NIVEL 1 | H270: PUESTO DE SALUD
A271: Z07 | B271: ZAMORA CHINCHIPE | C271: NANGARITZA | D271: 19D02 | E271: 001907 | F271: SHAIMI | G271: NIVEL 1 | H271: PUESTO DE SALUD
A272: Z07 | B272: ZAMORA CHINCHIPE | C272: NANGARITZA | D272: 19D02 | E272: 001908 | F272: GERANIOS | G272: NIVEL 1 | H272: PUESTO DE SALUD
A273: Z07 | B273: ZAMORA CHINCHIPE | C273: NANGARITZA | D273: 19D02 | E273: 001909 | F273: ZURMI | G273: NIVEL 1 | H273: PUESTO DE SALUD
A274: Z07 | B274: ZAMORA CHINCHIPE | C274: NANGARITZA | D274: 19D02 | E274: 001925 | F274: SANTA ELENA | G274: NIVEL 1 | H274: PUESTO DE SALUD
A275: Z07 | B275: ZAMORA CHINCHIPE | C275: NANGARITZA | D275: 19D02 | E275: 001926 | F275: GUAYZIMI | G275: NIVEL 1 | H275: CENTRO DE SALUD TIPO A
A276: Z07 | B276: ZAMORA CHINCHIPE | C276: PALANDA | D276: 19D03 | E276: 001904 | F276: SAN FRANCISCO DEL VERGEL | G276: NIVEL 1 | H276: PUESTO DE SALUD | I276: 9 | N276: 5 | Q276: 2 | R276: 12 | S276: 14 | U276: 14 | AF276: 14 | BS276: 1 | BT276: 1 | BU276: 1 | BV276: 1 | BW276: 4 | BX276: 3 | BY276: 4 | BZ276: 4 | CA276: 3 | CB276: 3 | CC276: 3 | CF276: 1 | CL276: 4 | CM276: 1
A277: Z07 | B277: ZAMORA CHINCHIPE | C277: PALANDA | D277: 19D03 | E277: 001937 | F277: EL PORVENIR DEL CARMEN | G277: NIVEL 1 | H277: PUESTO DE SALUD | I277: 2 | N277: 6 | Q277: 4 | R277: 4 | S277: 8 | U277: 8 | AF277: 8 | BS277: 1 | BU277: 1 | BV277: 1 | CA277: 2 | CB277: 2 | CC277: 2 | CD277: 2 | CE277: 2 | CG277: 2 | CH277: 2 | CI277: 2 | CM277: 1
A278: Z07 | B278: ZAMORA CHINCHIPE | C278: PALANDA | D278: 19D03 | E278: 001944 | F278: PALANDA | G278: NIVEL 1 | H278: CENTRO DE SALUD TIPO B | I278: 20 | N278: 19 | Q278: 23 | R278: 16 | S278: 35 | T278: 4 | U278: 39 | AF278: 39 | BP278: 1 | BQ278: 1 | BR278: 1 | BS278: 3 | BT278: 3 | BU278: 3 | BV278: 3 | BW278: 9 | BX278: 9 | BY278: 9 | BZ278: 9 | CA278: 5 | CB278: 5 | CC278: 5 | CD278: 6 | CE278: 6 | CF278: 3 | CG278: 5 | CH278: 5 | CI278: 5 | CJ278: 2 | CK278: 2 | CM278: 3 | CN278: 1
A279: Z07 | B279: ZAMORA CHINCHIPE | C279: PALANDA | D279: 19D03 | E279: 001945 | F279: VALLADOLID | G279: NIVEL 1 | H279: CENTRO DE SALUD TIPO A | I279: 8 | N279: 1 | Q279: 5 | R279: 4 | S279: 9 | U279: 9 | AF279: 9 | BS279: 2 | BT279: 2 | BU279: 2 | BV279: 2 | BW279: 3 | BX279: 3 | BY279: 3 | BZ279: 3 | CF279: 1 | CG279: 3 | CH279: 3 | CI279: 3
A280: Z07 | B280: ZAMORA CHINCHIPE | C280: PALANDA | D280: 19D03 | E280: 001946 | F280: LA CANELA | G280: NIVEL 1 | H280: PUESTO DE SALUD | I280: 2 | Q280: 1 | R280: 1 | S280: 2 | U280: 2 | AF280: 2 | CD280: 2 | CE280: 2
A281: Z07 | B281: ZAMORA CHINCHIPE | C281: PAQUISHA | D281: 19D02 | E281: 001899 | F281: PAQUISHA | G281: NIVEL 1 | H281: CENTRO DE SALUD TIPO B
A282: Z07 | B282: ZAMORA CHINCHIPE | C282: PAQUISHA | D282: 19D02 | E282: 001941 | F282: BELLAVISTA | G282: NIVEL 1 | H282: PUESTO DE SALUD
...

Sheet MARZO
A1: Zona | B1: provincia | C1: canton | D1: distrito | E1: unicodigo | F1: uni_nombre | G1: nivel | H1: tipo | I1: int_msp | J1: ext_CNH | K1: ext_cibv | L1: ext_educ_gene_basic | M1: ext_bachillerato | N1: ext_visita_domi | O1: ext_comuni | P1: ext_otros | Q1: sexo_h | R1: sexo_m | S1: pertenece_ES | T1: No_pertenece_ES | U1: ecuatoriano | V1: colombiano | W1: peruano | X1: cubano | Y1: venezolano | Z1: otros | AA1: indigena | AB1: afro | AC1: negro | AD1: mulato | AE1: montubio | AF1: mestizo | AG1: blanco | AH1: otro | AI1: Achuar | AJ1: Andoa | AK1: Awa | AL1: Chachi | AM1: Cofan | AN1: Epera | AO1: Huancavilca | AP1: Kichwa | AQ1: Manta | AR1: Secoya | AS1: Shiwiar | AT1: Shuar | AU1: Siona | AV1: Tsáchila | AW1: Waorani | AX1: Zapara | AY1: Chibuleo | AZ1: Kañari | BA1: Karanki | BB1: Kayambi | BC1: Kichwa Amazónico | BD1: Kisapincha | BE1: Kitukara | BF1: Natabuela | BG1: Otavalo | BH1: Paltas | BI1: Panzaleo | BJ1: Pastos | BK1: Puruha | BL1: Salasaka | BM1: Saraguro | BN1: Tomabela | BO1: Waramka | BP1: BCG_24 | BQ1: HB_24 | BR1: BCG_365 | BS1: rota_1 | BT1: fIPV_1 | BU1: neumo_1 | BV1: penta_1 | BW1: rota_2 | BX1: fIPV_2 | BY1: neumo_2 | BZ1: penta_2 | CA1: bopv_3 | CB1: neumo_3 | CC1: penta_3 | CD1: srp_1 | CE1: fa | CF1: varicela | CG1: srp_2 | CH1: bopv_4 | CI1: dpt_4 | CJ1: bopv_5 | CK1: dpt_5 | CL1: hpv_9a_1d | CM1: hpv_9a_2d | CN1: hpv_10a_2d | CO1: dt_3
A2: Z07 | B2: EL ORO | C2: ARENILLAS | D2: 07D05 | E2: 000541 | F2: SAN VICENTE | G2: NIVEL 1 | H2: CENTRO DE SALUD TIPO A
A3: Z07 | B3: EL ORO | C3: ARENILLAS | D3: 07D05 | E3: 000542 | F3: SAN ISIDRO URBANO | G3: NIVEL 1 | H3: CENTRO DE SALUD TIPO B
A4: Z07 | B4: EL ORO | C4: ARENILLAS | D4: 07D05 | E4: 000543 | F4: CAÑAS | G4: NIVEL 1 | H4: PUESTO DE SALUD
A5: Z07 | B5: EL ORO | C5: ARENILLAS | D5: 07D05 | E5: 000544 | F5: LA CUCA | G5: NIVEL 1 | H5: CENTRO DE SALUD TIPO A
A6: Z07 | B6: EL ORO | C6: ARENILLAS | D6: 07D05 | E6: 000545 | F6: CARCABON | G6: NIVEL 1 | H6: CENTRO DE SALUD TIPO A
A7: Z07 | B7: EL ORO | C7: ARENILLAS | D7: 07D05 | E7: 000546 | F7: CHACRAS | G7: NIVEL 1 | H7: CENTRO DE SALUD TIPO A
A8: Z07 | B8: EL ORO | C8: ARENILLAS | D8: 07D05 | E8: 000547 | F8: PALMALES | G8: NIVEL 1 | H8: CENTRO DE SALUD TIPO A
A9: Z07 | B9: EL ORO | C9: ARENILLAS | D9: 07D05 | E9: 000548 | F9: MANABI DE EL ORO | G9: NIVEL 1 | H9: PUESTO DE SALUD
A10: Z07 | B10: EL ORO | C10: ARENILLAS | D10: 07D05 | E10: 000591 | F10: HOSPITAL BASICO DE ARENILLAS | G10: NIVEL 2 | H10: HOSPITAL BASICO
A11: Z07 | B11: EL ORO | C11: ARENILLAS | D11: 07D05 | E11: 002763 | F11: EL JOBO SAN VICENTE | G11: NIVEL 1 | H11: PUESTO DE SALUD
A12: Z07 | B12: EL ORO | C12: ARENILLAS | D12: 07D05 | E12: 002900 | F12: CENTRO DE SALUD ARENILLAS | G12: NIVEL 1 | H12: CENTRO DE SALUD TIPO A
A13: Z07 | B13: EL ORO | C13: ATAHUALPA | D13: 07D03 | E13: 000576 | F13: AYAPAMBA | G13: NIVEL 1 | H13: CENTRO DE SALUD TIPO A
... A256: Z07 | B256: ZAMORA CHINCHIPE | C256: CENTINELA DEL CONDOR | D256: 19D02 | E256: 001900 | F256: ZUMBI | G256: NIVEL 1 | H256: CENTRO DE SALUD TIPO A
A257: Z07 | B257: ZAMORA CHINCHIPE | C257: CHINCHIPE | D257: 19D03 | E257: 001901 | F257: LA CHONTA | G257: NIVEL 1 | H257: CENTRO DE SALUD TIPO A | I257: 2 | N257: 2 | Q257: 1 | R257: 3 | S257: 4 | U257: 4 | AF257: 4 | CF257: 1 | CG257: 1 | CL257: 1 | CO257: 1
A258: Z07 | B258: ZAMORA CHINCHIPE | C258: CHINCHIPE | D258: 19D03 | E258: 001902 | F258: EL CHORRO | G258: NIVEL 1 | H258: PUESTO DE SALUD
A259: Z07 | B259: ZAMORA CHINCHIPE | C259: CHINCHIPE | D259: 19D03 | E259: 001903 | F259: CHITO | G259: NIVEL 1 | H259: CENTRO DE SALUD TIPO A | I259: 7 | N259: 4 | Q259: 5 | R259: 6 | S259: 10 | T259: 1 | U259: 10 | W259: 1 | AF259: 10 | AH259: 1 | BQ259: 1 | BW259: 1 | BX259: 1 | BY259: 1 | BZ259: 1 | CA259: 3 | CB259: 3 | CC259: 3 | CD259: 3 | CE259: 3 | CG259: 3 | CH259: 3 | CI259: 3
A260: Z07 | B260: ZAMORA CHINCHIPE | C260: CHINCHIPE | D260: 19D03 | E260: 001921 | F260: LA GUAYUZA | G260: NIVEL 1 | H260: PUESTO DE SALUD | I260: 0 | O260: 3 | Q260: 1 | R260: 2 | S260: 3 | U260: 3 | AF260: 3 | BW260: 1 | BX260: 1 | BY260: 1 | BZ260: 1 | CA260: 2 | CB260: 2 | CC260: 2 | CG260: 0 | CH260: 0 | CI260: 0 | CJ260: 1 | CK260: 1
A261: Z07 | B261: ZAMORA CHINCHIPE | C261: CHINCHIPE | D261: 19D03 | E261: 001922 | F261: LA DIVERSION | G261: NIVEL 1 | H261: CENTRO DE SALUD TIPO A | I261: 3 | N261: 4 | Q261: 3 | R261: 4 | S261: 7 | U261: 7 | AF261: 7 | BS261: 1 | BT261: 1 | BU261: 1 | BV261: 1 | BW261: 2 | BX261: 2 | BY261: 2 | BZ261: 2 | CG261: 2 | CH261: 2 | CI261: 2 | CJ261: 1 | CK261: 1 | CM261: 1
A262: Z07 | B262: ZAMORA CHINCHIPE | C262: CHINCHIPE | D262: 19D03 | E262: 001923 | F262: SAN ANDRES | G262: NIVEL 1 | H262: PUESTO DE SALUD | I262: 3 | Q262: 2 | R262: 1 | S262: 3 | U262: 3 | AF262: 3 | BW262: 1 | BX262: 1 | BY262: 1 | BZ262: 1 | CA262: 1 | CB262: 1 | CC262: 1 | CM262: 1
A263: Z07 | B263: ZAMORA CHINCHIPE | C263: CHINCHIPE | D263: 19D03 | E263: 001949 | F263: HOSPITAL BASICO DE ZUMBA | G263: NIVEL 2 | H263: HOSPITAL BASICO | I263: 11 | Q263: 2 | R263: 9 | S263: 10 | T263: 1 | U263: 11 | AF263: 11 | BP263: 11 | BQ263: 11
A264: Z07 | B264: ZAMORA CHINCHIPE | C264: CHINCHIPE | D264: 19D03 | E264: 002846 | F264: CENTRO DE SALUD DE ZUMBA | G264: NIVEL 1 | H264: CENTRO DE SALUD TIPO A | I264: 48 | N264: 8 | Q264: 28 | R264: 28 | S264: 56 | U264: 56 | AF264: 56 | BS264: 7 | BT264: 7 | BU264: 7 | BV264: 7 | BW264: 10 | BX264: 10 | BY264: 10 | BZ264: 10 | CA264: 11 | CB264: 11 | CC264: 11 | CD264: 7 | CE264: 7 | CF264: 10 | CG264: 10 | CH264: 10 | CI264: 10 | CJ264: 1 | CK264: 1
A265: Z07 | B265: ZAMORA CHINCHIPE | C265: EL PANGUI | D265: 19D04 | E265: 001912 | F265: PACHICUTZA | G265: NIVEL 1 | H265: PUESTO DE SALUD
A266: Z07 | B266: ZAMORA CHINCHIPE | C266: EL PANGUI | D266: 19D04 | E266: 001913 | F266: EL PANGUI | G266: NIVEL 1 | H266: CENTRO DE SALUD TIPO B
A267: Z07 | B267: ZAMORA CHINCHIPE | C267: EL PANGUI | D267: 19D04 | E267: 001914 | F267: TUNDAYME | G267: NIVEL 1 | H267: PUESTO DE SALUD
A268: Z07 | B268: ZAMORA CHINCHIPE | C268: EL PANGUI | D268: 19D04 | E268: 001933 | F268: EL GUISMI | G268: NIVEL 1 | H268: PUESTO DE SALUD
A269: Z07 | B269: ZAMORA CHINCHIPE | C269: EL PANGUI | D269: 19D04 | E269: 001934 | F269: CHUCHUMBLETZA | G269: NIVEL 1 | H269: PUESTO DE SALUD
A270: Z07 | B270: ZAMORA CHINCHIPE | C270: NANGARITZA | D270: 19D02 | E270: 001906 | F270: NUEVO PARAISO | G270: NIVEL 1 | H270: PUESTO DE SALUD
A271: Z07 | B271: ZAMORA CHINCHIPE | C271: NANGARITZA | D271: 19D02 | E271: 001907 | F271: SHAIMI | G271: NIVEL 1 | H271: PUESTO DE SALUD
A272: Z07 | B272: ZAMORA CHINCHIPE | C272: NANGARITZA | D272: 19D02 | E272: 001908 | F272: GERANIOS | G272: NIVEL 1 | H272: PUESTO DE SALUD
A273: Z07 | B273: ZAMORA CHINCHIPE | C273: NANGARITZA | D273: 19D02 | E273: 001909 | F273: ZURMI | G273: NIVEL 1 | H273: PUESTO DE SALUD
A274: Z07 | B274: ZAMORA CHINCHIPE | C274: NANGARITZA | D274: 19D02 | E274: 001925 | F274: SANTA ELENA | G274: NIVEL 1 | H274: PUESTO DE SALUD
A275: Z07 | B275: ZAMORA CHINCHIPE | C275: NANGARITZA | D275: 19D02 | E275: 001926 | F275: GUAYZIMI | G275: NIVEL 1 | H275: CENTRO DE SALUD TIPO A
A276: Z07 | B276: ZAMORA CHINCHIPE | C276: PALANDA | D276: 19D03 | E276: 001904 | F276: SAN FRANCISCO DEL VERGEL | G276: NIVEL 1 | H276: PUESTO DE SALUD | I276: 23 | N276: 2 | Q276: 12 | R276: 13 | S276: 19 | T276: 6 | U276: 25 | AF276: 25 | BR276: 3 | BS276: 3 | BT276: 3 | BU276: 3 | BV276: 3 | BX276: 2 | CA276: 6 | CB276: 6 | CC276: 6 | CD276: 3 | CE276: 3 | CF276: 3 | CG276: 5 | CH276: 5 | CI276: 6
A277: Z07 | B277: ZAMORA CHINCHIPE | C277: PALANDA | D277: 19D03 | E277: 001937 | F277: EL PORVENIR DEL CARMEN | G277: NIVEL 1 | H277: PUESTO DE SALUD | I277: 6 | Q277: 6 | S277: 6 | U277: 6 | AF277: 6 | BS277: 1 | BT277: 2 | BU277: 1 | BV277: 1 | BW277: 1 | BX277: 1 | BY277: 1 | BZ277: 1 | CG277: 2 | CH277: 3 | CI277: 2
A278: Z07 | B278: ZAMORA CHINCHIPE | C278: PALANDA | D278: 19D03 | E278: 001944 | F278: PALANDA | G278: NIVEL 1 | H278: CENTRO DE SALUD TIPO B | I278: 30 | N278: 14 | Q278: 24 | R278: 20 | S278: 34 | T278: 10 | U278: 44 | AF278: 44 | BP278: 4 | BQ278: 4 | BR278: 3 | BS278: 4 | BT278: 4 | BU278: 4 | BV278: 4 | BW278: 5 | BX278: 5 | BY278: 5 | BZ278: 5 | CA278: 9 | CB278: 9 | CC278: 9 | CD278: 4 | CE278: 4 | CF278: 3 | CG278: 8 | CH278: 8 | CI278: 8 | CJ278: 2 | CK278: 2 | CL278: 3
A279: Z07 | B279: ZAMORA CHINCHIPE | C279: PALANDA | D279: 19D03 | E279: 001945 | F279: VALLADOLID | G279: NIVEL 1 | H279: CENTRO DE SALUD TIPO A | I279: 7 | Q279: 2 | R279: 5 | S279: 7 | U279: 7 | AF279: 7 | BW279: 1 | BX279: 1 | BY279: 1 | BZ279: 1 | CA279: 2 | CB279: 2 | CC279: 2 | CD279: 1 | CE279: 1 | CF279: 2 | CG279: 1 | CH279: 1 | CI279: 1
A280: Z07 | B280: ZAMORA CHINCHIPE | C280: PALANDA | D280: 19D03 | E280: 001946 | F280: LA CANELA | G280: NIVEL 1 | H280: PUESTO DE SALUD | J280: 16 | Q280: 6 | R280: 10 | S280: 16 | U280: 16 | AF280: 16 | BS280: 3 | BT280: 3 | BU280: 3 | BV280: 3 | CH280: 3 | CI280: 3 | CL280: 1 | CM280: 2 | CO280: 7
A281: Z07 | B281: ZAMORA CHINCHIPE | C281: PAQUISHA | D281: 19D02 | E281: 001899 | F281: PAQUISHA | G281: NIVEL 1 | H281: CENTRO DE SALUD TIPO B
A282: Z07 | B282: ZAMORA CHINCHIPE | C282: PAQUISHA | D282: 19D02 | E282: 001941 | F282: BELLAVISTA | G282: NIVEL 1 | H282: PUESTO DE SALUD
...

Sheet ABRIL
A1: Zona | B1: provincia | C1: canton | D1: distrito | E1: unicodigo | F1: uni_nombre | G1: nivel | H1: tipo | I1: int_msp | J1: ext_CNH | K1: ext_cibv | L1: ext_educ_gene_basic | M1: ext_bachillerato | N1: ext_visita_domi | O1: ext_comuni | P1: ext_otros | Q1: sexo_h | R1: sexo_m | S1: pertenece_ES | T1: No_pertenece_ES | U1: ecuatoriano | V1: colombiano | W1: peruano | X1: cubano | Y1: venezolano | Z1: otros | AA1: indigena | AB1: afro | AC1: negro | AD1: mulato | AE1: montubio | AF1: mestizo | AG1: blanco | AH1: otro | AI1: Achuar | AJ1: Andoa | AK1: Awa | AL1: Chachi | AM1: Cofan | AN1: Epera | AO1: Huancavilca | AP1: Kichwa | AQ1: Manta | AR1: Secoya | AS1: Shiwiar | AT1: Shuar | AU1: Siona | AV1: Tsáchila | AW1: Waorani | AX1: Zapara | AY1: Chibuleo | AZ1: Kañari | BA1: Karanki | BB1: Kayambi | BC1: Kichwa Amazónico | BD1: Kisapincha | BE1: Kitukara | BF1: Natabuela | BG1: Otavalo | BH1: Paltas | BI1: Panzaleo | BJ1: Pastos | BK1: Puruha | BL1: Salasaka | BM1: Saraguro | BN1: Tomabela | BO1: Waramka | BP1: BCG_24 | BQ1: HB_24 | BR1: BCG_365 | BS1: rota_1 | BT1: fIPV_1 | BU1: neumo_1 | BV1: penta_1 | BW1: rota_2 | BX1: fIPV_2 | BY1: neumo_2 | BZ1: penta_2 | CA1: bopv_3 | CB1: neumo_3 | CC1: penta_3 | CD1: srp_1 | CE1: fa | CF1: varicela | CG1: srp_2 | CH1: bopv_4 | CI1: dpt_4 | CJ1: bopv_5 | CK1: dpt_5 | CL1: hpv_9a_1d | CM1: hpv_9a_2d | CN1: hpv_10a_2d | CO1: dt_3
A2: Z07 | B2: EL ORO | C2: ARENILLAS | D2: 07D05 | E2: 000541 | F2: SAN VICENTE | G2: NIVEL 1 | H2: CENTRO DE SALUD TIPO A
A3: Z07 | B3: EL ORO | C3: ARENILLAS | D3: 07D05 | E3: 000542 | F3: SAN ISIDRO URBANO | G3: NIVEL 1 | H3: CENTRO DE SALUD TIPO B
A4: Z07 | B4: EL ORO | C4: ARENILLAS | D4: 07D05 | E4: 000543 | F4: CAÑAS | G4: NIVEL 1 | H4: PUESTO DE SALUD
A5: Z07 | B5: EL ORO | C5: ARENILLAS | D5: 07D05 | E5: 000544 | F5: LA CUCA | G5: NIVEL 1 | H5: CENTRO DE SALUD TIPO A
A6: Z07 | B6: EL ORO | C6: ARENILLAS | D6: 07D05 | E6: 000545 | F6: CARCABON | G6: NIVEL 1 | H6: CENTRO DE SALUD TIPO A
A7: Z07 | B7: EL ORO | C7: ARENILLAS | D7: 07D05 | E7: 000546 | F7: CHACRAS | G7: NIVEL 1 | H7: CENTRO DE SALUD TIPO A
A8: Z07 | B8: EL ORO | C8: ARENILLAS | D8: 07D05 | E8: 000547 | F8: PALMALES | G8: NIVEL 1 | H8: CENTRO DE SALUD TIPO A
A9: Z07 | B9: EL ORO | C9: ARENILLAS | D9: 07D05 | E9: 000548 | F9: MANABI DE EL ORO | G9: NIVEL 1 | H9: PUESTO DE SALUD
A10: Z07 | B10: EL ORO | C10: ARENILLAS | D10: 07D05 | E10: 000591 | F10: HOSPITAL BASICO DE ARENILLAS | G10: NIVEL 2 | H10: HOSPITAL BASICO
A11: Z07 | B11: EL ORO | C11: ARENILLAS | D11: 07D05 | E11: 002763 | F11: EL JOBO SAN VICENTE | G11: NIVEL 1 | H11: PUESTO DE SALUD
A12: Z07 | B12: EL ORO | C12: ARENILLAS | D12: 07D05 | E12: 002900 | F12: CENTRO DE SALUD ARENILLAS | G12: NIVEL 1 | H12: CENTRO DE SALUD TIPO A
A13: Z07 | B13: EL ORO | C13: ATAHUALPA | D13: 07D03 | E13: 000576 | F13: AYAPAMBA | G13: NIVEL 1 | H13: CENTRO DE SALUD TIPO A
... A256: Z07 | B256: ZAMORA CHINCHIPE | C256: CENTINELA DEL CONDOR | D256: 19D02 | E256: 001900 | F256: ZUMBI | G256: NIVEL 1 | H256: CENTRO DE SALUD TIPO A
A257: Z07 | B257: ZAMORA CHINCHIPE | C257: CHINCHIPE | D257: 19D03 | E257: 001901 | F257: LA CHONTA | G257: NIVEL 1 | H257: CENTRO DE SALUD TIPO A | I257: 2 | J257: 3 | Q257: 4 | R257: 1 | S257: 5 | U257: 5 | AF257: 5 | CH257: 2 | CI257: 4 | CO257: 1
A258: Z07 | B258: ZAMORA CHINCHIPE | C258: CHINCHIPE | D258: 19D03 | E258: 001902 | F258: EL CHORRO | G258: NIVEL 1 | H258: PUESTO DE SALUD
A259: Z07 | B259: ZAMORA CHINCHIPE | C259: CHINCHIPE | D259: 19D03 | E259: 001903 | F259: CHITO | G259: NIVEL 1 | H259: CENTRO DE SALUD TIPO A | I259: 9 | N259: 7 | O259: 2 | Q259: 10 | R259: 8 | S259: 18 | U259: 17 | W259: 1 | AF259: 17 | AH259: 1 | BP259: 2 | BQ259: 1 | BS259: 1 | BT259: 1 | BU259: 1 | BV259: 1 | BW259: 6 | BX259: 6 | BY259: 6 | BZ259: 6 | CA259: 1 | CB259: 1 | CC259: 1 | CF259: 3 | CG259: 5 | CH259: 5 | CI259: 5
A260: Z07 | B260: ZAMORA CHINCHIPE | C260: CHINCHIPE | D260: 19D03 | E260: 001921 | F260: LA GUAYUZA | G260: NIVEL 1 | H260: PUESTO DE SALUD | I260: 0
A261: Z07 | B261: ZAMORA CHINCHIPE | C261: CHINCHIPE | D261: 19D03 | E261: 001922 | F261: LA DIVERSION | G261: NIVEL 1 | H261: CENTRO DE SALUD TIPO A | I261: 3 | N261: 1 | Q261: 3 | R261: 1 | S261: 4 | U261: 4 | AF261: 4 | BS261: 1 | BT261: 1 | BU261: 1 | BV261: 1 | CD261: 1 | CE261: 1 | CF261: 1 | CG261: 1 | CH261: 1 | CI261: 1
A262: Z07 | B262: ZAMORA CHINCHIPE | C262: CHINCHIPE | D262: 19D03 | E262: 001923 | F262: SAN ANDRES | G262: NIVEL 1 | H262: PUESTO DE SALUD | I262: 13 | Q262: 7 | R262: 6 | S262: 13 | U262: 13 | AF262: 13 | BW262: 1 | BX262: 1 | BY262: 1 | BZ262: 1 | CD262: 1 | CE262: 1 | CF262: 1 | CJ262: 5 | CK262: 5 | CO262: 5
A263: Z07 | B263: ZAMORA CHINCHIPE | C263: CHINCHIPE | D263: 19D03 | E263: 001949 | F263: HOSPITAL BASICO DE ZUMBA | G263: NIVEL 2 | H263: HOSPITAL BASICO | I263: 10 | P263: 2 | Q263: 6 | R263: 6 | S263: 12 | U263: 12 | AF263: 12 | BP263: 12 | BQ263: 12
A264: Z07 | B264: ZAMORA CHINCHIPE | C264: CHINCHIPE | D264: 19D03 | E264: 002846 | F264: CENTRO DE SALUD DE ZUMBA | G264: NIVEL 1 | H264: CENTRO DE SALUD TIPO A | I264: 57 | N264: 13 | Q264: 36 | R264: 34 | S264: 70 | U264: 70 | AF264: 70 | BS264: 9 | BT264: 9 | BU264: 9 | BV264: 9 | BW264: 9 | BX264: 9 | BY264: 10 | BZ264: 10 | CA264: 7 | CB264: 8 | CC264: 8 | CD264: 9 | CE264: 9 | CF264: 17 | CG264: 9 | CH264: 7 | CI264: 9 | CJ264: 4 | CK264: 5 | CL264: 1 | CM264: 2
A265: Z07 | B265: ZAMORA CHINCHIPE | C265: EL PANGUI | D265: 19D04 | E265: 001912 | F265: PACHICUTZA | G265: NIVEL 1 | H265: PUESTO DE SALUD
A266: Z07 | B266: ZAMORA CHINCHIPE | C266: EL PANGUI | D266: 19D04 | E266: 001913 | F266: EL PANGUI | G266: NIVEL 1 | H266: CENTRO DE SALUD TIPO B
A267: Z07 | B267: ZAMORA CHINCHIPE | C267: EL PANGUI | D267: 19D04 | E267: 001914 | F267: TUNDAYME | G267: NIVEL 1 | H267: PUESTO DE SALUD
A268: Z07 | B268: ZAMORA CHINCHIPE | C268: EL PANGUI | D268: 19D04 | E268: 001933 | F268: EL GUISMI | G268: NIVEL 1 | H268: PUESTO DE SALUD
A269: Z07 | B269: ZAMORA CHINCHIPE | C269: EL PANGUI | D269: 19D04 | E269: 001934 | F269: CHUCHUMBLETZA | G269: NIVEL 1 | H269: PUESTO DE SALUD
A270: Z07 | B270: ZAMORA CHINCHIPE | C270: NANGARITZA | D270: 19D02 | E270: 001906 | F270: NUEVO PARAISO | G270: NIVEL 1 | H270: PUESTO DE SALUD
A271: Z07 | B271: ZAMORA CHINCHIPE | C271: NANGARITZA | D271: 19D02 | E271: 001907 | F271: SHAIMI | G271: NIVEL 1 | H271: PUESTO DE SALUD
A272: Z07 | B272: ZAMORA CHINCHIPE | C272: NANGARITZA | D272: 19D02 | E272: 001908 | F272: GERANIOS | G272: NIVEL 1 | H272: PUESTO DE SALUD
A273: Z07 | B273: ZAMORA CHINCHIPE | C273: NANGARITZA | D273: 19D02 | E273: 001909 | F273: ZURMI | G273: NIVEL 1 | H273: PUESTO DE SALUD
A274: Z07 | B274: ZAMORA CHINCHIPE | C274: NANGARITZA | D274: 19D02 | E274: 001925 | F274: SANTA ELENA | G274: NIVEL 1 | H274: PUESTO DE SALUD
A275: Z07 | B275: ZAMORA CHINCHIPE | C275: NANGARITZA | D275: 19D02 | E275: 001926 | F275: GUAYZIMI | G275: NIVEL 1 | H275: CENTRO DE SALUD TIPO A
A276: Z07 | B276: ZAMORA CHINCHIPE | C276: PALANDA | D276: 19D03 | E276: 001904 | F276: SAN FRANCISCO DEL VERGEL | G276: NIVEL 1 | H276: PUESTO DE SALUD | I276: 16 | Q276: 7 | R276: 9 | S276: 14 | T276: 2 | U276: 16 | AF276: 16 | BS276: 2 | BT276: 2 | BU276: 2 | BV276: 2 | BW276: 4 | BX276: 4 | BY276: 4 | BZ276: 4 | CA276: 2 | CB276: 2 | CC276: 2 | CD276: 2 | CE276: 2 | CF276: 3 | CG276: 3 | CH276: 3 | CI276: 3
A277: Z07 | B277: ZAMORA CHINCHIPE | C277: PALANDA | D277: 19D03 | E277: 001937 | F277: EL PORVENIR DEL CARMEN | G277: NIVEL 1 | H277: PUESTO DE SALUD | I277: 6 | Q277: 2 | R277: 4 | S277: 6 | U277: 6 | AF277: 6 | BW277: 2 | BX277: 2 | BY277: 2 | BZ277: 2 | CA277: 1 | CB277: 1 | CC277: 1 | CD277: 1 | CG277: 1 | CH277: 1 | CI277: 1 | CJ277: 1 | CK277: 1
A278: Z07 | B278: ZAMORA CHINCHIPE | C278: PALANDA | D278: 19D03 | E278: 001944 | F278: PALANDA | G278: NIVEL 1 | H278: CENTRO DE SALUD TIPO B | I278: 35 | N278: 10 | Q278: 24 | R278: 21 | S278: 37 | T278: 8 | U278: 45 | AF278: 45 | BP278: 3 | BQ278: 2 | BS278: 4 | BT278: 4 | BU278: 4 | BV278: 4 | BW278: 2 | BX278: 2 | BY278: 2 | BZ278: 2 | CA278: 10 | CB278: 10 | CC278: 10 | CD278: 4 | CE278: 4 | CF278: 11 | CG278: 7 | CH278: 7 | CI278: 7 | CJ278: 2 | CK278: 2 | CL278: 1 | CM278: 1
A279: Z07 | B279: ZAMORA CHINCHIPE | C279: PALANDA | D279: 19D03 | E279: 001945 | F279: VALLADOLID | G279: NIVEL 1 | H279: CENTRO DE SALUD TIPO A | I279: 12 | N279: 3 | Q279: 8 | R279: 7 | S279: 15 | U279: 15 | AF279: 15 | BS279: 1 | BT279: 1 | BU279: 1 | BV279: 1 | BW279: 2 | BX279: 2 | BY279: 2 | BZ279: 2 | CA279: 4 | CB279: 4 | CC279: 4 | CD279: 2 | CE279: 2 | CF279: 2 | CG279: 3 | CH279: 3 | CI279: 3 | CO279: 1
A280: Z07 | B280: ZAMORA CHINCHIPE | C280: PALANDA | D280: 19D03 | E280: 001946 | F280: LA CANELA | G280: NIVEL 1 | H280: PUESTO DE SALUD | I280: 4 | Q280: 3 | R280: 1 | S280: 4 | U280: 4 | AF280: 4 | BW280: 2 | BX280: 2 | BY280: 2 | BZ280: 2 | CG280: 1 | CI280: 1 | CM280: 1
A281: Z07 | B281: ZAMORA CHINCHIPE | C281: PAQUISHA | D281: 19D02 | E281: 001899 | F281: PAQUISHA | G281: NIVEL 1 | H281: CENTRO DE SALUD TIPO B
A282: Z07 | B282: ZAMORA CHINCHIPE | C282: PAQUISHA | D282: 19D02 | E282: 001941 | F282: BELLAVISTA | G282: NIVEL 1 | H282: PUESTO DE SALUD
...

Sheet MAYO
A1: Zona | B1: provincia | C1: canton | D1: distrito | E1: unicodigo | F1: uni_nombre | G1: nivel | H1: tipo | I1: int_msp | J1: ext_CNH | K1: ext_cibv | L1: ext_educ_gene_basic | M1: ext_bachillerato | N1: ext_visita_domi | O1: ext_comuni | P1: ext_otros | Q1: sexo_h | R1: sexo_m | S1: pertenece_ES | T1: No_pertenece_ES | U1: ecuatoriano | V1: colombiano | W1: peruano | X1: cubano | Y1: venezolano | Z1: otros | AA1: indigena | AB1: afro | AC1: negro | AD1: mulato | AE1: montubio | AF1: mestizo | AG1: blanco | AH1: otro | AI1: Achuar | AJ1: Andoa | AK1: Awa | AL1: Chachi | AM1: Cofan | AN1: Epera | AO1: Huancavilca | AP1: Kichwa | AQ1: Manta | AR1: Secoya | AS1: Shiwiar | AT1: Shuar | AU1: Siona | AV1: Tsáchila | AW1: Waorani | AX1: Zapara | AY1: Chibuleo | AZ1: Kañari | BA1: Karanki | BB1: Kayambi | BC1: Kichwa Amazónico | BD1: Kisapincha | BE1: Kitukara | BF1: Natabuela | BG1: Otavalo | BH1: Paltas | BI1: Panzaleo | BJ1: Pastos | BK1: Puruha | BL1: Salasaka | BM1: Saraguro | BN1: Tomabela | BO1: Waramka | BP1: BCG_24 | BQ1: HB_24 | BR1: BCG_365 | BS1: rota_1 | BT1: fIPV_1 | BU1: neumo_1 | BV1: penta_1 | BW1: rota_2 | BX1: fIPV_2 | BY1: neumo_2 | BZ1: penta_2 | CA1: bopv_3 | CB1: neumo_3 | CC1: penta_3 | CD1: srp_1 | CE1: fa | CF1: varicela | CG1: srp_2 | CH1: bopv_4 | CI1: dpt_4 | CJ1: bopv_5 | CK1: dpt_5 | CL1: hpv_9a_1d | CM1: hpv_9a_2d | CN1: hpv_10a_2d | CO1: dt_3
A2: Z07 | B2: EL ORO | C2: ARENILLAS | D2: 07D05 | E2: 000541 | F2: SAN VICENTE | G2: NIVEL 1 | H2: CENTRO DE SALUD TIPO A
A3: Z07 | B3: EL ORO | C3: ARENILLAS | D3: 07D05 | E3: 000542 | F3: SAN ISIDRO URBANO | G3: NIVEL 1 | H3: CENTRO DE SALUD TIPO B
A4: Z07 | B4: EL ORO | C4: ARENILLAS | D4: 07D05 | E4: 000543 | F4: CAÑAS | G4: NIVEL 1 | H4: PUESTO DE SALUD
A5: Z07 | B5: EL ORO | C5: ARENILLAS | D5: 07D05 | E5: 000544 | F5: LA CUCA | G5: NIVEL 1 | H5: CENTRO DE SALUD TIPO A
A6: Z07 | B6: EL ORO | C6: ARENILLAS | D6: 07D05 | E6: 000545 | F6: CARCABON | G6: NIVEL 1 | H6: CENTRO DE SALUD TIPO A
A7: Z07 | B7: EL ORO | C7: ARENILLAS | D7: 07D05 | E7: 000546 | F7: CHACRAS | G7: NIVEL 1 | H7: CENTRO DE SALUD TIPO A
A8: Z07 | B8: EL ORO | C8: ARENILLAS | D8: 07D05 | E8: 000547 | F8: PALMALES | G8: NIVEL 1 | H8: CENTRO DE SALUD TIPO A
A9: Z07 | B9: EL ORO | C9: ARENILLAS | D9: 07D05 | E9: 000548 | F9: MANABI DE EL ORO | G9: NIVEL 1 | H9: PUESTO DE SALUD
A10: Z07 | B10: EL ORO | C10: ARENILLAS | D10: 07D05 | E10: 000591 | F10: HOSPITAL BASICO DE ARENILLAS | G10: NIVEL 2 | H10: HOSPITAL BASICO
A11: Z07 | B11: EL ORO | C11: ARENILLAS | D11: 07D05 | E11: 002763 | F11: EL JOBO SAN VICENTE | G11: NIVEL 1 | H11: PUESTO DE SALUD
A12: Z07 | B12: EL ORO | C12: ARENILLAS | D12: 07D05 | E12: 002900 | F12: CENTRO DE SALUD ARENILLAS | G12: NIVEL 1 | H12: CENTRO DE SALUD TIPO A
A13: Z07 | B13: EL ORO | C13: ATAHUALPA | D13: 07D03 | E13: 000576 | F13: AYAPAMBA | G13: NIVEL 1 | H13: CENTRO DE SALUD TIPO A
... A257: Z07 | B257: ZAMORA CHINCHIPE | C257: CHINCHIPE | D257: 19D03 | E257: 001901 | F257: LA CHONTA | G257: NIVEL 1 | H257: CENTRO DE SALUD TIPO A
A258: Z07 | B258: ZAMORA CHINCHIPE | C258: CHINCHIPE | D258: 19D03 | E258: 001902 | F258: EL CHORRO | G258: NIVEL 1 | H258: PUESTO DE SALUD | I258: 3 | Q258: 3 | S258: 3 | U258: 3 | AF258: 3 | CD258: 2 | CE258: 2 | CF258: 1
A259: Z07 | B259: ZAMORA CHINCHIPE | C259: CHINCHIPE | D259: 19D03 | E259: 001903 | F259: CHITO | G259: NIVEL 1 | H259: CENTRO DE SALUD TIPO A | I259: 9 | N259: 8 | Q259: 8 | R259: 9 | S259: 17 | U259: 17 | AF259: 17 | BW259: 3 | BX259: 3 | BY259: 3 | BZ259: 3 | CB259: 1 | CC259: 1 | CD259: 6 | CE259: 6 | CF259: 3 | CG259: 3 | CI259: 3 | CO259: 1
A260: Z07 | B260: ZAMORA CHINCHIPE | C260: CHINCHIPE | D260: 19D03 | E260: 001921 | F260: LA GUAYUZA | G260: NIVEL 1 | H260: PUESTO DE SALUD | I260: 0
A261: Z07 | B261: ZAMORA CHINCHIPE | C261: CHINCHIPE | D261: 19D03 | E261: 001922 | F261: LA DIVERSION | G261: NIVEL 1 | H261: CENTRO DE SALUD TIPO A | I261: 3 | N261: 6 | Q261: 5 | R261: 4 | S261: 9 | U261: 9 | AF261: 9 | BW261: 1 | BX261: 1 | BY261: 1 | BZ261: 1 | CB261: 2 | CC261: 2 | CF261: 1 | CG261: 1 | CI261: 1 | CK261: 3 | CO261: 1
A262: Z07 | B262: ZAMORA CHINCHIPE | C262: CHINCHIPE | D262: 19D03 | E262: 001923 | F262: SAN ANDRES | G262: NIVEL 1 | H262: PUESTO DE SALUD | I262: 4 | R262: 4 | S262: 4 | U262: 4 | AF262: 4 | BS262: 2 | BT262: 2 | BU262: 2 | BV262: 2 | CD262: 1 | CE262: 1 | CG262: 1 | CI262: 1
A263: Z07 | B263: ZAMORA CHINCHIPE | C263: CHINCHIPE | D263: 19D03 | E263: 001949 | F263: HOSPITAL BASICO DE ZUMBA | G263: NIVEL 2 | H263: HOSPITAL BASICO | I263: 5 | Q263: 3 | R263: 2 | S263: 5 | U263: 5 | AF263: 5 | BP263: 5 | BQ263: 5
A264: Z07 | B264: ZAMORA CHINCHIPE | C264: CHINCHIPE | D264: 19D03 | E264: 002846 | F264: CENTRO DE SALUD DE ZUMBA | G264: NIVEL 1 | H264: CENTRO DE SALUD TIPO A | I264: 55 | Q264: 30 | R264: 25 | S264: 55 | U264: 55 | AF264: 55 | BS264: 5 | BT264: 5 | BU264: 5 | BV264: 5 | BW264: 10 | BX264: 10 | BY264: 10 | BZ264: 10 | CB264: 10 | CC264: 10 | CD264: 6 | CE264: 6 | CF264: 8 | CG264: 7 | CI264: 7 | CK264: 6 | CO264: 3
A265: Z07 | B265: ZAMORA CHINCHIPE | C265: EL PANGUI | D265: 19D04 | E265: 001912 | F265: PACHICUTZA | G265: NIVEL 1 | H265: PUESTO DE SALUD
A266: Z07 | B266: ZAMORA CHINCHIPE | C266: EL PANGUI | D266: 19D04 | E266: 001913 | F266: EL PANGUI | G266: NIVEL 1 | H266: CENTRO DE SALUD TIPO B
A267: Z07 | B267: ZAMORA CHINCHIPE | C267: EL PANGUI | D267: 19D04 | E267: 001914 | F267: TUNDAYME | G267: NIVEL 1 | H267: PUESTO DE SALUD
A268: Z07 | B268: ZAMORA CHINCHIPE | C268: EL PANGUI | D268: 19D04 | E268: 001933 | F268: EL GUISMI | G268: NIVEL 1 | H268: PUESTO DE SALUD
A269: Z07 | B269: ZAMORA CHINCHIPE | C269: EL PANGUI | D269: 19D04 | E269: 001934 | F269: CHUCHUMBLETZA | G269: NIVEL 1 | H269: PUESTO DE SALUD
A270: Z07 | B270: ZAMORA CHINCHIPE | C270: NANGARITZA | D270: 19D02 | E270: 001906 | F270: NUEVO PARAISO | G270: NIVEL 1 | H270: PUESTO DE SALUD
A271: Z07 | B271: ZAMORA CHINCHIPE | C271: NANGARITZA | D271: 19D02 | E271: 001907 | F271: SHAIMI | G271: NIVEL 1 | H271: PUESTO DE SALUD
A272: Z07 | B272: ZAMORA CHINCHIPE | C272: NANGARITZA | D272: 19D02 | E272: 001908 | F272: GERANIOS | G272: NIVEL 1 | H272: PUESTO DE SALUD
A273: Z07 | B273: ZAMORA CHINCHIPE | C273: NANGARITZA | D273: 19D02 | E273: 001909 | F273: ZURMI | G273: NIVEL 1 | H273: PUESTO DE SALUD
A274: Z07 | B274: ZAMORA CHINCHIPE | C274: NANGARITZA | D274: 19D02 | E274: 001925 | F274: SANTA ELENA | G274: NIVEL 1 | H274: PUESTO DE SALUD
A275: Z07 | B275: ZAMORA CHINCHIPE | C275: NANGARITZA | D275: 19D02 | E275: 001926 | F275: GUAYZIMI | G275: NIVEL 1 | H275: CENTRO DE SALUD TIPO A
A276: Z07 | B276: ZAMORA CHINCHIPE | C276: PALANDA | D276: 19D03 | E276: 001904 | F276: SAN FRANCISCO DEL VERGEL | G276: NIVEL 1 | H276: PUESTO DE SALUD | I276: 18 | L276: 10 | N276: 2 | Q276: 7 | R276: 23 | S276: 29 | T276: 1 | U276: 30 | AF276: 30 | BS276: 4 | BT276: 4 | BU276: 4 | BV276: 4 | BW276: 2 | BX276: 2 | BY276: 2 | BZ276: 2 | CB276: 4 | CC276: 4 | CD276: 4 | CE276: 5 | CF276: 2 | CG276: 3 | CI276: 3 | CK276: 10
A277: Z07 | B277: ZAMORA CHINCHIPE | C277: PALANDA | D277: 19D03 | E277: 001937 | F277: EL PORVENIR DEL CARMEN | G277: NIVEL 1 | H277: PUESTO DE SALUD | I277: 1 | O277: 11 | Q277: 8 | R277: 4 | S277: 12 | U277: 12 | AF277: 12 | BS277: 1 | BT277: 1 | BU277: 1 | BV277: 1 | BW277: 1 | BX277: 1 | BY277: 1 | BZ277: 1 | CB277: 2 | CC277: 2 | CD277: 5 | CE277: 4 | CF277: 3 | CG277: 1
A278: Z07 | B278: ZAMORA CHINCHIPE | C278: PALANDA | D278: 19D03 | E278: 001944 | F278: PALANDA | G278: NIVEL 1 | H278: CENTRO DE SALUD TIPO B | I278: 34 | N278: 3 | Q278: 24 | R278: 13 | S278: 37 | U278: 37 | AF278: 37 | BP278: 3 | BQ278: 3 | BR278: 1 | BS278: 9 | BT278: 9 | BU278: 9 | BV278: 9 | BW278: 4 | BX278: 4 | BY278: 4 | BZ278: 4 | CB278: 3 | CC278: 3 | CD278: 5 | CE278: 5 | CF278: 6 | CG278: 1 | CI278: 1 | CK278: 6
A279: Z07 | B279: ZAMORA CHINCHIPE | C279: PALANDA | D279: 19D03 | E279: 001945 | F279: VALLADOLID | G279: NIVEL 1 | H279: CENTRO DE SALUD TIPO A | I279: 9 | L279: 8 | Q279: 7 | R279: 10 | S279: 17 | U279: 17 | AF279: 17 | BR279: 1 | BS279: 1 | BT279: 1 | BU279: 1 | BV279: 1 | BW279: 1 | BX279: 1 | BY279: 1 | BZ279: 1 | CB279: 1 | CC279: 1 | CD279: 1 | CE279: 1 | CF279: 1 | CG279: 1 | CI279: 1 | CK279: 9 | CO279: 1
A280: Z07 | B280: ZAMORA CHINCHIPE | C280: PALANDA | D280: 19D03 | E280: 001946 | F280: LA CANELA | G280: NIVEL 1 | H280: PUESTO DE SALUD | I280: 6 | Q280: 4 | R280: 2 | S280: 6 | U280: 6 | AF280: 6 | BS280: 1 | BT280: 1 | BU280: 1 | BV280: 1 | BW280: 1 | BX280: 1 | BY280: 1 | BZ280: 1 | CF280: 2 | CK280: 2
A281: Z07 | B281: ZAMORA CHINCHIPE | C281: PAQUISHA | D281: 19D02 | E281: 001899 | F281: PAQUISHA | G281: NIVEL 1 | H281: CENTRO DE SALUD TIPO B
A282: Z07 | B282: ZAMORA CHINCHIPE | C282: PAQUISHA | D282: 19D02 | E282: 001941 | F282: BELLAVISTA | G282: NIVEL 1 | H282: PUESTO DE SALUD
A283: Z07 | B283: ZAMORA CHINCHIPE | C283: PAQUISHA | D283: 19D02 | E283: 001942 | F283: CHINAPINTZA | G283: NIVEL 1 | H283: PUESTO DE SALUD
...

Sheet JUNIO
A1: Zona | B1: provincia | C1: canton | D1: distrito | E1: unicodigo | F1: uni_nombre | G1: nivel | H1: tipo | I1: int_msp | J1: ext_CNH | K1: ext_cibv | L1: ext_educ_gene_basic | M1: ext_bachillerato | N1: ext_visita_domi | O1: ext_comuni | P1: ext_otros | Q1: sexo_h | R1: sexo_m | S1: pertenece_ES | T1: No_pertenece_ES | U1: ecuatoriano | V1: colombiano | W1: peruano | X1: cubano | Y1: venezolano | Z1: otros | AA1: indigena | AB1: afro | AC1: negro | AD1: mulato | AE1: montubio | AF1: mestizo | AG1: blanco | AH1: otro | AI1: Achuar | AJ1: Andoa | AK1: Awa | AL1: Chachi | AM1: Cofan | AN1: Epera | AO1: Huancavilca | AP1: Kichwa | AQ1: Manta | AR1: Secoya | AS1: Shiwiar | AT1: Shuar | AU1: Siona | AV1: Tsáchila | AW1: Waorani | AX1: Zapara | AY1: Chibuleo | AZ1: Kañari | BA1: Karanki | BB1: Kayambi | BC1: Kichwa Amazónico | BD1: Kisapincha | BE1: Kitukara | BF1: Natabuela | BG1: Otavalo | BH1: Paltas | BI1: Panzaleo | BJ1: Pastos | BK1: Puruha | BL1: Salasaka | BM1: Saraguro | BN1: Tomabela | BO1: Waramka | BP1: BCG_24 | BQ1: HB_24 | BR1: BCG_365 | BS1: rota_1 | BT1: fIPV_1 | BU1: neumo_1 | BV1: penta_1 | BW1: rota_2 | BX1: fIPV_2 | BY1: neumo_2 | BZ1: penta_2 | CA1: bopv_3 | CB1: neumo_3 | CC1: penta_3 | CD1: srp_1 | CE1: fa | CF1: varicela | CG1: srp_2 | CH1: bopv_4 | CI1: dpt_4 | CJ1: bopv_5 | CK1: dpt_5 | CL1: hpv_9a_1d | CM1: hpv_9a_2d | CN1: hpv_10a_2d | CO1: dt_3
A2: Z07 | B2: EL ORO | C2: ARENILLAS | D2: 07D05 | E2: 000541 | F2: SAN VICENTE | G2: NIVEL 1 | H2: CENTRO DE SALUD TIPO A
A3: Z07 | B3: EL ORO | C3: ARENILLAS | D3: 07D05 | E3: 000542 | F3: SAN ISIDRO URBANO | G3: NIVEL 1 | H3: CENTRO DE SALUD TIPO B
A4: Z07 | B4: EL ORO | C4: ARENILLAS | D4: 07D05 | E4: 000543 | F4: CAÑAS | G4: NIVEL 1 | H4: PUESTO DE SALUD
A5: Z07 | B5: EL ORO | C5: ARENILLAS | D5: 07D05 | E5: 000544 | F5: LA CUCA | G5: NIVEL 1 | H5: CENTRO DE SALUD TIPO A
A6: Z07 | B6: EL ORO | C6: ARENILLAS | D6: 07D05 | E6: 000545 | F6: CARCABON | G6: NIVEL 1 | H6: CENTRO DE SALUD TIPO A
A7: Z07 | B7: EL ORO | C7: ARENILLAS | D7: 07D05 | E7: 000546 | F7: CHACRAS | G7: NIVEL 1 | H7: CENTRO DE SALUD TIPO A
A8: Z07 | B8: EL ORO | C8: ARENILLAS | D8: 07D05 | E8: 000547 | F8: PALMALES | G8: NIVEL 1 | H8: CENTRO DE SALUD TIPO A
A9: Z07 | B9: EL ORO | C9: ARENILLAS | D9: 07D05 | E9: 000548 | F9: MANABI DE EL ORO | G9: NIVEL 1 | H9: PUESTO DE SALUD
A10: Z07 | B10: EL ORO | C10: ARENILLAS | D10: 07D05 | E10: 000591 | F10: HOSPITAL BASICO DE ARENILLAS | G10: NIVEL 2 | H10: HOSPITAL BASICO
A11: Z07 | B11: EL ORO | C11: ARENILLAS | D11: 07D05 | E11: 002763 | F11: EL JOBO SAN VICENTE | G11: NIVEL 1 | H11: PUESTO DE SALUD
A12: Z07 | B12: EL ORO | C12: ARENILLAS | D12: 07D05 | E12: 002900 | F12: CENTRO DE SALUD ARENILLAS | G12: NIVEL 1 | H12: CENTRO DE SALUD TIPO A
A13: Z07 | B13: EL ORO | C13: ATAHUALPA | D13: 07D03 | E13: 000576 | F13: AYAPAMBA | G13: NIVEL 1 | H13: CENTRO DE SALUD TIPO A
... A256: Z07 | B256: ZAMORA CHINCHIPE | C256: CENTINELA DEL CONDOR | D256: 19D02 | E256: 001900 | F256: ZUMBI | G256: NIVEL 1 | H256: CENTRO DE SALUD TIPO A
A257: Z07 | B257: ZAMORA CHINCHIPE | C257: CHINCHIPE | D257: 19D03 | E257: 001901 | F257: LA CHONTA | G257: NIVEL 1 | H257: CENTRO DE SALUD TIPO A | I257: 2 | Q257: 1 | R257: 1 | S257: 2 | U257: 2 | AF257: 2 | CH257: 1 | CJ257: 1 | CK257: 1
A258: Z07 | B258: ZAMORA CHINCHIPE | C258: CHINCHIPE | D258: 19D03 | E258: 001902 | F258: EL CHORRO | G258: NIVEL 1 | H258: PUESTO DE SALUD
A259: Z07 | B259: ZAMORA CHINCHIPE | C259: CHINCHIPE | D259: 19D03 | E259: 001903 | F259: CHITO | G259: NIVEL 1 | H259: CENTRO DE SALUD TIPO A | I259: 17 | N259: 5 | Q259: 12 | R259: 10 | S259: 21 | T259: 1 | U259: 21 | W259: 1 | AF259: 21 | AH259: 1 | BS259: 1 | BT259: 1 | BU259: 1 | BV259: 1 | BW259: 2 | BX259: 2 | BY259: 2 | BZ259: 2 | CA259: 7 | CB259: 6 | CC259: 6 | CD259: 3 | CE259: 3 | CF259: 3 | CG259: 2 | CH259: 5 | CI259: 2 | CJ259: 1 | CK259: 1
A260: Z07 | B260: ZAMORA CHINCHIPE | C260: CHINCHIPE | D260: 19D03 | E260: 001921 | F260: LA GUAYUZA | G260: NIVEL 1 | H260: PUESTO DE SALUD | I260: 5 | Q260: 3 | R260: 2 | S260: 5 | U260: 5 | AF260: 5 | BS260: 0 | BT260: 0 | BU260: 0 | BV260: 0 | BW260: 0 | BX260: 0 | BY260: 0 | BZ260: 0 | CA260: 3 | CB260: 2 | CC260: 2 | CD260: 1 | CE260: 0 | CF260: 0 | CG260: 1 | CH260: 1 | CI260: 0 | CJ260: 0 | CK260: 0
A261: Z07 | B261: ZAMORA CHINCHIPE | C261: CHINCHIPE | D261: 19D03 | E261: 001922 | F261: LA DIVERSION | G261: NIVEL 1 | H261: CENTRO DE SALUD TIPO A | I261: 4 | N261: 5 | Q261: 5 | R261: 4 | S261: 8 | T261: 1 | U261: 9 | AF261: 9 | BW261: 1 | BX261: 1 | BY261: 1 | BZ261: 1 | CA261: 2 | CF261: 2 | CG261: 1 | CH261: 1 | CJ261: 2 | CK261: 1
A262: Z07 | B262: ZAMORA CHINCHIPE | C262: CHINCHIPE | D262: 19D03 | E262: 001923 | F262: SAN ANDRES | G262: NIVEL 1 | H262: PUESTO DE SALUD | I262: 1 | Q262: 1 | S262: 1 | U262: 1 | AF262: 1 | CB262: 1 | CC262: 1
A263: Z07 | B263: ZAMORA CHINCHIPE | C263: CHINCHIPE | D263: 19D03 | E263: 001949 | F263: HOSPITAL BASICO DE ZUMBA | G263: NIVEL 2 | H263: HOSPITAL BASICO | I263: 13 | Q263: 3 | R263: 10 | S263: 10 | T263: 3 | U263: 13 | AF263: 13 | BP263: 13 | BQ263: 13
A264: Z07 | B264: ZAMORA CHINCHIPE | C264: CHINCHIPE | D264: 19D03 | E264: 002846 | F264: CENTRO DE SALUD DE ZUMBA | G264: NIVEL 1 | H264: CENTRO DE SALUD TIPO A | I264: 63 | Q264: 36 | R264: 27 | S264: 63 | U264: 63 | AF264: 63 | BS264: 12 | BT264: 12 | BU264: 12 | BV264: 12 | BW264: 6 | BX264: 6 | BY264: 6 | BZ264: 6 | CA264: 13 | CB264: 14 | CC264: 14 | CD264: 10 | CE264: 10 | CF264: 2 | CG264: 9 | CH264: 9 | CI264: 7 | CJ264: 6 | CK264: 3 | CO264: 1
A265: Z07 | B265: ZAMORA CHINCHIPE | C265: EL PANGUI | D265: 19D04 | E265: 001912 | F265: PACHICUTZA | G265: NIVEL 1 | H265: PUESTO DE SALUD
A266: Z07 | B266: ZAMORA CHINCHIPE | C266: EL PANGUI | D266: 19D04 | E266: 001913 | F266: EL PANGUI | G266: NIVEL 1 | H266: CENTRO DE SALUD TIPO B
A267: Z07 | B267: ZAMORA CHINCHIPE | C267: EL PANGUI | D267: 19D04 | E267: 001914 | F267: TUNDAYME | G267: NIVEL 1 | H267: PUESTO DE SALUD
A268: Z07 | B268: ZAMORA CHINCHIPE | C268: EL PANGUI | D268: 19D04 | E268: 001933 | F268: EL GUISMI | G268: NIVEL 1 | H268: PUESTO DE SALUD
A269: Z07 | B269: ZAMORA CHINCHIPE | C269: EL PANGUI | D269: 19D04 | E269: 001934 | F269: CHUCHUMBLETZA | G269: NIVEL 1 | H269: PUESTO DE SALUD
A270: Z07 | B270: ZAMORA CHINCHIPE | C270: NANGARITZA | D270: 19D02 | E270: 001906 | F270: NUEVO PARAISO | G270: NIVEL 1 | H270: PUESTO DE SALUD
A271: Z07 | B271: ZAMORA CHINCHIPE | C271: NANGARITZA | D271: 19D02 | E271: 001907 | F271: SHAIMI | G271: NIVEL 1 | H271: PUESTO DE SALUD
A272: Z07 | B272: ZAMORA CHINCHIPE | C272: NANGARITZA | D272: 19D02 | E272: 001908 | F272: GERANIOS | G272: NIVEL 1 | H272: PUESTO DE SALUD
A273: Z07 | B273: ZAMORA CHINCHIPE | C273: NANGARITZA | D273: 19D02 | E273: 001909 | F273: ZURMI | G273: NIVEL 1 | H273: PUESTO DE SALUD
A274: Z07 | B274: ZAMORA CHINCHIPE | C274: NANGARITZA | D274: 19D02 | E274: 001925 | F274: SANTA ELENA | G274: NIVEL 1 | H274: PUESTO DE SALUD
A275: Z07 | B275: ZAMORA CHINCHIPE | C275: NANGARITZA | D275: 19D02 | E275: 001926 | F275: GUAYZIMI | G275: NIVEL 1 | H275: CENTRO DE SALUD TIPO A
A276: Z07 | B276: ZAMORA CHINCHIPE | C276: PALANDA | D276: 19D03 | E276: 001904 | F276: SAN FRANCISCO DEL VERGEL | G276: NIVEL 1 | H276: PUESTO DE SALUD | I276: 10 | Q276: 3 | R276: 7 | S276: 10 | U276: 10 | AF276: 10 | BS276: 1 | BT276: 1 | BU276: 1 | BV276: 1 | BW276: 1 | BX276: 1 | BY276: 1 | BZ276: 1 | CA276: 2 | CB276: 2 | CC276: 2 | CD276: 1 | CE276: 1 | CF276: 1 | CG276: 2 | CH276: 3 | CI276: 2
A277: Z07 | B277: ZAMORA CHINCHIPE | C277: PALANDA | D277: 19D03 | E277: 001937 | F277: EL PORVENIR DEL CARMEN | G277: NIVEL 1 | H277: PUESTO DE SALUD | I277: 5 | N277: 1 | Q277: 3 | R277: 3 | S277: 6 | U277: 6 | AF277: 6 | BP277: 1 | BQ277: 1 | BS277: 3 | BT277: 3 | BU277: 3 | BV277: 3 | CB277: 1 | CC277: 1 | CD277: 1 | CE277: 1 | CF277: 1 | CG277: 1 | CH277: 1 | CI277: 1
A278: Z07 | B278: ZAMORA CHINCHIPE | C278: PALANDA | D278: 19D03 | E278: 001944 | F278: PALANDA | G278: NIVEL 1 | H278: CENTRO DE SALUD TIPO B | I278: 20 | N278: 7 | Q278: 10 | R278: 17 | S278: 21 | T278: 6 | U278: 27 | AF278: 27 | BP278: 3 | BQ278: 3 | BS278: 3 | BT278: 3 | BU278: 3 | BV278: 3 | BW278: 2 | BX278: 2 | BY278: 2 | BZ278: 2 | CA278: 4 | CB278: 4 | CC278: 4 | CD278: 8 | CE278: 8 | CF278: 4 | CH278: 1 | CJ278: 1 | CK278: 1
A279: Z07 | B279: ZAMORA CHINCHIPE | C279: PALANDA | D279: 19D03 | E279: 001945 | F279: VALLADOLID | G279: NIVEL 1 | H279: CENTRO DE SALUD TIPO A | I279: 19 | Q279: 9 | R279: 10 | S279: 19 | U279: 19 | AF279: 19 | BS279: 1 | BT279: 1 | BU279: 1 | BV279: 1 | BW279: 1 | BX279: 1 | BY279: 1 | BZ279: 1 | CA279: 3 | CB279: 2 | CC279: 2 | CD279: 2 | CE279: 1 | CH279: 2 | CI279: 1 | CJ279: 9 | CO279: 1
A280: Z07 | B280: ZAMORA CHINCHIPE | C280: PALANDA | D280: 19D03 | E280: 001946 | F280: LA CANELA | G280: NIVEL 1 | H280: PUESTO DE SALUD | I280: 5 | Q280: 2 | R280: 3 | S280: 5 | U280: 5 | AF280: 5 | BS280: 1 | BT280: 1 | BU280: 1 | BV280: 1 | CA280: 2 | CB280: 2 | CC280: 2 | CD280: 1 | CE280: 1 | CF280: 1
A281: Z07 | B281: ZAMORA CHINCHIPE | C281: PAQUISHA | D281: 19D02 | E281: 001899 | F281: PAQUISHA | G281: NIVEL 1 | H281: CENTRO DE SALUD TIPO B
A282: Z07 | B282: ZAMORA CHINCHIPE | C282: PAQUISHA | D282: 19D02 | E282: 001941 | F282: BELLAVISTA | G282: NIVEL 1 | H282: PUESTO DE SALUD
...

Sheet JULIO
A1: Zona | B1: provincia | C1: canton | D1: distrito | E1: unicodigo | F1: uni_nombre | G1: nivel | H1: tipo | I1: int_msp | J1: ext_CNH | K1: ext_cibv | L1: ext_educ_gene_basic | M1: ext_bachillerato | N1: ext_visita_domi | O1: ext_comuni | P1: ext_otros | Q1: sexo_h | R1: sexo_m | S1: pertenece_ES | T1: No_pertenece_ES | U1: ecuatoriano | V1: colombiano | W1: peruano | X1: cubano | Y1: venezolano | Z1: otros | AA1: indigena | AB1: afro | AC1: negro | AD1: mulato | AE1: montubio | AF1: mestizo | AG1: blanco | AH1: otro | AI1: Achuar | AJ1: Andoa | AK1: Awa | AL1: Chachi | AM1: Cofan | AN1: Epera | AO1: Huancavilca | AP1: Kichwa | AQ1: Manta | AR1: Secoya | AS1: Shiwiar | AT1: Shuar | AU1: Siona | AV1: Tsáchila | AW1: Waorani | AX1: Zapara | AY1: Chibuleo | AZ1: Kañari | BA1: Karanki | BB1: Kayambi | BC1: Kichwa Amazónico | BD1: Kisapincha | BE1: Kitukara | BF1: Natabuela | BG1: Otavalo | BH1: Paltas | BI1: Panzaleo | BJ1: Pastos | BK1: Puruha | BL1: Salasaka | BM1: Saraguro | BN1: Tomabela | BO1: Waramka | BP1: BCG_24 | BQ1: HB_24 | BR1: BCG_365 | BS1: rota_1 | BT1: fIPV_1 | BU1: neumo_1 | BV1: penta_1 | BW1: rota_2 | BX1: fIPV_2 | BY1: neumo_2 | BZ1: penta_2 | CA1: bopv_3 | CB1: neumo_3 | CC1: penta_3 | CD1: srp_1 | CE1: fa | CF1: varicela | CG1: srp_2 | CH1: bopv_4 | CI1: dpt_4 | CJ1: bopv_5 | CK1: dpt_5 | CL1: hpv_9a_1d | CM1: hpv_9a_2d | CN1: hpv_10a_2d | CO1: dt_3
A2: Z07 | B2: EL ORO | C2: ARENILLAS | D2: 07D05 | E2: 000541 | F2: SAN VICENTE | G2: NIVEL 1 | H2: CENTRO DE SALUD TIPO A
A3: Z07 | B3: EL ORO | C3: ARENILLAS | D3: 07D05 | E3: 000542 | F3: SAN ISIDRO URBANO | G3: NIVEL 1 | H3: CENTRO DE SALUD TIPO B
A4: Z07 | B4: EL ORO | C4: ARENILLAS | D4: 07D05 | E4: 000543 | F4: CAÑAS | G4: NIVEL 1 | H4: PUESTO DE SALUD
A5: Z07 | B5: EL ORO | C5: ARENILLAS | D5: 07D05 | E5: 000544 | F5: LA CUCA | G5: NIVEL 1 | H5: CENTRO DE SALUD TIPO A
A6: Z07 | B6: EL ORO | C6: ARENILLAS | D6: 07D05 | E6: 000545 | F6: CARCABON | G6: NIVEL 1 | H6: CENTRO DE SALUD TIPO A
A7: Z07 | B7: EL ORO | C7: ARENILLAS | D7: 07D05 | E7: 000546 | F7: CHACRAS | G7: NIVEL 1 | H7: CENTRO DE SALUD TIPO A
A8: Z07 | B8: EL ORO | C8: ARENILLAS | D8: 07D05 | E8: 000547 | F8: PALMALES | G8: NIVEL 1 | H8: CENTRO DE SALUD TIPO A
A9: Z07 | B9: EL ORO | C9: ARENILLAS | D9: 07D05 | E9: 000548 | F9: MANABI DE EL ORO | G9: NIVEL 1 | H9: PUESTO DE SALUD
A10: Z07 | B10: EL ORO | C10: ARENILLAS | D10: 07D05 | E10: 000591 | F10: HOSPITAL BASICO DE ARENILLAS | G10: NIVEL 2 | H10: HOSPITAL BASICO
A11: Z07 | B11: EL ORO | C11: ARENILLAS | D11: 07D05 | E11: 002763 | F11: EL JOBO SAN VICENTE | G11: NIVEL 1 | H11: PUESTO DE SALUD
A12: Z07 | B12: EL ORO | C12: ARENILLAS | D12: 07D05 | E12: 002900 | F12: CENTRO DE SALUD ARENILLAS | G12: NIVEL 1 | H12: CENTRO DE SALUD TIPO A
A13: Z07 | B13: EL ORO | C13: ATAHUALPA | D13: 07D03 | E13: 000576 | F13: AYAPAMBA | G13: NIVEL 1 | H13: CENTRO DE SALUD TIPO A
... A258: Z07 | B258: ZAMORA CHINCHIPE | C258: CHINCHIPE | D258: 19D03 | E258: 001902 | F258: EL CHORRO | G258: NIVEL 1 | H258: PUESTO DE SALUD
A259: Z07 | B259: ZAMORA CHINCHIPE | C259: CHINCHIPE | D259: 19D03 | E259: 001903 | F259: CHITO | G259: NIVEL 1 | H259: CENTRO DE SALUD TIPO A | I259: 5 | N259: 4 | Q259: 5 | R259: 4 | S259: 9 | U259: 9 | AF259: 9 | BS259: 1 | BT259: 1 | BU259: 1 | BV259: 1 | CA259: 1 | CB259: 1 | CC259: 1 | CD259: 1 | CE259: 1 | CF259: 3 | CG259: 1 | CH259: 2 | CI259: 1 | CJ259: 1 | CK259: 1
A260: Z07 | B260: ZAMORA CHINCHIPE | C260: CHINCHIPE | D260: 19D03 | E260: 001921 | F260: LA GUAYUZA | G260: NIVEL 1 | H260: PUESTO DE SALUD | I260: 0 | BS260: 0 | BT260: 0 | BU260: 0 | BV260: 0 | BW260: 0 | BX260: 0 | BY260: 0 | BZ260: 0 | CA260: 0 | CB260: 0 | CC260: 0 | CD260: 0 | CE260: 0 | CF260: 0 | CG260: 0 | CH260: 0 | CI260: 0 | CJ260: 0 | CK260: 0
A261: Z07 | B261: ZAMORA CHINCHIPE | C261: CHINCHIPE | D261: 19D03 | E261: 001922 | F261: LA DIVERSION | G261: NIVEL 1 | H261: CENTRO DE SALUD TIPO A | J261: 4 | N261: 4 | Q261: 7 | R261: 1 | S261: 8 | U261: 8 | AF261: 8 | BS261: 2 | BU261: 2 | BV261: 2 | CA261: 1 | CB261: 1 | CC261: 1 | CD261: 1 | CE261: 1 | CF261: 1 | CH261: 1 | CI261: 1 | CJ261: 2 | CK261: 1
