Workbook

Sheet ENERO
A1: Zona | B1: provincia | C1: canton | D1: distrito | E1: unicodigo | F1: uni_nombre | G1: nivel | H1: tipo | I1: Establecimiento | J1: CNH | K1: CDI | L1: E. General Básica | M1: Bachillerato | N1: Atención Comunitaria | O1: Vistas Domiciliaras | P1: ext_OTROS | Q1: Hombre | R1: Mujer | S1: Pertenece_ES | T1: No_pertenece_ES | U1: Ecuatoriana | V1: Colombiana | W1: Peruana | X1: Cubana | Y1: Venezolana | Z1: Otras | AA1: Indigena | AB1: Afro ecuatoriano/ Afro descendiente | AC1: Negro/a | AD1: Mulato/a | AE1: Montubio/a | AF1: Mestizo/a | AG1: Blanco/a | AH1: Otro | AI1: Achuar | AJ1: Andoa | AK1: Awa | AL1: Chachi | AM1: Cofan | AN1: Epera | AO1: Huancavilca | AP1: Kichwa | AQ1: Manta | AR1: Secoya | AS1: Shiwiar | AT1: Shuar | AU1: Siona | AV1: Tsáchila | AW1: Waorani | AX1: Zapara | AY1: Chibuleo | AZ1: Kañari | BA1: Karanki | BB1: Kayambi | BC1: Kichwa Amazónico | BD1: Kisapincha | BE1: Kitukara | BF1: Natabuela | BG1: Otavalo | BH1: Paltas | BI1: Panzaleo | BJ1: Pastos | BK1: Puruha | BL1: Salasaka | BM1: Saraguro | BN1: Tomabela | BO1: Waramka | BP1: fIPV_1ano_1d | BQ1: HB_1ano_1d | BR1: DPT_1ano_1d | BS1: fIPV_1ano_2d | BT1: HB_1ano_2d | BU1: DPT_1ano_2d | BV1: bOPV_1ano_3d | BW1: HB_1ano_3d | BX1: DPT_1ano_3d | BY1: fIPV_2anos_1d | BZ1: SRP_2anos_1d | CA1: HB_2anos_1d | CB1: DPT_2anos_1d | CC1: fIPV_2anos_2d | CD1: SRP_2anos_2d | CE1: HB_2anos_2d | CF1: DPT_2anos_2d | CG1: bOPV_2anos_3d | CH1: HB_2anos_3d | CI1: DPT_2anos_3d | CJ1: bOPV_2anos_4d | CK1: DPT_2anos_4d | CL1: FA_2anos | CM1: fIPV_3anos_1d | CN1: SRP_3anos_1d | CO1: HB_3anos_1d | CP1: DPT_3anos_1d | CQ1: fIPV_3anos_2d | CR1: SRP_3anos_2d | CS1: HB_3anos_2d | CT1: DPT_3anos_2d | CU1: bOPV_3anos_3d | CV1: HB_3anos_3d | CW1: DPT_3anos_3d | CX1: bOPV_3anos_4d | CY1: DPT_3anos_4d | CZ1: FA_3anos | DA1: fIPV_4anos_1d | DB1: SRP_4anos_1d | DC1: HB_4anos_1d | DD1: DPT_4anos_1d | DE1: fIPV_4anos_2d | DF1: SRP_4anos_2d | DG1: HB_4anos_2d | DH1: DPT_4anos_2d | DI1: bOPV_4anos_3d | DJ1: HB_4anos_3d | DK1: DPT_4anos_3d | DL1: bOPV_4anos_4d | DM1: DPT_4anos_4d | DN1: FA_4anos | DO1: fIPV_5anos_1d | DP1: SRP_5anos_1d | DQ1: HB_5anos_1d | DR1: DPT_5anos_1d | DS1: fIPV_5anos_2d | DT1: SRP_5anos_2d | DU1: HB_5anos_2d | DV1: DPT_5anos_2d | DW1: bOPV_5anos_3d | DX1: HB_5anos_3d | DY1: DPT_5anos_3d | DZ1: bOPV_5anos_4d | EA1: DPT_5anos_4d | EB1: FA_5anos | EC1: SRP_6anos_1d | ED1: SRP_6anos_2d | EE1: FA_6anos | EF1: SR_7anos_1d | EG1: SR_7anos_2d | EH1: FA_7anos | EI1: FA_8anos | EJ1: dT adulto_7a14 años | EK1: FA_9a14 | EL1: FA_15a19 | EM1: FA_20a59 | EN1: SR_8a14_1d | EO1: SR_8a14_2d | EP1: SR_15a29_1d | EQ1: SR_15a29_2d | ER1: SR_30a50_1d | ES1: SR_30a50_2d | ET1: dTadulto_MEF_1D | EU1: dTadulto_MEF_2D | EV1: dTadulto_MEF_3D | EW1: dTadulto_MEF_4D | EX1: dTadulto_MEF_5D | EY1: dTadulto_EMB_1D | EZ1: dTadulto_EMB_2D | FA1: dTadulto_EMB_3D | FB1: dTadulto_EMB_4D | FC1: dTadulto_EMB_5D | FD1: dTadulto_HOMBRE_1D | FE1: dTadulto_HOMBRE_2D | FF1: dTadulto_HOMBRE_3D | FG1: dTadulto_HOMBRE_4D | FH1: dTadulto_HOMBRE_5D | FI1: HB_TSALUD_1D | FJ1: HB_TSALUD_2D | FK1: HB_TSALUD_3D | FL1: HB_ESTSALUD_1D | FM1: HB_ESTSALUD_2D | FN1: HB_ESTSALUD_3D | FO1: HB_TSEXUAL_1D | FP1: HB_TSEXUAL_2D | FQ1: HB_TSEXUAL_3D | FR1: HB_PVV_1D | FS1: HB_PVV_2D | FT1: HB_PVV_3D | FU1: HB_PPL_1D | FV1: HB_PPL_2D | FW1: HB_PPL_3D | FX1: HB_OGRUP_1D | FY1: HB_OGRUP_2D | FZ1: HB_OGRUP_3D | GA1: Inmunoglobulina_Antitetánica | GB1: Inmunoglobulina_Anti Hepatitis B | GC1: Inmunoglobulina_Antirrábica
A2: Z07 | B2: EL ORO | C2: ARENILLAS | D2: 07D05 | E2: 000541 | F2: SAN VICENTE | G2: NIVEL 1 | H2: CENTRO DE SALUD TIPO A
A3: Z07 | B3: EL ORO | C3: ARENILLAS | D3: 07D05 | E3: 000542 | F3: SAN ISIDRO URBANO | G3: NIVEL 1 | H3: CENTRO DE SALUD TIPO B
A4: Z07 | B4: EL ORO | C4: ARENILLAS | D4: 07D05 | E4: 000543 | F4: CAÑAS | G4: NIVEL 1 | H4: PUESTO DE SALUD
A5: Z07 | B5: EL ORO | C5: ARENILLAS | D5: 07D05 | E5: 000544 | F5: LA CUCA | G5: NIVEL 1 | H5: CENTRO DE SALUD TIPO A
A6: Z07 | B6: EL ORO | C6: ARENILLAS | D6: 07D05 | E6: 000545 | F6: CARCABON | G6: NIVEL 1 | H6: CENTRO DE SALUD TIPO A
A7: Z07 | B7: EL ORO | C7: ARENILLAS | D7: 07D05 | E7: 000546 | F7: CHACRAS | G7: NIVEL 1 | H7: CENTRO DE SALUD TIPO A
A8: Z07 | B8: EL ORO | C8: ARENILLAS | D8: 07D05 | E8: 000547 | F8: PALMALES | G8: NIVEL 1 | H8: CENTRO DE SALUD TIPO A
A9: Z07 | B9: EL ORO | C9: ARENILLAS | D9: 07D05 | E9: 000548 | F9: MANABI DE EL ORO | G9: NIVEL 1 | H9: PUESTO DE SALUD
A10: Z07 | B10: EL ORO | C10: ARENILLAS | D10: 07D05 | E10: 000591 | F10: HOSPITAL BASICO DE ARENILLAS | G10: NIVEL 2 | H10: HOSPITAL BASICO
A11: Z07 | B11: EL ORO | C11: ARENILLAS | D11: 07D05 | E11: 002763 | F11: EL JOBO SAN VICENTE | G11: NIVEL 1 | H11: PUESTO DE SALUD
A12: Z07 | B12: EL ORO | C12: ARENILLAS | D12: 07D05 | E12: 002900 | F12: CENTRO DE SALUD ARENILLAS | G12: NIVEL 1 | H12: CENTRO DE SALUD TIPO A
A13: Z07 | B13: EL ORO | C13: ATAHUALPA | D13: 07D03 | E13: 000576 | F13: AYAPAMBA | G13: NIVEL 1 | H13: CENTRO DE SALUD TIPO A
... A258: Z07 | B258: ZAMORA CHINCHIPE | C258: CHINCHIPE | D258: 19D03 | E258: 001902 | F258: EL CHORRO | G258: NIVEL 1 | H258: PUESTO DE SALUD
A259: Z07 | B259: ZAMORA CHINCHIPE | C259: CHINCHIPE | D259: 19D03 | E259: 001903 | F259: CHITO | G259: NIVEL 1 | H259: CENTRO DE SALUD TIPO A | I259: 6 | O259: 7 | Q259: 3 | R259: 10 | S259: 6 | T259: 7 | U259: 8 | V259: 2 | Y259: 3 | AF259: 8 | AH259: 5 | EL259: 2 | EM259: 2 | ET259: 2 | EY259: 1 | FD259: 2 | FO259: 3 | FP259: 2 | FQ259: 1
A260: Z07 | B260: ZAMORA CHINCHIPE | C260: CHINCHIPE | D260: 19D03 | E260: 001921 | F260: LA GUAYUZA | G260: NIVEL 1 | H260: PUESTO DE SALUD | I260: 1 | Q260: 1 | S260: 1 | U260: 1 | AF260: 1 | FD260: 1
A261: Z07 | B261: ZAMORA CHINCHIPE | C261: CHINCHIPE | D261: 19D03 | E261: 001922 | F261: LA DIVERSION | G261: NIVEL 1 | H261: CENTRO DE SALUD TIPO A | I261: 1 | R261: 1 | S261: 1 | U261: 1 | AF261: 1 | EM261: 1
A262: Z07 | B262: ZAMORA CHINCHIPE | C262: CHINCHIPE | D262: 19D03 | E262: 001923 | F262: SAN ANDRES | G262: NIVEL 1 | H262: PUESTO DE SALUD | I262: 2 | Q262: 1 | R262: 1 | S262: 2 | U262: 2 | AF262: 2 | EM262: 2
A263: Z07 | B263: ZAMORA CHINCHIPE | C263: CHINCHIPE | D263: 19D03 | E263: 001949 | F263: HOSPITAL BASICO DE ZUMBA | G263: NIVEL 2 | H263: HOSPITAL BASICO
A264: Z07 | B264: ZAMORA CHINCHIPE | C264: CHINCHIPE | D264: 19D03 | E264: 002846 | F264: CENTRO DE SALUD DE ZUMBA | G264: NIVEL 1 | H264: CENTRO DE SALUD TIPO A | I264: 46 | P264: 4 | Q264: 17 | R264: 33 | S264: 50 | U264: 50 | AF264: 50 | EI264: 1 | EM264: 22 | ET264: 4 | EU264: 2 | EV264: 4 | EY264: 8 | EZ264: 8 | FA264: 1 | FC264: 1 | FD264: 2 | FE264: 1 | FI264: 1 | FJ264: 1 | FK264: 1 | FO264: 3 | FP264: 1 | FQ264: 1
A265: Z07 | B265: ZAMORA CHINCHIPE | C265: EL PANGUI | D265: 19D04 | E265: 001912 | F265: PACHICUTZA | G265: NIVEL 1 | H265: PUESTO DE SALUD
A266: Z07 | B266: ZAMORA CHINCHIPE | C266: EL PANGUI | D266: 19D04 | E266: 001913 | F266: EL PANGUI | G266: NIVEL 1 | H266: CENTRO DE SALUD TIPO B
A267: Z07 | B267: ZAMORA CHINCHIPE | C267: EL PANGUI | D267: 19D04 | E267: 001914 | F267: TUNDAYME | G267: NIVEL 1 | H267: PUESTO DE SALUD
A268: Z07 | B268: ZAMORA CHINCHIPE | C268: EL PANGUI | D268: 19D04 | E268: 001933 | F268: EL GUISMI | G268: NIVEL 1 | H268: PUESTO DE SALUD
A269: Z07 | B269: ZAMORA CHINCHIPE | C269: EL PANGUI | D269: 19D04 | E269: 001934 | F269: CHUCHUMBLETZA | G269: NIVEL 1 | H269: PUESTO DE SALUD
A270: Z07 | B270: ZAMORA CHINCHIPE | C270: NANGARITZA | D270: 19D02 | E270: 001906 | F270: NUEVO PARAISO | G270: NIVEL 1 | H270: PUESTO DE SALUD
A271: Z07 | B271: ZAMORA CHINCHIPE | C271: NANGARITZA | D271: 19D02 | E271: 001907 | F271: SHAIMI | G271: NIVEL 1 | H271: PUESTO DE SALUD
A272: Z07 | B272: ZAMORA CHINCHIPE | C272: NANGARITZA | D272: 19D02 | E272: 001908 | F272: GERANIOS | G272: NIVEL 1 | H272: PUESTO DE SALUD
A273: Z07 | B273: ZAMORA CHINCHIPE | C273: NANGARITZA | D273: 19D02 | E273: 001909 | F273: ZURMI | G273: NIVEL 1 | H273: PUESTO DE SALUD
A274: Z07 | B274: ZAMORA CHINCHIPE | C274: NANGARITZA | D274: 19D02 | E274: 001925 | F274: SANTA ELENA | G274: NIVEL 1 | H274: PUESTO DE SALUD
A275: Z07 | B275: ZAMORA CHINCHIPE | C275: NANGARITZA | D275: 19D02 | E275: 001926 | F275: GUAYZIMI | G275: NIVEL 1 | H275: CENTRO DE SALUD TIPO A
A276: Z07 | B276: ZAMORA CHINCHIPE | C276: PALANDA | D276: 19D03 | E276: 001904 | F276: SAN FRANCISCO DEL VERGEL | G276: NIVEL 1 | H276: PUESTO DE SALUD | I276: 12 | Q276: 3 | R276: 9 | S276: 8 | T276: 4 | U276: 12 | AF276: 12 | EM276: 3 | ET276: 1 | EV276: 1 | EY276: 2 | EZ276: 3 | FD276: 3
A277: Z07 | B277: ZAMORA CHINCHIPE | C277: PALANDA | D277: 19D03 | E277: 001937 | F277: EL PORVENIR DEL CARMEN | G277: NIVEL 1 | H277: PUESTO DE SALUD | I277: 7 | Q277: 3 | R277: 4 | S277: 7 | U277: 7 | AF277: 7 | EV277: 1 | EW277: 1 | EY277: 1 | EZ277: 1 | FE277: 1 | FG277: 1 | FH277: 1 | FJ277: 1
A278: Z07 | B278: ZAMORA CHINCHIPE | C278: PALANDA | D278: 19D03 | E278: 001944 | F278: PALANDA | G278: NIVEL 1 | H278: CENTRO DE SALUD TIPO B | I278: 34 | Q278: 13 | R278: 21 | S278: 34 | U278: 34 | AF278: 34 | EM278: 14 | ET278: 1 | EU278: 1 | EV278: 1 | EW278: 1 | EY278: 7 | EZ278: 8 | FD278: 2 | FX278: 1
A279: Z07 | B279: ZAMORA CHINCHIPE | C279: PALANDA | D279: 19D03 | E279: 001945 | F279: VALLADOLID | G279: NIVEL 1 | H279: CENTRO DE SALUD TIPO A | I279: 7 | Q279: 3 | R279: 4 | S279: 7 | U279: 7 | AF279: 7 | EM279: 2 | EW279: 1 | EZ279: 2 | FD279: 1 | FE279: 1 | FX279: 1
A280: Z07 | B280: ZAMORA CHINCHIPE | C280: PALANDA | D280: 19D03 | E280: 001946 | F280: LA CANELA | G280: NIVEL 1 | H280: PUESTO DE SALUD | I280: 7 | Q280: 1 | R280: 6 | S280: 6 | T280: 1 | U280: 7 | AF280: 7 | EY280: 5 | EZ280: 1 | FH280: 1
A281: Z07 | B281: ZAMORA CHINCHIPE | C281: PAQUISHA | D281: 19D02 | E281: 001899 | F281: PAQUISHA | G281: NIVEL 1 | H281: CENTRO DE SALUD TIPO B
A282: Z07 | B282: ZAMORA CHINCHIPE | C282: PAQUISHA | D282: 19D02 | E282: 001941 | F282: BELLAVISTA | G282: NIVEL 1 | H282: PUESTO DE SALUD
A283: Z07 | B283: ZAMORA CHINCHIPE | C283: PAQUISHA | D283: 19D02 | E283: 001942 | F283: CHINAPINTZA | G283: NIVEL 1 | H283: PUESTO DE SALUD
A284: Z07 | B284: ZAMORA CHINCHIPE | C284: PAQUISHA | D284: 19D02 | E284: 001943 | F284: CISAM | G284: NIVEL 1 | H284: PUESTO DE SALUD
...

Sheet FEBRERO
A1: Zona | B1: provincia | C1: canton | D1: distrito | E1: unicodigo | F1: uni_nombre | G1: nivel | H1: tipo | I1: Establecimiento | J1: CNH | K1: CDI | L1: E. General Básica | M1: Bachillerato | N1: Atención Comunitaria | O1: Vistas Domiciliaras | P1: ext_OTROS | Q1: Hombre | R1: Mujer | S1: Pertenece_ES | T1: No_pertenece_ES | U1: Ecuatoriana | V1: Colombiana | W1: Peruana | X1: Cubana | Y1: Venezolana | Z1: Otras | AA1: Indigena | AB1: Afro ecuatoriano/ Afro descendiente | AC1: Negro/a | AD1: Mulato/a | AE1: Montubio/a | AF1: Mestizo/a | AG1: Blanco/a | AH1: Otro | AI1: Achuar | AJ1: Andoa | AK1: Awa | AL1: Chachi | AM1: Cofan | AN1: Epera | AO1: Huancavilca | AP1: Kichwa | AQ1: Manta | AR1: Secoya | AS1: Shiwiar | AT1: Shuar | AU1: Siona | AV1: Tsáchila | AW1: Waorani | AX1: Zapara | AY1: Chibuleo | AZ1: Kañari | BA1: Karanki | BB1: Kayambi | BC1: Kichwa Amazónico | BD1: Kisapincha | BE1: Kitukara | BF1: Natabuela | BG1: Otavalo | BH1: Paltas | BI1: Panzaleo | BJ1: Pastos | BK1: Puruha | BL1: Salasaka | BM1: Saraguro | BN1: Tomabela | BO1: Waramka | BP1: fIPV_1ano_1d | BQ1: HB_1ano_1d | BR1: DPT_1ano_1d | BS1: fIPV_1ano_2d | BT1: HB_1ano_2d | BU1: DPT_1ano_2d | BV1: bOPV_1ano_3d | BW1: HB_1ano_3d | BX1: DPT_1ano_3d | BY1: fIPV_2anos_1d | BZ1: SRP_2anos_1d | CA1: HB_2anos_1d | CB1: DPT_2anos_1d | CC1: fIPV_2anos_2d | CD1: SRP_2anos_2d | CE1: HB_2anos_2d | CF1: DPT_2anos_2d | CG1: bOPV_2anos_3d | CH1: HB_2anos_3d | CI1: DPT_2anos_3d | CJ1: bOPV_2anos_4d | CK1: DPT_2anos_4d | CL1: FA_2anos | CM1: fIPV_3anos_1d | CN1: SRP_3anos_1d | CO1: HB_3anos_1d | CP1: DPT_3anos_1d | CQ1: fIPV_3anos_2d | CR1: SRP_3anos_2d | CS1: HB_3anos_2d | CT1: DPT_3anos_2d | CU1: bOPV_3anos_3d | CV1: HB_3anos_3d | CW1: DPT_3anos_3d | CX1: bOPV_3anos_4d | CY1: DPT_3anos_4d | CZ1: FA_3anos | DA1: fIPV_4anos_1d | DB1: SRP_4anos_1d | DC1: HB_4anos_1d | DD1: DPT_4anos_1d | DE1: fIPV_4anos_2d | DF1: SRP_4anos_2d | DG1: HB_4anos_2d | DH1: DPT_4anos_2d | DI1: bOPV_4anos_3d | DJ1: HB_4anos_3d | DK1: DPT_4anos_3d | DL1: bOPV_4anos_4d | DM1: DPT_4anos_4d | DN1: FA_4anos | DO1: fIPV_5anos_1d | DP1: SRP_5anos_1d | DQ1: HB_5anos_1d | DR1: DPT_5anos_1d | DS1: fIPV_5anos_2d | DT1: SRP_5anos_2d | DU1: HB_5anos_2d | DV1: DPT_5anos_2d | DW1: bOPV_5anos_3d | DX1: HB_5anos_3d | DY1: DPT_5anos_3d | DZ1: bOPV_5anos_4d | EA1: DPT_5anos_4d | EB1: FA_5anos | EC1: SRP_6anos_1d | ED1: SRP_6anos_2d | EE1: FA_6anos | EF1: SR_7anos_1d | EG1: SR_7anos_2d | EH1: FA_7anos | EI1: FA_8anos | EJ1: dT adulto_7a14 años | EK1: FA_9a14 | EL1: FA_15a19 | EM1: FA_20a59 | EN1: SR_8a14_1d | EO1: SR_8a14_2d | EP1: SR_15a29_1d | EQ1: SR_15a29_2d | ER1: SR_30a50_1d | ES1: SR_30a50_2d | ET1: dTadulto_MEF_1D | EU1: dTadulto_MEF_2D | EV1: dTadulto_MEF_3D | EW1: dTadulto_MEF_4D | EX1: dTadulto_MEF_5D | EY1: dTadulto_EMB_1D | EZ1: dTadulto_EMB_2D | FA1: dTadulto_EMB_3D | FB1: dTadulto_EMB_4D | FC1: dTadulto_EMB_5D | FD1: dTadulto_HOMBRE_1D | FE1: dTadulto_HOMBRE_2D | FF1: dTadulto_HOMBRE_3D | FG1: dTadulto_HOMBRE_4D | FH1: dTadulto_HOMBRE_5D | FI1: HB_TSALUD_1D | FJ1: HB_TSALUD_2D | FK1: HB_TSALUD_3D | FL1: HB_ESTSALUD_1D | FM1: HB_ESTSALUD_2D | FN1: HB_ESTSALUD_3D | FO1: HB_TSEXUAL_1D | FP1: HB_TSEXUAL_2D | FQ1: HB_TSEXUAL_3D | FR1: HB_PVV_1D | FS1: HB_PVV_2D | FT1: HB_PVV_3D | FU1: HB_PPL_1D | FV1: HB_PPL_2D | FW1: HB_PPL_3D | FX1: HB_OGRUP_1D | FY1: HB_OGRUP_2D | FZ1: HB_OGRUP_3D | GA1: Inmunoglobulina_Antitetánica | GB1: Inmunoglobulina_Anti Hepatitis B | GC1: Inmunoglobulina_Antirrábica
A2: Z07 | B2: EL ORO | C2: ARENILLAS | D2: 07D05 | E2: 000541 | F2: SAN VICENTE | G2: NIVEL 1 | H2: CENTRO DE SALUD TIPO A
A3: Z07 | B3: EL ORO | C3: ARENILLAS | D3: 07D05 | E3: 000542 | F3: SAN ISIDRO URBANO | G3: NIVEL 1 | H3: CENTRO DE SALUD TIPO B
A4: Z07 | B4: EL ORO | C4: ARENILLAS | D4: 07D05 | E4: 000543 | F4: CAÑAS | G4: NIVEL 1 | H4: PUESTO DE SALUD
A5: Z07 | B5: EL ORO | C5: ARENILLAS | D5: 07D05 | E5: 000544 | F5: LA CUCA | G5: NIVEL 1 | H5: CENTRO DE SALUD TIPO A
A6: Z07 | B6: EL ORO | C6: ARENILLAS | D6: 07D05 | E6: 000545 | F6: CARCABON | G6: NIVEL 1 | H6: CENTRO DE SALUD TIPO A
A7: Z07 | B7: EL ORO | C7: ARENILLAS | D7: 07D05 | E7: 000546 | F7: CHACRAS | G7: NIVEL 1 | H7: CENTRO DE SALUD TIPO A
A8: Z07 | B8: EL ORO | C8: ARENILLAS | D8: 07D05 | E8: 000547 | F8: PALMALES | G8: NIVEL 1 | H8: CENTRO DE SALUD TIPO A
A9: Z07 | B9: EL ORO | C9: ARENILLAS | D9: 07D05 | E9: 000548 | F9: MANABI DE EL ORO | G9: NIVEL 1 | H9: PUESTO DE SALUD
A10: Z07 | B10: EL ORO | C10: ARENILLAS | D10: 07D05 | E10: 000591 | F10: HOSPITAL BASICO DE ARENILLAS | G10: NIVEL 2 | H10: HOSPITAL BASICO
A11: Z07 | B11: EL ORO | C11: ARENILLAS | D11: 07D05 | E11: 002763 | F11: EL JOBO SAN VICENTE | G11: NIVEL 1 | H11: PUESTO DE SALUD
A12: Z07 | B12: EL ORO | C12: ARENILLAS | D12: 07D05 | E12: 002900 | F12: CENTRO DE SALUD ARENILLAS | G12: NIVEL 1 | H12: CENTRO DE SALUD TIPO A
A13: Z07 | B13: EL ORO | C13: ATAHUALPA | D13: 07D03 | E13: 000576 | F13: AYAPAMBA | G13: NIVEL 1 | H13: CENTRO DE SALUD TIPO A
... A256: Z07 | B256: ZAMORA CHINCHIPE | C256: CENTINELA DEL CONDOR | D256: 19D02 | E256: 001900 | F256: ZUMBI | G256: NIVEL 1 | H256: CENTRO DE SALUD TIPO A
A257: Z07 | B257: ZAMORA CHINCHIPE | C257: CHINCHIPE | D257: 19D03 | E257: 001901 | F257: LA CHONTA | G257: NIVEL 1 | H257: CENTRO DE SALUD TIPO A | I257: 5 | P257: 3 | Q257: 2 | R257: 6 | S257: 5 | T257: 3 | U257: 8 | AA257: 1 | AF257: 7 | EM257: 6 | ET257: 6 | EY257: 1
A258: Z07 | B258: ZAMORA CHINCHIPE | C258: CHINCHIPE | D258: 19D03 | E258: 001902 | F258: EL CHORRO | G258: NIVEL 1 | H258: PUESTO DE SALUD
A259: Z07 | B259: ZAMORA CHINCHIPE | C259: CHINCHIPE | D259: 19D03 | E259: 001903 | F259: CHITO | G259: NIVEL 1 | H259: CENTRO DE SALUD TIPO A | I259: 7 | O259: 3 | Q259: 6 | R259: 4 | S259: 10 | U259: 10 | AF259: 10 | EM259: 6 | EY259: 2 | EZ259: 2
A260: Z07 | B260: ZAMORA CHINCHIPE | C260: CHINCHIPE | D260: 19D03 | E260: 001921 | F260: LA GUAYUZA | G260: NIVEL 1 | H260: PUESTO DE SALUD | I260: 1 | R260: 1 | S260: 1 | U260: 1 | AF260: 1 | EY260: 1
A261: Z07 | B261: ZAMORA CHINCHIPE | C261: CHINCHIPE | D261: 19D03 | E261: 001922 | F261: LA DIVERSION | G261: NIVEL 1 | H261: CENTRO DE SALUD TIPO A
A262: Z07 | B262: ZAMORA CHINCHIPE | C262: CHINCHIPE | D262: 19D03 | E262: 001923 | F262: SAN ANDRES | G262: NIVEL 1 | H262: PUESTO DE SALUD | I262: 3 | Q262: 1 | R262: 2 | S262: 3 | U262: 3 | AF262: 3 | EZ262: 1 | FH262: 1 | FX262: 1
A263: Z07 | B263: ZAMORA CHINCHIPE | C263: CHINCHIPE | D263: 19D03 | E263: 001949 | F263: HOSPITAL BASICO DE ZUMBA | G263: NIVEL 2 | H263: HOSPITAL BASICO | I263: 1 | Q263: 1 | S263: 1 | U263: 1 | AF263: 1 | GB263: 4
A264: Z07 | B264: ZAMORA CHINCHIPE | C264: CHINCHIPE | D264: 19D03 | E264: 002846 | F264: CENTRO DE SALUD DE ZUMBA | G264: NIVEL 1 | H264: CENTRO DE SALUD TIPO A | I264: 40 | Q264: 11 | R264: 29 | S264: 40 | U264: 39 | V264: 1 | AF264: 39 | AH264: 1 | CD264: 1 | CJ264: 1 | CK264: 1 | EL264: 1 | EM264: 10 | ET264: 2 | EU264: 5 | EW264: 2 | EY264: 7 | EZ264: 6 | FC264: 1 | FD264: 2 | FE264: 1 | FJ264: 1 | FK264: 2 | FO264: 1 | FP264: 2 | FQ264: 2 | FX264: 2
A265: Z07 | B265: ZAMORA CHINCHIPE | C265: EL PANGUI | D265: 19D04 | E265: 001912 | F265: PACHICUTZA | G265: NIVEL 1 | H265: PUESTO DE SALUD
A266: Z07 | B266: ZAMORA CHINCHIPE | C266: EL PANGUI | D266: 19D04 | E266: 001913 | F266: EL PANGUI | G266: NIVEL 1 | H266: CENTRO DE SALUD TIPO B
A267: Z07 | B267: ZAMORA CHINCHIPE | C267: EL PANGUI | D267: 19D04 | E267: 001914 | F267: TUNDAYME | G267: NIVEL 1 | H267: PUESTO DE SALUD
A268: Z07 | B268: ZAMORA CHINCHIPE | C268: EL PANGUI | D268: 19D04 | E268: 001933 | F268: EL GUISMI | G268: NIVEL 1 | H268: PUESTO DE SALUD
A269: Z07 | B269: ZAMORA CHINCHIPE | C269: EL PANGUI | D269: 19D04 | E269: 001934 | F269: CHUCHUMBLETZA | G269: NIVEL 1 | H269: PUESTO DE SALUD
A270: Z07 | B270: ZAMORA CHINCHIPE | C270: NANGARITZA | D270: 19D02 | E270: 001906 | F270: NUEVO PARAISO | G270: NIVEL 1 | H270: PUESTO DE SALUD
A271: Z07 | B271: ZAMORA CHINCHIPE | C271: NANGARITZA | D271: 19D02 | E271: 001907 | F271: SHAIMI | G271: NIVEL 1 | H271: PUESTO DE SALUD
A272: Z07 | B272: ZAMORA CHINCHIPE | C272: NANGARITZA | D272: 19D02 | E272: 001908 | F272: GERANIOS | G272: NIVEL 1 | H272: PUESTO DE SALUD
A273: Z07 | B273: ZAMORA CHINCHIPE | C273: NANGARITZA | D273: 19D02 | E273: 001909 | F273: ZURMI | G273: NIVEL 1 | H273: PUESTO DE SALUD
A274: Z07 | B274: ZAMORA CHINCHIPE | C274: NANGARITZA | D274: 19D02 | E274: 001925 | F274: SANTA ELENA | G274: NIVEL 1 | H274: PUESTO DE SALUD
A275: Z07 | B275: ZAMORA CHINCHIPE | C275: NANGARITZA | D275: 19D02 | E275: 001926 | F275: GUAYZIMI | G275: NIVEL 1 | H275: CENTRO DE SALUD TIPO A
A276: Z07 | B276: ZAMORA CHINCHIPE | C276: PALANDA | D276: 19D03 | E276: 001904 | F276: SAN FRANCISCO DEL VERGEL | G276: NIVEL 1 | H276: PUESTO DE SALUD | I276: 6 | J276: 1 | O276: 1 | R276: 8 | S276: 8 | U276: 8 | AF276: 8 | EY276: 3 | EZ276: 3 | FA276: 2
A277: Z07 | B277: ZAMORA CHINCHIPE | C277: PALANDA | D277: 19D03 | E277: 001937 | F277: EL PORVENIR DEL CARMEN | G277: NIVEL 1 | H277: PUESTO DE SALUD | I277: 4 | R277: 4 | S277: 4 | U277: 4 | AF277: 4 | EV277: 1 | EW277: 1 | EX277: 1 | FC277: 1
A278: Z07 | B278: ZAMORA CHINCHIPE | C278: PALANDA | D278: 19D03 | E278: 001944 | F278: PALANDA | G278: NIVEL 1 | H278: CENTRO DE SALUD TIPO B | I278: 32 | Q278: 16 | R278: 16 | S278: 32 | U278: 32 | AF278: 32 | EK278: 1 | EM278: 16 | ET278: 3 | EW278: 2 | EZ278: 5 | FA278: 1 | FD278: 4 | FE278: 3 | FF278: 1 | FG278: 1
A279: Z07 | B279: ZAMORA CHINCHIPE | C279: PALANDA | D279: 19D03 | E279: 001945 | F279: VALLADOLID | G279: NIVEL 1 | H279: CENTRO DE SALUD TIPO A | I279: 13 | Q279: 10 | R279: 3 | S279: 13 | U279: 13 | AF279: 13 | EM279: 5 | EP279: 1 | ER279: 1 | EZ279: 1 | FD279: 3 | FX279: 3
A280: Z07 | B280: ZAMORA CHINCHIPE | C280: PALANDA | D280: 19D03 | E280: 001946 | F280: LA CANELA | G280: NIVEL 1 | H280: PUESTO DE SALUD | I280: 3 | Q280: 2 | R280: 1 | S280: 3 | U280: 3 | AF280: 3 | EM280: 3
A281: Z07 | B281: ZAMORA CHINCHIPE | C281: PAQUISHA | D281: 19D02 | E281: 001899 | F281: PAQUISHA | G281: NIVEL 1 | H281: CENTRO DE SALUD TIPO B
A282: Z07 | B282: ZAMORA CHINCHIPE | C282: PAQUISHA | D282: 19D02 | E282: 001941 | F282: BELLAVISTA | G282: NIVEL 1 | H282: PUESTO DE SALUD
...

Sheet MARZO
A1: Zona | B1: provincia | C1: canton | D1: distrito | E1: unicodigo | F1: uni_nombre | G1: nivel | H1: tipo | I1: Establecimiento | J1: CNH | K1: CDI | L1: E. General Básica | M1: Bachillerato | N1: Atención Comunitaria | O1: Vistas Domiciliaras | P1: ext_OTROS | Q1: Hombre | R1: Mujer | S1: Pertenece_ES | T1: No_pertenece_ES | U1: Ecuatoriana | V1: Colombiana | W1: Peruana | X1: Cubana | Y1: Venezolana | Z1: Otras | AA1: Indigena | AB1: Afro ecuatoriano/ Afro descendiente | AC1: Negro/a | AD1: Mulato/a | AE1: Montubio/a | AF1: Mestizo/a | AG1: Blanco/a | AH1: Otro | AI1: Achuar | AJ1: Andoa | AK1: Awa | AL1: Chachi | AM1: Cofan | AN1: Epera | AO1: Huancavilca | AP1: Kichwa | AQ1: Manta | AR1: Secoya | AS1: Shiwiar | AT1: Shuar | AU1: Siona | AV1: Tsáchila | AW1: Waorani | AX1: Zapara | AY1: Chibuleo | AZ1: Kañari | BA1: Karanki | BB1: Kayambi | BC1: Kichwa Amazónico | BD1: Kisapincha | BE1: Kitukara | BF1: Natabuela | BG1: Otavalo | BH1: Paltas | BI1: Panzaleo | BJ1: Pastos | BK1: Puruha | BL1: Salasaka | BM1: Saraguro | BN1: Tomabela | BO1: Waramka | BP1: fIPV_1ano_1d | BQ1: HB_1ano_1d | BR1: DPT_1ano_1d | BS1: fIPV_1ano_2d | BT1: HB_1ano_2d | BU1: DPT_1ano_2d | BV1: bOPV_1ano_3d | BW1: HB_1ano_3d | BX1: DPT_1ano_3d | BY1: fIPV_2anos_1d | BZ1: SRP_2anos_1d | CA1: HB_2anos_1d | CB1: DPT_2anos_1d | CC1: fIPV_2anos_2d | CD1: SRP_2anos_2d | CE1: HB_2anos_2d | CF1: DPT_2anos_2d | CG1: bOPV_2anos_3d | CH1: HB_2anos_3d | CI1: DPT_2anos_3d | CJ1: bOPV_2anos_4d | CK1: DPT_2anos_4d | CL1: FA_2anos | CM1: fIPV_3anos_1d | CN1: SRP_3anos_1d | CO1: HB_3anos_1d | CP1: DPT_3anos_1d | CQ1: fIPV_3anos_2d | CR1: SRP_3anos_2d | CS1: HB_3anos_2d | CT1: DPT_3anos_2d | CU1: bOPV_3anos_3d | CV1: HB_3anos_3d | CW1: DPT_3anos_3d | CX1: bOPV_3anos_4d | CY1: DPT_3anos_4d | CZ1: FA_3anos | DA1: fIPV_4anos_1d | DB1: SRP_4anos_1d | DC1: HB_4anos_1d | DD1: DPT_4anos_1d | DE1: fIPV_4anos_2d | DF1: SRP_4anos_2d | DG1: HB_4anos_2d | DH1: DPT_4anos_2d | DI1: bOPV_4anos_3d | DJ1: HB_4anos_3d | DK1: DPT_4anos_3d | DL1: bOPV_4anos_4d | DM1: DPT_4anos_4d | DN1: FA_4anos | DO1: fIPV_5anos_1d | DP1: SRP_5anos_1d | DQ1: HB_5anos_1d | DR1: DPT_5anos_1d | DS1: fIPV_5anos_2d | DT1: SRP_5anos_2d | DU1: HB_5anos_2d | DV1: DPT_5anos_2d | DW1: bOPV_5anos_3d | DX1: HB_5anos_3d | DY1: DPT_5anos_3d | DZ1: bOPV_5anos_4d | EA1: DPT_5anos_4d | EB1: FA_5anos | EC1: SRP_6anos_1d | ED1: SRP_6anos_2d | EE1: FA_6anos | EF1: SR_7anos_1d | EG1: SR_7anos_2d | EH1: FA_7anos | EI1: FA_8anos | EJ1: dT adulto_7a14 años | EK1: FA_9a14 | EL1: FA_15a19 | EM1: FA_20a59 | EN1: SR_8a14_1d | EO1: SR_8a14_2d | EP1: SR_15a29_1d | EQ1: SR_15a29_2d | ER1: SR_30a50_1d | ES1: SR_30a50_2d | ET1: dTadulto_MEF_1D | EU1: dTadulto_MEF_2D | EV1: dTadulto_MEF_3D | EW1: dTadulto_MEF_4D | EX1: dTadulto_MEF_5D | EY1: dTadulto_EMB_1D | EZ1: dTadulto_EMB_2D | FA1: dTadulto_EMB_3D | FB1: dTadulto_EMB_4D | FC1: dTadulto_EMB_5D | FD1: dTadulto_HOMBRE_1D | FE1: dTadulto_HOMBRE_2D | FF1: dTadulto_HOMBRE_3D | FG1: dTadulto_HOMBRE_4D | FH1: dTadulto_HOMBRE_5D | FI1: HB_TSALUD_1D | FJ1: HB_TSALUD_2D | FK1: HB_TSALUD_3D | FL1: HB_ESTSALUD_1D | FM1: HB_ESTSALUD_2D | FN1: HB_ESTSALUD_3D | FO1: HB_TSEXUAL_1D | FP1: HB_TSEXUAL_2D | FQ1: HB_TSEXUAL_3D | FR1: HB_PVV_1D | FS1: HB_PVV_2D | FT1: HB_PVV_3D | FU1: HB_PPL_1D | FV1: HB_PPL_2D | FW1: HB_PPL_3D | FX1: HB_OGRUP_1D | FY1: HB_OGRUP_2D | FZ1: HB_OGRUP_3D | GA1: Inmunoglobulina_Antitetánica | GB1: Inmunoglobulina_Anti Hepatitis B | GC1: Inmunoglobulina_Antirrábica
A2: Z07 | B2: EL ORO | C2: ARENILLAS | D2: 07D05 | E2: 000541 | F2: SAN VICENTE | G2: NIVEL 1 | H2: CENTRO DE SALUD TIPO A
A3: Z07 | B3: EL ORO | C3: ARENILLAS | D3: 07D05 | E3: 000542 | F3: SAN ISIDRO URBANO | G3: NIVEL 1 | H3: CENTRO DE SALUD TIPO B
A4: Z07 | B4: EL ORO | C4: ARENILLAS | D4: 07D05 | E4: 000543 | F4: CAÑAS | G4: NIVEL 1 | H4: PUESTO DE SALUD
A5: Z07 | B5: EL ORO | C5: ARENILLAS | D5: 07D05 | E5: 000544 | F5: LA CUCA | G5: NIVEL 1 | H5: CENTRO DE SALUD TIPO A
A6: Z07 | B6: EL ORO | C6: ARENILLAS | D6: 07D05 | E6: 000545 | F6: CARCABON | G6: NIVEL 1 | H6: CENTRO DE SALUD TIPO A
A7: Z07 | B7: EL ORO | C7: ARENILLAS | D7: 07D05 | E7: 000546 | F7: CHACRAS | G7: NIVEL 1 | H7: CENTRO DE SALUD TIPO A
A8: Z07 | B8: EL ORO | C8: ARENILLAS | D8: 07D05 | E8: 000547 | F8: PALMALES | G8: NIVEL 1 | H8: CENTRO DE SALUD TIPO A
A9: Z07 | B9: EL ORO | C9: ARENILLAS | D9: 07D05 | E9: 000548 | F9: MANABI DE EL ORO | G9: NIVEL 1 | H9: PUESTO DE SALUD
A10: Z07 | B10: EL ORO | C10: ARENILLAS | D10: 07D05 | E10: 000591 | F10: HOSPITAL BASICO DE ARENILLAS | G10: NIVEL 2 | H10: HOSPITAL BASICO
A11: Z07 | B11: EL ORO | C11: ARENILLAS | D11: 07D05 | E11: 002763 | F11: EL JOBO SAN VICENTE | G11: NIVEL 1 | H11: PUESTO DE SALUD
A12: Z07 | B12: EL ORO | C12: ARENILLAS | D12: 07D05 | E12: 002900 | F12: CENTRO DE SALUD ARENILLAS | G12: NIVEL 1 | H12: CENTRO DE SALUD TIPO A
A13: Z07 | B13: EL ORO | C13: ATAHUALPA | D13: 07D03 | E13: 000576 | F13: AYAPAMBA | G13: NIVEL 1 | H13: CENTRO DE SALUD TIPO A
... A256: Z07 | B256: ZAMORA CHINCHIPE | C256: CENTINELA DEL CONDOR | D256: 19D02 | E256: 001900 | F256: ZUMBI | G256: NIVEL 1 | H256: CENTRO DE SALUD TIPO A
A257: Z07 | B257: ZAMORA CHINCHIPE | C257: CHINCHIPE | D257: 19D03 | E257: 001901 | F257: LA CHONTA | G257: NIVEL 1 | H257: CENTRO DE SALUD TIPO A | I257: 2 | N257: 1 | P257: 1 | Q257: 1 | R257: 3 | S257: 4 | U257: 4 | AF257: 4 | EU257: 3 | FD257: 1
A258: Z07 | B258: ZAMORA CHINCHIPE | C258: CHINCHIPE | D258: 19D03 | E258: 001902 | F258: EL CHORRO | G258: NIVEL 1 | H258: PUESTO DE SALUD
A259: Z07 | B259: ZAMORA CHINCHIPE | C259: CHINCHIPE | D259: 19D03 | E259: 001903 | F259: CHITO | G259: NIVEL 1 | H259: CENTRO DE SALUD TIPO A | I259: 12 | Q259: 1 | R259: 11 | S259: 12 | U259: 12 | AF259: 12 | EL259: 1 | EM259: 5 | EU259: 1 | EY259: 5 | EZ259: 1
A260: Z07 | B260: ZAMORA CHINCHIPE | C260: CHINCHIPE | D260: 19D03 | E260: 001921 | F260: LA GUAYUZA | G260: NIVEL 1 | H260: PUESTO DE SALUD | I260: 0 | N260: 5 | Q260: 5 | S260: 5 | U260: 5 | AF260: 5 | EM260: 2 | FD260: 3
A261: Z07 | B261: ZAMORA CHINCHIPE | C261: CHINCHIPE | D261: 19D03 | E261: 001922 | F261: LA DIVERSION | G261: NIVEL 1 | H261: CENTRO DE SALUD TIPO A
A262: Z07 | B262: ZAMORA CHINCHIPE | C262: CHINCHIPE | D262: 19D03 | E262: 001923 | F262: SAN ANDRES | G262: NIVEL 1 | H262: PUESTO DE SALUD | I262: 3 | R262: 3 | S262: 3 | U262: 3 | AF262: 3 | ET262: 2 | EX262: 1
A263: Z07 | B263: ZAMORA CHINCHIPE | C263: CHINCHIPE | D263: 19D03 | E263: 001949 | F263: HOSPITAL BASICO DE ZUMBA | G263: NIVEL 2 | H263: HOSPITAL BASICO
A264: Z07 | B264: ZAMORA CHINCHIPE | C264: CHINCHIPE | D264: 19D03 | E264: 002846 | F264: CENTRO DE SALUD DE ZUMBA | G264: NIVEL 1 | H264: CENTRO DE SALUD TIPO A | I264: 24 | Q264: 8 | R264: 16 | S264: 24 | U264: 24 | AF264: 24 | EL264: 2 | EM264: 10 | ET264: 3 | EU264: 2 | EV264: 1 | EW264: 1 | EY264: 3 | EZ264: 4 | FD264: 3 | FO264: 1 | FP264: 1 | FQ264: 1
A265: Z07 | B265: ZAMORA CHINCHIPE | C265: EL PANGUI | D265: 19D04 | E265: 001912 | F265: PACHICUTZA | G265: NIVEL 1 | H265: PUESTO DE SALUD
A266: Z07 | B266: ZAMORA CHINCHIPE | C266: EL PANGUI | D266: 19D04 | E266: 001913 | F266: EL PANGUI | G266: NIVEL 1 | H266: CENTRO DE SALUD TIPO B
A267: Z07 | B267: ZAMORA CHINCHIPE | C267: EL PANGUI | D267: 19D04 | E267: 001914 | F267: TUNDAYME | G267: NIVEL 1 | H267: PUESTO DE SALUD
A268: Z07 | B268: ZAMORA CHINCHIPE | C268: EL PANGUI | D268: 19D04 | E268: 001933 | F268: EL GUISMI | G268: NIVEL 1 | H268: PUESTO DE SALUD
A269: Z07 | B269: ZAMORA CHINCHIPE | C269: EL PANGUI | D269: 19D04 | E269: 001934 | F269: CHUCHUMBLETZA | G269: NIVEL 1 | H269: PUESTO DE SALUD
A270: Z07 | B270: ZAMORA CHINCHIPE | C270: NANGARITZA | D270: 19D02 | E270: 001906 | F270: NUEVO PARAISO | G270: NIVEL 1 | H270: PUESTO DE SALUD
A271: Z07 | B271: ZAMORA CHINCHIPE | C271: NANGARITZA | D271: 19D02 | E271: 001907 | F271: SHAIMI | G271: NIVEL 1 | H271: PUESTO DE SALUD
A272: Z07 | B272: ZAMORA CHINCHIPE | C272: NANGARITZA | D272: 19D02 | E272: 001908 | F272: GERANIOS | G272: NIVEL 1 | H272: PUESTO DE SALUD
A273: Z07 | B273: ZAMORA CHINCHIPE | C273: NANGARITZA | D273: 19D02 | E273: 001909 | F273: ZURMI | G273: NIVEL 1 | H273: PUESTO DE SALUD
A274: Z07 | B274: ZAMORA CHINCHIPE | C274: NANGARITZA | D274: 19D02 | E274: 001925 | F274: SANTA ELENA | G274: NIVEL 1 | H274: PUESTO DE SALUD
A275: Z07 | B275: ZAMORA CHINCHIPE | C275: NANGARITZA | D275: 19D02 | E275: 001926 | F275: GUAYZIMI | G275: NIVEL 1 | H275: CENTRO DE SALUD TIPO A
A276: Z07 | B276: ZAMORA CHINCHIPE | C276: PALANDA | D276: 19D03 | E276: 001904 | F276: SAN FRANCISCO DEL VERGEL | G276: NIVEL 1 | H276: PUESTO DE SALUD | I276: 7 | O276: 2 | Q276: 2 | R276: 7 | S276: 6 | T276: 3 | U276: 9 | AF276: 9 | EM276: 2 | EV276: 2 | EY276: 2 | EZ276: 2 | FA276: 1 | FD276: 2
A277: Z07 | B277: ZAMORA CHINCHIPE | C277: PALANDA | D277: 19D03 | E277: 001937 | F277: EL PORVENIR DEL CARMEN | G277: NIVEL 1 | H277: PUESTO DE SALUD | I277: 3 | O277: 1 | Q277: 1 | R277: 3 | S277: 4 | U277: 4 | AF277: 4 | ET277: 1 | EW277: 1 | EY277: 1 | FD277: 1
A278: Z07 | B278: ZAMORA CHINCHIPE | C278: PALANDA | D278: 19D03 | E278: 001944 | F278: PALANDA | G278: NIVEL 1 | H278: CENTRO DE SALUD TIPO B | I278: 33 | Q278: 18 | R278: 15 | S278: 33 | U278: 33 | AF278: 33 | CL278: 1 | EK278: 2 | EL278: 4 | EM278: 12 | ET278: 1 | EU278: 1 | EV278: 2 | EW278: 0 | EX278: 0 | EY278: 4 | EZ278: 2 | FA278: 0 | FB278: 0 | FC278: 0 | FD278: 4 | FE278: 2 | FF278: 1 | FG278: 0 | FH278: 0
A279: Z07 | B279: ZAMORA CHINCHIPE | C279: PALANDA | D279: 19D03 | E279: 001945 | F279: VALLADOLID | G279: NIVEL 1 | H279: CENTRO DE SALUD TIPO A | I279: 5 | Q279: 2 | R279: 3 | S279: 5 | U279: 5 | AF279: 5 | EV279: 1 | EY279: 1 | FD279: 1 | FF279: 1 | FK279: 3
A280: Z07 | B280: ZAMORA CHINCHIPE | C280: PALANDA | D280: 19D03 | E280: 001946 | F280: LA CANELA | G280: NIVEL 1 | H280: PUESTO DE SALUD | I280: 8 | Q280: 2 | R280: 6 | S280: 8 | U280: 8 | AF280: 8 | ET280: 1 | EU280: 2 | EY280: 4 | EZ280: 1
A281: Z07 | B281: ZAMORA CHINCHIPE | C281: PAQUISHA | D281: 19D02 | E281: 001899 | F281: PAQUISHA | G281: NIVEL 1 | H281: CENTRO DE SALUD TIPO B
A282: Z07 | B282: ZAMORA CHINCHIPE | C282: PAQUISHA | D282: 19D02 | E282: 001941 | F282: BELLAVISTA | G282: NIVEL 1 | H282: PUESTO DE SALUD
...

Sheet ABRIL
A1: Zona | B1: provincia | C1: canton | D1: distrito | E1: unicodigo | F1: uni_nombre | G1: nivel | H1: tipo | I1: Establecimiento | J1: CNH | K1: CDI | L1: E. General Básica | M1: Bachillerato | N1: Atención Comunitaria | O1: Vistas Domiciliaras | P1: ext_OTROS | Q1: Hombre | R1: Mujer | S1: Pertenece_ES | T1: No_pertenece_ES | U1: Ecuatoriana | V1: Colombiana | W1: Peruana | X1: Cubana | Y1: Venezolana | Z1: Otras | AA1: Indigena | AB1: Afro ecuatoriano/ Afro descendiente | AC1: Negro/a | AD1: Mulato/a | AE1: Montubio/a | AF1: Mestizo/a | AG1: Blanco/a | AH1: Otro | AI1: Achuar | AJ1: Andoa | AK1: Awa | AL1: Chachi | AM1: Cofan | AN1: Epera | AO1: Huancavilca | AP1: Kichwa | AQ1: Manta | AR1: Secoya | AS1: Shiwiar | AT1: Shuar | AU1: Siona | AV1: Tsáchila | AW1: Waorani | AX1: Zapara | AY1: Chibuleo | AZ1: Kañari | BA1: Karanki | BB1: Kayambi | BC1: Kichwa Amazónico | BD1: Kisapincha | BE1: Kitukara | BF1: Natabuela | BG1: Otavalo | BH1: Paltas | BI1: Panzaleo | BJ1: Pastos | BK1: Puruha | BL1: Salasaka | BM1: Saraguro | BN1: Tomabela | BO1: Waramka | BP1: fIPV_1ano_1d | BQ1: HB_1ano_1d | BR1: DPT_1ano_1d | BS1: fIPV_1ano_2d | BT1: HB_1ano_2d | BU1: DPT_1ano_2d | BV1: bOPV_1ano_3d | BW1: HB_1ano_3d | BX1: DPT_1ano_3d | BY1: fIPV_2anos_1d | BZ1: SRP_2anos_1d | CA1: HB_2anos_1d | CB1: DPT_2anos_1d | CC1: fIPV_2anos_2d | CD1: SRP_2anos_2d | CE1: HB_2anos_2d | CF1: DPT_2anos_2d | CG1: bOPV_2anos_3d | CH1: HB_2anos_3d | CI1: DPT_2anos_3d | CJ1: bOPV_2anos_4d | CK1: DPT_2anos_4d | CL1: FA_2anos | CM1: fIPV_3anos_1d | CN1: SRP_3anos_1d | CO1: HB_3anos_1d | CP1: DPT_3anos_1d | CQ1: fIPV_3anos_2d | CR1: SRP_3anos_2d | CS1: HB_3anos_2d | CT1: DPT_3anos_2d | CU1: bOPV_3anos_3d | CV1: HB_3anos_3d | CW1: DPT_3anos_3d | CX1: bOPV_3anos_4d | CY1: DPT_3anos_4d | CZ1: FA_3anos | DA1: fIPV_4anos_1d | DB1: SRP_4anos_1d | DC1: HB_4anos_1d | DD1: DPT_4anos_1d | DE1: fIPV_4anos_2d | DF1: SRP_4anos_2d | DG1: HB_4anos_2d | DH1: DPT_4anos_2d | DI1: bOPV_4anos_3d | DJ1: HB_4anos_3d | DK1: DPT_4anos_3d | DL1: bOPV_4anos_4d | DM1: DPT_4anos_4d | DN1: FA_4anos | DO1: fIPV_5anos_1d | DP1: SRP_5anos_1d | DQ1: HB_5anos_1d | DR1: DPT_5anos_1d | DS1: fIPV_5anos_2d | DT1: SRP_5anos_2d | DU1: HB_5anos_2d | DV1: DPT_5anos_2d | DW1: bOPV_5anos_3d | DX1: HB_5anos_3d | DY1: DPT_5anos_3d | DZ1: bOPV_5anos_4d | EA1: DPT_5anos_4d | EB1: FA_5anos | EC1: SRP_6anos_1d | ED1: SRP_6anos_2d | EE1: FA_6anos | EF1: SR_7anos_1d | EG1: SR_7anos_2d | EH1: FA_7anos | EI1: FA_8anos | EJ1: dT adulto_7a14 años | EK1: FA_9a14 | EL1: FA_15a19 | EM1: FA_20a59 | EN1: SR_8a14_1d | EO1: SR_8a14_2d | EP1: SR_15a29_1d | EQ1: SR_15a29_2d | ER1: SR_30a50_1d | ES1: SR_30a50_2d | ET1: dTadulto_MEF_1D | EU1: dTadulto_MEF_2D | EV1: dTadulto_MEF_3D | EW1: dTadulto_MEF_4D | EX1: dTadulto_MEF_5D | EY1: dTadulto_EMB_1D | EZ1: dTadulto_EMB_2D | FA1: dTadulto_EMB_3D | FB1: dTadulto_EMB_4D | FC1: dTadulto_EMB_5D | FD1: dTadulto_HOMBRE_1D | FE1: dTadulto_HOMBRE_2D | FF1: dTadulto_HOMBRE_3D | FG1: dTadulto_HOMBRE_4D | FH1: dTadulto_HOMBRE_5D | FI1: HB_TSALUD_1D | FJ1: HB_TSALUD_2D | FK1: HB_TSALUD_3D | FL1: HB_ESTSALUD_1D | FM1: HB_ESTSALUD_2D | FN1: HB_ESTSALUD_3D | FO1: HB_TSEXUAL_1D | FP1: HB_TSEXUAL_2D | FQ1: HB_TSEXUAL_3D | FR1: HB_PVV_1D | FS1: HB_PVV_2D | FT1: HB_PVV_3D | FU1: HB_PPL_1D | FV1: HB_PPL_2D | FW1: HB_PPL_3D | FX1: HB_OGRUP_1D | FY1: HB_OGRUP_2D | FZ1: HB_OGRUP_3D | GA1: Inmunoglobulina_Antitetánica | GB1: Inmunoglobulina_Anti Hepatitis B | GC1: Inmunoglobulina_Antirrábica
A2: Z07 | B2: EL ORO | C2: ARENILLAS | D2: 07D05 | E2: 000541 | F2: SAN VICENTE | G2: NIVEL 1 | H2: CENTRO DE SALUD TIPO A
A3: Z07 | B3: EL ORO | C3: ARENILLAS | D3: 07D05 | E3: 000542 | F3: SAN ISIDRO URBANO | G3: NIVEL 1 | H3: CENTRO DE SALUD TIPO B
A4: Z07 | B4: EL ORO | C4: ARENILLAS | D4: 07D05 | E4: 000543 | F4: CAÑAS | G4: NIVEL 1 | H4: PUESTO DE SALUD
A5: Z07 | B5: EL ORO | C5: ARENILLAS | D5: 07D05 | E5: 000544 | F5: LA CUCA | G5: NIVEL 1 | H5: CENTRO DE SALUD TIPO A
A6: Z07 | B6: EL ORO | C6: ARENILLAS | D6: 07D05 | E6: 000545 | F6: CARCABON | G6: NIVEL 1 | H6: CENTRO DE SALUD TIPO A
A7: Z07 | B7: EL ORO | C7: ARENILLAS | D7: 07D05 | E7: 000546 | F7: CHACRAS | G7: NIVEL 1 | H7: CENTRO DE SALUD TIPO A
A8: Z07 | B8: EL ORO | C8: ARENILLAS | D8: 07D05 | E8: 000547 | F8: PALMALES | G8: NIVEL 1 | H8: CENTRO DE SALUD TIPO A
A9: Z07 | B9: EL ORO | C9: ARENILLAS | D9: 07D05 | E9: 000548 | F9: MANABI DE EL ORO | G9: NIVEL 1 | H9: PUESTO DE SALUD
A10: Z07 | B10: EL ORO | C10: ARENILLAS | D10: 07D05 | E10: 000591 | F10: HOSPITAL BASICO DE ARENILLAS | G10: NIVEL 2 | H10: HOSPITAL BASICO
A11: Z07 | B11: EL ORO | C11: ARENILLAS | D11: 07D05 | E11: 002763 | F11: EL JOBO SAN VICENTE | G11: NIVEL 1 | H11: PUESTO DE SALUD
A12: Z07 | B12: EL ORO | C12: ARENILLAS | D12: 07D05 | E12: 002900 | F12: CENTRO DE SALUD ARENILLAS | G12: NIVEL 1 | H12: CENTRO DE SALUD TIPO A
A13: Z07 | B13: EL ORO | C13: ATAHUALPA | D13: 07D03 | E13: 000576 | F13: AYAPAMBA | G13: NIVEL 1 | H13: CENTRO DE SALUD TIPO A
... A256: Z07 | B256: ZAMORA CHINCHIPE | C256: CENTINELA DEL CONDOR | D256: 19D02 | E256: 001900 | F256: ZUMBI | G256: NIVEL 1 | H256: CENTRO DE SALUD TIPO A
A257: Z07 | B257: ZAMORA CHINCHIPE | C257: CHINCHIPE | D257: 19D03 | E257: 001901 | F257: LA CHONTA | G257: NIVEL 1 | H257: CENTRO DE SALUD TIPO A | I257: 2 | R257: 2 | S257: 2 | U257: 2 | AF257: 2 | ET257: 2
A258: Z07 | B258: ZAMORA CHINCHIPE | C258: CHINCHIPE | D258: 19D03 | E258: 001902 | F258: EL CHORRO | G258: NIVEL 1 | H258: PUESTO DE SALUD
A259: Z07 | B259: ZAMORA CHINCHIPE | C259: CHINCHIPE | D259: 19D03 | E259: 001903 | F259: CHITO | G259: NIVEL 1 | H259: CENTRO DE SALUD TIPO A | I259: 2 | N259: 1 | R259: 3 | S259: 3 | U259: 3 | AF259: 3 | EY259: 1 | EZ259: 2
A260: Z07 | B260: ZAMORA CHINCHIPE | C260: CHINCHIPE | D260: 19D03 | E260: 001921 | F260: LA GUAYUZA | G260: NIVEL 1 | H260: PUESTO DE SALUD
A261: Z07 | B261: ZAMORA CHINCHIPE | C261: CHINCHIPE | D261: 19D03 | E261: 001922 | F261: LA DIVERSION | G261: NIVEL 1 | H261: CENTRO DE SALUD TIPO A | I261: 2 | N261: 1 | R261: 3 | S261: 3 | U261: 3 | AF261: 3 | EL261: 1 | EW261: 1 | EY261: 1
A262: Z07 | B262: ZAMORA CHINCHIPE | C262: CHINCHIPE | D262: 19D03 | E262: 001923 | F262: SAN ANDRES | G262: NIVEL 1 | H262: PUESTO DE SALUD | I262: 12 | Q262: 4 | R262: 8 | S262: 12 | U262: 12 | AF262: 12 | EM262: 9 | ET262: 1 | EU262: 2 | EW262: 1 | FD262: 1
A263: Z07 | B263: ZAMORA CHINCHIPE | C263: CHINCHIPE | D263: 19D03 | E263: 001949 | F263: HOSPITAL BASICO DE ZUMBA | G263: NIVEL 2 | H263: HOSPITAL BASICO
A264: Z07 | B264: ZAMORA CHINCHIPE | C264: CHINCHIPE | D264: 19D03 | E264: 002846 | F264: CENTRO DE SALUD DE ZUMBA | G264: NIVEL 1 | H264: CENTRO DE SALUD TIPO A | I264: 52 | Q264: 10 | R264: 42 | S264: 52 | U264: 51 | Y264: 1 | AF264: 51 | AH264: 1 | EM264: 23 | ET264: 10 | EU264: 4 | EV264: 3 | EW264: 5 | EY264: 8 | EZ264: 4 | FB264: 2 | FD264: 5 | FG264: 3
A265: Z07 | B265: ZAMORA CHINCHIPE | C265: EL PANGUI | D265: 19D04 | E265: 001912 | F265: PACHICUTZA | G265: NIVEL 1 | H265: PUESTO DE SALUD
A266: Z07 | B266: ZAMORA CHINCHIPE | C266: EL PANGUI | D266: 19D04 | E266: 001913 | F266: EL PANGUI | G266: NIVEL 1 | H266: CENTRO DE SALUD TIPO B
A267: Z07 | B267: ZAMORA CHINCHIPE | C267: EL PANGUI | D267: 19D04 | E267: 001914 | F267: TUNDAYME | G267: NIVEL 1 | H267: PUESTO DE SALUD
A268: Z07 | B268: ZAMORA CHINCHIPE | C268: EL PANGUI | D268: 19D04 | E268: 001933 | F268: EL GUISMI | G268: NIVEL 1 | H268: PUESTO DE SALUD
A269: Z07 | B269: ZAMORA CHINCHIPE | C269: EL PANGUI | D269: 19D04 | E269: 001934 | F269: CHUCHUMBLETZA | G269: NIVEL 1 | H269: PUESTO DE SALUD
A270: Z07 | B270: ZAMORA CHINCHIPE | C270: NANGARITZA | D270: 19D02 | E270: 001906 | F270: NUEVO PARAISO | G270: NIVEL 1 | H270: PUESTO DE SALUD
A271: Z07 | B271: ZAMORA CHINCHIPE | C271: NANGARITZA | D271: 19D02 | E271: 001907 | F271: SHAIMI | G271: NIVEL 1 | H271: PUESTO DE SALUD
A272: Z07 | B272: ZAMORA CHINCHIPE | C272: NANGARITZA | D272: 19D02 | E272: 001908 | F272: GERANIOS | G272: NIVEL 1 | H272: PUESTO DE SALUD
A273: Z07 | B273: ZAMORA CHINCHIPE | C273: NANGARITZA | D273: 19D02 | E273: 001909 | F273: ZURMI | G273: NIVEL 1 | H273: PUESTO DE SALUD
A274: Z07 | B274: ZAMORA CHINCHIPE | C274: NANGARITZA | D274: 19D02 | E274: 001925 | F274: SANTA ELENA | G274: NIVEL 1 | H274: PUESTO DE SALUD
A275: Z07 | B275: ZAMORA CHINCHIPE | C275: NANGARITZA | D275: 19D02 | E275: 001926 | F275: GUAYZIMI | G275: NIVEL 1 | H275: CENTRO DE SALUD TIPO A
A276: Z07 | B276: ZAMORA CHINCHIPE | C276: PALANDA | D276: 19D03 | E276: 001904 | F276: SAN FRANCISCO DEL VERGEL | G276: NIVEL 1 | H276: PUESTO DE SALUD | I276: 5 | R276: 5 | S276: 2 | T276: 3 | U276: 5 | AF276: 5 | EV276: 1 | EY276: 3 | FA276: 1
A277: Z07 | B277: ZAMORA CHINCHIPE | C277: PALANDA | D277: 19D03 | E277: 001937 | F277: EL PORVENIR DEL CARMEN | G277: NIVEL 1 | H277: PUESTO DE SALUD | I277: 6 | Q277: 1 | R277: 5 | S277: 6 | U277: 6 | AF277: 6 | BZ277: 1 | EV277: 1 | EW277: 1 | EZ277: 2 | FG277: 1
A278: Z07 | B278: ZAMORA CHINCHIPE | C278: PALANDA | D278: 19D03 | E278: 001944 | F278: PALANDA | G278: NIVEL 1 | H278: CENTRO DE SALUD TIPO B | I278: 23 | Q278: 9 | R278: 14 | S278: 23 | U278: 23 | AF278: 23 | EK278: 1 | EM278: 9 | ET278: 1 | EV278: 3 | EY278: 5 | EZ278: 2 | FA278: 1 | FD278: 4 | FF278: 2
A279: Z07 | B279: ZAMORA CHINCHIPE | C279: PALANDA | D279: 19D03 | E279: 001945 | F279: VALLADOLID | G279: NIVEL 1 | H279: CENTRO DE SALUD TIPO A | I279: 3 | Q279: 1 | R279: 2 | S279: 3 | U279: 3 | AF279: 3 | EY279: 1 | EZ279: 1 | FD279: 1
A280: Z07 | B280: ZAMORA CHINCHIPE | C280: PALANDA | D280: 19D03 | E280: 001946 | F280: LA CANELA | G280: NIVEL 1 | H280: PUESTO DE SALUD | I280: 1 | R280: 1 | S280: 1 | U280: 1 | AF280: 1 | EU280: 1
A281: Z07 | B281: ZAMORA CHINCHIPE | C281: PAQUISHA | D281: 19D02 | E281: 001899 | F281: PAQUISHA | G281: NIVEL 1 | H281: CENTRO DE SALUD TIPO B
A282: Z07 | B282: ZAMORA CHINCHIPE | C282: PAQUISHA | D282: 19D02 | E282: 001941 | F282: BELLAVISTA | G282: NIVEL 1 | H282: PUESTO DE SALUD
...

Sheet MAYO
A1: Zona | B1: provincia | C1: canton | D1: distrito | E1: unicodigo | F1: uni_nombre | G1: nivel | H1: tipo | I1: Establecimiento | J1: CNH | K1: CDI | L1: E. General Básica | M1: Bachillerato | N1: Atención Comunitaria | O1: Vistas Domiciliaras | P1: ext_OTROS | Q1: Hombre | R1: Mujer | S1: Pertenece_ES | T1: No_pertenece_ES | U1: Ecuatoriana | V1: Colombiana | W1: Peruana | X1: Cubana | Y1: Venezolana | Z1: Otras | AA1: Indigena | AB1: Afro ecuatoriano/ Afro descendiente | AC1: Negro/a | AD1: Mulato/a | AE1: Montubio/a | AF1: Mestizo/a | AG1: Blanco/a | AH1: Otro | AI1: Achuar | AJ1: Andoa | AK1: Awa | AL1: Chachi | AM1: Cofan | AN1: Epera | AO1: Huancavilca | AP1: Kichwa | AQ1: Manta | AR1: Secoya | AS1: Shiwiar | AT1: Shuar | AU1: Siona | AV1: Tsáchila | AW1: Waorani | AX1: Zapara | AY1: Chibuleo | AZ1: Kañari | BA1: Karanki | BB1: Kayambi | BC1: Kichwa Amazónico | BD1: Kisapincha | BE1: Kitukara | BF1: Natabuela | BG1: Otavalo | BH1: Paltas | BI1: Panzaleo | BJ1: Pastos | BK1: Puruha | BL1: Salasaka | BM1: Saraguro | BN1: Tomabela | BO1: Waramka | BP1: fIPV_1ano_1d | BQ1: HB_1ano_1d | BR1: DPT_1ano_1d | BS1: fIPV_1ano_2d | BT1: HB_1ano_2d | BU1: DPT_1ano_2d | BV1: bOPV_1ano_3d | BW1: HB_1ano_3d | BX1: DPT_1ano_3d | BY1: fIPV_2anos_1d | BZ1: SRP_2anos_1d | CA1: HB_2anos_1d | CB1: DPT_2anos_1d | CC1: fIPV_2anos_2d | CD1: SRP_2anos_2d | CE1: HB_2anos_2d | CF1: DPT_2anos_2d | CG1: bOPV_2anos_3d | CH1: HB_2anos_3d | CI1: DPT_2anos_3d | CJ1: bOPV_2anos_4d | CK1: DPT_2anos_4d | CL1: FA_2anos | CM1: fIPV_3anos_1d | CN1: SRP_3anos_1d | CO1: HB_3anos_1d | CP1: DPT_3anos_1d | CQ1: fIPV_3anos_2d | CR1: SRP_3anos_2d | CS1: HB_3anos_2d | CT1: DPT_3anos_2d | CU1: bOPV_3anos_3d | CV1: HB_3anos_3d | CW1: DPT_3anos_3d | CX1: bOPV_3anos_4d | CY1: DPT_3anos_4d | CZ1: FA_3anos | DA1: fIPV_4anos_1d | DB1: SRP_4anos_1d | DC1: HB_4anos_1d | DD1: DPT_4anos_1d | DE1: fIPV_4anos_2d | DF1: SRP_4anos_2d | DG1: HB_4anos_2d | DH1: DPT_4anos_2d | DI1: bOPV_4anos_3d | DJ1: HB_4anos_3d | DK1: DPT_4anos_3d | DL1: bOPV_4anos_4d | DM1: DPT_4anos_4d | DN1: FA_4anos | DO1: fIPV_5anos_1d | DP1: SRP_5anos_1d | DQ1: HB_5anos_1d | DR1: DPT_5anos_1d | DS1: fIPV_5anos_2d | DT1: SRP_5anos_2d | DU1: HB_5anos_2d | DV1: DPT_5anos_2d | DW1: bOPV_5anos_3d | DX1: HB_5anos_3d | DY1: DPT_5anos_3d | DZ1: bOPV_5anos_4d | EA1: DPT_5anos_4d | EB1: FA_5anos | EC1: SRP_6anos_1d | ED1: SRP_6anos_2d | EE1: FA_6anos | EF1: SR_7anos_1d | EG1: SR_7anos_2d | EH1: FA_7anos | EI1: FA_8anos | EJ1: dT adulto_7a14 años | EK1: FA_9a14 | EL1: FA_15a19 | EM1: FA_20a59 | EN1: SR_8a14_1d | EO1: SR_8a14_2d | EP1: SR_15a29_1d | EQ1: SR_15a29_2d | ER1: SR_30a50_1d | ES1: SR_30a50_2d | ET1: dTadulto_MEF_1D | EU1: dTadulto_MEF_2D | EV1: dTadulto_MEF_3D | EW1: dTadulto_MEF_4D | EX1: dTadulto_MEF_5D | EY1: dTadulto_EMB_1D | EZ1: dTadulto_EMB_2D | FA1: dTadulto_EMB_3D | FB1: dTadulto_EMB_4D | FC1: dTadulto_EMB_5D | FD1: dTadulto_HOMBRE_1D | FE1: dTadulto_HOMBRE_2D | FF1: dTadulto_HOMBRE_3D | FG1: dTadulto_HOMBRE_4D | FH1: dTadulto_HOMBRE_5D | FI1: HB_TSALUD_1D | FJ1: HB_TSALUD_2D | FK1: HB_TSALUD_3D | FL1: HB_ESTSALUD_1D | FM1: HB_ESTSALUD_2D | FN1: HB_ESTSALUD_3D | FO1: HB_TSEXUAL_1D | FP1: HB_TSEXUAL_2D | FQ1: HB_TSEXUAL_3D | FR1: HB_PVV_1D | FS1: HB_PVV_2D | FT1: HB_PVV_3D | FU1: HB_PPL_1D | FV1: HB_PPL_2D | FW1: HB_PPL_3D | FX1: HB_OGRUP_1D | FY1: HB_OGRUP_2D | FZ1: HB_OGRUP_3D | GA1: Inmunoglobulina_Antitetánica | GB1: Inmunoglobulina_Anti Hepatitis B | GC1: Inmunoglobulina_Antirrábica
A2: Z07 | B2: EL ORO | C2: ARENILLAS | D2: 07D05 | E2: 000541 | F2: SAN VICENTE | G2: NIVEL 1 | H2: CENTRO DE SALUD TIPO A
A3: Z07 | B3: EL ORO | C3: ARENILLAS | D3: 07D05 | E3: 000542 | F3: SAN ISIDRO URBANO | G3: NIVEL 1 | H3: CENTRO DE SALUD TIPO B
A4: Z07 | B4: EL ORO | C4: ARENILLAS | D4: 07D05 | E4: 000543 | F4: CAÑAS | G4: NIVEL 1 | H4: PUESTO DE SALUD
A5: Z07 | B5: EL ORO | C5: ARENILLAS | D5: 07D05 | E5: 000544 | F5: LA CUCA | G5: NIVEL 1 | H5: CENTRO DE SALUD TIPO A
A6: Z07 | B6: EL ORO | C6: ARENILLAS | D6: 07D05 | E6: 000545 | F6: CARCABON | G6: NIVEL 1 | H6: CENTRO DE SALUD TIPO A
A7: Z07 | B7: EL ORO | C7: ARENILLAS | D7: 07D05 | E7: 000546 | F7: CHACRAS | G7: NIVEL 1 | H7: CENTRO DE SALUD TIPO A
A8: Z07 | B8: EL ORO | C8: ARENILLAS | D8: 07D05 | E8: 000547 | F8: PALMALES | G8: NIVEL 1 | H8: CENTRO DE SALUD TIPO A
A9: Z07 | B9: EL ORO | C9: ARENILLAS | D9: 07D05 | E9: 000548 | F9: MANABI DE EL ORO | G9: NIVEL 1 | H9: PUESTO DE SALUD
A10: Z07 | B10: EL ORO | C10: ARENILLAS | D10: 07D05 | E10: 000591 | F10: HOSPITAL BASICO DE ARENILLAS | G10: NIVEL 2 | H10: HOSPITAL BASICO
A11: Z07 | B11: EL ORO | C11: ARENILLAS | D11: 07D05 | E11: 002763 | F11: EL JOBO SAN VICENTE | G11: NIVEL 1 | H11: PUESTO DE SALUD
A12: Z07 | B12: EL ORO | C12: ARENILLAS | D12: 07D05 | E12: 002900 | F12: CENTRO DE SALUD ARENILLAS | G12: NIVEL 1 | H12: CENTRO DE SALUD TIPO A
A13: Z07 | B13: EL ORO | C13: ATAHUALPA | D13: 07D03 | E13: 000576 | F13: AYAPAMBA | G13: NIVEL 1 | H13: CENTRO DE SALUD TIPO A
... A258: Z07 | B258: ZAMORA CHINCHIPE | C258: CHINCHIPE | D258: 19D03 | E258: 001902 | F258: EL CHORRO | G258: NIVEL 1 | H258: PUESTO DE SALUD
A259: Z07 | B259: ZAMORA CHINCHIPE | C259: CHINCHIPE | D259: 19D03 | E259: 001903 | F259: CHITO | G259: NIVEL 1 | H259: CENTRO DE SALUD TIPO A | I259: 5 | O259: 3 | Q259: 2 | R259: 6 | S259: 8 | U259: 8 | AF259: 8 | EY259: 3 | EZ259: 3 | FD259: 2
A260: Z07 | B260: ZAMORA CHINCHIPE | C260: CHINCHIPE | D260: 19D03 | E260: 001921 | F260: LA GUAYUZA | G260: NIVEL 1 | H260: PUESTO DE SALUD
A261: Z07 | B261: ZAMORA CHINCHIPE | C261: CHINCHIPE | D261: 19D03 | E261: 001922 | F261: LA DIVERSION | G261: NIVEL 1 | H261: CENTRO DE SALUD TIPO A | I261: 1 | R261: 1 | S261: 1 | U261: 1 | AF261: 1 | EV261: 1
A262: Z07 | B262: ZAMORA CHINCHIPE | C262: CHINCHIPE | D262: 19D03 | E262: 001923 | F262: SAN ANDRES | G262: NIVEL 1 | H262: PUESTO DE SALUD | I262: 2 | Q262: 1 | R262: 1 | S262: 2 | U262: 2 | AF262: 2 | EZ262: 1 | FD262: 1
A263: Z07 | B263: ZAMORA CHINCHIPE | C263: CHINCHIPE | D263: 19D03 | E263: 001949 | F263: HOSPITAL BASICO DE ZUMBA | G263: NIVEL 2 | H263: HOSPITAL BASICO
A264: Z07 | B264: ZAMORA CHINCHIPE | C264: CHINCHIPE | D264: 19D03 | E264: 002846 | F264: CENTRO DE SALUD DE ZUMBA | G264: NIVEL 1 | H264: CENTRO DE SALUD TIPO A | I264: 35 | Q264: 4 | R264: 31 | S264: 35 | U264: 34 | V264: 1 | AF264: 34 | AH264: 1 | CB264: 1 | CD264: 1 | EL264: 2 | EM264: 12 | ET264: 8 | EU264: 3 | EV264: 1 | EX264: 1 | EY264: 6 | EZ264: 4 | FD264: 4 | FQ264: 1
A265: Z07 | B265: ZAMORA CHINCHIPE | C265: EL PANGUI | D265: 19D04 | E265: 001912 | F265: PACHICUTZA | G265: NIVEL 1 | H265: PUESTO DE SALUD
A266: Z07 | B266: ZAMORA CHINCHIPE | C266: EL PANGUI | D266: 19D04 | E266: 001913 | F266: EL PANGUI | G266: NIVEL 1 | H266: CENTRO DE SALUD TIPO B
A267: Z07 | B267: ZAMORA CHINCHIPE | C267: EL PANGUI | D267: 19D04 | E267: 001914 | F267: TUNDAYME | G267: NIVEL 1 | H267: PUESTO DE SALUD
A268: Z07 | B268: ZAMORA CHINCHIPE | C268: EL PANGUI | D268: 19D04 | E268: 001933 | F268: EL GUISMI | G268: NIVEL 1 | H268: PUESTO DE SALUD
A269: Z07 | B269: ZAMORA CHINCHIPE | C269: EL PANGUI | D269: 19D04 | E269: 001934 | F269: CHUCHUMBLETZA | G269: NIVEL 1 | H269: PUESTO DE SALUD
A270: Z07 | B270: ZAMORA CHINCHIPE | C270: NANGARITZA | D270: 19D02 | E270: 001906 | F270: NUEVO PARAISO | G270: NIVEL 1 | H270: PUESTO DE SALUD
A271: Z07 | B271: ZAMORA CHINCHIPE | C271: NANGARITZA | D271: 19D02 | E271: 001907 | F271: SHAIMI | G271: NIVEL 1 | H271: PUESTO DE SALUD
A272: Z07 | B272: ZAMORA CHINCHIPE | C272: NANGARITZA | D272: 19D02 | E272: 001908 | F272: GERANIOS | G272: NIVEL 1 | H272: PUESTO DE SALUD
A273: Z07 | B273: ZAMORA CHINCHIPE | C273: NANGARITZA | D273: 19D02 | E273: 001909 | F273: ZURMI | G273: NIVEL 1 | H273: PUESTO DE SALUD
A274: Z07 | B274: ZAMORA CHINCHIPE | C274: NANGARITZA | D274: 19D02 | E274: 001925 | F274: SANTA ELENA | G274: NIVEL 1 | H274: PUESTO DE SALUD
A275: Z07 | B275: ZAMORA CHINCHIPE | C275: NANGARITZA | D275: 19D02 | E275: 001926 | F275: GUAYZIMI | G275: NIVEL 1 | H275: CENTRO DE SALUD TIPO A
A276: Z07 | B276: ZAMORA CHINCHIPE | C276: PALANDA | D276: 19D03 | E276: 001904 | F276: SAN FRANCISCO DEL VERGEL | G276: NIVEL 1 | H276: PUESTO DE SALUD | I276: 7 | Q276: 1 | R276: 6 | S276: 4 | T276: 3 | U276: 7 | AF276: 7 | EV276: 1 | EY276: 3 | EZ276: 2 | FD276: 1
A277: Z07 | B277: ZAMORA CHINCHIPE | C277: PALANDA | D277: 19D03 | E277: 001937 | F277: EL PORVENIR DEL CARMEN | G277: NIVEL 1 | H277: PUESTO DE SALUD | I277: 8 | O277: 1 | Q277: 2 | R277: 7 | S277: 9 | U277: 9 | AF277: 9 | CD277: 1 | CI277: 2 | EM277: 1 | EV277: 1 | EW277: 1 | EZ277: 3 | FD277: 1
A278: Z07 | B278: ZAMORA CHINCHIPE | C278: PALANDA | D278: 19D03 | E278: 001944 | F278: PALANDA | G278: NIVEL 1 | H278: CENTRO DE SALUD TIPO B | I278: 31 | Q278: 7 | R278: 24 | S278: 31 | U278: 31 | AF278: 31 | EI278: 1 | EM278: 4 | EU278: 5 | EV278: 2 | EW278: 2 | EY278: 6 | EZ278: 7 | FA278: 1 | FD278: 4 | FE278: 1
A279: Z07 | B279: ZAMORA CHINCHIPE | C279: PALANDA | D279: 19D03 | E279: 001945 | F279: VALLADOLID | G279: NIVEL 1 | H279: CENTRO DE SALUD TIPO A | I279: 7 | Q279: 5 | R279: 2 | S279: 7 | U279: 7 | AF279: 7 | ET279: 1 | EX279: 1 | FD279: 1 | FE279: 1 | FG279: 1 | FY279: 2
A280: Z07 | B280: ZAMORA CHINCHIPE | C280: PALANDA | D280: 19D03 | E280: 001946 | F280: LA CANELA | G280: NIVEL 1 | H280: PUESTO DE SALUD | I280: 3 | Q280: 1 | R280: 2 | S280: 3 | U280: 3 | AF280: 3 | EX280: 1 | EZ280: 1 | FD280: 1
A281: Z07 | B281: ZAMORA CHINCHIPE | C281: PAQUISHA | D281: 19D02 | E281: 001899 | F281: PAQUISHA | G281: NIVEL 1 | H281: CENTRO DE SALUD TIPO B
A282: Z07 | B282: ZAMORA CHINCHIPE | C282: PAQUISHA | D282: 19D02 | E282: 001941 | F282: BELLAVISTA | G282: NIVEL 1 | H282: PUESTO DE SALUD
A283: Z07 | B283: ZAMORA CHINCHIPE | C283: PAQUISHA | D283: 19D02 | E283: 001942 | F283: CHINAPINTZA | G283: NIVEL 1 | H283: PUESTO DE SALUD
A284: Z07 | B284: ZAMORA CHINCHIPE | C284: PAQUISHA | D284: 19D02 | E284: 001943 | F284: CISAM | G284: NIVEL 1 | H284: PUESTO DE SALUD
...

Sheet JUNIO
A1: Zona | B1: provincia | C1: canton | D1: distrito | E1: unicodigo | F1: uni_nombre | G1: nivel | H1: tipo | I1: Establecimiento | J1: CNH | K1: CDI | L1: E. General Básica | M1: Bachillerato | N1: Atención Comunitaria | O1: Vistas Domiciliaras | P1: ext_OTROS | Q1: Hombre | R1: Mujer | S1: Pertenece_ES | T1: No_pertenece_ES | U1: Ecuatoriana | V1: Colombiana | W1: Peruana | X1: Cubana | Y1: Venezolana | Z1: Otras | AA1: Indigena | AB1: Afro ecuatoriano/ Afro descendiente | AC1: Negro/a | AD1: Mulato/a | AE1: Montubio/a | AF1: Mestizo/a | AG1: Blanco/a | AH1: Otro | AI1: Achuar | AJ1: Andoa | AK1: Awa | AL1: Chachi | AM1: Cofan | AN1: Epera | AO1: Huancavilca | AP1: Kichwa | AQ1: Manta | AR1: Secoya | AS1: Shiwiar | AT1: Shuar | AU1: Siona | AV1: Tsáchila | AW1: Waorani | AX1: Zapara | AY1: Chibuleo | AZ1: Kañari | BA1: Karanki | BB1: Kayambi | BC1: Kichwa Amazónico | BD1: Kisapincha | BE1: Kitukara | BF1: Natabuela | BG1: Otavalo | BH1: Paltas | BI1: Panzaleo | BJ1: Pastos | BK1: Puruha | BL1: Salasaka | BM1: Saraguro | BN1: Tomabela | BO1: Waramka | BP1: fIPV_1ano_1d | BQ1: HB_1ano_1d | BR1: DPT_1ano_1d | BS1: fIPV_1ano_2d | BT1: HB_1ano_2d | BU1: DPT_1ano_2d | BV1: bOPV_1ano_3d | BW1: HB_1ano_3d | BX1: DPT_1ano_3d | BY1: fIPV_2anos_1d | BZ1: SRP_2anos_1d | CA1: HB_2anos_1d | CB1: DPT_2anos_1d | CC1: fIPV_2anos_2d | CD1: SRP_2anos_2d | CE1: HB_2anos_2d | CF1: DPT_2anos_2d | CG1: bOPV_2anos_3d | CH1: HB_2anos_3d | CI1: DPT_2anos_3d | CJ1: bOPV_2anos_4d | CK1: DPT_2anos_4d | CL1: FA_2anos | CM1: fIPV_3anos_1d | CN1: SRP_3anos_1d | CO1: HB_3anos_1d | CP1: DPT_3anos_1d | CQ1: fIPV_3anos_2d | CR1: SRP_3anos_2d | CS1: HB_3anos_2d | CT1: DPT_3anos_2d | CU1: bOPV_3anos_3d | CV1: HB_3anos_3d | CW1: DPT_3anos_3d | CX1: bOPV_3anos_4d | CY1: DPT_3anos_4d | CZ1: FA_3anos | DA1: fIPV_4anos_1d | DB1: SRP_4anos_1d | DC1: HB_4anos_1d | DD1: DPT_4anos_1d | DE1: fIPV_4anos_2d | DF1: SRP_4anos_2d | DG1: HB_4anos_2d | DH1: DPT_4anos_2d | DI1: bOPV_4anos_3d | DJ1: HB_4anos_3d | DK1: DPT_4anos_3d | DL1: bOPV_4anos_4d | DM1: DPT_4anos_4d | DN1: FA_4anos | DO1: fIPV_5anos_1d | DP1: SRP_5anos_1d | DQ1: HB_5anos_1d | DR1: DPT_5anos_1d | DS1: fIPV_5anos_2d | DT1: SRP_5anos_2d | DU1: HB_5anos_2d | DV1: DPT_5anos_2d | DW1: bOPV_5anos_3d | DX1: HB_5anos_3d | DY1: DPT_5anos_3d | DZ1: bOPV_5anos_4d | EA1: DPT_5anos_4d | EB1: FA_5anos | EC1: SRP_6anos_1d | ED1: SRP_6anos_2d | EE1: FA_6anos | EF1: SR_7anos_1d | EG1: SR_7anos_2d | EH1: FA_7anos | EI1: FA_8anos | EJ1: dT adulto_7a14 años | EK1: FA_9a14 | EL1: FA_15a19 | EM1: FA_20a59 | EN1: SR_8a14_1d | EO1: SR_8a14_2d | EP1: SR_15a29_1d | EQ1: SR_15a29_2d | ER1: SR_30a50_1d | ES1: SR_30a50_2d | ET1: dTadulto_MEF_1D | EU1: dTadulto_MEF_2D | EV1: dTadulto_MEF_3D | EW1: dTadulto_MEF_4D | EX1: dTadulto_MEF_5D | EY1: dTadulto_EMB_1D | EZ1: dTadulto_EMB_2D | FA1: dTadulto_EMB_3D | FB1: dTadulto_EMB_4D | FC1: dTadulto_EMB_5D | FD1: dTadulto_HOMBRE_1D | FE1: dTadulto_HOMBRE_2D | FF1: dTadulto_HOMBRE_3D | FG1: dTadulto_HOMBRE_4D | FH1: dTadulto_HOMBRE_5D | FI1: HB_TSALUD_1D | FJ1: HB_TSALUD_2D | FK1: HB_TSALUD_3D | FL1: HB_ESTSALUD_1D | FM1: HB_ESTSALUD_2D | FN1: HB_ESTSALUD_3D | FO1: HB_TSEXUAL_1D | FP1: HB_TSEXUAL_2D | FQ1: HB_TSEXUAL_3D | FR1: HB_PVV_1D | FS1: HB_PVV_2D | FT1: HB_PVV_3D | FU1: HB_PPL_1D | FV1: HB_PPL_2D | FW1: HB_PPL_3D | FX1: HB_OGRUP_1D | FY1: HB_OGRUP_2D | FZ1: HB_OGRUP_3D | GA1: Inmunoglobulina_Antitetánica | GB1: Inmunoglobulina_Anti Hepatitis B | GC1: Inmunoglobulina_Antirrábica
A2: Z07 | B2: EL ORO | C2: ARENILLAS | D2: 07D05 | E2: 000541 | F2: SAN VICENTE | G2: NIVEL 1 | H2: CENTRO DE SALUD TIPO A
A3: Z07 | B3: EL ORO | C3: ARENILLAS | D3: 07D05 | E3: 000542 | F3: SAN ISIDRO URBANO | G3: NIVEL 1 | H3: CENTRO DE SALUD TIPO B
A4: Z07 | B4: EL ORO | C4: ARENILLAS | D4: 07D05 | E4: 000543 | F4: CAÑAS | G4: NIVEL 1 | H4: PUESTO DE SALUD
A5: Z07 | B5: EL ORO | C5: ARENILLAS | D5: 07D05 | E5: 000544 | F5: LA CUCA | G5: NIVEL 1 | H5: CENTRO DE SALUD TIPO A
A6: Z07 | B6: EL ORO | C6: ARENILLAS | D6: 07D05 | E6: 000545 | F6: CARCABON | G6: NIVEL 1 | H6: CENTRO DE SALUD TIPO A
A7: Z07 | B7: EL ORO | C7: ARENILLAS | D7: 07D05 | E7: 000546 | F7: CHACRAS | G7: NIVEL 1 | H7: CENTRO DE SALUD TIPO A
A8: Z07 | B8: EL ORO | C8: ARENILLAS | D8: 07D05 | E8: 000547 | F8: PALMALES | G8: NIVEL 1 | H8: CENTRO DE SALUD TIPO A
A9: Z07 | B9: EL ORO | C9: ARENILLAS | D9: 07D05 | E9: 000548 | F9: MANABI DE EL ORO | G9: NIVEL 1 | H9: PUESTO DE SALUD
A10: Z07 | B10: EL ORO | C10: ARENILLAS | D10: 07D05 | E10: 000591 | F10: HOSPITAL BASICO DE ARENILLAS | G10: NIVEL 2 | H10: HOSPITAL BASICO
A11: Z07 | B11: EL ORO | C11: ARENILLAS | D11: 07D05 | E11: 002763 | F11: EL JOBO SAN VICENTE | G11: NIVEL 1 | H11: PUESTO DE SALUD
A12: Z07 | B12: EL ORO | C12: ARENILLAS | D12: 07D05 | E12: 002900 | F12: CENTRO DE SALUD ARENILLAS | G12: NIVEL 1 | H12: CENTRO DE SALUD TIPO A
A13: Z07 | B13: EL ORO | C13: ATAHUALPA | D13: 07D03 | E13: 000576 | F13: AYAPAMBA | G13: NIVEL 1 | H13: CENTRO DE SALUD TIPO A
... A256: Z07 | B256: ZAMORA CHINCHIPE | C256: CENTINELA DEL CONDOR | D256: 19D02 | E256: 001900 | F256: ZUMBI | G256: NIVEL 1 | H256: CENTRO DE SALUD TIPO A
A257: Z07 | B257: ZAMORA CHINCHIPE | C257: CHINCHIPE | D257: 19D03 | E257: 001901 | F257: LA CHONTA | G257: NIVEL 1 | H257: CENTRO DE SALUD TIPO A | I257: 8 | Q257: 1 | R257: 7 | S257: 8 | U257: 8 | AF257: 8 | CJ257: 1 | CK257: 1 | EU257: 1 | EX257: 2 | EY257: 1 | FD257: 1 | FI257: 2
A258: Z07 | B258: ZAMORA CHINCHIPE | C258: CHINCHIPE | D258: 19D03 | E258: 001902 | F258: EL CHORRO | G258: NIVEL 1 | H258: PUESTO DE SALUD
A259: Z07 | B259: ZAMORA CHINCHIPE | C259: CHINCHIPE | D259: 19D03 | E259: 001903 | F259: CHITO | G259: NIVEL 1 | H259: CENTRO DE SALUD TIPO A | I259: 6 | R259: 6 | S259: 6 | U259: 5 | W259: 1 | AF259: 5 | AH259: 1 | EY259: 2 | EZ259: 4
A260: Z07 | B260: ZAMORA CHINCHIPE | C260: CHINCHIPE | D260: 19D03 | E260: 001921 | F260: LA GUAYUZA | G260: NIVEL 1 | H260: PUESTO DE SALUD | I260: 2 | N260: 0 | Q260: 1 | R260: 1 | S260: 2 | U260: 2 | AF260: 2 | ET260: 2 | EY260: 0
A261: Z07 | B261: ZAMORA CHINCHIPE | C261: CHINCHIPE | D261: 19D03 | E261: 001922 | F261: LA DIVERSION | G261: NIVEL 1 | H261: CENTRO DE SALUD TIPO A | I261: 2 | R261: 2 | S261: 2 | U261: 2 | AF261: 2 | EM261: 2 | ET261: 2 | FI261: 2
A262: Z07 | B262: ZAMORA CHINCHIPE | C262: CHINCHIPE | D262: 19D03 | E262: 001923 | F262: SAN ANDRES | G262: NIVEL 1 | H262: PUESTO DE SALUD | I262: 3 | Q262: 1 | R262: 2 | S262: 3 | U262: 3 | AF262: 3 | EM262: 3
A263: Z07 | B263: ZAMORA CHINCHIPE | C263: CHINCHIPE | D263: 19D03 | E263: 001949 | F263: HOSPITAL BASICO DE ZUMBA | G263: NIVEL 2 | H263: HOSPITAL BASICO
A264: Z07 | B264: ZAMORA CHINCHIPE | C264: CHINCHIPE | D264: 19D03 | E264: 002846 | F264: CENTRO DE SALUD DE ZUMBA | G264: NIVEL 1 | H264: CENTRO DE SALUD TIPO A | I264: 41 | Q264: 17 | R264: 24 | S264: 41 | U264: 39 | V264: 1 | Y264: 1 | AF264: 39 | AH264: 2 | EL264: 1 | EM264: 9 | EQ264: 10 | ET264: 3 | EU264: 1 | EV264: 4 | EY264: 5 | EZ264: 1 | FA264: 1 | FC264: 1 | FD264: 4 | FE264: 1 | FF264: 1 | FG264: 3 | FI264: 6 | FJ264: 3 | FK264: 2 | FN264: 1 | FO264: 1 | FP264: 1
A265: Z07 | B265: ZAMORA CHINCHIPE | C265: EL PANGUI | D265: 19D04 | E265: 001912 | F265: PACHICUTZA | G265: NIVEL 1 | H265: PUESTO DE SALUD
A266: Z07 | B266: ZAMORA CHINCHIPE | C266: EL PANGUI | D266: 19D04 | E266: 001913 | F266: EL PANGUI | G266: NIVEL 1 | H266: CENTRO DE SALUD TIPO B
A267: Z07 | B267: ZAMORA CHINCHIPE | C267: EL PANGUI | D267: 19D04 | E267: 001914 | F267: TUNDAYME | G267: NIVEL 1 | H267: PUESTO DE SALUD
A268: Z07 | B268: ZAMORA CHINCHIPE | C268: EL PANGUI | D268: 19D04 | E268: 001933 | F268: EL GUISMI | G268: NIVEL 1 | H268: PUESTO DE SALUD
A269: Z07 | B269: ZAMORA CHINCHIPE | C269: EL PANGUI | D269: 19D04 | E269: 001934 | F269: CHUCHUMBLETZA | G269: NIVEL 1 | H269: PUESTO DE SALUD
A270: Z07 | B270: ZAMORA CHINCHIPE | C270: NANGARITZA | D270: 19D02 | E270: 001906 | F270: NUEVO PARAISO | G270: NIVEL 1 | H270: PUESTO DE SALUD
A271: Z07 | B271: ZAMORA CHINCHIPE | C271: NANGARITZA | D271: 19D02 | E271: 001907 | F271: SHAIMI | G271: NIVEL 1 | H271: PUESTO DE SALUD
A272: Z07 | B272: ZAMORA CHINCHIPE | C272: NANGARITZA | D272: 19D02 | E272: 001908 | F272: GERANIOS | G272: NIVEL 1 | H272: PUESTO DE SALUD
A273: Z07 | B273: ZAMORA CHINCHIPE | C273: NANGARITZA | D273: 19D02 | E273: 001909 | F273: ZURMI | G273: NIVEL 1 | H273: PUESTO DE SALUD
A274: Z07 | B274: ZAMORA CHINCHIPE | C274: NANGARITZA | D274: 19D02 | E274: 001925 | F274: SANTA ELENA | G274: NIVEL 1 | H274: PUESTO DE SALUD
A275: Z07 | B275: ZAMORA CHINCHIPE | C275: NANGARITZA | D275: 19D02 | E275: 001926 | F275: GUAYZIMI | G275: NIVEL 1 | H275: CENTRO DE SALUD TIPO A
A276: Z07 | B276: ZAMORA CHINCHIPE | C276: PALANDA | D276: 19D03 | E276: 001904 | F276: SAN FRANCISCO DEL VERGEL | G276: NIVEL 1 | H276: PUESTO DE SALUD | I276: 4 | R276: 4 | S276: 4 | U276: 4 | AF276: 4 | EY276: 1 | EZ276: 2 | FA276: 1
A277: Z07 | B277: ZAMORA CHINCHIPE | C277: PALANDA | D277: 19D03 | E277: 001937 | F277: EL PORVENIR DEL CARMEN | G277: NIVEL 1 | H277: PUESTO DE SALUD | I277: 2 | R277: 2 | S277: 2 | U277: 2 | AF277: 2 | EU277: 1 | EY277: 1
