Workbook
Name __Anonymous_Sheet_DB__1: #REF!
Name __Anonymous_Sheet_DB__1: #REF!
Name __Anonymous_Sheet_DB__1: #REF!
Name __xlnm._FilterDatabase_1: #REF!
Name __xlnm._FilterDatabase_1: #REF!
Name __xlnm._FilterDatabase_1: #REF!

Sheet ENE2023
A1: MINISTERIO DEL TRABAJO
A2: DIRECCIÓN REGIONAL DE TRABAJO Y SERVICIO PÚBLICO DE LOJA
A3: SOLICITUDES DE CERTIFICACIÓN DE DOCUMENTOS
A5: NÚMERO | B5: No. DE EXTERNO | C5: FECHA DE INGRESO AL MDT | D5: FECHA DE INGRESO A LA DSG | E5: CANTIDAD DE FOJAS DESPACHADAS | F5: ESTADO | G5: FUNCIONARIO ACTUAL | H5: DIRECCIÓN O UNIDAD | I5: TECN. CETIFI RESPONSABLE | J5: FECHA RESOLUCIÓN | K5: FECHA DE NOTIFICACIÓN | L5: TIEMPO DE RESPUESTA HASTA LA NOTIFICACIÓN | M5: NUMERO DE OFICIO DE RESPUESTA | N5: CUIDAD A LA QUE SE DEBE ENVIAR LA RESPUESTA | O5: NOTIFICADO / O ENTREGADO A: | P5: NUMERO DE GUÍA O CÉDULA | Q5: CUMPLE EN EL PLAZO ESTABLECIDO | R5: FERIADO
A6: 1 | B6: MDT-DPTSPZCH-2023-0004-E | C6: 44930 | D6: 44930 | E6: 8 | F6: ATENDIDO | G6: Mayté Del Cisne Elizalde Vivanco | H6: DELEGACIÓN PROVINCIAL DE TRABAJO Y SERVICIO PÚBLICO DE ZAMORA CHINCHIPE | I6: Mayté Del Cisne Elizalde Vivanco | J6: 44935 | K6: 44935 | L6: =+NETWORKDAYS(D6,K6,$R$6:$R$9)-1 -> 3 | M6: MDT-DRTSPL-2023-0122-O | N6: LOJA | O6: Marjorie Elizabeth Zambrano Gordillo | P6: juridicogadprovincialzch@hotmail.com | Q6: =IF(L6>15,"FUERA DE TIEMPO","DENTRO DEL TIEMPO") -> DENTRO DEL TIEMPO
A7: 2 | B7: MDT-DPTSPZCH-2023-0053-E | C7: 44939 | D7: 44939 | E7: 4299 | F7: ATENDIDO | G7: Mayté Del Cisne Elizalde Vivanco | H7: DELEGACIÓN PROVINCIAL DE TRABAJO Y SERVICIO PÚBLICO DE ZAMORA CHINCHIPE | I7: Mayté Del Cisne Elizalde Vivanco | J7: 44951 | K7: 44951 | L7: =+NETWORKDAYS(D7,K7,$R$6:$R$9)-1 -> 8 | M7: MDT-DRTSPL-2023-0431-O | N7: LOJA | O7: Marjorie Elizabeth Zambrano Gordillo | P7: juridicogadprovincialzch@hotmail.com | Q7: =IF(L7>15,"FUERA DE TIEMPO","DENTRO DEL TIEMPO") -> DENTRO DEL TIEMPO
A8: 3 | B8: MDT-DRTSPL-2023-0003-E | C8: 44929 | D8: 44929 | E8: 2 | F8: ATENDIDO | G8: Yajaira Katherine Lozada Bravo | H8: DIRECCIÓN REGIONAL DEL TRABAJO Y SERVICIO PÚBLICO DE LOJA | I8: Yajaira Katherine Lozada Bravo | J8: 44930 | K8: 44930 | L8: =+NETWORKDAYS(D8,K8,$R$6:$R$9)-1 -> 1 | M8: MDT-DRTSPL-2023-0038-O | N8: LOJA | O8: Jaime Antonio Guzmán Regalado | P8: jaimeantonio07@hotmail.es | Q8: =IF(L8>15,"FUERA DE TIEMPO","DENTRO DEL TIEMPO") -> DENTRO DEL TIEMPO
A9: 4 | B9: MDT-DRTSPL-2023-0004-E | C9: 44929 | D9: 44929 | E9: 2 | F9: ATENDIDO | G9: Yajaira Katherine Lozada Bravo | H9: DIRECCIÓN REGIONAL DEL TRABAJO Y SERVICIO PÚBLICO DE LOJA | I9: Yajaira Katherine Lozada Bravo | J9: 44930 | K9: 44930 | L9: =+NETWORKDAYS(D9,K9,$R$6:$R$9)-1 -> 1 | M9: MDT-DRTSPL-2023-0039-O | N9: LOJA | O9: Jaime Antonio Guzmán Regalado | P9: jaimeantonio07@hotmail.es | Q9: =IF(L9>15,"FUERA DE TIEMPO","DENTRO DEL TIEMPO") -> DENTRO DEL TIEMPO
A10: 5 | B10: MDT-DRTSPL-2023-0005-E | C10: 44929 | D10: 44929 | E10: 2 | F10: ATENDIDO | G10: Yajaira Katherine Lozada Bravo | H10: DIRECCIÓN REGIONAL DEL TRABAJO Y SERVICIO PÚBLICO DE LOJA | I10: Yajaira Katherine Lozada Bravo | J10: 44930 | K10: 44930 | L10: =+NETWORKDAYS(D10,K10,$R$6:$R$9)-1 -> 1 | M10: MDT-DRTSPL-2023-0040-O | N10: LOJA | O10: Jaime Antonio Guzmán Regalado | P10: jaimeantonio07@hotmail.es | Q10: =IF(L10>15,"FUERA DE TIEMPO","DENTRO DEL TIEMPO") -> DENTRO DEL TIEMPO
A11: 6 | B11: MDT-DRTSPL-2023-0006-E | C11: 44929 | D11: 44929 | E11: 2 | F11: ATENDIDO | G11: Yajaira Katherine Lozada Bravo | H11: DIRECCIÓN REGIONAL DEL TRABAJO Y SERVICIO PÚBLICO DE LOJA | I11: Yajaira Katherine Lozada Bravo | J11: 44930 | K11: 44930 | L11: =+NETWORKDAYS(D11,K11,$R$6:$R$9)-1 -> 1 | M11: MDT-DRTSPL-2023-0042-O | N11: LOJA | O11: Alvaro Javier Jaramillo Gonzalez | P11: javierjaramillo2021@yahoo.com | Q11: =IF(L11>15,"FUERA DE TIEMPO","DENTRO DEL TIEMPO") -> DENTRO DEL TIEMPO
A12: 7 | B12: MDT-DRTSPL-2023-0010-E | C12: 44929 | D12: 44929 | E12: 2 | F12: ATENDIDO | G12: Yajaira Katherine Lozada Bravo | H12: DIRECCIÓN REGIONAL DEL TRABAJO Y SERVICIO PÚBLICO DE LOJA | I12: Yajaira Katherine Lozada Bravo | J12: 44930 | K12: 44930 | L12: =+NETWORKDAYS(D12,K12,$R$6:$R$9)-1 -> 1 | M12: MDT-DRTSPL-2023-0043-O | N12: LOJA | O12: Jhuliana Katherine Aguilar Gonzalez | P12: diegocm12396@gmail.com | Q12: =IF(L12>15,"FUERA DE TIEMPO","DENTRO DEL TIEMPO") -> DENTRO DEL TIEMPO
A13: 8 | B13: MDT-DRTSPL-2023-0011-E | C13: 44929 | D13: 44929 | E13: 2 | F13: ATENDIDO | G13: Yajaira Katherine Lozada Bravo | H13: DIRECCIÓN REGIONAL DEL TRABAJO Y SERVICIO PÚBLICO DE LOJA | I13: Yajaira Katherine Lozada Bravo | J13: 44931 | K13: 44931 | L13: =+NETWORKDAYS(D13,K13,$R$6:$R$9)-1 -> 2 | M13: MDT-DRTSPL-2023-0043-O | N13: LOJA | O13: Milenne Alejandra Cabrera Cueva | P13: milennecabrera@hotmail.com | Q13: =IF(L13>15,"FUERA DE TIEMPO","DENTRO DEL TIEMPO") -> DENTRO DEL TIEMPO
A14: 9 | B14: MDT-DRTSPL-2023-0014-E | C14: 44929 | D14: 44929 | E14: 2 | F14: ATENDIDO | G14: Yajaira Katherine Lozada Bravo | H14: DIRECCIÓN REGIONAL DEL TRABAJO Y SERVICIO PÚBLICO DE LOJA | I14: Yajaira Katherine Lozada Bravo | J14: 44931 | K14: 44931 | L14: =+NETWORKDAYS(D14,K14,$R$6:$R$9)-1 -> 2 | M14: MDT-DRTSPL-2023-0045-O | N14: LOJA | O14: María Teresa Alverca Jiménez | P14: marisuca_22@hotmail.com | Q14: =IF(L14>15,"FUERA DE TIEMPO","DENTRO DEL TIEMPO") -> DENTRO DEL TIEMPO
A15: 10 | B15: MDT-DRTSPL-2023-0019-E | C15: 44929 | D15: 44929 | E15: 2 | F15: ATENDIDO | G15: Yajaira Katherine Lozada Bravo | H15: DIRECCIÓN REGIONAL DEL TRABAJO Y SERVICIO PÚBLICO DE LOJA | I15: Yajaira Katherine Lozada Bravo | J15: 44932 | K15: 44932 | L15: =+NETWORKDAYS(D15,K15,$R$6:$R$9)-1 -> 3 | M15: MDT-DRTSPL-2023-0078-O | N15: LOJA | O15: Juan Carlos Benitez Poma | P15: lorepd910@gmail.com | Q15: =IF(L15>15,"FUERA DE TIEMPO","DENTRO DEL TIEMPO") -> DENTRO DEL TIEMPO
A16: 11 | B16: MDT-DRTSPL-2023-0021-E | C16: 44930 | D16: 44930 | E16: 2 | F16: ATENDIDO | G16: Yajaira Katherine Lozada Bravo | H16: DIRECCIÓN REGIONAL DEL TRABAJO Y SERVICIO PÚBLICO DE LOJA | I16: Yajaira Katherine Lozada Bravo | J16: 44931 | K16: 44931 | L16: =+NETWORKDAYS(D16,K16,$R$6:$R$9)-1 -> 1 | M16: MDT-DRTSPL-2023-0046-O | N16: LOJA | O16: Víctor Emilio Santín Salazar | P16: asalas_1971@hotmail.com | Q16: =IF(L16>15,"FUERA DE TIEMPO","DENTRO DEL TIEMPO") -> DENTRO DEL TIEMPO
A17: 12 | B17: MDT-DRTSPL-2023-0023-E | C17: 44930 | D17: 44930 | E17: 2 | F17: ATENDIDO | G17: Yajaira Katherine Lozada Bravo | H17: DIRECCIÓN REGIONAL DEL TRABAJO Y SERVICIO PÚBLICO DE LOJA | I17: Yajaira Katherine Lozada Bravo | J17: 44931 | K17: 44931 | L17: =+NETWORKDAYS(D17,K17,$R$6:$R$9)-1 -> 1 | M17: MDT-DRTSPL-2023-0047-O | N17: LOJA | O17: Jorge David Astudillo Ruiz | P17: consorciojuridicoastudillos@gmail.com | Q17: =IF(L17>15,"FUERA DE TIEMPO","DENTRO DEL TIEMPO") -> DENTRO DEL TIEMPO
... A146: 141 | B146: MDT-DRTSPL-2023-0331-E | C146: 44943 | D146: 44943 | E146: 2 | F146: ATENDIDO | G146: Yajaira Katherine Lozada Bravo | H146: DIRECCIÓN REGIONAL DEL TRABAJO Y SERVICIO PÚBLICO DE LOJA | I146: Yajaira Katherine Lozada Bravo | J146: 44945 | K146: 44945 | L146: =+NETWORKDAYS(D146,K146,$R$6:$R$9)-1 -> 2 | M146: MDT-DRTSPL-2023-0344-O | N146: LOJA | O146: Jorge Orlando Puchaicela Quizhpe | P146: jpuchaicelaq@hotmail.com | Q146: =IF(L146>15,"FUERA DE TIEMPO","DENTRO DEL TIEMPO") -> DENTRO DEL TIEMPO
A147: 142 | B147: MDT-DRTSPL-2023-0337-E | C147: 44943 | D147: 44943 | E147: 0 | F147: REASIGNADO | G147: Diego Alejandro Romero Guillén | H147: DIRECCIÓN DE RECURSOS Y SUMARIOS ADMINISTRATIVOS | I147: Diego Alejandro Romero Guillén | L147: =+NETWORKDAYS(D147,K147,$R$6:$R$9)-1 -> -32103 | N147: LOJA | O147: Manuel Ramiro Antuash Jimbicti | Q147: =IF(L147>15,"FUERA DE TIEMPO","DENTRO DEL TIEMPO") -> DENTRO DEL TIEMPO
A148: 143 | B148: MDT-DRTSPL-2023-0340-E | C148: 44943 | D148: 44943 | E148: 2 | F148: ATENDIDO | G148: Yajaira Katherine Lozada Bravo | H148: DIRECCIÓN REGIONAL DEL TRABAJO Y SERVICIO PÚBLICO DE LOJA | I148: Yajaira Katherine Lozada Bravo | J148: 44945 | K148: 44945 | L148: =+NETWORKDAYS(D148,K148,$R$6:$R$9)-1 -> 2 | M148: MDT-DRTSPL-2023-0345-O | N148: LOJA | O148: Victoria Anabel Chalaco Coronel | P148: vickopv94a@gmail.com | Q148: =IF(L148>15,"FUERA DE TIEMPO","DENTRO DEL TIEMPO") -> DENTRO DEL TIEMPO
A149: 144 | B149: MDT-DRTSPL-2023-0346-E | C149: 44943 | D149: 44943 | E149: 2 | F149: ATENDIDO | G149: Yajaira Katherine Lozada Bravo | H149: DIRECCIÓN REGIONAL DEL TRABAJO Y SERVICIO PÚBLICO DE LOJA | I149: Yajaira Katherine Lozada Bravo | J149: 44945 | K149: 44945 | L149: =+NETWORKDAYS(D149,K149,$R$6:$R$9)-1 -> 2 | M149: MDT-DRTSPL-2023-0346-O | N149: LOJA | O149: Luis Lautaro Moreno Arrobo | P149: mluislautaro@yahoo.com | Q149: =IF(L149>15,"FUERA DE TIEMPO","DENTRO DEL TIEMPO") -> DENTRO DEL TIEMPO
A150: 145 | B150: MDT-DRTSPL-2023-0349-E | C150: 44943 | D150: 44943 | E150: 2 | F150: ATENDIDO | G150: Yajaira Katherine Lozada Bravo | H150: DIRECCIÓN REGIONAL DEL TRABAJO Y SERVICIO PÚBLICO DE LOJA | I150: Yajaira Katherine Lozada Bravo | J150: 44945 | K150: 44945 | L150: =+NETWORKDAYS(D150,K150,$R$6:$R$9)-1 -> 2 | M150: MDT-DRTSPL-2023-0347-O | N150: LOJA | O150: Byron Fabian Amay Mora | P150: byronamay@gmail.com | Q150: =IF(L150>15,"FUERA DE TIEMPO","DENTRO DEL TIEMPO") -> DENTRO DEL TIEMPO
A151: 146 | B151: MDT-DRTSPL-2023-0350-E | C151: 44943 | D151: 44943 | E151: 2 | F151: ATENDIDO | G151: Yajaira Katherine Lozada Bravo | H151: DIRECCIÓN REGIONAL DEL TRABAJO Y SERVICIO PÚBLICO DE LOJA | I151: Yajaira Katherine Lozada Bravo | J151: 44945 | K151: 44945 | L151: =+NETWORKDAYS(D151,K151,$R$6:$R$9)-1 -> 2 | M151: MDT-DRTSPL-2023-0351-O | N151: LOJA | O151: Jose Sigifredo Valdez Ramirez | P151: eselisanchez@gmail.com | Q151: =IF(L151>15,"FUERA DE TIEMPO","DENTRO DEL TIEMPO") -> DENTRO DEL TIEMPO
A152: 147 | B152: MDT-DRTSPL-2023-0351-E | C152: 44943 | D152: 44943 | E152: 2 | F152: ATENDIDO | G152: Yajaira Katherine Lozada Bravo | H152: DIRECCIÓN REGIONAL DEL TRABAJO Y SERVICIO PÚBLICO DE LOJA | I152: Yajaira Katherine Lozada Bravo | J152: 44945 | K152: 44945 | L152: =+NETWORKDAYS(D152,K152,$R$6:$R$9)-1 -> 2 | M152: MDT-DRTSPL-2023-0352-O | N152: LOJA | O152: Carmen Isabel Sinche Morocho | P152: chavelitabelisima@gmail.com | Q152: =IF(L152>15,"FUERA DE TIEMPO","DENTRO DEL TIEMPO") -> DENTRO DEL TIEMPO
A153: 148 | B153: MDT-DRTSPL-2023-0353-E | C153: 44944 | D153: 44944 | E153: 2 | F153: ATENDIDO | G153: Yajaira Katherine Lozada Bravo | H153: DIRECCIÓN REGIONAL DEL TRABAJO Y SERVICIO PÚBLICO DE LOJA | I153: Yajaira Katherine Lozada Bravo | J153: 44945 | K153: 44945 | L153: =+NETWORKDAYS(D153,K153,$R$6:$R$9)-1 -> 1 | M153: MDT-DRTSPL-2023-0354-O | N153: LOJA | O153: Ivan Danilo Solano Jimenez | P153: ivandanilo85@gmail.com | Q153: =IF(L153>15,"FUERA DE TIEMPO","DENTRO DEL TIEMPO") -> DENTRO DEL TIEMPO
A154: 149 | B154: MDT-DRTSPL-2023-0354-E | C154: 44944 | D154: 44944 | E154: 2 | F154: ATENDIDO | G154: Yajaira Katherine Lozada Bravo | H154: DIRECCIÓN REGIONAL DEL TRABAJO Y SERVICIO PÚBLICO DE LOJA | I154: Yajaira Katherine Lozada Bravo | J154: 44945 | K154: 44945 | L154: =+NETWORKDAYS(D154,K154,$R$6:$R$9)-1 -> 1 | M154: MDT-DRTSPL-2023-0355-O | N154: LOJA | O154: Edgar Cristóbal Flores Criollo | P154: rosoto_82@hotmail.com | Q154: =IF(L154>15,"FUERA DE TIEMPO","DENTRO DEL TIEMPO") -> DENTRO DEL TIEMPO
A155: 150 | B155: MDT-DRTSPL-2023-0355-E | C155: 44944 | D155: 44944 | E155: 2 | F155: ATENDIDO | G155: Yajaira Katherine Lozada Bravo | H155: DIRECCIÓN REGIONAL DEL TRABAJO Y SERVICIO PÚBLICO DE LOJA | I155: Yajaira Katherine Lozada Bravo | J155: 44945 | K155: 44945 | L155: =+NETWORKDAYS(D155,K155,$R$6:$R$9)-1 -> 1 | M155: MDT-DRTSPL-2023-0356-O | N155: LOJA | O155: Edgar Cristóbal Flores Criollo | P155: rosoto_82@hotmail.com | Q155: =IF(L155>15,"FUERA DE TIEMPO","DENTRO DEL TIEMPO") -> DENTRO DEL TIEMPO
A156: 151 | B156: MDT-DRTSPL-2023-0356-E | C156: 44944 | D156: 44944 | E156: 2 | F156: ATENDIDO | G156: Yajaira Katherine Lozada Bravo | H156: DIRECCIÓN REGIONAL DEL TRABAJO Y SERVICIO PÚBLICO DE LOJA | I156: Yajaira Katherine Lozada Bravo | J156: 44945 | K156: 44945 | L156: =+NETWORKDAYS(D156,K156,$R$6:$R$9)-1 -> 1 | M156: MDT-DRTSPL-2023-0357-O | N156: LOJA | O156: Rodrigo Fernando :ayala Sanchez | P156: grupoempresarialayala@gmail.com | Q156: =IF(L156>15,"FUERA DE TIEMPO","DENTRO DEL TIEMPO") -> DENTRO DEL TIEMPO
A157: 152 | B157: MDT-DRTSPL-2023-0360-E | C157: 44944 | D157: 44944 | E157: 2 | F157: ATENDIDO | G157: Yajaira Katherine Lozada Bravo | H157: DIRECCIÓN REGIONAL DEL TRABAJO Y SERVICIO PÚBLICO DE LOJA | I157: Yajaira Katherine Lozada Bravo | J157: 44945 | K157: 44945 | L157: =+NETWORKDAYS(D157,K157,$R$6:$R$9)-1 -> 1 | M157: MDT-DRTSPL-2023-0358-O | N157: LOJA | O157: Diego Xavier Rodriguez Peñarreta | P157: diego.rodriguezasesorialegal@hotmail.com | Q157: =IF(L157>15,"FUERA DE TIEMPO","DENTRO DEL TIEMPO") -> DENTRO DEL TIEMPO
A158: 153 | B158: MDT-DRTSPL-2023-0369-E | C158: 44944 | D158: 44944 | E158: 2 | F158: ATENDIDO | G158: Yajaira Katherine Lozada Bravo | H158: DIRECCIÓN REGIONAL DEL TRABAJO Y SERVICIO PÚBLICO DE LOJA | I158: Yajaira Katherine Lozada Bravo | J158: 44944 | K158: 44944 | L158: =+NETWORKDAYS(D158,K158,$R$6:$R$9)-1 -> 0 | M158: MDT-DRTSPL-2023-0338-O | N158: LOJA | O158: Veronica Yesenia Solano Pineda | P158: veroyess2011@hotmail.com | Q158: =IF(L158>15,"FUERA DE TIEMPO","DENTRO DEL TIEMPO") -> DENTRO DEL TIEMPO
A159: 154 | B159: MDT-DRTSPL-2023-0382-E | C159: 44944 | D159: 44944 | E159: 2 | F159: ATENDIDO | G159: Yajaira Katherine Lozada Bravo | H159: DIRECCIÓN REGIONAL DEL TRABAJO Y SERVICIO PÚBLICO DE LOJA | I159: Yajaira Katherine Lozada Bravo | J159: 44945 | K159: 44945 | L159: =+NETWORKDAYS(D159,K159,$R$6:$R$9)-1 -> 1 | M159: MDT-DRTSPL-2023-0359-O | N159: LOJA | O159: Luis Patricio Jaramillo Reyes | P159: raficocuenca1982@hotmail.es | Q159: =IF(L159>15,"FUERA DE TIEMPO","DENTRO DEL TIEMPO") -> DENTRO DEL TIEMPO
... A332: 327 | B332: MDT-DPTSPOM-2022-7519-E | C332: 45280 | D332: 44931 | E332: 1 | F332: ATENDIDO | G332: GLADYS CARBALLO | H332: SECRETARIA GENERAL | I332: GLADYS CARBALLO | J332: 44944 | K332: 44944 | L332: =+NETWORKDAYS(D332,K332,$R$6:$R$9)-1 -> 9 | M332: MDT-DPTSPOM-2023-0050-O | N332: MACHALA | O332: USUARIO EXTERNO | P332: enviado quipux correo electronico | Q332: =IF(L332>15,"FUERA DE TIEMPO","DENTRO DEL TIEMPO") -> DENTRO DEL TIEMPO
A333: 328 | B333: MDT-DPTSPOM-2022-5556-EXTERNO | C333: 45240 | D333: 44931 | E333: =270+1 -> 271 | F333: ATENDIDO | G333: GLADYS CARBALLO | H333: SECRETARIA GENERAL | I333: GLADYS CARBALLO | J333: 44944 | K333: 44944 | L333: =+NETWORKDAYS(D333,K333,$R$6:$R$9)-1 -> 9 | M333: MDT-DPTSPOM-2023-0048-O | N333: MACHALA | O333: UNIDAD JUDICIAL | P333: enviado quipux -ventanilla virtual | Q333: =IF(L333>15,"FUERA DE TIEMPO","DENTRO DEL TIEMPO") -> DENTRO DEL TIEMPO
A334: 329 | B334: MDT-DPTSPOM-2022-7524-E | C334: 45280 | D334: 44931 | E334: 1 | F334: ATENDIDO | G334: GLADYS CARBALLO | H334: SECRETARIA GENERAL | I334: GLADYS CARBALLO | J334: 44944 | K334: 44944 | L334: =+NETWORKDAYS(D334,K334,$R$6:$R$9)-1 -> 9 | M334: MDT-DPTSPOM-2023-00051-O | N334: MACHALA | O334: UNIDAD JUDICIAL | P334: enviado quipux -ventanilla virtual | Q334: =IF(L334>15,"FUERA DE TIEMPO","DENTRO DEL TIEMPO") -> DENTRO DEL TIEMPO
A335: 330 | B335: MDT-DPTSPOM-2022-7522-E | C335: 45280 | D335: 44931 | E335: 1 | F335: ATENDIDO | G335: GLADYS CARBALLO | H335: SECRETARIA GENERAL | I335: GLADYS CARBALLO | J335: 44944 | K335: 44944 | L335: =+NETWORKDAYS(D335,K335,$R$6:$R$9)-1 -> 9 | M335: MDT-DPTSPOM-2022-0052-O | N335: MACHALA | O335: UNIDAD JUDICIAL | P335: enviado quipux -ventanilla virtual | Q335: =IF(L335>15,"FUERA DE TIEMPO","DENTRO DEL TIEMPO") -> DENTRO DEL TIEMPO
A336: 331 | B336: MDT-DPTSPOM-2023-0077-E | C336: 44931 | D336: 44931 | E336: 1 | F336: ATENDIDO | G336: GLADYS CARBALLO | H336: SECRETARIA GENERAL | I336: GLADYS CARBALLO | J336: 44938 | K336: 44938 | L336: =+NETWORKDAYS(D336,K336,$R$6:$R$9)-1 -> 5 | M336: MDT-DPTSPOM-2023-0032-O | O336: USUARIO EXTERNO | P336: enviado quipux correo electronico | Q336: =IF(L336>15,"FUERA DE TIEMPO","DENTRO DEL TIEMPO") -> DENTRO DEL TIEMPO
A337: 332 | B337: MDT-DPTSPOM-2023-0080-E | C337: 44931 | D337: 44931 | E337: 1 | F337: ATENDIDO | G337: GLADYS CARBALLO | H337: SECRETARIA GENERAL | I337: GLADYS CARBALLO | J337: 44936 | K337: 44936 | L337: =+NETWORKDAYS(D337,K337,$R$6:$R$9)-1 -> 3 | M337: MDT-DPTSPOM-2023-0029-O | N337: MACHALA | O337: UNIDAD JUDICIAL | P337: enviado quipux correo electronico | Q337: =IF(L337>15,"FUERA DE TIEMPO","DENTRO DEL TIEMPO") -> DENTRO DEL TIEMPO
A338: 333 | B338: PROVIDENCIA DE INSPECTOR | C338: 44932 | D338: 44932 | E338: 10 | F338: ATENDIDO | G338: GLADYS CARBALLO | H338: SECRETARIA GENERAL | I338: GLADYS CARBALLO | J338: 44932 | K338: 44932 | L338: =+NETWORKDAYS(D338,K338,$R$6:$R$9)-1 -> 0 | M338: MDT-DPTSPOM-2023-0015-O | N338: MACHALA | O338: USUARIO EXTERNO | P338: enviado quipux correo electronico | Q338: =IF(L338>15,"FUERA DE TIEMPO","DENTRO DEL TIEMPO") -> DENTRO DEL TIEMPO
A339: 334 | B339: PROVIDENCIA DE INSPECTOR | C339: 44932 | D339: 44932 | E339: 27 | F339: ATENDIDO | G339: GLADYS CARBALLO | H339: SECRETARIA GENERAL | I339: GLADYS CARBALLO | J339: 44932 | K339: 44932 | L339: =+NETWORKDAYS(D339,K339,$R$6:$R$9)-1 -> 0 | M339: MDT-DPTSPOM-2023-0016-O | N339: MACHALA | O339: USUARIO EXTERNO | P339: enviado quipux correo electronico | Q339: =IF(L339>15,"FUERA DE TIEMPO","DENTRO DEL TIEMPO") -> DENTRO DEL TIEMPO
A340: 335 | B340: MDT-DPTSPOM-2023-0104-E | C340: 44932 | D340: 44932 | E340: 1 | F340: ATENDIDO | G340: GLADYS CARBALLO | H340: SECRETARIA GENERAL | I340: GLADYS CARBALLO | J340: 44938 | K340: 44938 | L340: =+NETWORKDAYS(D340,K340,$R$6:$R$9)-1 -> 4 | M340: MDT-DPTSPOM-2023-0033-O | N340: MACHALA | O340: USUARIO EXTERNO | P340: enviado quipux correo electronico | Q340: =IF(L340>15,"FUERA DE TIEMPO","DENTRO DEL TIEMPO") -> DENTRO DEL TIEMPO
A341: 336 | B341: MDT-DPTSPOM-2023-0088-E | C341: 44931 | D341: 44935 | E341: 2 | F341: ATENDIDO | G341: GLADYS CARBALLO | H341: SECRETARIA GENERAL | I341: GLADYS CARBALLO | J341: 44949 | K341: 44949 | L341: =+NETWORKDAYS(D341,K341,$R$6:$R$9)-1 -> 10 | M341: MDT-DPTSPOM-2023-0053-O | N341: MACHALA | O341: USUARIO EXTERNO | P341: enviado quipux correo electronico | Q341: =IF(L341>15,"FUERA DE TIEMPO","DENTRO DEL TIEMPO") -> DENTRO DEL TIEMPO
...

Sheet FEB2023
A1: MINISTERIO DEL TRABAJO
A2: DIRECCIÓN REGIONAL DE TRABAJO Y SERVICIO PÚBLICO DE LOJA
A3: SOLICITUDES DE CERTIFICACIÓN DE DOCUMENTOS
A5: NÚMERO | B5: No. DE EXTERNO | C5: FECHA DE INGRESO AL MDT | D5: FECHA DE INGRESO A LA DSG | E5: CANTIDAD DE FOJAS DESPACHADAS | F5: ESTADO | G5: FUNCIONARIO ACTUAL | H5: DIRECCIÓN O UNIDAD | I5: TECN. CETIFI RESPONSABLE | J5: FECHA RESOLUCIÓN | K5: FECHA DE NOTIFICACIÓN | L5: TIEMPO DE RESPUESTA HASTA LA NOTIFICACIÓN | M5: NUMERO DE OFICIO DE RESPUESTA | N5: CUIDAD A LA QUE SE DEBE ENVIAR LA RESPUESTA | O5: NOTIFICADO / O ENTREGADO A: | P5: NUMERO DE GUÍA O CÉDULA | Q5: CUMPLE EN EL PLAZO ESTABLECIDO | R5: FERIADO
A6: 1 | B6: MDT-DPTSPOM-2023-0516-E | C6: 44956 | D6: 44964 | E6: 51 | F6: ATENDIDO | G6: GLADYS CARBALLO | H6: SECRETARIA GENERAL | I6: GLADYS CARBALLO | J6: 44974 | K6: 44974 | L6: =+NETWORKDAYS(D6,K6,$R$6:$R$9)-1 -> 8 | M6: MDT-DPTSPOM-2023-0120-O | N6: MACHALA | O6: UNIDAD JUDICIAL | P6: enviado quipux -ventanilla virtual | Q6: =IF(L6>15,"FUERA DE TIEMPO","DENTRO DEL TIEMPO") -> DENTRO DEL TIEMPO
A7: 2 | B7: MDT-DPTSPOM-2023-0517-E | C7: 44956 | D7: 44964 | E7: 51 | F7: ATENDIDO | G7: GLADYS CARBALLO | H7: SECRETARIA GENERAL | I7: GLADYS CARBALLO | J7: 44974 | K7: 44974 | L7: =+NETWORKDAYS(D7,K7,$R$6:$R$9)-1 -> 8 | M7: MDT-DPTSPOM-2023-0121-O | N7: MACHALA | O7: UNIDAD JUDICIAL | P7: enviado quipux -ventanilla virtual | Q7: =IF(L7>15,"FUERA DE TIEMPO","DENTRO DEL TIEMPO") -> DENTRO DEL TIEMPO
A8: 3 | B8: MDT-DPTSPOM-2023-0549-E | C8: 44958 | D8: 44964 | E8: 1 | F8: ATENDIDO | G8: GLADYS CARBALLO | H8: SECRETARIA GENERAL | I8: GLADYS CARBALLO | J8: 44964 | K8: 44964 | L8: =+NETWORKDAYS(D8,K8,$R$6:$R$9)-1 -> 0 | M8: MDT-DPTSPOM-2023-0087-O | N8: MACHALA | O8: USUARIO EXTERNO | P8: enviado quipux correo electronico | Q8: =IF(L8>15,"FUERA DE TIEMPO","DENTRO DEL TIEMPO") -> DENTRO DEL TIEMPO
A9: 4 | B9: MDT-DPTSPOM-2023-0551-E | C9: 44958 | D9: 44964 | E9: 75 | F9: ATENDIDO | G9: GLADYS CARBALLO | H9: SECRETARIA GENERAL | I9: GLADYS CARBALLO | J9: 44974 | K9: 44974 | L9: =+NETWORKDAYS(D9,K9,$R$6:$R$9)-1 -> 8 | M9: MDT-DPTSPOM-2023-0118-O | N9: MACHALA | O9: USUARIO EXTERNO | P9: enviado quipux correo electronico | Q9: =IF(L9>15,"FUERA DE TIEMPO","DENTRO DEL TIEMPO") -> DENTRO DEL TIEMPO
A10: 5 | B10: MDT-DPTSPOM-2023-0554-E | C10: 44958 | D10: 44958 | E10: 1 | F10: ATENDIDO | G10: GLADYS CARBALLO | H10: SECRETARIA GENERAL | I10: GLADYS CARBALLO | J10: 44964 | K10: 44964 | L10: =+NETWORKDAYS(D10,K10,$R$6:$R$9)-1 -> 4 | M10: MDT-DPTSPOM-2023-0088-O | N10: MACHALA | O10: UNIDAD JUDICIAL | P10: enviado quipux correo electronico | Q10: =IF(L10>15,"FUERA DE TIEMPO","DENTRO DEL TIEMPO") -> DENTRO DEL TIEMPO
A11: 6 | B11: MDT-DPTSPOM-2023-0555-E | C11: 44958 | D11: 44958 | E11: 1 | F11: ATENDIDO | G11: GLADYS CARBALLO | H11: SECRETARIA GENERAL | I11: GLADYS CARBALLO | J11: 44964 | K11: 44964 | L11: =+NETWORKDAYS(D11,K11,$R$6:$R$9)-1 -> 4 | M11: MDT-DPTSPOM-2023-0089-O | N11: MACHALA | O11: USUARIO EXTERNO | P11: enviado quipux correo electronico | Q11: =IF(L11>15,"FUERA DE TIEMPO","DENTRO DEL TIEMPO") -> DENTRO DEL TIEMPO
A12: 7 | B12: MDT-DPTSPOM-2023-0580-E | C12: 44959 | D12: 44959 | E12: 2 | F12: ATENDIDO | G12: GLADYS CARBALLO | H12: SECRETARIA GENERAL | I12: GLADYS CARBALLO | J12: 44959 | K12: 44959 | L12: =+NETWORKDAYS(D12,K12,$R$6:$R$9)-1 -> 0 | M12: MDT-DPTSPOM-2023-0083-O | N12: MACHALA | O12: USUARIO EXTERNO | P12: enviado quipux correo electronico | Q12: =IF(L12>15,"FUERA DE TIEMPO","DENTRO DEL TIEMPO") -> DENTRO DEL TIEMPO
A13: 8 | B13: MDT-DPTSPOM-2023-0610-E | C13: 44959 | D13: 44965 | E13: 42 | F13: ATENDIDO | G13: GLADYS CARBALLO | H13: SECRETARIA GENERAL | I13: GLADYS CARBALLO | J13: 44970 | K13: 44970 | L13: =+NETWORKDAYS(D13,K13,$R$6:$R$9)-1 -> 3 | M13: MDT-DPTSPOM-2023-0101-O | N13: MACHALA | O13: USUARIO EXTERNO | P13: enviado quipux correo electronico | Q13: =IF(L13>15,"FUERA DE TIEMPO","DENTRO DEL TIEMPO") -> DENTRO DEL TIEMPO
A14: 9 | B14: MDT-DPTSPOM-2023-0611-E | C14: 44960 | D14: 44960 | E14: 1 | F14: ATENDIDO | G14: GLADYS CARBALLO | H14: SECRETARIA GENERAL | I14: GLADYS CARBALLO | J14: 44964 | K14: 44964 | L14: =+NETWORKDAYS(D14,K14,$R$6:$R$9)-1 -> 2 | M14: MDT-DPTSPOM-2023-0090-O | N14: MACHALA | O14: USUARIO EXTERNO | P14: enviado quipux correo electronico | Q14: =IF(L14>15,"FUERA DE TIEMPO","DENTRO DEL TIEMPO") -> DENTRO DEL TIEMPO
A15: 10 | B15: MDT-DPTSPOM-2023-0615-E | C15: 44960 | D15: 44960 | E15: 8 | F15: ATENDIDO | G15: GLADYS CARBALLO | H15: SECRETARIA GENERAL | I15: GLADYS CARBALLO | J15: 44964 | K15: 44964 | L15: =+NETWORKDAYS(D15,K15,$R$6:$R$9)-1 -> 2 | M15: MDT-DPTSPOM-2023-0091-O | N15: MACHALA | O15: USUARIO EXTERNO | P15: enviado quipux correo electronico | Q15: =IF(L15>15,"FUERA DE TIEMPO","DENTRO DEL TIEMPO") -> DENTRO DEL TIEMPO
A16: 11 | B16: MDT-DPTSPOM-2023-0616-E | C16: 44960 | D16: 44960 | E16: 8 | F16: ATENDIDO | G16: GLADYS CARBALLO | H16: SECRETARIA GENERAL | I16: GLADYS CARBALLO | J16: 44966 | K16: 44966 | L16: =+NETWORKDAYS(D16,K16,$R$6:$R$9)-1 -> 4 | M16: MDT-DPTSPOM-2023-0095-O | N16: MACHALA | O16: USUARIO EXTERNO | P16: enviado quipux correo electronico | Q16: =IF(L16>15,"FUERA DE TIEMPO","DENTRO DEL TIEMPO") -> DENTRO DEL TIEMPO
A17: 12 | B17: MDT-DPTSPOM-2023-0637-E | C17: 44964 | D17: 44964 | E17: 1 | F17: ATENDIDO | G17: GLADYS CARBALLO | H17: SECRETARIA GENERAL | I17: GLADYS CARBALLO | J17: 44966 | K17: 44966 | L17: =+NETWORKDAYS(D17,K17,$R$6:$R$9)-1 -> 2 | M17: MDT-DPTSPOM-2023-0096-O | N17: MACHALA | O17: USUARIO EXTERNO | P17: enviado quipux correo electronico | Q17: =IF(L17>15,"FUERA DE TIEMPO","DENTRO DEL TIEMPO") -> DENTRO DEL TIEMPO
... A370: 365 | B370: MDT-DPTSPOP-2023-0037-E | C370: 44959 | D370: 44959 | E370: 2 | F370: ATENDIDO | G370: Andrea Karlina Aguilar Salazar | H370: DELEGACIÓN PROVINCIAL DE TRABAJO Y SERVICIO PÚBLICO DE EL ORO - PORTOVELO | I370: Andrea Karlina Aguilar Salazar | J370: 44971 | K370: 44971 | L370: =+NETWORKDAYS(D370,K370,$R$6:$R$9)-1 -> 8 | M370: MDT-DPTSPOP-2023-0007-O | N370: PORTOVELO | O370: Magdonio Gelacio Pisco Rabanal | P370: NOTIFICACION ELECTRÓNICA | Q370: =IF(L370>15,"FUERA DE TIEMPO","DENTRO DEL TIEMPO") -> DENTRO DEL TIEMPO

Sheet MAR2023
A1: MINISTERIO DEL TRABAJO
A2: DIRECCIÓN REGIONAL DE TRABAJO Y SERVICIO PÚBLICO DE LOJA
A3: SOLICITUDES DE CERTIFICACIÓN DE DOCUMENTOS
A5: NÚMERO | B5: No. DE EXTERNO | C5: FECHA DE INGRESO AL MDT | D5: FECHA DE INGRESO A LA DSG | E5: CANTIDAD DE FOJAS DESPACHADAS | F5: ESTADO | G5: FUNCIONARIO ACTUAL | H5: DIRECCIÓN O UNIDAD | I5: TECN. CETIFI RESPONSABLE | J5: FECHA RESOLUCIÓN | K5: FECHA DE NOTIFICACIÓN | L5: TIEMPO DE RESPUESTA HASTA LA NOTIFICACIÓN | M5: NUMERO DE OFICIO DE RESPUESTA | N5: CUIDAD A LA QUE SE DEBE ENVIAR LA RESPUESTA | O5: NOTIFICADO / O ENTREGADO A: | P5: NUMERO DE GUÍA O CÉDULA | Q5: CUMPLE EN EL PLAZO ESTABLECIDO | R5: FERIADO
A6: 1 | B6: MDT-DRTSPL-2023-0880-E | C6: 44964 | D6: 45009 | E6: 2 | F6: ATENDIDO | G6: Mónica de las Mercedes Torres Gutiérrez | H6: DIRECCIÓN DE CONTROL E INSPECCIONES | I6: Mónica de las Mercedes Torres Gutiérrez | J6: 45009 | K6: 45009 | L6: =+NETWORKDAYS(D6,K6,$R$6:$R$416)-1 -> 0 | M6: MDT-DCI-2023-0310-M / MDT-DRTSPL-2023-2076-O | N6: LOJA | O6: Cristian Jose Ogoño Banegas | P6: cristianogono@gmail.com | Q6: =IF(L6>15,"FUERA DE TIEMPO","DENTRO DEL TIEMPO") -> DENTRO DEL TIEMPO
A7: 2 | B7: MDT-DRTSPL-2023-1167-E | C7: 44974 | D7: 45012 | E7: 29 | F7: ATENDIDO | G7: Mayté Del Cisne Elizalde Vivanco | H7: DIRECCIÓN REGIONAL DEL TRABAJO Y SERVICIO PÚBLICO DE LOJA | I7: Mayté Del Cisne Elizalde Vivanco | J7: 45012 | K7: 45012 | L7: =+NETWORKDAYS(D7,K7,$R$6:$R$416)-1 -> 0 | M7: MDT-DSG-2023-0627-M / MDT-DRTSPL-2023-0546-M / MDT-DRTSPL-2023-0784-M | N7: LOJA | O7: Jorge Adolfo Jaramillo Ramón | P7: N/A | Q7: =IF(L7>15,"FUERA DE TIEMPO","DENTRO DEL TIEMPO") -> DENTRO DEL TIEMPO
A8: 3 | B8: MDT-DRTSPL-2023-1321-E | C8: 44984 | D8: 45014 | E8: 5 | F8: ATENDIDO | G8: Yajaira Katherine Lozada Bravo | H8: DIRECCIÓN REGIONAL DEL TRABAJO Y SERVICIO PÚBLICO DE LOJA | I8: Yajaira Katherine Lozada Bravo | J8: 45014 | K8: 45014 | L8: =+NETWORKDAYS(D8,K8,$R$6:$R$416)-1 -> 0 | M8: MDT-DRTSPL-2023-2094-O | N8: LOJA | O8: Miguel Angel Chiriboga Pichino | P8: ochoamonterofm@gmail.com | Q8: =IF(L8>15,"FUERA DE TIEMPO","DENTRO DEL TIEMPO") -> DENTRO DEL TIEMPO
A9: 4 | B9: MDT-DRTSPL-2023-1386-E | C9: 44986 | D9: 44986 | E9: 2 | F9: ATENDIDO | G9: Yajaira Katherine Lozada Bravo | H9: DIRECCIÓN REGIONAL DEL TRABAJO Y SERVICIO PÚBLICO DE LOJA | I9: Yajaira Katherine Lozada Bravo | J9: 44988 | K9: 44988 | L9: =+NETWORKDAYS(D9,K9,$R$6:$R$416)-1 -> 2 | M9: MDT-DRTSPL-2023-1248-O | N9: LOJA | O9: Boris Alejandro Zúñiga Mora | P9: maira_celi1983@outlook.es | Q9: =IF(L9>15,"FUERA DE TIEMPO","DENTRO DEL TIEMPO") -> DENTRO DEL TIEMPO
A10: 5 | B10: MDT-DRTSPL-2023-1393-E | C10: 44986 | D10: 44986 | E10: 2 | F10: ATENDIDO | G10: Mayté Del Cisne Elizalde Vivanco | H10: DIRECCIÓN REGIONAL DEL TRABAJO Y SERVICIO PÚBLICO DE LOJA | I10: Mayté Del Cisne Elizalde Vivanco | J10: 44987 | K10: 44987 | L10: =+NETWORKDAYS(D10,K10,$R$6:$R$416)-1 -> 1 | M10: MDT-DRTSPL-2023-1200-O | N10: LOJA | O10: Cesar Augusto Santin Nivelo | P10: cesarsamtin4@gmail.com | Q10: =IF(L10>15,"FUERA DE TIEMPO","DENTRO DEL TIEMPO") -> DENTRO DEL TIEMPO
A11: 6 | B11: MDT-DRTSPL-2023-1394-E | C11: 44986 | D11: 44986 | E11: 2 | F11: ATENDIDO | G11: Mayté Del Cisne Elizalde Vivanco | H11: DIRECCIÓN REGIONAL DEL TRABAJO Y SERVICIO PÚBLICO DE LOJA | I11: Mayté Del Cisne Elizalde Vivanco | J11: 44987 | K11: 44987 | L11: =+NETWORKDAYS(D11,K11,$R$6:$R$416)-1 -> 1 | M11: MDT-DRTSPL-2023-1201-O | N11: LOJA | O11: Junior Manuel Quezada Eras | P11: gabytapogo@yahoo.es | Q11: =IF(L11>15,"FUERA DE TIEMPO","DENTRO DEL TIEMPO") -> DENTRO DEL TIEMPO
A12: 7 | B12: MDT-DRTSPL-2023-1396-E | C12: 44986 | D12: 44986 | E12: 2 | F12: ATENDIDO | G12: Yajaira Katherine Lozada Bravo | H12: DIRECCIÓN REGIONAL DEL TRABAJO Y SERVICIO PÚBLICO DE LOJA | I12: Yajaira Katherine Lozada Bravo | J12: 44988 | K12: 44988 | L12: =+NETWORKDAYS(D12,K12,$R$6:$R$416)-1 -> 2 | M12: MDT-DRTSPL-2023-1249-O | N12: LOJA | O12: Fabian Alexander Castillo Maza | P12: alexcastillo@gmail.com | Q12: =IF(L12>15,"FUERA DE TIEMPO","DENTRO DEL TIEMPO") -> DENTRO DEL TIEMPO
A13: 8 | B13: MDT-DRTSPL-2023-1397-E | C13: 44986 | D13: 44986 | E13: 2 | F13: ATENDIDO | G13: Yajaira Katherine Lozada Bravo | H13: DIRECCIÓN REGIONAL DEL TRABAJO Y SERVICIO PÚBLICO DE LOJA | I13: Yajaira Katherine Lozada Bravo | J13: 44988 | K13: 44988 | L13: =+NETWORKDAYS(D13,K13,$R$6:$R$416)-1 -> 2 | M13: MDT-DRTSPL-2023-1250-O | N13: LOJA | O13: Wilson Jose Guallpa Pintado | P13: bladimirbetancourtgranillo@hotmail.com | Q13: =IF(L13>15,"FUERA DE TIEMPO","DENTRO DEL TIEMPO") -> DENTRO DEL TIEMPO
A14: 9 | B14: MDT-DRTSPL-2023-1399-E | C14: 44986 | D14: 44986 | E14: 2 | F14: ATENDIDO | G14: Yajaira Katherine Lozada Bravo | H14: DIRECCIÓN REGIONAL DEL TRABAJO Y SERVICIO PÚBLICO DE LOJA | I14: Yajaira Katherine Lozada Bravo | J14: 44991 | K14: 44991 | L14: =+NETWORKDAYS(D14,K14,$R$6:$R$416)-1 -> 3 | M14: MDT-DRTSPL-2023-1251-O | N14: LOJA | O14: Mariuxi Lisseth Lozano Montaño | P14: ricardo163@outlook.com | Q14: =IF(L14>15,"FUERA DE TIEMPO","DENTRO DEL TIEMPO") -> DENTRO DEL TIEMPO
A15: 10 | B15: MDT-DRTSPL-2023-1400-E | C15: 44986 | D15: 44986 | E15: 2 | F15: ATENDIDO | G15: Yajaira Katherine Lozada Bravo | H15: DIRECCIÓN REGIONAL DEL TRABAJO Y SERVICIO PÚBLICO DE LOJA | I15: Yajaira Katherine Lozada Bravo | J15: 44991 | K15: 44991 | L15: =+NETWORKDAYS(D15,K15,$R$6:$R$416)-1 -> 3 | M15: MDT-DRTSPL-2023-1252-O | N15: LOJA | O15: David Alberto Astudillo Celi | P15: dad_aven@hotmail.com | Q15: =IF(L15>15,"FUERA DE TIEMPO","DENTRO DEL TIEMPO") -> DENTRO DEL TIEMPO
A16: 11 | B16: MDT-DRTSPL-2023-1408-E | C16: 44986 | D16: 44986 | E16: 2 | F16: ATENDIDO | G16: Yajaira Katherine Lozada Bravo | H16: DIRECCIÓN REGIONAL DEL TRABAJO Y SERVICIO PÚBLICO DE LOJA | I16: Yajaira Katherine Lozada Bravo | J16: 44991 | K16: 44991 | L16: =+NETWORKDAYS(D16,K16,$R$6:$R$416)-1 -> 3 | M16: MDT-DRTSPL-2023-1253-O | N16: LOJA | O16: Dolores Maria Gordillo Velez | P16: carlosgp85@yahoo.es | Q16: =IF(L16>15,"FUERA DE TIEMPO","DENTRO DEL TIEMPO") -> DENTRO DEL TIEMPO
A17: 12 | B17: MDT-DRTSPL-2023-1409-E | C17: 44986 | D17: 44986 | E17: 2 | F17: ATENDIDO | G17: Yajaira Katherine Lozada Bravo | H17: DIRECCIÓN REGIONAL DEL TRABAJO Y SERVICIO PÚBLICO DE LOJA | I17: Yajaira Katherine Lozada Bravo | J17: 44991 | K17: 44991 | L17: =+NETWORKDAYS(D17,K17,$R$6:$R$416)-1 -> 3 | M17: MDT-DRTSPL-2023-1254-O | N17: LOJA | O17: Jhuliana Estefanía Rodríguez Padilla | P17: ejrodriguezduran@gmail.com | Q17: =IF(L17>15,"FUERA DE TIEMPO","DENTRO DEL TIEMPO") -> DENTRO DEL TIEMPO
... A263: 258 | B263: MDT-DRTSPL-2023-1948-E | C263: 45008 | D263: 45008 | E263: 0 | F263: ATENDIDO | G263: Yajaira Katherine Lozada Bravo | H263: DIRECCIÓN REGIONAL DEL TRABAJO Y SERVICIO PÚBLICO DE LOJA | I263: Yajaira Katherine Lozada Bravo | J263: 45009 | K263: 45009 | L263: =+NETWORKDAYS(D263,K263,$R$6:$R$416)-1 -> 1 | M263: MDT-DRTSPL-2023-1847-O | N263: LOJA | O263: Blanca Georgina Mendoza Guzman | P263: vjorgeluis623@gmail.com | Q263: =IF(L263>15,"FUERA DE TIEMPO","DENTRO DEL TIEMPO") -> DENTRO DEL TIEMPO
A264: 259 | B264: MDT-DRTSPL-2023-1957-E | C264: 45008 | D264: 45008 | E264: 0 | F264: REASIGNADO | G264: Ivette Natalie Garzon Andrango | H264: DIRECCIÓN DE PLANIFICACIÓN Y APOYO A LA GESTIÓN DEL TALENTO HUMANO | I264: Ivette Natalie Garzon Andrango | L264: =+NETWORKDAYS(D264,K264,$R$6:$R$416)-1 -> -32150 | N264: LOJA | O264: Gilber Franklin Ramon Samaniego | P264: N/A | Q264: =IF(L264>15,"FUERA DE TIEMPO","DENTRO DEL TIEMPO") -> DENTRO DEL TIEMPO
A265: 260 | B265: MDT-DRTSPL-2023-1958-E | C265: 45008 | D265: 45008 | E265: 2 | F265: ATENDIDO | G265: Yajaira Katherine Lozada Bravo | H265: DIRECCIÓN REGIONAL DEL TRABAJO Y SERVICIO PÚBLICO DE LOJA | I265: Yajaira Katherine Lozada Bravo | J265: 45009 | K265: 45009 | L265: =+NETWORKDAYS(D265,K265,$R$6:$R$416)-1 -> 1 | M265: MDT-DRTSPL-2023-1848-O | N265: LOJA | O265: Juan Rosalino Abad Santin | P265: N/A | Q265: =IF(L265>15,"FUERA DE TIEMPO","DENTRO DEL TIEMPO") -> DENTRO DEL TIEMPO
A266: 261 | B266: MDT-DRTSPL-2023-1959-E | C266: 45008 | D266: 45008 | E266: 2 | F266: ATENDIDO | G266: Yajaira Katherine Lozada Bravo | H266: DIRECCIÓN REGIONAL DEL TRABAJO Y SERVICIO PÚBLICO DE LOJA | I266: Yajaira Katherine Lozada Bravo | J266: 45009 | K266: 45009 | L266: =+NETWORKDAYS(D266,K266,$R$6:$R$416)-1 -> 1 | M266: MDT-DRTSPL-2023-1849-O | N266: LOJA | O266: María Verónica Medina Sotomayor | P266: maverlegal@gmail.com | Q266: =IF(L266>15,"FUERA DE TIEMPO","DENTRO DEL TIEMPO") -> DENTRO DEL TIEMPO
A267: 262 | B267: MDT-DRTSPL-2023-1961-E | C267: 45008 | D267: 45008 | E267: 0 | F267: REASIGNADO | G267: Wilmer Ricardo Vallejos Cazar | H267: DIRECCION REGIONAL DEL TRABAJO Y SERVICIO PÚBLICO DE QUITO | I267: Wilmer Ricardo Vallejos Cazar | L267: =+NETWORKDAYS(D267,K267,$R$6:$R$416)-1 -> -32150 | N267: LOJA | O267: Luis German Uyaguari Criollo | P267: N/A | Q267: =IF(L267>15,"FUERA DE TIEMPO","DENTRO DEL TIEMPO") -> DENTRO DEL TIEMPO
A268: 263 | B268: MDT-DRTSPL-2023-1964-E | C268: 45009 | D268: 45009 | E268: 2 | F268: ATENDIDO | G268: Yajaira Katherine Lozada Bravo | H268: DIRECCIÓN REGIONAL DEL TRABAJO Y SERVICIO PÚBLICO DE LOJA | I268: Yajaira Katherine Lozada Bravo | J268: 45009 | K268: 45009 | L268: =+NETWORKDAYS(D268,K268,$R$6:$R$416)-1 -> 0 | M268: MDT-DRTSPL-2023-1887-O | N268: LOJA | O268: Christian Andres Guaman Oliveros | P268: abg.christianguamanoliveros@gmail.com | Q268: =IF(L268>15,"FUERA DE TIEMPO","DENTRO DEL TIEMPO") -> DENTRO DEL TIEMPO
A269: 264 | B269: MDT-DRTSPL-2023-1966-E | C269: 45009 | D269: 45009 | E269: 2 | F269: ATENDIDO | G269: Yajaira Katherine Lozada Bravo | H269: DIRECCIÓN REGIONAL DEL TRABAJO Y SERVICIO PÚBLICO DE LOJA | I269: Yajaira Katherine Lozada Bravo | J269: 45009 | K269: 45009 | L269: =+NETWORKDAYS(D269,K269,$R$6:$R$416)-1 -> 0 | M269: MDT-DRTSPL-2023-1888-O | N269: LOJA | O269: Israel Enrique Espinoza Aguirre | P269: conjuriaguirreasociados@gmail.com | Q269: =IF(L269>15,"FUERA DE TIEMPO","DENTRO DEL TIEMPO") -> DENTRO DEL TIEMPO
A270: 265 | B270: MDT-DRTSPL-2023-1968-E | C270: 45009 | D270: 45009 | E270: 2 | F270: ATENDIDO | G270: Yajaira Katherine Lozada Bravo | H270: DIRECCIÓN REGIONAL DEL TRABAJO Y SERVICIO PÚBLICO DE LOJA | I270: Yajaira Katherine Lozada Bravo | J270: 45009 | K270: 45009 | L270: =+NETWORKDAYS(D270,K270,$R$6:$R$416)-1 -> 0 | M270: MDT-DRTSPL-2023-1890-O | N270: LOJA | O270: Diego Gustavo Quezada Quezada | P270: secretaria@cacpeLoja.fin.ec | Q270: =IF(L270>15,"FUERA DE TIEMPO","DENTRO DEL TIEMPO") -> DENTRO DEL TIEMPO
A271: 266 | B271: MDT-DRTSPL-2023-1969-E | C271: 45009 | D271: 45009 | E271: 2 | F271: ATENDIDO | G271: Yajaira Katherine Lozada Bravo | H271: DIRECCIÓN REGIONAL DEL TRABAJO Y SERVICIO PÚBLICO DE LOJA | I271: Yajaira Katherine Lozada Bravo | J271: 45009 | K271: 45009 | L271: =+NETWORKDAYS(D271,K271,$R$6:$R$416)-1 -> 0 | M271: MDT-DRTSPL-2023-1891-O | N271: LOJA | O271: Diego Gustavo Quezada Quezada | P271: secretaria@cacpeLoja.fin.ec | Q271: =IF(L271>15,"FUERA DE TIEMPO","DENTRO DEL TIEMPO") -> DENTRO DEL TIEMPO
A272: 267 | B272: MDT-DRTSPL-2023-1970-E | C272: 45009 | D272: 45009 | E272: 2 | F272: ATENDIDO | G272: Yajaira Katherine Lozada Bravo | H272: DIRECCIÓN REGIONAL DEL TRABAJO Y SERVICIO PÚBLICO DE LOJA | I272: Yajaira Katherine Lozada Bravo | J272: 45012 | K272: 45012 | L272: =+NETWORKDAYS(D272,K272,$R$6:$R$416)-1 -> 1 | M272: MDT-DRTSPL-2023-1894-O | N272: LOJA | O272: Diego Gustavo Quezada Quezada | P272: secretaria@cacpeLoja.fin.ec | Q272: =IF(L272>15,"FUERA DE TIEMPO","DENTRO DEL TIEMPO") -> DENTRO DEL TIEMPO
A273: 268 | B273: MDT-DRTSPL-2023-1971-E | C273: 45009 | D273: 45009 | E273: 2 | F273: ATENDIDO | G273: Yajaira Katherine Lozada Bravo | H273: DIRECCIÓN REGIONAL DEL TRABAJO Y SERVICIO PÚBLICO DE LOJA | I273: Yajaira Katherine Lozada Bravo | J273: 45012 | K273: 45012 | L273: =+NETWORKDAYS(D273,K273,$R$6:$R$416)-1 -> 1 | M273: MDT-DRTSPL-2023-1895-O | N273: LOJA | O273: Diego Gustavo Quezada Quezada | P273: secretaria@cacpeLoja.fin.ec | Q273: =IF(L273>15,"FUERA DE TIEMPO","DENTRO DEL TIEMPO") -> DENTRO DEL TIEMPO
A274: 269 | B274: MDT-DRTSPL-2023-1974-E | C274: 45009 | D274: 45009 | E274: 2 | F274: ATENDIDO | G274: Yajaira Katherine Lozada Bravo | H274: DIRECCIÓN REGIONAL DEL TRABAJO Y SERVICIO PÚBLICO DE LOJA | I274: Yajaira Katherine Lozada Bravo | J274: 45012 | K274: 45012 | L274: =+NETWORKDAYS(D274,K274,$R$6:$R$416)-1 -> 1 | M274: MDT-DRTSPL-2023-1917-O | N274: LOJA | O274: Mercy Yaqueline Obando Calderon | P274: diegopppprodriguez@hotmail.com | Q274: =IF(L274>15,"FUERA DE TIEMPO","DENTRO DEL TIEMPO") -> DENTRO DEL TIEMPO
A275: 270 | B275: MDT-DRTSPL-2023-1977-E | C275: 45009 | D275: 45009 | E275: 2 | F275: ATENDIDO | G275: Yajaira Katherine Lozada Bravo | H275: DIRECCIÓN REGIONAL DEL TRABAJO Y SERVICIO PÚBLICO DE LOJA | I275: Yajaira Katherine Lozada Bravo | J275: 45012 | K275: 45012 | L275: =+NETWORKDAYS(D275,K275,$R$6:$R$416)-1 -> 1 | M275: MDT-DRTSPL-2023-1920-O | N275: LOJA | O275: Luis Patricio Jaramillo Reyes | P275: bladimirbetancourtgranillo@hotmail.com | Q275: =IF(L275>15,"FUERA DE TIEMPO","DENTRO DEL TIEMPO") -> DENTRO DEL TIEMPO
A276: 271 | B276: MDT-DRTSPL-2023-1980-E | C276: 45009 | D276: 45009 | E276: 2 | F276: ATENDIDO | G276: Mayté Del Cisne Elizalde Vivanco | H276: DIRECCIÓN REGIONAL DEL TRABAJO Y SERVICIO PÚBLICO DE LOJA | I276: Mayté Del Cisne Elizalde Vivanco | J276: 45009 | K276: 45009 | L276: =+NETWORKDAYS(D276,K276,$R$6:$R$416)-1 -> 0 | M276: MDT-DRTSPL-2023-1892-O | N276: LOJA | O276: Julio Cesar Sarmiento Espinoza | P276: julio.sarmiento85@hotmail.com | Q276: =IF(L276>15,"FUERA DE TIEMPO","DENTRO DEL TIEMPO") -> DENTRO DEL TIEMPO
A277: 272 | B277: MDT-DRTSPL-2023-1981-E | C277: 45009 | D277: 45009 | E277: 2 | F277: ATENDIDO | G277: Mayté Del Cisne Elizalde Vivanco | H277: DIRECCIÓN REGIONAL DEL TRABAJO Y SERVICIO PÚBLICO DE LOJA | I277: Mayté Del Cisne Elizalde Vivanco | J277: 45009 | K277: 45009 | L277: =+NETWORKDAYS(D277,K277,$R$6:$R$416)-1 -> 0 | M277: MDT-DRTSPL-2023-1893-O | N277: LOJA | O277: Diana Maricela Cabrera Davila | P277: maricelacabrera688@gmail.com | Q277: =IF(L277>15,"FUERA DE TIEMPO","DENTRO DEL TIEMPO") -> DENTRO DEL TIEMPO
A278: 273 | B278: MDT-DRTSPL-2023-1988-E | C278: 45009 | D278: 45009 | E278: 50 | F278: ATENDIDO | G278: Mayté Del Cisne Elizalde Vivanco | H278: DIRECCIÓN REGIONAL DEL TRABAJO Y SERVICIO PÚBLICO DE LOJA | I278: Mayté Del Cisne Elizalde Vivanco | J278: 45013 | K278: 45013 | L278: =+NETWORKDAYS(D278,K278,$R$6:$R$416)-1 -> 2 | M278: MDT-DRTSPL-2023-2068-O | N278: LOJA | O278: Víctor Manuel Guzmán Sarango | P278: vguzmnsarango@yahoo.com | Q278: =IF(L278>15,"FUERA DE TIEMPO","DENTRO DEL TIEMPO") -> DENTRO DEL TIEMPO
A279: 274 | B279: MDT-DRTSPL-2023-1990-E | C279: 45009 | D279: 45009 | E279: 2 | F279: ATENDIDO | G279: Yajaira Katherine Lozada Bravo | H279: DIRECCIÓN REGIONAL DEL TRABAJO Y SERVICIO PÚBLICO DE LOJA | I279: Yajaira Katherine Lozada Bravo | J279: 45012 | K279: 45012 | L279: =+NETWORKDAYS(D279,K279,$R$6:$R$416)-1 -> 1 | M279: MDT-DRTSPL-2023-1918-O | N279: LOJA | O279: Nuvia Piedad Apolo Pinza | P279: lauravalarzobravo@hotmail.com | Q279: =IF(L279>15,"FUERA DE TIEMPO","DENTRO DEL TIEMPO") -> DENTRO DEL TIEMPO
... A416: 411 | B416: MDT-DPTSPOP-2023-0036-E | C416: 44958 | D416: 45009 | E416: 2 | F416: ATENDIDO | G416: Andrea Karlina Aguilar Salazar | H416: DELEGACIÓN PROVINCIAL DE TRABAJO Y SERVICIO PÚBLICO DE ZAMORA CHINCHIPE | I416: Andrea Karlina Aguilar Salazar | J416: 45009 | K416: 45009 | L416: =+NETWORKDAYS(D416,K416,$R$6:$R$416)-1 -> 0 | M416: MDT-DPTSPOP-2023-008-O | N416: LOJA | O416: Angel Medardo Gualsaqui Enriquez | P416: N/A | Q416: =IF(L416>15,"FUERA DE TIEMPO","DENTRO DEL TIEMPO") -> DENTRO DEL TIEMPO
A417: 412 | B417: MDT-DPTSPZCH-2023-0177-E | C417: 44985 | D417: 44986 | E417: 2 | F417: ATENDIDO | G417: MARLENE REY | H417: DELEGACIÓN PROVINCIAL DE TRABAJO Y SERVICIO PÚBLICO DE ZAMORA CHINCHIPE | I417: MARLENE REY | J417: 44986 | K417: 44986 | L417: =+NETWORKDAYS(D417,K417,$R$6:$R$416)-1 -> 0 | M417: MDT-DPTSPZCH-2023-0062-O | N417: ZAMORA | O417: USUARIO EXTERNO | P417: FIRMA ELECTRONICA | Q417: DENTRO DEL TIEMPO
A418: 413 | B418: MDT-DPTSPZCH-2023-0182-E | C418: 44987 | D418: 44987 | E418: 2 | F418: ATENDIDO | G418: MARLENE REY | H418: DELEGACIÓN PROVINCIAL DE TRABAJO Y SERVICIO PÚBLICO DE ZAMORA CHINCHIPE | I418: MARLENE REY | J418: 44987 | K418: 44987 | L418: =+NETWORKDAYS(D418,K418,$R$6:$R$416)-1 -> 0 | M418: MDT-DPTSPZCH-2023-0063-O | N418: ZAMORA | O418: USUARIO EXTERNO | P418: FIRMA ELECTRONICA | Q418: DENTRO DEL TIEMPO
A419: 414 | B419: MDT-DPTSPZCH-2023-0184-E | C419: 44987 | D419: 44987 | E419: 2 | F419: ATENDIDO | G419: MARLENE REY | H419: DELEGACIÓN PROVINCIAL DE TRABAJO Y SERVICIO PÚBLICO DE ZAMORA CHINCHIPE | I419: MARLENE REY | J419: 44987 | K419: 44987 | L419: =+NETWORKDAYS(D419,K419,$R$6:$R$416)-1 -> 0 | M419: MDT-DPTSPZCH-2023-0064-O | N419: ZAMORA | O419: UNIDAD JUDICIAL | P419: FIRMA ELECTRONICA | Q419: DENTRO DEL TIEMPO
A420: 415 | B420: MDT-DPTSPZCH-2023-0185-E | C420: 44987 | D420: 44987 | E420: 2 | F420: ATENDIDO | G420: MARLENE REY | H420: DELEGACIÓN PROVINCIAL DE TRABAJO Y SERVICIO PÚBLICO DE ZAMORA CHINCHIPE | I420: MARLENE REY | J420: 44987 | K420: 44987 | L420: =+NETWORKDAYS(D420,K420,$R$6:$R$416)-1 -> 0 | M420: MDT-DPTSPZCH-2023-0065-O | N420: ZAMORA | O420: UNIDAD JUDICIAL | P420: FIRMA ELECTRONICA | Q420: DENTRO DEL TIEMPO
A421: 416 | B421: MDT-DPTSPZCH-2023-0187-E | C421: 44987 | D421: 44987 | E421: 2 | F421: ATENDIDO | G421: MARLENE REY | H421: DELEGACIÓN PROVINCIAL DE TRABAJO Y SERVICIO PÚBLICO DE ZAMORA CHINCHIPE | I421: MARLENE REY | J421: 44987 | K421: 44987 | L421: =+NETWORKDAYS(D421,K421,$R$6:$R$416)-1 -> 0 | M421: MDT-DPTSPZCH-2023-0066-O | N421: ZAMORA | O421: USUARIO EXTERNO | P421: FIRMA ELECTRONICA | Q421: DENTRO DEL TIEMPO
A422: 417 | B422: MDT-DPTSPZCH-2023-0198-E | C422: 44988 | D422: 44988 | E422: 2 | F422: ATENDIDO | G422: MARLENE REY | H422: DELEGACIÓN PROVINCIAL DE TRABAJO Y SERVICIO PÚBLICO DE ZAMORA CHINCHIPE | I422: MARLENE REY | J422: 44988 | K422: 44988 | L422: =+NETWORKDAYS(D422,K422,$R$6:$R$416)-1 -> 0 | M422: MDT-DPTSPZCH-2023-0067-O | N422: ZAMORA | O422: USUARIO EXTERNO | P422: FIRMA ELECTRONICA | Q422: DENTRO DEL TIEMPO
...

Sheet ABR2023
A1: MINISTERIO DEL TRABAJO
A2: DIRECCIÓN REGIONAL DE TRABAJO Y SERVICIO PÚBLICO DE LOJA
A3: SOLICITUDES DE CERTIFICACIÓN DE DOCUMENTOS
A5: NÚMERO | B5: No. DE EXTERNO | C5: FECHA DE INGRESO AL MDT | D5: FECHA DE INGRESO A LA DSG | E5: CANTIDAD DE FOJAS DESPACHADAS | F5: ESTADO | G5: FUNCIONARIO ACTUAL | H5: DIRECCIÓN O UNIDAD | I5: TECN. CETIFI RESPONSABLE | J5: FECHA RESOLUCIÓN | K5: FECHA DE NOTIFICACIÓN | L5: TIEMPO DE RESPUESTA HASTA LA NOTIFICACIÓN | M5: NUMERO DE OFICIO DE RESPUESTA | N5: CUIDAD A LA QUE SE DEBE ENVIAR LA RESPUESTA | O5: NOTIFICADO / O ENTREGADO A: | P5: NUMERO DE GUÍA O CÉDULA | Q5: CUMPLE EN EL PLAZO ESTABLECIDO | R5: FERIADO
A6: 1 | B6: MDT-DPTSPOM-2023-1440-E | C6: 45019 | D6: 45036 | E6: 23 | F6: ATENDIDO | G6: Mayté Del Cisne Elizalde Vivanco | H6: DIRECCIÓN REGIONAL DEL TRABAJO Y SERVICIO PÚBLICO DE LOJA | I6: Mayté Del Cisne Elizalde Vivanco | J6: 45041 | K6: 45041 | L6: =+NETWORKDAYS(D6,K6,$R$6:$R$405)-1 -> 3 | M6: MDT-DRTSPL-2023-1119-M / MDT-DRTSPL-2023-3497-O | N6: LOJA | O6: Marco Rodrigo Troya | P6: N/A | Q6: =IF(L6>15,"FUERA DE TIEMPO","DENTRO DEL TIEMPO") -> DENTRO DEL TIEMPO
A7: 2 | B7: MDT-DRTSPL-2023-1915-E | C7: 45007 | D7: 45028 | E7: 76 | F7: ATENDIDO | G7: Mayté Del Cisne Elizalde Vivanco | H7: DIRECCIÓN REGIONAL DEL TRABAJO Y SERVICIO PÚBLICO DE LOJA | I7: Mayté Del Cisne Elizalde Vivanco | J7: 45030 | K7: 45030 | L7: =+NETWORKDAYS(D7,K7,$R$6:$R$405)-1 -> 2 | M7: MDT-DRTSPL-2023-3252-O | N7: LOJA | O7: Oswaldo Santiago Quiroga Acaro | P7: N/A | Q7: =IF(L7>15,"FUERA DE TIEMPO","DENTRO DEL TIEMPO") -> DENTRO DEL TIEMPO
A8: 3 | B8: MDT-DRTSPL-2023-2162-E | C8: 45016 | D8: 45019 | E8: 2 | F8: ATENDIDO | G8: Andrea Jhovanna Procel Moreno | H8: DIRECCIÓN REGIONAL DEL TRABAJO Y SERVICIO PÚBLICO DE LOJA | I8: Andrea Jhovanna Procel Moreno | J8: 45019 | K8: 45019 | L8: =+NETWORKDAYS(D8,K8,$R$6:$R$405)-1 -> 0 | M8: MDT-DRTSPL-2023-0885-M / MDT-DRTSPL-2023-2185-O | N8: LOJA | O8: Franco Rómulo Carrión Paz | P8: N/A | Q8: =IF(L8>15,"FUERA DE TIEMPO","DENTRO DEL TIEMPO") -> DENTRO DEL TIEMPO
A9: 4 | B9: MDT-DRTSPL-2023-2205-E | C9: 45019 | D9: 45019 | E9: 2 | F9: ATENDIDO | G9: Yajaira Katherine Lozada Bravo | H9: DIRECCIÓN REGIONAL DEL TRABAJO Y SERVICIO PÚBLICO DE LOJA | I9: Yajaira Katherine Lozada Bravo | J9: 45021.47 | K9: 45021.47 | L9: =+NETWORKDAYS(D9,K9,$R$6:$R$405)-1 -> 2 | M9: MDT-DRTSPL-2023-2918-O | N9: LOJA | O9: Carlos Rodrigo Tapia Muñoz | P9: N/A | Q9: =IF(L9>15,"FUERA DE TIEMPO","DENTRO DEL TIEMPO") -> DENTRO DEL TIEMPO
A10: 5 | B10: MDT-DRTSPL-2023-2208-E | C10: 45019 | D10: 45019 | E10: 2 | F10: ATENDIDO | G10: Yajaira Katherine Lozada Bravo | H10: DIRECCIÓN REGIONAL DEL TRABAJO Y SERVICIO PÚBLICO DE LOJA | I10: Yajaira Katherine Lozada Bravo | J10: 45021.546 | K10: 45021.546 | L10: =+NETWORKDAYS(D10,K10,$R$6:$R$405)-1 -> 2 | M10: MDT-DRTSPL-2023-2953-O | N10: LOJA | O10: Miltón Ilidio Roa Salazar | P10: N/A | Q10: =IF(L10>15,"FUERA DE TIEMPO","DENTRO DEL TIEMPO") -> DENTRO DEL TIEMPO
A11: 6 | B11: MDT-DRTSPL-2023-2209-E | C11: 45019 | D11: 45019 | E11: 2 | F11: ATENDIDO | G11: Yajaira Katherine Lozada Bravo | H11: DIRECCIÓN REGIONAL DEL TRABAJO Y SERVICIO PÚBLICO DE LOJA | I11: Yajaira Katherine Lozada Bravo | J11: 45021.554 | K11: 45021.554 | L11: =+NETWORKDAYS(D11,K11,$R$6:$R$405)-1 -> 2 | M11: MDT-DRTSPL-2023-2954-O | N11: LOJA | O11: Angel Rodrigo Cajas Encalada | P11: N/A | Q11: =IF(L11>15,"FUERA DE TIEMPO","DENTRO DEL TIEMPO") -> DENTRO DEL TIEMPO
A12: 7 | B12: MDT-DRTSPL-2023-2210-E | C12: 45019 | D12: 45019 | E12: 2 | F12: ATENDIDO | G12: Yajaira Katherine Lozada Bravo | H12: DIRECCIÓN REGIONAL DEL TRABAJO Y SERVICIO PÚBLICO DE LOJA | I12: Yajaira Katherine Lozada Bravo | J12: 45021.56 | K12: 45021.56 | L12: =+NETWORKDAYS(D12,K12,$R$6:$R$405)-1 -> 2 | M12: MDT-DRTSPL-2023-2955-O | N12: LOJA | O12: Angel Rodrigo Cajas Encalada | P12: N/A | Q12: =IF(L12>15,"FUERA DE TIEMPO","DENTRO DEL TIEMPO") -> DENTRO DEL TIEMPO
A13: 8 | B13: MDT-DRTSPL-2023-2211-E | C13: 45019 | D13: 45019 | E13: 2 | F13: ATENDIDO | G13: Yajaira Katherine Lozada Bravo | H13: DIRECCIÓN REGIONAL DEL TRABAJO Y SERVICIO PÚBLICO DE LOJA | I13: Yajaira Katherine Lozada Bravo | J13: 45021.595 | K13: 45021.595 | L13: =+NETWORKDAYS(D13,K13,$R$6:$R$405)-1 -> 2 | M13: MDT-DRTSPL-2023-2977-O | N13: LOJA | O13: René Fabricio Agila Guamán | P13: N/A | Q13: =IF(L13>15,"FUERA DE TIEMPO","DENTRO DEL TIEMPO") -> DENTRO DEL TIEMPO
A14: 9 | B14: MDT-DRTSPL-2023-2213-E | C14: 45019 | D14: 45019 | E14: 21 | F14: ATENDIDO | G14: Mayté Del Cisne Elizalde Vivanco | H14: DIRECCIÓN REGIONAL DEL TRABAJO Y SERVICIO PÚBLICO DE LOJA | I14: Mayté Del Cisne Elizalde Vivanco | J14: 45033.46 | K14: 45033.46 | L14: =+NETWORKDAYS(D14,K14,$R$6:$R$405)-1 -> 10 | M14: MDT-DRTSPL-2023-3306-O | N14: LOJA | O14: Tania Elizabeth Jimenez Cumbicus | P14: N/A | Q14: =IF(L14>15,"FUERA DE TIEMPO","DENTRO DEL TIEMPO") -> DENTRO DEL TIEMPO
A15: 10 | B15: MDT-DRTSPL-2023-2216-E | C15: 45019 | D15: 45019 | E15: 2 | F15: ATENDIDO | G15: Yajaira Katherine Lozada Bravo | H15: DIRECCIÓN REGIONAL DEL TRABAJO Y SERVICIO PÚBLICO DE LOJA | I15: Yajaira Katherine Lozada Bravo | J15: 45041.46 | K15: 45041.46 | L15: =+NETWORKDAYS(D15,K15,$R$6:$R$405)-1 -> 16 | M15: MDT-DRTSPL-2023-2978-O | N15: LOJA | O15: Edgar Cristóbal Flores Criollo | P15: N/A | Q15: =IF(L15>15,"FUERA DE TIEMPO","DENTRO DEL TIEMPO") -> FUERA DE TIEMPO
A16: 11 | B16: MDT-DRTSPL-2023-2218-E | C16: 45019 | D16: 45019 | E16: 2 | F16: ATENDIDO | G16: Yajaira Katherine Lozada Bravo | H16: DIRECCIÓN REGIONAL DEL TRABAJO Y SERVICIO PÚBLICO DE LOJA | I16: Yajaira Katherine Lozada Bravo | J16: 45021.626 | K16: 45021.626 | L16: =+NETWORKDAYS(D16,K16,$R$6:$R$405)-1 -> 2 | M16: MDT-DRTSPL-2023-2979-O | N16: LOJA | O16: Johanna Michelle Canchingre Campoverde | P16: N/A | Q16: =IF(L16>15,"FUERA DE TIEMPO","DENTRO DEL TIEMPO") -> DENTRO DEL TIEMPO
A17: 12 | B17: MDT-DRTSPL-2023-2219-E | C17: 45019 | D17: 45019 | E17: 46 | F17: ATENDIDO | G17: Mayté Del Cisne Elizalde Vivanco | H17: DIRECCIÓN REGIONAL DEL TRABAJO Y SERVICIO PÚBLICO DE LOJA | I17: Mayté Del Cisne Elizalde Vivanco | J17: 45022.407 | K17: 45022.407 | L17: =+NETWORKDAYS(D17,K17,$R$6:$R$405)-1 -> 3 | M17: MDT-DRTSPL-2023-3006-O | N17: LOJA | O17: Fernando Hermel Sigcho Vasquez | P17: N/A | Q17: =IF(L17>15,"FUERA DE TIEMPO","DENTRO DEL TIEMPO") -> DENTRO DEL TIEMPO
... A324: 319 | B324: MDT-DRTSPL-2023-1192-M | C324: 45042.422 | D324: 45042.422 | E324: 40 | F324: ATENDIDO | G324: Mayté Del Cisne Elizalde Vivanco | H324: DIRECCIÓN REGIONAL DEL TRABAJO Y SERVICIO PÚBLICO DE LOJA | I324: Mayté Del Cisne Elizalde Vivanco | J324: 45042.422 | K324: 45042.422 | L324: =+NETWORKDAYS(D324,K324,$R$6:$R$405)-1 -> 0 | M324: MDT-DRTSPL-2023-1218-M | N324: LOJA | O324: Sandra Maritza Torres Guarnizo | P324: N/A | Q324: =IF(L324>15,"FUERA DE TIEMPO","DENTRO DEL TIEMPO") -> DENTRO DEL TIEMPO
A325: 320 | B325: MDT-DPTSPZCH-2023-0281-E | C325: 45019 | D325: 45019 | E325: 2 | F325: ATENDIDO | G325: MARLENE REY | H325: DELEGACIÓN PROVINCIAL DE TRABAJO Y SERVICIO PÚBLICO DE ZAMORA CHINCHIPE | I325: MARLENE REY | J325: 45019 | K325: 45019 | L325: 0 | M325: MDT-DPTSPZCH-2023-0095-O | N325: ZAMORA | O325: www.funcionjudicial.gob.ec | P325: FIRMA ELECTRONICA | Q325: =IF(L325>15,"FUERA DE TIEMPO","DENTRO DEL TIEMPO") -> DENTRO DEL TIEMPO
A326: 321 | B326: MDT-DPTSPZCH-2023-0285-E | C326: 45020 | D326: 45021 | E326: 107 | F326: ATENDIDO | G326: MARLENE REY | H326: DELEGACIÓN PROVINCIAL DE TRABAJO Y SERVICIO PÚBLICO DE ZAMORA CHINCHIPE | I326: MARLENE REY | J326: 45021 | K326: 45021 | L326: 1 | M326: MDT-DPTSPZCH-2023-0096-O | N326: ZAMORA | O326: www.fiscalia.gob.ec | P326: FIRMA ELECTRONICA | Q326: =IF(L326>15,"FUERA DE TIEMPO","DENTRO DEL TIEMPO") -> DENTRO DEL TIEMPO
A327: 322 | B327: MDT-DPTSPZCH-2023-0287-E | C327: 45021 | D327: 45022 | E327: 2 | F327: ATENDIDO | G327: MARLENE REY | H327: DELEGACIÓN PROVINCIAL DE TRABAJO Y SERVICIO PÚBLICO DE ZAMORA CHINCHIPE | I327: MARLENE REY | J327: 45022 | K327: 45022 | L327: 1 | M327: MDT-DPTSPZCH-2023-0097-O | N327: ZAMORA | O327: dariosaca@gmail.com | P327: FIRMA ELECTRONICA | Q327: =IF(L327>15,"FUERA DE TIEMPO","DENTRO DEL TIEMPO") -> DENTRO DEL TIEMPO
A328: 323 | B328: MDT-DPTSPZCH-2023-0289-E | C328: 45021 | D328: 45022 | E328: 2 | F328: ATENDIDO | G328: MARLENE REY | H328: DELEGACIÓN PROVINCIAL DE TRABAJO Y SERVICIO PÚBLICO DE ZAMORA CHINCHIPE | I328: MARLENE REY | J328: 45022 | K328: 45022 | L328: 1 | M328: MDT-DPTSPZCH-2023-0098-O | N328: ZAMORA | O328: herman_e69@hotmail.com | P328: FIRMA ELECTRONICA | Q328: =IF(L328>15,"FUERA DE TIEMPO","DENTRO DEL TIEMPO") -> DENTRO DEL TIEMPO
A329: 324 | B329: MDT-DPTSPZCH-2023-0291-E | C329: 45022 | D329: 45022 | E329: 2 | F329: ATENDIDO | G329: MARLENE REY | H329: DELEGACIÓN PROVINCIAL DE TRABAJO Y SERVICIO PÚBLICO DE ZAMORA CHINCHIPE | I329: MARLENE REY | J329: 45022 | K329: 45022 | L329: 0 | M329: MDT-DPTSPZCH-2023-0099-O | N329: ZAMORA | O329: www.fiscalia.gob.ec | P329: FIRMA ELECTRONICA | Q329: =IF(L329>15,"FUERA DE TIEMPO","DENTRO DEL TIEMPO") -> DENTRO DEL TIEMPO
A330: 325 | B330: MDT-DPTSPZCH-2023-0292-E | C330: 45022 | D330: 45022 | E330: 2 | F330: ATENDIDO | G330: MARLENE REY | H330: DELEGACIÓN PROVINCIAL DE TRABAJO Y SERVICIO PÚBLICO DE ZAMORA CHINCHIPE | I330: MARLENE REY | J330: 45022 | K330: 45022 | L330: 0 | M330: MDT-DPTSPZCH-2023-0100-O | N330: ZAMORA | O330: www.funcionjudicial.gob.ec | P330: FIRMA ELECTRONICA | Q330: =IF(L330>15,"FUERA DE TIEMPO","DENTRO DEL TIEMPO") -> DENTRO DEL TIEMPO
A331: 326 | B331: MDT-DPTSPZCH-2023-0283-E | C331: 45020 | D331: 45025 | E331: 2 | F331: ATENDIDO | G331: MARLENE REY | H331: DELEGACIÓN PROVINCIAL DE TRABAJO Y SERVICIO PÚBLICO DE ZAMORA CHINCHIPE | I331: MARLENE REY | J331: 45026 | K331: 45026 | L331: 5 | M331: MDT-DPTSPZCH-2023-0101-O | N331: ZAMORA | O331: www.fiscalia.gob.ec | P331: FIRMA ELECTRONICA | Q331: =IF(L331>15,"FUERA DE TIEMPO","DENTRO DEL TIEMPO") -> DENTRO DEL TIEMPO
A332: 327 | B332: MDT-DPTSPZCH-2023-0293-E | C332: 45026 | D332: 45026 | E332: 2 | F332: ATENDIDO | G332: MARLENE REY | H332: DELEGACIÓN PROVINCIAL DE TRABAJO Y SERVICIO PÚBLICO DE ZAMORA CHINCHIPE | I332: MARLENE REY | J332: 45026 | K332: 45026 | L332: 0 | M332: MDT-DPTSPZCH-2023-0102-O | N332: ZAMORA | O332: www.funcionjudicial.gob.ec | P332: FIRMA ELECTRONICA | Q332: =IF(L332>15,"FUERA DE TIEMPO","DENTRO DEL TIEMPO") -> DENTRO DEL TIEMPO
A333: 328 | B333: MDT-DPTSPZCH-2023-0297-E | C333: 45027 | D333: 45027 | E333: 6 | F333: ATENDIDO | G333: MARLENE REY | H333: DELEGACIÓN PROVINCIAL DE TRABAJO Y SERVICIO PÚBLICO DE ZAMORA CHINCHIPE | I333: MARLENE REY | J333: 45027 | K333: 45027 | L333: 0 | M333: MDT-DPTSPZCH-2023-0103-O | N333: ZAMORA | O333: mnueltipan19672020@gmail.com | P333: FIRMA ELECTRONICA | Q333: =IF(L333>15,"FUERA DE TIEMPO","DENTRO DEL TIEMPO") -> DENTRO DEL TIEMPO
A334: 329 | B334: MDT-DPTSPZCH-2023-0303-E | C334: 45028 | D334: 45029 | E334: 2 | F334: ATENDIDO | G334: MARLENE REY | H334: DELEGACIÓN PROVINCIAL DE TRABAJO Y SERVICIO PÚBLICO DE ZAMORA CHINCHIPE | I334: MARLENE REY | J334: 45029 | K334: 45029 | L334: 0 | M334: MDT-DPTSPZCH-2023-0104-O | N334: ZAMORA | O334: stalinleon81@gmail.com | P334: FIRMA ELECTRONICA | Q334: =IF(L334>15,"FUERA DE TIEMPO","DENTRO DEL TIEMPO") -> DENTRO DEL TIEMPO
A335: 330 | B335: MDT-DPTSPZCH-2023-0307-E | C335: 45029 | D335: 45030 | E335: 2 | F335: ATENDIDO | G335: MARLENE REY | H335: DELEGACIÓN PROVINCIAL DE TRABAJO Y SERVICIO PÚBLICO DE ZAMORA CHINCHIPE | I335: MARLENE REY | J335: 45030 | K335: 45030 | L335: 0 | M335: MDT-DPTSPZCH-2023-0105-O | N335: ZAMORA | O335: vargasbm@fiscalia.gob.ec | P335: FIRMA ELECTRONICA | Q335: =IF(L335>15,"FUERA DE TIEMPO","DENTRO DEL TIEMPO") -> DENTRO DEL TIEMPO
A336: 331 | B336: MDT-DPTSPZCH-2023-0311-E | C336: 45033 | D336: 45033 | E336: 2 | F336: ATENDIDO | G336: MARLENE REY | H336: DELEGACIÓN PROVINCIAL DE TRABAJO Y SERVICIO PÚBLICO DE ZAMORA CHINCHIPE | I336: MARLENE REY | J336: 45033 | K336: 45033 | L336: 0 | M336: MDT-DPTSPZCH-2023-0106-O | N336: ZAMORA | O336: guevarasm@fiscalia.ob.ec | P336: FIRMA ELECTRONICA | Q336: =IF(L336>15,"FUERA DE TIEMPO","DENTRO DEL TIEMPO") -> DENTRO DEL TIEMPO
A337: 332 | B337: MDT-DPTSPZCH-2023-0312-E | C337: 45033 | D337: 45033 | E337: 2 | F337: ATENDIDO | G337: MARLENE REY | H337: DELEGACIÓN PROVINCIAL DE TRABAJO Y SERVICIO PÚBLICO DE ZAMORA CHINCHIPE | I337: MARLENE REY | J337: 17/042023 | K337: 45033 | L337: 0 | M337: MDT-DPTSPZCH-2023-0107-O | N337: ZAMORA | O337: vargasbm@fiscalia.gob.ec | P337: FIRMA ELECTRONICA | Q337: =IF(L337>15,"FUERA DE TIEMPO","DENTRO DEL TIEMPO") -> DENTRO DEL TIEMPO
A338: 333 | B338: MDT-DPTSPZCH-2023-0318-E | C338: 45034 | D338: 45034 | E338: 5 | F338: ATENDIDO | G338: MARLENE REY | H338: DELEGACIÓN PROVINCIAL DE TRABAJO Y SERVICIO PÚBLICO DE ZAMORA CHINCHIPE | I338: MARLENE REY | J338: 45034 | K338: 45034 | L338: 0 | M338: MDT-DPTSPZCH-2023-0108-O | N338: ZAMORA | O338: angelitoacaro16julio@gmail.com | P338: FIRMA ELECTRONICA | Q338: =IF(L338>15,"FUERA DE TIEMPO","DENTRO DEL TIEMPO") -> DENTRO DEL TIEMPO
A339: 334 | B339: MDT-DPTSPZCH-2023-0324-E | C339: 45035 | D339: 45035 | E339: 2 | F339: ATENDIDO | G339: MARLENE REY | H339: DELEGACIÓN PROVINCIAL DE TRABAJO Y SERVICIO PÚBLICO DE ZAMORA CHINCHIPE | I339: MARLENE REY | J339: 45035 | K339: 45035 | L339: 0 | M339: MDT-DPTSPZCH-2023-0109-O | N339: ZAMORA | O339: guevarasm@fiscalia.ob.ec | P339: FIRMA ELECTRONICA | Q339: =IF(L339>15,"FUERA DE TIEMPO","DENTRO DEL TIEMPO") -> DENTRO DEL TIEMPO
A340: 335 | B340: MDT-DPTSPZCH-2023-0327-E | C340: 45035 | D340: 45035 | E340: 2 | F340: ATENDIDO | G340: MARLENE REY | H340: DELEGACIÓN PROVINCIAL DE TRABAJO Y SERVICIO PÚBLICO DE ZAMORA CHINCHIPE | I340: MARLENE REY | J340: 45035 | K340: 19/042023 | L340: 0 | M340: MDT-DPTSPZCH-2023-0110-O | N340: ZAMORA | O340: michesita46@hotmail.com | P340: FIRMA ELECTRONICA | Q340: =IF(L340>15,"FUERA DE TIEMPO","DENTRO DEL TIEMPO") -> DENTRO DEL TIEMPO
A341: 336 | B341: MDT-DPTSPZCH-2023-0331-E | C341: 45036 | D341: 45036 | E341: 2 | F341: ATENDIDO | G341: MARLENE REY | H341: DELEGACIÓN PROVINCIAL DE TRABAJO Y SERVICIO PÚBLICO DE ZAMORA CHINCHIPE | I341: MARLENE REY | J341: 45036 | K341: 45036 | L341: 0 | M341: MDT-DPTSPZCH-2023-0111-O | N341: ZAMORA | O341: joseguayanay1977@gmail.com | P341: FIRMA ELECTRONICA | Q341: =IF(L341>15,"FUERA DE TIEMPO","DENTRO DEL TIEMPO") -> DENTRO DEL TIEMPO
A342: 337 | B342: MDT-DPTSPZCH-2023-0333-E | C342: 45036 | D342: 45036 | E342: 2 | F342: ATENDIDO | G342: MARLENE REY | H342: DELEGACIÓN PROVINCIAL DE TRABAJO Y SERVICIO PÚBLICO DE ZAMORA CHINCHIPE | I342: MARLENE REY | J342: 45036 | K342: 45036 | L342: 0 | M342: MDT-DPTSPZCH-2023-0112-O | N342: ZAMORA | O342: megrada@utpl.edi.ec | P342: FIRMA ELECTRONICA | Q342: =IF(L342>15,"FUERA DE TIEMPO","DENTRO DEL TIEMPO") -> DENTRO DEL TIEMPO
A343: 338 | B343: MDT-DPTSPZCH-2023-0336-E | C343: 45036 | D343: 45036 | E343: 2 | F343: ATENDIDO | G343: MARLENE REY | H343: DELEGACIÓN PROVINCIAL DE TRABAJO Y SERVICIO PÚBLICO DE ZAMORA CHINCHIPE | I343: MARLENE REY | J343: 45036 | K343: 45036 | L343: 0 | M343: MDT-DPTSPZCH-2023-0113-O | N343: ZAMORA | O343: edwin2@hotmail.es | P343: FIRMA ELECTRONICA | Q343: =IF(L343>15,"FUERA DE TIEMPO","DENTRO DEL TIEMPO") -> DENTRO DEL TIEMPO
A344: 339 | B344: MDT-DPTSPZCH-2022-0341-E | C344: 45040 | D344: 45040 | E344: 2 | F344: ATENDIDO | G344: MARLENE REY | H344: DELEGACIÓN PROVINCIAL DE TRABAJO Y SERVICIO PÚBLICO DE ZAMORA CHINCHIPE | I344: MARLENE REY | J344: 45040 | K344: 45040 | L344: 0 | M344: MDT-DPTSPZCH-2023-0114-O | N344: ZAMORA | O344: angelrolandoarmijosgranda@gmail.cin | P344: FIRMA ELECTRONICA | Q344: =IF(L344>15,"FUERA DE TIEMPO","DENTRO DEL TIEMPO") -> DENTRO DEL TIEMPO
A345: 340 | B345: MDT-DPTSPZCH-2022-0343-E | C345: 45040 | D345: 45040 | E345: 2 | F345: ATENDIDO | G345: MARLENE REY | H345: DELEGACIÓN PROVINCIAL DE TRABAJO Y SERVICIO PÚBLICO DE ZAMORA CHINCHIPE | I345: MARLENE REY | J345: 45040 | K345: 45040 | L345: 0 | M345: MDT-DPTSPZCH-2023-0115-O | N345: ZAMORA | O345: ama_santi_ak@hotmail.com | P345: FIRMA ELECTRONICA | Q345: =IF(L345>15,"FUERA DE TIEMPO","DENTRO DEL TIEMPO") -> DENTRO DEL TIEMPO
A346: 341 | B346: MDT-DPTSPZCH-2022-0344-E | C346: 45040 | D346: 45040 | E346: 2 | F346: ATENDIDO | G346: MARLENE REY | H346: DELEGACIÓN PROVINCIAL DE TRABAJO Y SERVICIO PÚBLICO DE ZAMORA CHINCHIPE | I346: MARLENE REY | J346: 45041 | K346: 45070 | L346: 0 | M346: MDT-DPTSPZCH-2023-0116-O | N346: ZAMORA | O346: ana.solano@funcionjudicial.gob.ec | P346: FIRMA ELECTRONICA | Q346: =IF(L346>15,"FUERA DE TIEMPO","DENTRO DEL TIEMPO") -> DENTRO DEL TIEMPO
A347: 342 | B347: MDT-DPTSPZCH-2022-0345-E | C347: 45041 | D347: 45041 | E347: 2 | F347: ATENDIDO | G347: MARLENE REY | H347: DELEGACIÓN PROVINCIAL DE TRABAJO Y SERVICIO PÚBLICO DE ZAMORA CHINCHIPE | I347: MARLENE REY | J347: 45041 | K347: 45041 | L347: 0 | M347: MDT-DPTSPZCH-2023-0117-O | N347: ZAMORA | O347: alexey.zozoranga@funcionjudicial.gob.ec | P347: FIRMA ELECTRONICA | Q347: =IF(L347>15,"FUERA DE TIEMPO","DENTRO DEL TIEMPO") -> DENTRO DEL TIEMPO
...

